File: demonstration_data/squid/000_MA2936-3_211005_Qrod_IP_buchner_standard_001_MH_300K.dat
[Header]
; MPMS3 Data File (default extension .dat)
; Copyright (c) 2007, Quantum Design, Inc. All rights reserved.
TITLE,
FILEOPENTIME,3842600357.39223,10/05/2021,2:02 pm
BYAPP,MPMS3 w/ AC,1.0,1.1
INFO,MPMS3 Measurement Release 1.1.16 Build 424, MultiVu Release 2.3.4.19,APPNAME
INFO,Linear Motor Servo Controller,MOTOR_MODULE_NAME
INFO,3101-100 J0,MOTOR_HW_VERSION
INFO,MMC714,MOTOR_SERIAL_NUMBER
INFO,01.04.28,MOTOR_SOFTWARE_VERSION
INFO,Quantum Design Squid Module,SQUID_MODULE_NAME
INFO,3101-501 B0,SQUID_HW_VERSION
INFO,SQM189,SQUID_SERIAL_NUMBER
INFO,01.03.04,SQUID_SOFTWARE_VERSION
INFO,Quantum Design VSM Oven,OVEN_MODULE_NAME
INFO,3101-201 A1,OVEN_HW_VERSION
INFO,OVB229,OVEN_SERIAL_NUMBER
INFO,01.07.07,OVEN_SOFTWARE_VERSION
INFO,SQUID AC,AC_MODULE_NAME
INFO,3101-401 F1,AC_HW_VERSION
INFO,SAC108,AC_SERIAL_NUMBER
INFO,SQUID AC 00.95.07,AC_SOFTWARE_VERSION
INFO,TCI177,COIL_SERIAL_NUMBER
INFO,0,MOMENT_UNITS
INFO,A2481,SAMPLE_MATERIAL
INFO,,SAMPLE_COMMENT
INFO,,SAMPLE_MASS
INFO,,SAMPLE_VOLUME
INFO,,SAMPLE_MOLECULAR_WEIGHT
INFO,5mm x 5mm,SAMPLE_SIZE
INFO,,SAMPLE_SHAPE
INFO,Straw,SAMPLE_HOLDER
INFO,Standard,SAMPLE_HOLDER_DETAIL
INFO,65.98,SAMPLE_OFFSET
DATATYPE,COMMENT,1
DATATYPE,TIME,2
STARTUPAXIS,X,2
STARTUPAXIS,Y1,5
FIELDGROUP, VSM,2,3,4,5,6,8,9,10,11,14,15
FIELDGROUP, DC, 2,3,4,14,56,57,58,59,60,61,62,63,64,65,66,67,68,69
FIELDGROUP, AC, 2,3,4,11,16,17,18,19,20,21,22,23,24,25,26,27,28,29,30
STARTUPGROUP, All
[Data]
Comment,Time Stamp (sec),Temperature (K),Magnetic Field (Oe),Moment (emu),M. Std. Err. (emu),Transport Action,Averaging Time (sec),Frequency (Hz),Peak Amplitude (mm),Center Position (mm),Lockin Signal' (V),Lockin Signal (V),Range,M. Quad. Signal (emu),AC Moment (emu),AC M. Std Err. (emu),AC Phase (deg),AC Phase Std. Err. (deg),AC Susceptibility (emu/Oe),AC Suscept. Std Err. (emu/Oe),AC X' (emu/Oe),AC X' Std Err. (emu/Oe),AC X'' (emu/Oe),AC X'' Std Err. (emu/Oe),AC Drive (Oe),AC Frequency (Hz),AC Averaging Time (sec),AC Cycles,AC Range,AC Measure Type,AC Signal' (V),AC Signal'' (V),AC Trim Coil Ratio,AC Trim Coil Phase,Min. Temperature (K),Max. Temperature (K),Min. Field (Oe),Max. Field (Oe),Mass (grams),Motor Lag (deg),Pressure (Torr),Measure Count,Measurement Number,SQUID Status (code),Motor Status (code),Measure Status (code),Motor Current (amps),Motor Temp. (C),Temp. Status (code),Field Status (code),Chamber Status (code),Chamber Temp (K),Redirection State,Evercool Status,Average Temp (K),Rotation Angle (deg),Rotator state,DC Moment Fixed Ctr (emu),DC Moment Err Fixed Ctr (emu),DC Moment Free Ctr (emu),DC Moment Err Free Ctr (emu),DC Fixed Fit,DC Free Fit,DC Calculated Center (mm),DC Calculated Center Err (mm),DC Scan Length (mm),DC Scan Time (s),DC Number of Points,DC Squid Drift,DC Min V (V),DC Max V (V),DC Scans per Measure,Map 01,Map 02,Map 03,Map 04,Map 05,Map 06,Map 07,Map 08,Map 09,Map 10,Map 11,Map 12,Map 13,Map 14,Map 15,Map 16
,3842600520.58284,299.999206542969,69999.828125,-0.000415030383638286,7.89838896115516E-7,1,10,13.3016452789307,8.00910964756253,32.3100015521049,-0.816438903832088,-0.122393064574207,1,-1.08611871003285E-6,,,,,,,,,,,,,,,,,,,,,299.999206542969,299.999206542969,69999.828125,69999.828125,54.241111092025,5.60531783976765,9.59065818786621,133,1,0,0,1,0.469207763671875,31.2805480957031,1,1,1,299.999206542969,0,742395904,299.999206542969,,,,,,,,,,,,,,,,,,,,,,,,,,,,,,,,,
,3842600587.14118,299.999252319336,55875.296875,-0.000330518431634763,9.82956767835319E-7,1,10,13.3016452789307,8.00903636175388,32.3100015521049,-0.650178936101185,-0.0975144052034229,1,-8.87583907903319E-7,,,,,,,,,,,,,,,,,,,,,299.999176025391,299.999328613281,55875.296875,55875.296875,54.6045683534673,5.60549397498831,9.58353805541992,133,1,0,0,1,0.472793579101562,32.7468223571777,1,1,1,299.999328613281,0,742397024,299.999252319336,,,,,,,,,,,,,,,,,,,,,,,,,,,,,,,,,
,3842600672.11754,299.999771118164,35600.8203125,-0.000209635574754069,5.91266741584603E-7,1,10,13.3016452789307,8.00898908039341,32.3100015521049,-0.412374360233135,-0.0619083611648759,1,-5.92838638220208E-7,,,,,,,,,,,,,,,,,,,,,299.999664306641,299.999877929687,35600.8203125,35600.8203125,54.6999270328135,5.60581938067871,9.59144878387451,133,1,0,0,1,0.472793579101562,33.2355842590332,1,1,1,299.999877929687,0,742397024,299.999771118164,,,,,,,,,,,,,,,,,,,,,,,,,,,,,,,,,
,3842600749.02681,299.999771118164,22682.90625,-0.00013256668715354,2.98591386313568E-7,1,10,13.3016452789307,8.00893248579409,32.3100015521049,-0.260786945726273,-0.039040687271315,1,-3.200195949992E-7,,,,,,,,,,,,,,,,,,,,,299.999450683594,300.000091552734,22682.90625,22682.90625,54.8492180799866,5.60633899595918,9.58509540557861,133,1,0,0,1,0.472946166992188,33.2355842590332,1,1,1,299.999450683594,0,742397056,299.999771118164,,,,,,,,,,,,,,,,,,,,,,,,,,,,,,,,,
,3842600814.35881,300.00032043457,14452.5986328125,-8.34467127513498E-5,1.85108586273255E-7,1,10,13.3016452789307,8.00882486472326,32.3100015521049,-0.164159341420358,-0.0245537846987094,1,-1.90790885384335E-7,,,,,,,,,,,,,,,,,,,,,299.999969482422,300.000671386719,14452.5986328125,14452.5986328125,54.8570343651789,5.60722523251913,9.57722091674805,133,1,0,0,1,0.466384887695313,33.7243423461914,1,1,1,300.000671386719,0,742397152,300.00032043457,,,,,,,,,,,,,,,,,,,,,,,,,,,,,,,,,
,3842600878.75831,299.999847412109,9208.44921875,-5.21975534039487E-5,1.2088755494893E-7,1,10,13.3016452789307,8.00885178790983,32.3100015521049,-0.102695680517672,-0.0152868740582029,1,-8.2742056545494E-8,,,,,,,,,,,,,,,,,,,,,299.999694824219,300,9208.44921875,9208.44921875,54.945358387852,5.60632411332081,9.58975791931152,133,1,0,0,1,0.472869873046875,33.7243423461914,1,1,1,299.999694824219,0,742397088,299.999847412109,,,,,,,,,,,,,,,,,,,,,,,,,,,,,,,,,
,3842600938.13274,299.999954223633,5867.2802734375,-3.22957951332892E-5,8.02872762592806E-8,1,10,13.3016452789307,8.0087681932911,32.3100015521049,-0.0635413881583486,-0.00944714196668029,1,-4.55362798351917E-8,,,,,,,,,,,,,,,,,,,,,299.999572753906,300.000335693359,5867.2802734375,5867.2802734375,54.8929892770635,5.60648222380208,9.58646869659424,133,1,0,0,1,0.465469360351562,33.7243423461914,1,1,1,299.999572753906,0,742397312,299.999954223633,,,,,,,,,,,,,,,,,,,,,,,,,,,,,,,,,
,3842600996.27662,299.999786376953,3738.30639648438,-1.96238015840695E-5,5.62130714968832E-8,1,10,13.3016452789307,8.00871708429548,32.3100015521049,-0.0386127490816123,-0.00571713165945552,1,-1.58859460907881E-8,,,,,,,,,,,,,,,,,,,,,299.999694824219,299.999877929687,3738.30639648438,3738.30639648438,54.9922560990058,5.606842898921,9.58927536010742,133,1,0,0,1,0.472869873046875,34.2131004333496,1,1,1,299.999877929687,0,742397216,299.999786376953,,,,,,,,,,,,,,,,,,,,,,,,,,,,,,,,,
,3842601051.24094,299.999786376953,2381.98046875,-1.15976012335208E-5,4.11809556968861E-8,1,10,13.3016452789307,8.00870842539487,32.3100015521049,-0.0228228998639723,-0.00335905481792833,1,6.47059947595655E-10,,,,,,,,,,,,,,,,,,,,,299.999755859375,299.999816894531,2381.98046875,2381.98046875,54.869149607227,5.60649120589868,9.59064769744873,133,1,0,0,1,0.465927124023438,34.2131004333496,1,1,1,299.999755859375,0,742397216,299.999786376953,,,,,,,,,,,,,,,,,,,,,,,,,,,,,,,,,
,3842601106.6566,300,1517.90222167969,-6.54392693280741E-6,3.09899984396533E-8,1,10,13.3016452789307,8.0086221613643,32.3100015521049,-0.0128799333751488,-0.0018801996735738,1,8.05361706097671E-9,,,,,,,,,,,,,,,,,,,,,299.999542236328,300.000457763672,1517.90222167969,1517.90222167969,54.9211279037558,5.60683886875351,9.58065700531006,133,1,0,0,1,0.465927124023438,33.7243423461914,1,1,1,300.000457763672,0,742397408,300,,,,,,,,,,,,,,,,,,,,,,,,,,,,,,,,,
,3842601162.051,300.000610351562,967.186889648438,-3.44712184495321E-6,2.55750865504139E-8,1,10,13.3016452789307,8.00866957656532,32.3100015521049,-0.00678941162499497,-0.000958703790160748,1,2.03642039766785E-8,,,,,,,,,,,,,,,,,,,,,300,300.001220703125,967.186889648438,967.186889648438,54.8761842639,5.60701209198692,9.58905601501465,133,1,0,0,1,0.465850830078125,34.2131004333496,1,1,1,300,0,742397216,300.000610351562,,,,,,,,,,,,,,,,,,,,,,,,,,,,,,,,,
,3842601218.03086,300.000442504883,616.445007324219,-1.66493856710204E-6,2.30272279413352E-8,1,10,13.3016452789307,8.00869273676333,32.3100015521049,-0.00328777198681877,-0.000405163344985515,1,3.92508964905999E-8,,,,,,,,,,,,,,,,,,,,,300.000335693359,300.000549316406,616.445007324219,616.445007324219,54.98795714215,5.60705881081672,9.58543682098389,133,1,0,0,1,0.465545654296875,34.2131004333496,1,1,1,300.000549316406,0,742397376,300.000442504883,,,,,,,,,,,,,,,,,,,,,,,,,,,,,,,,,
,3842601476.24588,299.999725341797,392.807342529297,-7.15511875454216E-7,2.04379041207397E-8,1,10,13.3016452789307,8.00864188560441,32.3100015521049,-0.00142423125655523,-9.73224555492681E-5,1,5.58935519691548E-8,,,,,,,,,,,,,,,,,,,,,299.999664306641,299.999786376953,392.807342529297,392.807342529297,54.955519558602,5.60649551755641,9.58760452270508,133,1,0,0,1,0.46630859375,34.7018585205078,1,1,1,299.999786376953,0,742397408,299.999725341797,,,,,,,,,,,,,,,,,,,,,,,,,,,,,,,,,
,3842601577.32505,300.000793457031,250.282806396484,-1.9429057538117E-7,1.87738965426085E-8,1,10,13.3016452789307,8.00843543127726,32.3100015521049,-0.00039072249207488,6.81653788997443E-7,1,2.89529911383746E-8,,,,,,,,,,,,,,,,,,,,,300.000793457031,300.000793457031,250.282806396484,250.282806396484,54.9441859450731,5.60712770385317,9.58866786956787,133,1,0,0,1,0.469436645507812,34.7018585205078,1,1,1,300.000793457031,0,742397472,300.000793457031,,,,,,,,,,,,,,,,,,,,,,,,,,,,,,,,,
,3842601713.63086,299.999969482422,159.834060668945,8.0644034972818E-8,1.86260798525974E-8,1,10,13.3016452789307,8.00840040881962,32.3100015521049,0.00015211417212194,6.80583614587444E-5,1,2.27115941618431E-8,,,,,,,,,,,,,,,,,,,,,299.999969482422,299.999969482422,159.834060668945,159.834060668945,55.0086702979097,5.60764806590849,9.596999168396,133,1,0,0,1,0.466079711914063,34.2131004333496,1,1,1,299.999969482422,0,742397408,299.999969482422,,,,,,,,,,,,,,,,,,,,,,,,,,,,,,,,,
,3842601849.08052,300.000518798828,101.980239868164,2.23448954729817E-7,1.75312263634394E-8,1,10,13.3016452789307,8.00830627469925,32.3100015521049,0.000433413425312038,0.000107498997076118,1,2.17285071687406E-8,,,,,,,,,,,,,,,,,,,,,300.000518798828,300.000518798828,101.980239868164,101.980239868164,54.9801408569577,5.60759678508458,9.58948993682861,133,1,0,0,1,0.465469360351562,34.2131004333496,1,1,1,300.000518798828,0,742397216,300.000518798828,,,,,,,,,,,,,,,,,,,,,,,,,,,,,,,,,
,3842601899.53615,299.999710083008,64.9812774658203,2.95957616142277E-7,1.80499578525348E-8,1,10,13.3016452789307,8.00817935189024,32.3100015521049,0.00056512650874355,0.000202987640357674,1,5.95784316461647E-8,,,,,,,,,,,,,,,,,,,,,299.999450683594,299.999969482422,64.9812774658203,64.9812774658203,55.0840974500154,5.60864750371687,9.59220600128174,133,1,0,0,1,0.46722412109375,34.2131004333496,1,1,1,299.999969482422,0,742397280,299.999710083008,,,,,,,,,,,,,,,,,,,,,,,,,,,,,,,,,
,3842602000.07979,300.000610351562,41.5379638671875,3.51081970049116E-7,1.67244942113823E-8,1,10,13.3016452789307,8.00819071798239,32.3100015521049,0.000683060119388499,0.000154716566410049,1,2.69317182768672E-8,,,,,,,,,,,,,,,,,,,,,300.000610351562,300.000610351562,41.5379638671875,41.5379638671875,54.9082310331885,5.60811417508798,9.59917259216309,133,1,0,0,1,0.474929809570313,34.7018585205078,1,1,1,300.000610351562,0,742397184,300.000610351562,,,,,,,,,,,,,,,,,,,,,,,,,,,,,,,,,
,3842602090.09897,299.999588012695,26.608341217041,3.87481160517029E-7,1.69530889032763E-8,1,10,13.3016452789307,8.00820462129031,32.3100015521049,0.00075426712136425,0.00016811852706624,1,2.83829512363608E-8,,,,,,,,,,,,,,,,,,,,,299.999542236328,299.999633789063,26.608341217041,26.608341217041,54.9731062002847,5.60839407381682,9.602219581604,133,1,0,0,1,0.466384887695313,34.7018585205078,1,1,1,299.999633789063,0,742397184,299.999588012695,,,,,,,,,,,,,,,,,,,,,,,,,,,,,,,,,
,3842602144.03563,299.999237060547,17.0519104003906,4.06331221371026E-7,1.64789837799507E-8,1,10,13.3016452789307,8.00815105924835,32.3100015521049,0.000791210618078581,0.000174577521456811,1,2.88901913216685E-8,,,,,,,,,,,,,,,,,,,,,299.999114990234,299.999359130859,17.0519104003906,17.0519104003906,55.0801893074193,5.6081570347813,9.60266971588135,133,1,0,0,1,0.467147827148438,34.7018585205078,1,1,1,299.999114990234,0,742396928,299.999237060547,,,,,,,,,,,,,,,,,,,,,,,,,,,,,,,,,
,3842602197.91669,299.999435424805,11.0040035247803,4.22836788937164E-7,1.72934019720214E-8,1,10,13.3016452789307,8.00812139925714,32.3100015521049,0.000826535657110227,0.00016002320705856,1,1.90639287098951E-8,,,,,,,,,,,,,,,,,,,,,299.999145507812,299.999725341797,11.0040035247803,11.0040035247803,54.9273809319096,5.6077763635173,9.58684539794922,133,1,0,0,1,0.474090576171875,34.7018585205078,1,1,1,299.999725341797,0,742397376,299.999435424805,,,,,,,,,,,,,,,,,,,,,,,,,,,,,,,,,
,3842602251.7704,300.000106811523,7.1397213935852,4.29978862330809E-7,1.64021097103691E-8,1,10,13.3016452789307,8.00803800104318,32.3100015521049,0.000840579561308793,0.000162128346945562,1,1.90826267212448E-8,,,,,,,,,,,,,,,,,,,,,300,300.000213623047,7.1397213935852,7.1397213935852,55.0067162266116,5.608646977288,9.58924293518066,133,1,0,0,1,0.466537475585937,34.2131004333496,1,1,1,300.000213623047,0,742397280,300.000106811523,,,,,,,,,,,,,,,,,,,,,,,,,,,,,,,,,
,3842602303.82359,300.000534057617,4.55126571655273,4.4035016783918E-7,1.67781511440979E-8,1,10,13.3016452789307,8.00802503704431,32.3100015521049,0.000861012424669197,0.000164962734855303,1,1.8996062125012E-8,,,,,,,,,,,,,,,,,,,,,300.000091552734,300.0009765625,4.55126571655273,4.55126571655273,54.9121391757847,5.6087147920408,9.59183979034424,133,1,0,0,1,0.473785400390625,34.7018585205078,1,1,1,300.0009765625,0,742397472,300.000534057617,,,,,,,,,,,,,,,,,,,,,,,,,,,,,,,,,
,3842602353.67589,299.999755859375,3.20183372497559,4.39447029005442E-7,1.66290265396386E-8,1,10,13.3016452789307,8.00795427647216,32.3100015521049,0.000860582810453932,0.000155519146841836,1,1.43303388388362E-8,,,,,,,,,,,,,,,,,,,,,299.999420166016,300.000091552734,3.20183372497559,3.20183372497559,54.9195646467173,5.60883050237315,9.57621574401855,133,1,0,0,1,0.474777221679687,34.2131004333496,1,1,1,299.999420166016,0,742397216,299.999755859375,,,,,,,,,,,,,,,,,,,,,,,,,,,,,,,,,
,3842602404.13461,300.000396728516,2.06095051765442,4.43346094441509E-7,1.69959347414373E-8,1,10,13.3016452789307,8.0079845486469,32.3100015521049,0.000868889903089985,0.000152351499577638,1,1.21463353401155E-8,,,,,,,,,,,,,,,,,,,,,300.000152587891,300.000640869141,2.06095051765442,2.06095051765442,55.0110151834674,5.609185894429,9.58437442779541,133,1,0,0,1,0.466766357421875,34.2131004333496,1,1,1,300.000183105469,0,742397312,300.000396728516,,,,,,,,,,,,,,,,,,,,,,,,,,,,,,,,,
,3842602456.13535,300.000534057617,-0.797391533851624,4.50761943471555E-7,1.65804265017229E-8,1,10,13.3016452789307,8.00802215077213,32.3100015521049,0.000883173004842843,0.000156619449085453,1,1.32231589732303E-8,,,,,,,,,,,,,,,,,,,,,300.000335693359,300.000732421875,-0.797391533851624,-0.797391533851624,54.8261600386693,5.6089932094713,9.58859920501709,133,1,0,0,1,0.470123291015625,34.2131004333496,1,1,1,300.000732421875,0,742397216,300.000534057617,,,,,,,,,,,,,,,,,,,,,,,,,,,,,,,,,
,3842602506.35746,299.999954223633,-1.43530476093292,4.54443371793262E-7,1.60801897207567E-8,1,10,13.3016452789307,8.00788693592252,32.3100015521049,0.000891311440411076,0.000151554850220531,1,1.01080906924538E-8,,,,,,,,,,,,,,,,,,,,,299.999938964844,299.999969482422,-1.43530476093292,-1.43530476093292,54.8847821776116,5.60881139954691,9.5922737121582,133,1,0,0,1,0.470809936523438,34.2131004333496,1,1,1,299.999969482422,0,742397376,299.999954223633,,,,,,,,,,,,,,,,,,,,,,,,,,,,,,,,,
,3842602556.6163,299.999069213867,-2.61299085617065,4.47807882142165E-7,1.63457335494761E-8,1,10,13.3016452789307,8.00776423293572,32.3100015521049,0.000877505009568721,0.000154669492604137,1,1.2668572481707E-8,,,,,,,,,,,,,,,,,,,,,299.998931884766,299.999206542969,-2.61299085617065,-2.61299085617065,54.9023688192943,5.60964582338888,9.58292293548584,133,1,0,0,1,0.4681396484375,34.2131004333496,1,1,1,299.998931884766,0,742397184,299.999069213867,,,,,,,,,,,,,,,,,,,,,,,,,,,,,,,,,
,3842602606.08053,300.000289916992,-4.15870380401611,4.54983412202753E-7,1.62692848827335E-8,1,10,13.3016452789307,8.00771325005438,32.3100015521049,0.000891933991578949,0.00015462566229437,1,1.15900788883909E-8,,,,,,,,,,,,,,,,,,,,,300.000152587891,300.000427246094,-4.15870380401611,-4.15870380401611,55.1036381629962,5.60907314370279,9.59185123443603,133,1,0,0,1,0.47027587890625,34.2131004333496,1,1,1,300.000427246094,0,742397376,300.000289916992,,,,,,,,,,,,,,,,,,,,,,,,,,,,,,,,,
,3842602658.13831,300.000015258789,-6.47727298736572,4.60022844920449E-7,1.65277792602449E-8,1,10,13.3016452789307,8.00777096990772,32.3100015521049,0.000902648444704676,0.000150690132809159,1,8.84776666144004E-9,,,,,,,,,,,,,,,,,,,,,299.999603271484,300.000427246094,-6.47727298736572,-6.47727298736572,54.9797500426981,5.60964794522861,9.58169269561768,133,1,0,0,1,0.468368530273438,34.2131004333496,1,1,1,299.999603271484,0,742397216,300.000015258789,,,,,,,,,,,,,,,,,,,,,,,,,,,,,,,,,
,3842602714.34552,300.000198364258,-10.3660898208618,4.59202643567496E-7,1.67592859848441E-8,1,10,13.3016452789307,8.00777529201113,32.3100015521049,0.000899854150782138,0.000158471022366723,1,1.29227038136383E-8,,,,,,,,,,,,,,,,,,,,,300.000183105469,300.000213623047,-10.3660898208618,-10.3660898208618,55.0626026657366,5.60867130080674,9.56121826171875,133,1,0,0,1,0.465774536132812,34.2131004333496,1,1,1,300.000213623047,0,742397152,300.000198364258,,,,,,,,,,,,,,,,,,,,,,,,,,,,,,,,,
,3842602770.2262,299.999862670898,-16.438533782959,4.73919401004053E-7,1.65569168872321E-8,1,10,13.3016452789307,8.00777983493983,32.3100015521049,0.0009293303734895,0.000159223781401131,1,1.11383868743284E-8,,,,,,,,,,,,,,,,,,,,,299.999694824219,300.000030517578,-16.438533782959,-16.438533782959,54.9293350032077,5.60963057350298,9.55966567993164,133,1,0,0,1,0.474853515625,34.2131004333496,1,1,1,300.000030517578,0,742397056,299.999862670898,,,,,,,,,,,,,,,,,,,,,,,,,,,,,,,,,
,3842602825.30323,299.999877929687,-26.0072326660156,4.80993261988668E-7,1.69113008968545E-8,1,10,13.3016452789307,8.00774923243635,32.3100015521049,0.000941141992817939,0.000175576498048538,1,1.84073886965536E-8,,,,,,,,,,,,,,,,,,,,,299.999755859375,300,-26.0072326660156,-26.0072326660156,54.9566920013808,5.6091464196892,9.55305290222168,133,1,0,0,1,0.474319458007812,34.2131004333496,1,1,1,299.999755859375,0,742397280,299.999877929687,,,,,,,,,,,,,,,,,,,,,,,,,,,,,,,,,
,3842602880.9573,300.00032043457,-40.8509826660156,5.08847725147115E-7,1.60406247603721E-8,1,10,13.3016452789307,8.00773480613069,32.3100015521049,0.000991634894573134,0.000212964996147876,1,3.3306936256491E-8,,,,,,,,,,,,,,,,,,,,,299.999938964844,300.000701904297,-40.8509826660156,-40.8509826660156,54.9176105754193,5.6086538960309,9.54764080047607,133,1,0,0,1,0.473861694335937,34.2131004333496,1,1,1,299.999938964844,0,742397184,300.00032043457,,,,,,,,,,,,,,,,,,,,,,,,,,,,,,,,,
,3842603020.30741,300.000732421875,-64.2820281982422,5.57160586776508E-7,1.73612827419472E-8,1,10,13.3016452789307,8.00755292323853,32.3100015521049,0.00109073225363104,0.000199496940392538,1,1.93504203414698E-8,,,,,,,,,,,,,,,,,,,,,300.000732421875,300.000732421875,-64.2820281982422,-64.2820281982422,54.9844398138135,5.60985432515915,9.568528175354,133,1,0,0,1,0.474319458007812,34.2131004333496,1,1,1,300.000732421875,0,742397216,300.000732421875,,,,,,,,,,,,,,,,,,,,,,,,,,,,,,,,,
,3842603108.66881,299.999710083008,-101.109245300293,6.02708494984954E-7,1.59115644457456E-8,1,10,13.3016452789307,8.00754175542192,32.3100015521049,0.00116977407987883,0.000284570567433874,1,5.58787585560814E-8,,,,,,,,,,,,,,,,,,,,,299.999481201172,299.999938964844,-101.109245300293,-101.109245300293,54.9586460726789,5.61019257639023,9.57195472717285,133,1,0,0,1,0.467910766601562,34.2131004333496,1,1,1,299.999481201172,0,742397216,299.999710083008,,,,,,,,,,,,,,,,,,,,,,,,,,,,,,,,,
,3842603247.91247,299.999725341797,-159.134811401367,7.1687649963474E-7,1.5531694000158E-8,1,10,13.3016452789307,8.00739822016383,32.3100015521049,0.00140322040543496,0.000257813523057639,1,2.54724332166431E-8,,,,,,,,,,,,,,,,,,,,,299.999725341797,299.999725341797,-159.134811401367,-159.134811401367,54.8644598361116,5.61010276099655,9.57440662384033,133,1,0,0,1,0.468215942382812,34.7018585205078,1,1,1,299.999725341797,0,742397408,299.999725341797,,,,,,,,,,,,,,,,,,,,,,,,,,,,,,,,,
,3842603381.78592,300.000152587891,-249.804351806641,9.46428276046278E-7,1.40290393080072E-8,1,10,13.3016452789307,8.00728847272932,32.3100015521049,0.00185632767588042,0.000314592735749734,1,2.05309104689192E-8,,,,,,,,,,,,,,,,,,,,,300.000152587891,300.000152587891,-249.804351806641,-249.804351806641,54.8011479260539,5.61069416084459,9.55852890014648,133,1,0,0,1,0.469284057617188,34.7018585205078,1,1,1,300.000152587891,0,742397216,300.000152587891,,,,,,,,,,,,,,,,,,,,,,,,,,,,,,,,,
,3842603475.99312,300.000213623047,-392.304382324219,1.41565213073813E-6,1.28860496970478E-8,1,10,13.3016452789307,8.00728231755718,32.3100015521049,0.00277929995305967,0.000452658088121432,1,2.16105722045113E-8,,,,,,,,,,,,,,,,,,,,,300.000213623047,300.000213623047,-392.304382324219,-392.304382324219,54.9875663278904,5.6111531811455,9.57541465759277,133,1,0,0,1,0.466461181640625,34.2131004333496,1,1,1,300.000213623047,0,742397408,300.000213623047,,,,,,,,,,,,,,,,,,,,,,,,,,,,,,,,,
,3842603564.6978,300.000762939453,-615.684387207031,2.37472308877257E-6,1.25552430574389E-8,1,10,13.3016452789307,8.00713525210772,32.3100015521049,0.00466477807804343,0.000741551470955382,1,2.72232507405136E-8,,,,,,,,,,,,,,,,,,,,,300.000732421875,300.000793457031,-615.684387207031,-615.684387207031,54.8535170368423,5.61119014403137,9.56920146942139,133,1,0,0,1,0.467376708984375,34.2131004333496,1,1,1,300.000793457031,0,742397216,300.000762939453,,,,,,,,,,,,,,,,,,,,,,,,,,,,,,,,,
,3842603617.97239,299.999526977539,-966.364929199219,4.18953111382032E-6,9.17565917341949E-9,1,10,13.3016452789307,8.00712484866418,32.3100015521049,0.00824032390408047,0.00123598865499789,1,1.1299256206108E-8,,,,,,,,,,,,,,,,,,,,,299.999420166016,299.999633789063,-966.364929199219,-966.364929199219,54.8288957384866,5.61133974000257,9.58315467834473,133,1,0,0,1,0.46661376953125,34.7018585205078,1,1,1,299.999420166016,0,742397440,299.999526977539,,,,,,,,,,,,,,,,,,,,,,,,,,,,,,,,,
,3842603672.05183,299.999557495117,-1517.09252929687,7.283720490819E-6,5.44358394637276E-9,1,10,13.3016452789307,8.00704529612045,32.3100015521049,0.0143296097680934,0.00212537546296501,1,7.72964202064795E-9,,,,,,,,,,,,,,,,,,,,,299.999542236328,299.999572753906,-1517.09252929687,-1517.09252929687,55.046970095352,5.61119895812356,9.57118892669678,133,1,0,0,1,0.468368530273438,34.7018585205078,1,1,1,299.999542236328,0,742397312,299.999557495117,,,,,,,,,,,,,,,,,,,,,,,,,,,,,,,,,
,3842603725.68996,299.999359130859,-2381.20727539062,1.23021449755457E-5,1.45441548148705E-8,1,10,13.3016452789307,8.00707978369218,32.3100015521049,0.0242019522917077,0.00359450908103123,1,1.54736700118308E-8,,,,,,,,,,,,,,,,,,,,,299.999053955078,299.999664306641,-2381.20727539062,-2381.20727539062,54.9906928419674,5.61137270846263,9.58341121673584,133,1,0,0,1,0.468826293945313,34.2131004333496,1,1,1,299.999664306641,0,742397184,299.999359130859,,,,,,,,,,,,,,,,,,,,,,,,,,,,,,,,,
,3842603780.90799,299.999725341797,-3737.7177734375,2.02688685530732E-5,3.44405853934499E-8,1,10,13.3016452789307,8.00703413413794,32.3100015521049,0.039877164140192,0.00590567845220575,1,1.70712991113583E-8,,,,,,,,,,,,,,,,,,,,,299.999389648438,300.000061035156,-3737.7177734375,-3737.7177734375,54.9019780050346,5.61188651042719,9.59125900268555,133,1,0,0,1,0.468292236328125,34.2131004333496,1,1,1,300.000061035156,0,742397120,299.999725341797,,,,,,,,,,,,,,,,,,,,,,,,,,,,,,,,,
,3842603837.44735,300.000457763672,-5866.49560546875,3.28858918993868E-5,6.30066187468157E-8,1,10,13.3016452789307,8.00698654248081,32.3100015521049,0.064697486030335,0.00959755766339671,1,3.56908090168305E-8,,,,,,,,,,,,,,,,,,,,,300.000213623047,300.000701904297,-5866.49560546875,-5866.49560546875,54.8890811344673,5.61194483021602,9.59496688842773,133,1,0,0,1,0.467376708984375,34.2131004333496,1,1,1,300.000213623047,0,742397312,300.000457763672,,,,,,,,,,,,,,,,,,,,,,,,,,,,,,,,,
,3842603895.89317,300.00016784668,-9207.8232421875,5.27154409409883E-5,1.05138377806309E-7,1,10,13.3016452789307,8.00711205412891,32.3100015521049,0.103706517147576,0.0154064994602769,1,6.82238706155576E-8,,,,,,,,,,,,,,,,,,,,,299.999877929687,300.000457763672,-9207.8232421875,-9207.8232421875,54.9992907556789,5.61141987629929,9.59662628173828,133,1,0,0,1,0.469512939453125,34.2131004333496,1,1,1,299.999877929687,0,742396992,300.00016784668,,,,,,,,,,,,,,,,,,,,,,,,,,,,,,,,,
,3842603956.61932,299.999786376953,-14451.7158203125,8.38895448046765E-5,1.82041935107207E-7,1,10,13.3016452789307,8.00696242024848,32.3100015521049,0.165025273257174,0.0245714992070347,1,1.36205789193998E-7,,,,,,,,,,,,,,,,,,,,,299.999755859375,299.999816894531,-14451.7158203125,-14451.7158203125,54.8562527366597,5.6114093651997,9.62161827087402,133,1,0,0,1,0.468826293945313,34.2131004333496,1,1,1,299.999816894531,0,742396960,299.999786376953,,,,,,,,,,,,,,,,,,,,,,,,,,,,,,,,,
,3842604022.18595,299.999969482422,-22682.232421875,0.000132902319233079,2.92543549150586E-7,1,10,13.3016452789307,8.00679964246054,32.3100015521049,0.261432044514112,0.0389738751738318,1,2.39583536187622E-7,,,,,,,,,,,,,,,,,,,,,299.999969482422,299.999969482422,-22682.232421875,-22682.232421875,54.8453099373904,5.61169781374983,9.6122522354126,133,1,0,0,1,0.469894409179687,34.2131004333496,1,1,1,299.999969482422,0,742397152,299.999969482422,,,,,,,,,,,,,,,,,,,,,,,,,,,,,,,,,
,3842604094.37309,299.999816894531,-35600.08203125,0.00020972349168841,5.84277712952438E-7,1,10,13.3016452789307,8.00673670085746,32.3100015521049,0.412544398306976,0.061506385264168,1,3.80516003420605E-7,,,,,,,,,,,,,,,,,,,,,299.999633789063,300,-35600.08203125,-35600.08203125,54.747215558227,5.61384812353329,9.6053991317749,133,1,0,0,1,0.4705810546875,34.2131004333496,1,1,1,299.999633789063,0,742397152,299.999816894531,,,,,,,,,,,,,,,,,,,,,,,,,,,,,,,,,
,3842604177.24787,300.000335693359,-55874.47265625,0.000330639702139759,1.09551257247013E-6,1,10,13.3016452789307,8.0064723566196,32.3100015521049,0.6503543152585,0.0971758228009143,1,7.06466897574311E-7,,,,,,,,,,,,,,,,,,,,,300.000213623047,300.000457763672,-55874.47265625,-55874.47265625,54.6186376668135,5.61274184749584,9.62232112884521,133,1,0,0,1,0.467376708984375,34.2131004333496,1,1,1,300.000457763672,0,742397024,300.000335693359,,,,,,,,,,,,,,,,,,,,,,,,,,,,,,,,,
,3842604273.4102,300.000122070313,-55875.234375,0.000330298352494712,1.04603943433916E-6,1,10,13.3016452789307,8.00620728816986,32.3100015521049,0.649708703768651,0.0968171623988774,1,5.75346750405714E-7,,,,,,,,,,,,,,,,,,,,,299.999877929687,300.000366210937,-55875.234375,-55875.234375,54.6241090664481,5.61353646931529,9.61359691619873,133,1,0,0,1,0.46966552734375,34.2131004333496,1,1,1,300.00048828125,0,742396992,300.000122070313,,,,,,,,,,,,,,,,,,,,,,,,,,,,,,,,,
,3842604358.07748,300.000198364258,-35600.95703125,0.000209407965884127,5.79488796757692E-7,1,10,13.3016452789307,8.00620613881876,32.3100015521049,0.411906656613948,0.0614244390156842,1,3.86475913327604E-7,,,,,,,,,,,,,,,,,,,,,299.999908447266,300.00048828125,-35600.95703125,-35600.95703125,54.8042744401308,5.61373186737705,9.61141490936279,133,1,0,0,1,0.470428466796875,34.2131004333496,1,1,1,299.999908447266,0,742396992,300.000198364258,,,,,,,,,,,,,,,,,,,,,,,,,,,,,,,,,
,3842604431.93209,299.999801635742,-22682.90625,0.000132446073741253,3.03583548340211E-7,1,10,13.3016452789307,8.00596999643428,32.3100015521049,0.260538745455216,0.03870745484325,1,1.72491055698684E-7,,,,,,,,,,,,,,,,,,,,,299.999725341797,299.999877929687,-22682.90625,-22682.90625,54.8953341626212,5.61478351921754,9.59664535522461,133,1,0,0,1,0.47027587890625,34.2131004333496,1,1,1,299.999725341797,0,742397120,299.999801635742,,,,,,,,,,,,,,,,,,,,,,,,,,,,,,,,,
,3842604499.52554,299.999984741211,-14452.3896484375,8.33933735524063E-5,1.86401684816226E-7,1,10,13.3016452789307,8.00627531593256,32.3100015521049,0.16404937632845,0.0243707534102598,1,1.07827849022013E-7,,,,,,,,,,,,,,,,,,,,,299.999938964844,300.000030517578,-14452.3896484375,-14452.3896484375,55.0211763542174,5.61371020918951,9.60233879089356,133,1,0,0,1,0.47027587890625,34.2131004333496,1,1,1,299.999938964844,0,742397184,299.999984741211,,,,,,,,,,,,,,,,,,,,,,,,,,,,,,,,,
,3842604561.89097,300.000137329102,-9208.400390625,5.21921319829571E-5,1.19939981754273E-7,1,10,13.3016452789307,8.00634473643144,32.3100015521049,0.102677445322286,0.0152126709850196,1,4.71790362813876E-8,,,,,,,,,,,,,,,,,,,,,300.000061035156,300.000213623047,-9208.400390625,-9208.400390625,54.6964097044769,5.61408998234993,9.59362411499023,133,1,0,0,1,0.469207763671875,34.7018585205078,1,1,1,300.000213623047,0,742397152,300.000137329102,,,,,,,,,,,,,,,,,,,,,,,,,,,,,,,,,
,3842604621.45992,300.000076293945,-5867.255859375,3.23060844066645E-5,8.13056847392209E-8,1,10,13.3016452789307,8.00631640202991,32.3100015521049,0.0635633673119924,0.00936328880303297,1,2.22053106133339E-9,,,,,,,,,,,,,,,,,,,,,299.999450683594,300.000701904297,-5867.255859375,-5867.255859375,54.9363696598808,5.61405033825855,9.6054220199585,133,1,0,0,1,0.471267700195313,34.2131004333496,1,1,1,300.000701904297,0,742397184,300.000076293945,,,,,,,,,,,,,,,,,,,,,,,,,,,,,,,,,
,3842604680.71865,299.99983215332,-3738.45361328125,1.96518046243083E-5,5.57721533247492E-8,1,10,13.3016452789307,8.00616744217379,32.3100015521049,0.0386660122892629,0.00569027061833005,1,-1.37495386205108E-9,,,,,,,,,,,,,,,,,,,,,299.999542236328,300.000122070313,-3738.45361328125,-3738.45361328125,55.0016356412366,5.61349591897958,9.60746479034424,133,1,0,0,1,0.472564697265625,34.7018585205078,1,1,1,299.999542236328,0,742397344,299.99983215332,,,,,,,,,,,,,,,,,,,,,,,,,,,,,,,,,
,3842604739.13311,299.999649047852,-2382.04150390625,1.16386490179559E-5,4.23826009909789E-8,1,10,13.3016452789307,8.00612316331647,32.3100015521049,0.0229033594736787,0.0033445828359654,1,-1.37397937717411E-8,,,,,,,,,,,,,,,,,,,,,299.999389648438,299.999908447266,-2382.04150390625,-2382.04150390625,54.7952857121596,5.61414427196327,9.61370182037353,133,1,0,0,1,0.468826293945313,34.2131004333496,1,1,1,299.999908447266,0,742397312,299.999649047852,,,,,,,,,,,,,,,,,,,,,,,,,,,,,,,,,
,3842604796.19811,300.000610351562,-1517.80407714844,6.59419958035903E-6,3.19942673571722E-8,1,10,13.3016452789307,8.00613955098461,32.3100015521049,0.0129804768893505,0.00186828864186824,1,-2.1344667807629E-8,,,,,,,,,,,,,,,,,,,,,300.000091552734,300.001129150391,-1517.80407714844,-1517.80407714844,55.0035897125347,5.61411645613682,9.61756801605225,133,1,0,0,1,0.47576904296875,34.7018585205078,1,1,1,300.001129150391,0,742397344,300.000610351562,,,,,,,,,,,,,,,,,,,,,,,,,,,,,,,,,
,3842604852.3152,300.000076293945,-967.370849609375,3.49962827717884E-6,2.60839418222764E-8,1,10,13.3016452789307,8.00601069280473,32.3100015521049,0.00689356060577782,0.000959507882176044,1,-2.75964214026659E-8,,,,,,,,,,,,,,,,,,,,,299.999969482422,300.000183105469,-967.370849609375,-967.370849609375,54.8288957384866,5.61380463040189,9.62476539611816,133,1,0,0,1,0.467376708984375,34.7018585205078,1,1,1,300.000183105469,0,742397312,300.000076293945,,,,,,,,,,,,,,,,,,,,,,,,,,,,,,,,,
,3842605114.17947,300,-616.530883789063,1.73842860124306E-6,2.3029740886285E-8,1,10,13.3016452789307,8.00577970367001,32.3100015521049,0.00342953475812535,0.00044105843683941,1,-3.17854599831058E-8,,,,,,,,,,,,,,,,,,,,,300,300,-616.530883789063,-616.530883789063,54.9465308306308,5.61442919292499,9.68063545227051,133,1,0,0,1,0.468902587890625,34.7018585205078,1,1,1,300,0,742397248,300,,,,,,,,,,,,,,,,,,,,,,,,,,,,,,,,,
,3842605204.78964,299.999557495117,-392.819610595703,7.65738599614458E-7,2.16206658309036E-8,1,10,13.3016452789307,8.00564945919657,32.3100015521049,0.00152163013183302,0.000119489383130966,1,-5.20117135975291E-8,,,,,,,,,,,,,,,,,,,,,299.999450683594,299.999664306641,-392.819610595703,-392.819610595703,54.8683679787077,5.61586505059192,9.6712703704834,133,1,0,0,1,0.470809936523438,34.7018585205078,1,1,1,299.999664306641,0,742397184,299.999557495117,,,,,,,,,,,,,,,,,,,,,,,,,,,,,,,,,
,3842605305.92836,299.999176025391,-250.454559326172,2.48472756913957E-7,1.95295147163655E-8,1,10,13.3016452789307,8.00553968502971,32.3100015521049,0.000497175502754329,1.54833610114856E-5,1,-2.87144063877802E-8,,,,,,,,,,,,,,,,,,,,,299.999176025391,299.999176025391,-250.454559326172,-250.454559326172,54.9633358437943,5.6154776492697,9.66481590270996,133,1,0,0,1,0.4693603515625,34.7018585205078,1,1,1,299.999176025391,0,742397216,299.999176025391,,,,,,,,,,,,,,,,,,,,,,,,,,,,,,,,,
,3842605441.54428,299.999618530273,-159.576446533203,-1.58591059207004E-8,1.93443165432174E-8,1,10,13.3016452789307,8.00520664553163,32.3100015521049,-2.28653965523682E-5,-6.12095772833778E-5,1,-2.87768217307868E-8,,,,,,,,,,,,,,,,,,,,,299.999603271484,299.999633789063,-159.576446533203,-159.576446533203,54.9375421026597,5.61610253548834,9.67436981201172,133,1,0,0,1,0.471343994140625,35.6793746948242,1,1,1,299.999633789063,0,742397184,299.999618530273,,,,,,,,,,,,,,,,,,,,,,,,,,,,,,,,,
,3842605577.96594,300.000549316406,-102.004776000977,-1.64182598595619E-7,1.75837424453355E-8,1,10,13.3016452789307,8.00524044569598,32.3100015521049,-0.000314013512453375,-0.00010869033381639,1,-3.10718267756336E-8,,,,,,,,,,,,,,,,,,,,,300.000549316406,300.000549316406,-102.004776000977,-102.004776000977,55.0074978551308,5.6155634915678,9.68554782867432,133,1,0,0,1,0.469131469726562,34.7018585205078,1,1,1,300.000579833984,0,742397184,300.000549316406,,,,,,,,,,,,,,,,,,,,,,,,,,,,,,,,,
,3842605628.40962,300.00032043457,-65.0058135986328,-2.28827500245579E-7,1.6978950695072E-8,1,10,13.3016452789307,8.00525082856242,32.3100015521049,-0.000433088272339521,-0.000182487553900721,1,-5.9063559751505E-8,,,,,,,,,,,,,,,,,,,,,299.999908447266,300.000732421875,-65.0058135986328,-65.0058135986328,55.0102335549481,5.6157263643772,9.69283294677734,133,1,0,0,1,0.471725463867188,34.7018585205078,1,1,1,299.999908447266,0,742397184,300.00032043457,,,,,,,,,,,,,,,,,,,,,,,,,,,,,,,,,
,3842605729.0828,300,-41.5747680664063,-2.90445221431872E-7,1.86881336209085E-8,1,10,13.3016452789307,8.00525279838454,32.3100015521049,-0.000562569717949422,-0.000144276551104546,1,-3.05692083016801E-8,,,,,,,,,,,,,,,,,,,,,300,300,-41.5747680664063,-41.5747680664063,54.8965066054,5.6157999943087,9.67618656158447,133,1,0,0,1,0.468826293945313,34.2131004333496,1,1,1,300,0,742397216,300,,,,,,,,,,,,,,,,,,,,,,,,,,,,,,,,,
,3842605819.90408,300.000823974609,-26.4734001159668,-3.24557562789601E-7,1.73401350065308E-8,1,10,13.3016452789307,8.00521210677774,32.320000231266,-0.000629174274997274,-0.000157598443524251,1,-3.23181498133213E-8,,,,,,,,,,,,,,,,,,,,,300.000640869141,300.001007080078,-26.4734001159668,-26.4734001159668,54.8300681812654,5.61677898594377,9.6623477935791,133,1,0,0,1,0.4730224609375,34.7018585205078,1,1,1,300.001007080078,0,742397408,300.000823974609,,,,,,,,,,,,,,,,,,,,,,,,,,,,,,,,,
,3842605875.04144,299.999526977539,-17.1132488250732,-3.48585822356725E-7,1.68084616439236E-8,1,10,13.3016452789307,8.00520993736342,32.3100015521049,-0.000676773019420178,-0.000162347729291858,1,-3.11943195449264E-8,,,,,,,,,,,,,,,,,,,,,299.999206542969,299.999847412109,-17.1132488250732,-17.1132488250732,55.1931346284481,5.61581901342275,9.66790008544922,133,1,0,0,1,0.472793579101562,34.7018585205078,1,1,1,299.999847412109,0,742397152,299.999526977539,,,,,,,,,,,,,,,,,,,,,,,,,,,,,,,,,
,3842605927.98175,300.000137329102,-11.0162706375122,-3.65281640221949E-7,1.82334963568265E-8,1,10,13.3016452789307,8.00515691587206,32.3100015521049,-0.000711147885192376,-0.000156791551721436,1,-2.5912269410182E-8,,,,,,,,,,,,,,,,,,,,,300,300.000274658203,-11.0162706375122,-11.0162706375122,54.8476548229481,5.61656320498178,9.66894054412842,133,1,0,0,1,0.464935302734375,34.2131004333496,1,1,1,300.000274658203,0,742397120,300.000137329102,,,,,,,,,,,,,,,,,,,,,,,,,,,,,,,,,
,3842605981.61795,299.999664306641,-7.25012922286987,-3.5377604468646E-7,1.708436251442E-8,1,10,13.3016452789307,8.00536213793521,32.3100015521049,-0.000690501016080967,-0.000140017326971477,1,-1.90791921191533E-8,,,,,,,,,,,,,,,,,,,,,299.999450683594,299.999877929687,-7.25012922286987,-7.25012922286987,54.8226427103327,5.6166090826896,9.67523574829102,133,1,0,0,1,0.472030639648438,34.7018585205078,1,1,1,299.999877929687,0,742397216,299.999664306641,,,,,,,,,,,,,,,,,,,,,,,,,,,,,,,,,
,3842606033.44376,299.99983215332,-4.50219535827637,-3.67941854206626E-7,1.73724153718324E-8,1,10,13.3016452789307,8.00520257835521,32.3100015521049,-0.000718253905639457,-0.000144861620171082,1,-1.94565404127058E-8,,,,,,,,,,,,,,,,,,,,,299.999694824219,299.999969482422,-4.50219535827637,-4.50219535827637,54.9664623578712,5.61573674449483,9.6728458404541,133,1,0,0,1,0.467987060546875,35.190616607666,1,1,1,299.999969482422,0,742397184,299.99983215332,,,,,,,,,,,,,,,,,,,,,,,,,,,,,,,,,
,3842606083.6161,300.000122070313,-3.23863649368286,-3.66936508172639E-7,1.71209199057483E-8,1,10,13.3016452789307,8.00536457122018,32.3100015521049,-0.000716489932538937,-0.000143173726177899,1,-1.87458141252918E-8,,,,,,,,,,,,,,,,,,,,,300.000061035156,300.000183105469,-3.23863649368286,-3.23863649368286,55.1110636339289,5.61549585900346,9.67811298370361,133,1,0,0,1,0.47149658203125,34.2131004333496,1,1,1,300.000183105469,0,742397344,300.000122070313,,,,,,,,,,,,,,,,,,,,,,,,,,,,,,,,,
,3842606133.30978,300.000198364258,-2.14682340621948,-3.74371417146436E-7,1.72372778381994E-8,1,10,13.3016452789307,8.00525823579779,32.3100015521049,-0.000732586672430277,-0.000135311723748248,1,-1.36555482595689E-8,,,,,,,,,,,,,,,,,,,,,300.000030517578,300.000366210937,-2.14682340621948,-2.14682340621948,54.8296773670058,5.61647474283693,9.66140651702881,133,1,0,0,1,0.46966552734375,34.2131004333496,1,1,1,300.000366210937,0,742397344,300.000198364258,,,,,,,,,,,,,,,,,,,,,,,,,,,,,,,,,
,3842606183.13666,299.999664306641,-1.45983994007111,-3.7746608039825E-7,1.69848419549488E-8,1,10,13.3016452789307,8.00521915881071,32.3100015521049,-0.000738691279324779,-0.000136084591641233,1,-1.35929249669709E-8,,,,,,,,,,,,,,,,,,,,,299.999420166016,299.999908447266,-1.45983994007111,-1.45983994007111,54.7175136744962,5.61680402871109,9.67754554748535,133,1,0,0,1,0.471954345703125,34.7018585205078,1,1,1,299.999908447266,0,742397152,299.999664306641,,,,,,,,,,,,,,,,,,,,,,,,,,,,,,,,,
,3842606234.93432,299.999969482422,1.37396705150604,-3.8094927761271E-7,1.67356600406814E-8,1,10,13.3016452789307,8.00529991435553,32.3100015521049,-0.000745720587234911,-0.000135924386032906,1,-1.29982546351394E-8,,,,,,,,,,,,,,,,,,,,,299.999908447266,300.000030517578,1.37396705150604,1.37396705150604,54.8558619224,5.6164394060975,9.68387603759766,133,1,0,0,1,0.467605590820313,34.7018585205078,1,1,1,300.000030517578,0,742397184,299.999969482422,,,,,,,,,,,,,,,,,,,,,,,,,,,,,,,,,
,3842606285.35324,299.999938964844,2.37990713119507,-3.85883193126251E-7,1.70496672781327E-8,1,10,13.3016452789307,8.00530088158703,32.3100015521049,-0.000754494806343346,-0.000143689692528488,1,-1.62187553129702E-8,,,,,,,,,,,,,,,,,,,,,299.999847412109,300.000030517578,2.37990713119507,2.37990713119507,54.8343671381212,5.61623082428162,9.68862342834473,133,1,0,0,1,0.469970703125,34.2131004333496,1,1,1,300.000030517578,0,742397344,299.999938964844,,,,,,,,,,,,,,,,,,,,,,,,,,,,,,,,,
,3842606335.11113,300.000625610352,3.97469019889832,-3.85347585977008E-7,1.72127226704651E-8,1,10,13.3016452789307,8.00517107270238,32.3100015521049,-0.000753893414072826,-0.000140414647865122,1,-1.46336179525127E-8,,,,,,,,,,,,,,,,,,,,,300.000305175781,300.000946044922,3.97469019889832,3.97469019889832,54.7706644138039,5.61591966787936,9.69258403778076,133,1,0,0,1,0.467147827148438,34.2131004333496,1,1,1,300.000946044922,0,742397248,300.000625610352,,,,,,,,,,,,,,,,,,,,,,,,,,,,,,,,,
,3842606386.89653,299.999420166016,6.51407527923584,-3.87021129883705E-7,1.70648930655405E-8,1,10,13.3016452789307,8.00517860298232,32.3100015521049,-0.000758346649047813,-0.00013301889305375,1,-1.06280224730956E-8,,,,,,,,,,,,,,,,,,,,,299.998779296875,300.000061035156,6.51407527923584,6.51407527923584,54.7890326840058,5.61597952569999,9.69344520568848,133,1,0,0,1,0.469818115234375,34.7018585205078,1,1,1,299.998779296875,0,742397152,299.999420166016,,,,,,,,,,,,,,,,,,,,,,,,,,,,,,,,,
,3842606440.97268,300.000183105469,10.4028921127319,-3.92395239966722E-7,1.62949902683443E-8,1,10,13.3016452789307,8.00513244890655,32.3100015521049,-0.000768246696020098,-0.000139129158999254,1,-1.29427433030872E-8,,,,,,,,,,,,,,,,,,,,,300.000091552734,300.000274658203,10.4028921127319,10.4028921127319,54.9445767593327,5.61610760264001,9.69510364532471,133,1,0,0,1,0.470733642578125,34.7018585205078,1,1,1,300.000274658203,0,742397056,300.000183105469,,,,,,,,,,,,,,,,,,,,,,,,,,,,,,,,,
,3842606497.83438,299.999649047852,16.4139976501465,-4.05269182453013E-7,1.66568478582918E-8,1,10,13.3016452789307,8.00498731991348,32.3100015521049,-0.000792594195096976,-0.000149462665034599,1,-1.63003843290637E-8,,,,,,,,,,,,,,,,,,,,,299.999603271484,299.999694824219,16.4139976501465,16.4139976501465,54.8800924064962,5.61649482037873,9.68610000610352,133,1,0,0,1,0.472183227539063,34.7018585205078,1,1,1,299.999694824219,0,742397152,299.999649047852,,,,,,,,,,,,,,,,,,,,,,,,,,,,,,,,,
,3842606553.11786,300.000137329102,25.7864170074463,-4.2130274364628E-7,1.7371899667244E-8,1,10,13.3016452789307,8.00492588971338,32.3100015521049,-0.000822046576066833,-0.000168288430058841,1,-2.35090131370802E-8,,,,,,,,,,,,,,,,,,,,,300,300.000274658203,25.7864170074463,25.7864170074463,54.8871270631693,5.61638287730997,9.70421981811523,133,1,0,0,1,0.472335815429687,34.7018585205078,1,1,1,300,0,742397376,300.000137329102,,,,,,,,,,,,,,,,,,,,,,,,,,,,,,,,,
,3842606608.21479,300.000534057617,40.7528419494629,-4.37301110136292E-7,1.72188434900978E-8,1,10,13.3016452789307,8.00468405956202,32.3100015521049,-0.000851124874196802,-0.000189097657031513,1,-3.1732297826273E-8,,,,,,,,,,,,,,,,,,,,,300.000518798828,300.000549316406,40.7528419494629,40.7528419494629,55.1591337878616,5.6174387846747,9.69833374023437,133,1,0,0,1,0.471420288085937,34.7018585205078,1,1,1,300.000549316406,0,742397248,300.000534057617,,,,,,,,,,,,,,,,,,,,,,,,,,,,,,,,,
,3842606747.49349,299.999481201172,64.2452239990234,-4.79313780985785E-7,1.63277156501665E-8,1,10,13.3016452789307,8.00468247891805,32.3100015521049,-0.000935771291339722,-0.000187726685148876,1,-2.48496561385001E-8,,,,,,,,,,,,,,,,,,,,,299.999481201172,299.999481201172,64.2452239990234,64.2452239990234,54.7280656595058,5.6169053140035,9.70902252197266,133,1,0,0,1,0.470199584960937,34.2131004333496,1,1,1,299.999481201172,0,742397408,299.999481201172,,,,,,,,,,,,,,,,,,,,,,,,,,,,,,,,,
,3842606836.40368,300.000442504883,101.072448730469,-5.31288088221708E-7,1.62750473396557E-8,1,10,13.3016452789307,8.0045611424291,32.3100015521049,-0.00102974974123424,-0.000258904121443808,1,-5.33779487427484E-8,,,,,,,,,,,,,,,,,,,,,300,300.000885009766,101.072448730469,101.072448730469,54.9883479564097,5.61707132720935,9.71997833251953,133,1,0,0,1,0.469970703125,34.2131004333496,1,1,1,300.000823974609,0,742397120,300.000442504883,,,,,,,,,,,,,,,,,,,,,,,,,,,,,,,,,
,3842606975.43435,300.000305175781,158.96305847168,-6.43457329754065E-7,1.61926733216856E-8,1,10,13.3016452789307,8.00452617733031,32.3100015521049,-0.00125819188240468,-0.000238602176006483,1,-2.65432577250677E-8,,,,,,,,,,,,,,,,,,,,,300.000305175781,300.000305175781,158.96305847168,158.96305847168,54.9332431458039,5.61752550395967,9.71166801452637,133,1,0,0,1,0.4693603515625,34.2131004333496,1,1,1,300.000305175781,0,742397216,300.000305175781,,,,,,,,,,,,,,,,,,,,,,,,,,,,,,,,,
,3842607064.14191,299.999481201172,249.632614135742,-8.75515083793443E-7,1.7245944893823E-8,1,10,13.3016452789307,8.0046743615208,32.3100015521049,-0.00170156170930405,-0.000395322156855435,1,-7.20359430643044E-8,,,,,,,,,,,,,,,,,,,,,299.999176025391,299.999786376953,249.632614135742,249.632614135742,54.8890811344673,5.6166632421466,9.71946239471436,133,1,0,0,1,0.469741821289063,34.7018585205078,1,1,1,299.999786376953,0,742397184,299.999481201172,,,,,,,,,,,,,,,,,,,,,,,,,,,,,,,,,
,3842607158.33578,299.999786376953,392.279815673828,-1.33318940150369E-6,1.5270677762364E-8,1,10,13.3016452789307,8.00443386825812,32.3100015521049,-0.00260685811151362,-0.000494311378395982,1,-5.49704555163767E-8,,,,,,,,,,,,,,,,,,,,,299.999572753906,300,392.279815673828,392.279815673828,55.0157049545827,5.61781642484416,9.72461128234863,133,1,0,0,1,0.47027587890625,34.7018585205078,1,1,1,300.000030517578,0,742397312,299.999786376953,,,,,,,,,,,,,,,,,,,,,,,,,,,,,,,,,
,3842607252.13745,299.999618530273,615.659851074219,-2.30281945030391E-6,1.21724460380918E-8,1,10,13.3016452789307,8.00438977073186,32.3100015521049,-0.00452086254004693,-0.000731246021096908,1,-3.26435928655364E-8,,,,,,,,,,,,,,,,,,,,,299.999267578125,299.999969482422,615.659851074219,615.659851074219,54.8175621249577,5.61816386331859,9.71429538726807,133,1,0,0,1,0.467605590820313,34.2131004333496,1,1,1,299.999267578125,0,742397312,299.999618530273,,,,,,,,,,,,,,,,,,,,,,,,,,,,,,,,,
,3842607306.11681,300.000091552734,966.683898925781,-4.12738722195323E-6,8.79415358980642E-9,1,10,13.3016452789307,8.0041778536492,32.3100015521049,-0.00811725546202126,-0.00121180793633384,1,-8.28621438004784E-9,,,,,,,,,,,,,,,,,,,,,299.999938964844,300.000244140625,966.683898925781,966.683898925781,55.0500966094289,5.61930429696717,9.7123556137085,133,1,0,0,1,0.4718017578125,34.2131004333496,1,1,1,300.000244140625,0,742397248,300.000091552734,,,,,,,,,,,,,,,,,,,,,,,,,,,,,,,,,
,3842607360.20678,299.999710083008,1517.23986816406,-7.22539809890025E-6,5.82845476666021E-9,1,10,13.3016452789307,8.00417400904816,32.3100015521049,-0.0142115270991423,-0.00211136914714811,1,-9.41271376531631E-9,,,,,,,,,,,,,,,,,,,,,299.999450683594,299.999969482422,1517.23986816406,1517.23986816406,55.0289926394097,5.61888514002566,9.71002960205078,133,1,0,0,1,0.472488403320313,34.2131004333496,1,1,1,299.999450683594,0,742397248,299.999710083008,,,,,,,,,,,,,,,,,,,,,,,,,,,,,,,,,
,3842607415.31781,299.999389648438,2381.55102539062,-1.22403523005937E-5,1.34434306818938E-8,1,10,13.3016452789307,8.00408549324625,32.3100015521049,-0.0240768556938664,-0.00356566176479561,1,-1.02882796482277E-8,,,,,,,,,,,,,,,,,,,,,299.999237060547,299.999542236328,2381.55102539062,2381.55102539062,54.9699796862077,5.61847587664007,9.71578979492188,133,1,0,0,1,0.4705810546875,34.2131004333496,1,1,1,299.999237060547,0,742397312,299.999389648438,,,,,,,,,,,,,,,,,,,,,,,,,,,,,,,,,
,3842607470.55342,300.00016784668,3737.80322265625,-2.01975056891339E-5,3.21696550297625E-8,1,10,13.3016452789307,8.00404756424216,32.3100015521049,-0.039727441269718,-0.00589095837749141,1,-2.0719091039915E-8,,,,,,,,,,,,,,,,,,,,,300.000030517578,300.000305175781,3737.80322265625,3737.80322265625,54.9062769618904,5.61906293795914,9.73268985748291,133,1,0,0,1,0.473098754882812,33.7243423461914,1,1,1,300.000305175781,0,742397216,300.00016784668,,,,,,,,,,,,,,,,,,,,,,,,,,,,,,,,,
,3842607526.31469,300.000244140625,5866.45849609375,-3.28167196528402E-5,6.06651319753562E-8,1,10,13.3016452789307,8.00392971429983,32.3100015521049,-0.0645463717511708,-0.00958424065469298,1,-4.01426871977259E-8,,,,,,,,,,,,,,,,,,,,,300.000244140625,300.000244140625,5866.45849609375,5866.45849609375,54.871103678525,5.61934315862773,9.73700714111328,133,1,0,0,1,0.470504760742188,34.7018585205078,1,1,1,300.000244140625,0,742397184,300.000244140625,,,,,,,,,,,,,,,,,,,,,,,,,,,,,,,,,
,3842607584.76735,299.999954223633,9207.7861328125,-5.26303066567351E-5,1.03483362273192E-7,1,10,13.3016452789307,8.00386398865724,32.3100015521049,-0.103518893696152,-0.0153561646339628,1,-5.69400808488599E-8,,,,,,,,,,,,,,,,,,,,,299.999877929687,300.000030517578,9207.7861328125,9207.7861328125,54.8652414646308,5.61912791970397,9.73674392700195,133,1,0,0,1,0.471725463867188,34.2131004333496,1,1,1,300.000030517578,0,742397056,299.999954223633,,,,,,,,,,,,,,,,,,,,,,,,,,,,,,,,,
,3842607645.25307,300.000411987305,14451.751953125,-8.38357887777498E-5,1.76898049676149E-7,1,10,13.3016452789307,8.00381949028941,32.320000231266,-0.164885411940338,-0.0245373662515374,1,-1.29498609560564E-7,,,,,,,,,,,,,,,,,,,,,300.000305175781,300.000518798828,14451.751953125,14451.751953125,54.8054468829097,5.61853972678511,9.75611305236816,133,1,0,0,1,0.46844482421875,34.2131004333496,1,1,1,300.000518798828,0,742397152,300.000411987305,,,,,,,,,,,,,,,,,,,,,,,,,,,,,,,,,
,3842607710.08322,300.000259399414,22682.18359375,-0.000132748444263845,2.84913581870033E-7,1,10,13.3016452789307,8.00393857369479,32.320000231266,-0.261075828371054,-0.0389318269277006,1,-2.44805466623155E-7,,,,,,,,,,,,,,,,,,,,,300.000213623047,300.000305175781,22682.18359375,22682.18359375,54.6452130364673,5.61897677962337,9.75147724151611,133,1,0,0,1,0.4681396484375,34.2131004333496,1,1,1,300.000213623047,0,742397152,300.000259399414,,,,,,,,,,,,,,,,,,,,,,,,,,,,,,,,,
,3842607782.65126,299.999725341797,35600.16015625,-0.000209615457942214,5.6181616036433E-7,1,10,13.3016452789307,8.00372155982173,32.3100015521049,-0.412253136524505,-0.0614096361096778,1,-3.53795280182182E-7,,,,,,,,,,,,,,,,,,,,,299.999694824219,299.999755859375,35600.16015625,35600.16015625,54.6999270328135,5.61946747754254,9.72389888763428,133,1,0,0,1,0.47088623046875,34.2131004333496,1,1,1,299.999694824219,0,742397024,299.999725341797,,,,,,,,,,,,,,,,,,,,,,,,,,,,,,,,,
,3842607866.1121,300.000213623047,55874.57421875,-0.000330555071702692,1.07379819817341E-6,1,10,13.3016452789307,8.00373208423921,32.3100015521049,-0.650077727975763,-0.0970390097405795,1,-6.58792225056446E-7,,,,,,,,,,,,,,,,,,,,,299.999969482422,300.000457763672,55874.57421875,55874.57421875,54.5885449688231,5.61918738068076,9.72616863250732,133,1,0,0,1,0.471572875976562,34.2131004333496,1,1,1,300.000457763672,0,742397088,300.000213623047,,,,,,,,,,,,,,,,,,,,,,,,,,,,,,,,,
,3842607937.53306,299.999649047852,69999.4765625,-0.000414546356567536,7.96148709604753E-7,1,10,13.3016452789307,8.00354708458275,32.3100015521049,-0.815268928482812,-0.12154228921501,1,-7.48940123168477E-7,,,,,,,,,,,,,,,,,,,,,299.999420166016,299.999877929687,69999.4765625,69999.4765625,54.5338309724769,5.6199505318416,9.73237037658691,133,1,0,0,1,0.472335815429687,34.7018585205078,1,1,1,299.999877929687,0,742397184,299.999649047852,,,,,,,,,,,,,,,,,,,,,,,,,,,,,,,,,