File: demonstration_data/squid/000_MA2936-3_211005_Qrod_IP_buchner_standard_004_MT-w_100Oe_post-ZFC.dat
[Header]
; MPMS3 Data File (default extension .dat)
; Copyright (c) 2007, Quantum Design, Inc. All rights reserved.
TITLE,
FILEOPENTIME,3842628147.96785,10/05/2021,9:45 pm
BYAPP,MPMS3 w/ AC,1.0,1.1
INFO,MPMS3 Measurement Release 1.1.16 Build 424, MultiVu Release 2.3.4.19,APPNAME
INFO,Linear Motor Servo Controller,MOTOR_MODULE_NAME
INFO,3101-100 J0,MOTOR_HW_VERSION
INFO,MMC714,MOTOR_SERIAL_NUMBER
INFO,01.04.28,MOTOR_SOFTWARE_VERSION
INFO,Quantum Design Squid Module,SQUID_MODULE_NAME
INFO,3101-501 B0,SQUID_HW_VERSION
INFO,SQM189,SQUID_SERIAL_NUMBER
INFO,01.03.04,SQUID_SOFTWARE_VERSION
INFO,Quantum Design VSM Oven,OVEN_MODULE_NAME
INFO,3101-201 A1,OVEN_HW_VERSION
INFO,OVB229,OVEN_SERIAL_NUMBER
INFO,01.07.07,OVEN_SOFTWARE_VERSION
INFO,SQUID AC,AC_MODULE_NAME
INFO,3101-401 F1,AC_HW_VERSION
INFO,SAC108,AC_SERIAL_NUMBER
INFO,SQUID AC 00.95.07,AC_SOFTWARE_VERSION
INFO,TCI177,COIL_SERIAL_NUMBER
INFO,0,MOMENT_UNITS
INFO,A2481,SAMPLE_MATERIAL
INFO,,SAMPLE_COMMENT
INFO,,SAMPLE_MASS
INFO,,SAMPLE_VOLUME
INFO,,SAMPLE_MOLECULAR_WEIGHT
INFO,5mm x 5mm,SAMPLE_SIZE
INFO,,SAMPLE_SHAPE
INFO,Straw,SAMPLE_HOLDER
INFO,Standard,SAMPLE_HOLDER_DETAIL
INFO,65.98,SAMPLE_OFFSET
DATATYPE,COMMENT,1
DATATYPE,TIME,2
STARTUPAXIS,X,2
STARTUPAXIS,Y1,5
FIELDGROUP, VSM,2,3,4,5,6,8,9,10,11,14,15
FIELDGROUP, DC, 2,3,4,14,56,57,58,59,60,61,62,63,64,65,66,67,68,69
FIELDGROUP, AC, 2,3,4,11,16,17,18,19,20,21,22,23,24,25,26,27,28,29,30
STARTUPGROUP, All
[Data]
Comment,Time Stamp (sec),Temperature (K),Magnetic Field (Oe),Moment (emu),M. Std. Err. (emu),Transport Action,Averaging Time (sec),Frequency (Hz),Peak Amplitude (mm),Center Position (mm),Lockin Signal' (V),Lockin Signal (V),Range,M. Quad. Signal (emu),AC Moment (emu),AC M. Std Err. (emu),AC Phase (deg),AC Phase Std. Err. (deg),AC Susceptibility (emu/Oe),AC Suscept. Std Err. (emu/Oe),AC X' (emu/Oe),AC X' Std Err. (emu/Oe),AC X'' (emu/Oe),AC X'' Std Err. (emu/Oe),AC Drive (Oe),AC Frequency (Hz),AC Averaging Time (sec),AC Cycles,AC Range,AC Measure Type,AC Signal' (V),AC Signal'' (V),AC Trim Coil Ratio,AC Trim Coil Phase,Min. Temperature (K),Max. Temperature (K),Min. Field (Oe),Max. Field (Oe),Mass (grams),Motor Lag (deg),Pressure (Torr),Measure Count,Measurement Number,SQUID Status (code),Motor Status (code),Measure Status (code),Motor Current (amps),Motor Temp. (C),Temp. Status (code),Field Status (code),Chamber Status (code),Chamber Temp (K),Redirection State,Evercool Status,Average Temp (K),Rotation Angle (deg),Rotator state,DC Moment Fixed Ctr (emu),DC Moment Err Fixed Ctr (emu),DC Moment Free Ctr (emu),DC Moment Err Free Ctr (emu),DC Fixed Fit,DC Free Fit,DC Calculated Center (mm),DC Calculated Center Err (mm),DC Scan Length (mm),DC Scan Time (s),DC Number of Points,DC Squid Drift,DC Min V (V),DC Max V (V),DC Scans per Measure,Map 01,Map 02,Map 03,Map 04,Map 05,Map 06,Map 07,Map 08,Map 09,Map 10,Map 11,Map 12,Map 13,Map 14,Map 15,Map 16
,3842628189.71521,3.00078511238098,99.6003341674805,-3.28165955656732E-7,6.61321266862745E-9,1,10,13.3016452789307,7.99255075571245,31.3699990510941,-0.000646338934456498,-8.6321380685305E-5,1,4.40330979185765E-9,,,,,,,,,,,,,,,,,,,,,3.00078511238098,3.00078511238098,99.6003341674805,99.6003341674805,54.7538594006404,5.68135952892237,4.58464288711548,133,1,0,0,1,0.474472045898438,31.2805480957031,1,1,1,3.00078511238098,0,742397440,3.00078511238098,,,,,,,,,,,,,,,,,,,,,,,,,,,,,,,,,
,3842628259.10986,3.49758422374725,99.6003341674805,-3.39122223283387E-7,6.82047897526162E-9,1,10,13.3016452789307,7.98148350309553,31.3699990510941,-0.000666009684680953,-9.85607097193205E-5,1,-2.49169615241146E-10,,,,,,,,,,,,,,,,,,,,,3.46038508415222,3.53478336334229,99.6003341674805,99.6003341674805,54.7061800609673,5.62147859495808,4.77243280410767,133,1,0,0,1,0.46661376953125,31.2805480957031,6,1,1,3.53478336334229,0,742397248,3.49758422374725,,,,,,,,,,,,,,,,,,,,,,,,,,,,,,,,,
,3842628329.05503,4.02550959587097,99.6003341674805,-3.46755931967503E-7,6.82357456753182E-9,1,10,13.3016452789307,7.98108280660553,31.3699990510941,-0.000680436688053594,-0.000104482921430785,1,-2.14189408665512E-9,,,,,,,,,,,,,,,,,,,,,3.98709726333618,4.06392192840576,99.6003341674805,99.6003341674805,54.7010994755923,5.6218881450695,4.93074703216553,133,1,0,0,1,0.469970703125,33.2355842590332,6,1,1,4.06392192840576,0,742397280,4.02550959587097,,,,,,,,,,,,,,,,,,,,,,,,,,,,,,,,,
,3842628399.07283,4.56336808204651,99.6003341674805,-3.48934823145735E-7,6.51771682596718E-9,1,10,13.3016452789307,7.98079015967279,31.3699990510941,-0.000685056007926656,-0.000102706750825894,1,-9.17836920370311E-10,,,,,,,,,,,,,,,,,,,,,4.52578544616699,4.60095071792603,99.6003341674805,99.6003341674805,54.627235580525,5.62196596299466,6.3245062828064,133,1,0,0,1,0.466384887695313,33.2355842590332,6,1,1,4.60095071792603,0,742397216,4.56336808204651,,,,,,,,,,,,,,,,,,,,,,,,,,,,,,,,,
,3842628469.17472,5.10321521759033,99.6003341674805,-3.50612983246561E-7,6.69789974606479E-9,1,10,13.3016452789307,7.98072273170404,31.3699990510941,-0.000687535281671081,-0.000108716111902229,1,-3.73071114368479E-9,,,,,,,,,,,,,,,,,,,,,5.06591892242432,5.14051151275635,99.6003341674805,99.6003341674805,54.8097458397654,5.62298882486483,6.47615194320679,133,1,0,0,1,0.466766357421875,33.2355842590332,6,1,1,5.14051151275635,0,742397472,5.10321521759033,,,,,,,,,,,,,,,,,,,,,,,,,,,,,,,,,
,3842628539.08241,5.64884638786316,99.6003341674805,-3.5435689801231E-7,6.94357855266845E-9,1,10,13.3016452789307,7.98079680217831,31.3800014555454,-0.000694580752039775,-0.000111913805857958,1,-4.80730277501866E-9,,,,,,,,,,,,,,,,,,,,,5.61133623123169,5.68635654449463,99.6003341674805,99.6003341674805,54.899633119477,5.62185635303919,6.59479570388794,133,1,0,0,1,0.47454833984375,33.2355842590332,6,1,1,5.68635654449463,0,742397248,5.64884638786316,,,,,,,,,,,,,,,,,,,,,,,,,,,,,,,,,
,3842628609.02772,6.19930958747864,99.6003341674805,-3.5581900882197E-7,7.12002668786691E-9,1,10,13.3016452789307,7.98063060045369,31.3699990510941,-0.000699364698079667,-9.9291636273534E-5,1,1.83401633960204E-9,,,,,,,,,,,,,,,,,,,,,6.16052341461182,6.23809576034546,99.6003341674805,99.6003341674805,54.8722761213039,5.62290904058452,6.70912027359009,133,1,0,0,1,0.467987060546875,33.2355842590332,6,1,1,6.23809576034546,0,742397344,6.19930958747864,,,,,,,,,,,,,,,,,,,,,,,,,,,,,,,,,
,3842628679.00292,6.72279357910156,99.6003341674805,-3.57792225652523E-7,6.5989455987065E-9,1,10,13.3016452789307,7.98043584627282,31.3699990510941,-0.000702476946043636,-0.00010497848054603,1,-7.7170868706298E-10,,,,,,,,,,,,,,,,,,,,,6.68350791931152,6.7620792388916,99.6003341674805,99.6003341674805,54.7222034456115,5.62233376035979,6.82021808624268,133,1,0,0,1,0.467605590820313,34.2131004333496,6,1,1,6.7620792388916,0,742397248,6.72279357910156,,,,,,,,,,,,,,,,,,,,,,,,,,,,,,,,,
,3842628749.04773,7.25949501991272,99.6003341674805,-3.63788581650084E-7,6.74462269141406E-9,1,10,13.3016452789307,7.98051309218963,31.3699990510941,-0.000714113882910861,-0.000107689309563651,1,-1.26879555218373E-9,,,,,,,,,,,,,,,,,,,,,7.22444772720337,7.29454231262207,99.6003341674805,99.6003341674805,54.6811679483519,5.62279559219578,6.90233659744263,133,1,0,0,1,0.472335815429687,33.7243423461914,6,1,1,7.29454231262207,0,742397248,7.25949501991272,,,,,,,,,,,,,,,,,,,,,,,,,,,,,,,,,
,3842628819.01721,7.79171514511108,99.6003341674805,-3.625773187197E-7,6.54861143729754E-9,1,10,13.3016452789307,7.98056266343079,31.3699990510941,-0.000713058950808765,-9.83640883556113E-5,1,3.30111422782707E-9,,,,,,,,,,,,,,,,,,,,,7.75396490097046,7.82946538925171,99.6003341674805,99.6003341674805,54.8589884364769,5.62298630131442,6.95655632019043,133,1,0,0,1,0.46844482421875,34.2131004333496,6,1,1,7.82946538925171,0,742397312,7.79171514511108,,,,,,,,,,,,,,,,,,,,,,,,,,,,,,,,,
,3842628889.0315,8.34677839279175,99.6003341674805,-3.68608381928921E-7,7.57524329324243E-9,1,10,13.3016452789307,7.98049666111656,31.3699990510941,-0.000724900437650211,-0.000100108862395123,1,3.30049213767697E-9,,,,,,,,,,,,,,,,,,,,,8.3071117401123,8.38644504547119,99.6003341674805,99.6003341674805,54.7659746426885,5.62302994583879,7.04396247863769,133,1,0,0,1,0.470428466796875,33.2355842590332,6,1,1,8.38644504547119,0,742397216,8.34677839279175,,,,,,,,,,,,,,,,,,,,,,,,,,,,,,,,,
,3842628959.00654,8.90713930130005,99.6003341674805,-3.67851115158151E-7,7.12306961537965E-9,1,10,13.3016452789307,7.98043728815315,31.3699990510941,-0.000722219229134627,-0.00010797783813194,1,-8.17847119867295E-10,,,,,,,,,,,,,,,,,,,,,8.86795616149902,8.94632244110107,99.6003341674805,99.6003341674805,54.9582552584193,5.62271845307525,7.11618328094482,133,1,0,0,1,0.465621948242188,34.2131004333496,6,1,1,8.94632244110107,0,742397248,8.90713930130005,,,,,,,,,,,,,,,,,,,,,,,,,,,,,,,,,
,3842629029.08266,9.46930170059204,99.6003341674805,-3.67103493978295E-7,6.47203708785385E-9,1,10,13.3016452789307,7.98040374574035,31.3699990510941,-0.000720566888415589,-0.000108999614650396,1,-1.4483112106004E-9,,,,,,,,,,,,,,,,,,,,,9.43037986755371,9.50822353363037,99.6003341674805,99.6003341674805,54.7862969841885,5.6236266809458,7.18469047546387,133,1,0,0,1,0.469284057617188,33.7243423461914,6,1,1,9.50822353363037,0,742397248,9.46930170059204,,,,,,,,,,,,,,,,,,,,,,,,,,,,,,,,,
,3842629099.0653,10.0301246643066,99.6003341674805,-3.65132695660696E-7,6.49344451687064E-9,1,10,13.3016452789307,7.98038679788016,31.3699990510941,-0.000717065697134575,-0.000105914679697508,1,-1.67795648410926E-10,,,,,,,,,,,,,,,,,,,,,9.99130249023437,10.0689468383789,99.6003341674805,99.6003341674805,54.8773567066789,5.62333421841881,7.24182558059692,133,1,0,0,1,0.467987060546875,33.7243423461914,6,1,1,10.0689468383789,0,742397216,10.0301246643066,,,,,,,,,,,,,,,,,,,,,,,,,,,,,,,,,
,3842629169.00511,10.5929455757141,99.6003341674805,-3.69092292841226E-7,6.52664965561199E-9,1,10,13.3016452789307,7.98023333815542,31.3699990510941,-0.000725431696606329,-0.000103001855999333,1,1.89775201863722E-9,,,,,,,,,,,,,,,,,,,,,10.5529451370239,10.6329460144043,99.6003341674805,99.6003341674805,54.9082310331885,5.62332444983337,7.29520130157471,133,1,0,0,1,0.4632568359375,34.2131004333496,6,1,1,10.6329460144043,0,742397312,10.5929455757141,,,,,,,,,,,,,,,,,,,,,,,,,,,,,,,,,
,3842629238.95271,11.158194065094,99.6003341674805,-3.67814843124528E-7,6.40972749771506E-9,1,10,13.3016452789307,7.98025051678411,31.3699990510941,-0.000722318059923143,-0.000106746068298831,1,-1.96728151649166E-10,,,,,,,,,,,,,,,,,,,,,11.1196165084839,11.1967716217041,99.6003341674805,99.6003341674805,54.7952857121596,5.62370361746614,7.3462028503418,133,1,0,0,1,0.462188720703125,34.2131004333496,6,1,1,11.1967716217041,0,742397216,11.158194065094,,,,,,,,,,,,,,,,,,,,,,,,,,,,,,,,,
,3842629308.99786,11.7257151603699,99.6003341674805,-3.6847211628086E-7,6.53228717557008E-9,1,10,13.3016452789307,7.98029253778186,31.3699990510941,-0.000723885281962989,-0.000105074057446642,1,7.51550357530899E-10,,,,,,,,,,,,,,,,,,,,,11.6869487762451,11.7644815444946,99.6003341674805,99.6003341674805,54.8976790481789,5.62302932421568,7.3912296295166,133,1,0,0,1,0.467376708984375,33.7243423461914,6,1,1,11.7664451599121,0,742397216,11.7257151603699,,,,,,,,,,,,,,,,,,,,,,,,,,,,,,,,,
,3842629378.93395,12.2939028739929,99.6003341674805,-3.67838254473806E-7,6.391526790631E-9,1,10,13.3016452789307,7.98041687219873,31.3699990510941,-0.000723121105012023,-0.000101669962669855,1,2.39195098196205E-9,,,,,,,,,,,,,,,,,,,,,12.2533664703369,12.3344392776489,99.6003341674805,99.6003341674805,54.9070585904097,5.62339594921569,7.43429803848267,133,1,0,0,1,0.468368530273438,33.7243423461914,6,1,1,12.3344392776489,0,742397376,12.2939028739929,,,,,,,,,,,,,,,,,,,,,,,,,,,,,,,,,
,3842629448.91554,12.861376285553,99.6003341674805,-3.69269487043406E-7,6.76164131993236E-9,1,10,13.3016452789307,7.98064040365472,31.3699990510941,-0.000724385645280857,-0.000112666103518153,1,-2.99530090362213E-9,,,,,,,,,,,,,,,,,,,,,12.8215589523315,12.9011936187744,99.6003341674805,99.6003341674805,54.884391363352,5.62355397855836,7.48830270767212,133,1,0,0,1,0.468597412109375,34.2131004333496,6,1,1,12.9011936187744,0,742397184,12.861376285553,,,,,,,,,,,,,,,,,,,,,,,,,,,,,,,,,
,3842629518.95762,13.4342083930969,99.6003341674805,-3.6661755025284E-7,6.66010395666568E-9,1,10,13.3016452789307,7.98043571827132,31.3699990510941,-0.000719194288681254,-0.000111710818476025,1,-2.90019176214553E-9,,,,,,,,,,,,,,,,,,,,,13.3947525024414,13.4736642837524,99.6003341674805,99.6003341674805,54.8292865527462,5.6236870685877,7.52472162246704,133,1,0,0,1,0.470123291015625,34.2131004333496,6,1,1,13.4736642837524,0,742397184,13.4342083930969,,,,,,,,,,,,,,,,,,,,,,,,,,,,,,,,,
,3842629588.95319,14.0046362876892,99.6003341674805,-3.70773140183863E-7,6.40318861694086E-9,1,10,13.3016452789307,7.98042345098051,31.3699990510941,-0.000728296077740371,-0.000106522074198449,1,3.53555469217573E-10,,,,,,,,,,,,,,,,,,,,,13.9639177322388,14.0453548431396,99.6003341674805,99.6003341674805,54.8730577498231,5.6224431418007,7.55545997619629,133,1,0,0,1,0.470046997070313,33.7243423461914,6,1,1,14.0453548431396,0,742397248,14.0046362876892,,,,,,,,,,,,,,,,,,,,,,,,,,,,,,,,,
,3842629658.8999,14.5771970748901,99.6003341674805,-3.69818200391998E-7,6.53234249762607E-9,1,10,13.3016452789307,7.98016580284483,31.3699990510941,-0.000726257053214342,-0.000107264799234806,1,-1.66213300915395E-10,,,,,,,,,,,,,,,,,,,,,14.5355081558228,14.6188859939575,99.6003341674805,99.6003341674805,54.8003662975346,5.62360569226561,7.57953023910522,133,1,0,0,1,0.46234130859375,33.7243423461914,6,1,1,14.6188859939575,0,742397376,14.5771970748901,,,,,,,,,,,,,,,,,,,,,,,,,,,,,,,,,
,3842629728.91458,15.1504430770874,99.6003341674805,-3.67780785925195E-7,6.92776963257652E-9,1,10,13.3016452789307,7.98006278806188,31.3699990510941,-0.000721571076421573,-0.000111288758544101,1,-2.51551663625893E-9,,,,,,,,,,,,,,,,,,,,,15.1063194274902,15.1945667266846,99.6003341674805,99.6003341674805,54.7382268302558,5.62392019452751,7.61164855957031,133,1,0,0,1,0.468673706054687,34.2131004333496,6,1,1,15.1945667266846,0,742397248,15.1504430770874,,,,,,,,,,,,,,,,,,,,,,,,,,,,,,,,,
,3842629798.88053,15.7863006591797,99.6003341674805,-3.71962518447071E-7,6.64541188498111E-9,1,10,13.3016452789307,7.98013865919624,31.3699990510941,-0.000730945311122914,-0.000104635974197311,1,1.48794401488604E-9,,,,,,,,,,,,,,,,,,,,,15.7449789047241,15.8276224136353,99.6003341674805,99.6003341674805,54.9410594309962,5.62379258946848,7.61369371414185,133,1,0,0,1,0.470428466796875,34.2131004333496,2,1,1,15.8276224136353,0,742397248,15.7863006591797,,,,,,,,,,,,,,,,,,,,,,,,,,,,,,,,,
,3842629868.88641,16.3754367828369,99.6003341674805,-3.68729495482573E-7,6.61689175980096E-9,1,10,13.3016452789307,7.98013048805243,31.3699990510941,-0.000724614297491669,-0.000103572714325131,1,1.5532847130566E-9,,,,,,,,,,,,,,,,,,,,,16.3356132507324,16.4152603149414,99.6003341674805,99.6003341674805,54.9367604741404,5.62347628192448,7.63836812973022,133,1,0,0,1,0.4693603515625,33.7243423461914,2,1,1,16.4152603149414,0,742397472,16.3754367828369,,,,,,,,,,,,,,,,,,,,,,,,,,,,,,,,,
,3842629938.92206,16.9485168457031,99.6003341674805,-3.70473755646494E-7,6.73079967499063E-9,1,10,13.3016452789307,7.98009891523461,31.3699990510941,-0.000728104322741916,-0.000103628486048161,1,1.7815872468106E-9,,,,,,,,,,,,,,,,,,,,,16.9083003997803,16.988733291626,99.6003341674805,99.6003341674805,54.9336339600635,5.62424855967732,7.64363718032837,133,1,0,0,1,0.462875366210937,34.2131004333496,2,1,1,16.988733291626,0,742397344,16.9485168457031,,,,,,,,,,,,,,,,,,,,,,,,,,,,,,,,,
,3842630008.96077,17.5247659683228,99.6003341674805,-3.73257124500042E-7,6.20755658908635E-9,1,10,13.3016452789307,7.98003466487496,31.3699990510941,-0.000732412613654757,-0.000112275715009216,1,-2.21185503976415E-9,,,,,,,,,,,,,,,,,,,,,17.4849166870117,17.5646152496338,99.6003341674805,99.6003341674805,54.8402293520154,5.62414046978341,7.66085958480835,133,1,0,0,1,0.468597412109375,34.2131004333496,2,1,1,17.5646152496338,0,742397344,17.5247659683228,,,,,,,,,,,,,,,,,,,,,,,,,,,,,,,,,
,3842630078.96825,18.09827709198,99.6003341674805,-3.7264300724352E-7,6.66263656061725E-9,1,10,13.3016452789307,7.98025224896137,31.3699990510941,-0.000732425874627733,-0.000103894716551417,1,1.96599395986991E-9,,,,,,,,,,,,,,,,,,,,,18.0588130950928,18.1377410888672,99.6003341674805,99.6003341674805,54.96763480065,5.62403952304337,7.66786909103394,133,1,0,0,1,0.464401245117188,34.2131004333496,2,1,1,18.1377410888672,0,742397312,18.09827709198,,,,,,,,,,,,,,,,,,,,,,,,,,,,,,,,,
,3842630148.88299,18.6727304458618,99.6003341674805,-3.70389136486273E-7,6.65523066985979E-9,1,10,13.3016452789307,7.98026198884132,31.3699990510941,-0.000727212726850444,-0.000108589072690187,1,-7.56064954120871E-10,,,,,,,,,,,,,,,,,,,,,18.6338901519775,18.7115707397461,99.6003341674805,99.6003341674805,54.914874875602,5.62324743434903,7.69171619415283,133,1,0,0,1,0.467453002929687,33.2355842590332,2,1,1,18.7115707397461,0,742397280,18.6727304458618,,,,,,,,,,,,,,,,,,,,,,,,,,,,,,,,,
,3842630218.88129,19.2451515197754,99.6003341674805,-3.68556204821689E-7,6.37696647845158E-9,1,10,13.3016452789307,7.98018994100657,31.3699990510941,-0.000722911924159257,-0.000112794440166274,1,-3.16749518521134E-9,,,,,,,,,,,,,,,,,,,,,19.2030639648438,19.287239074707,99.6003341674805,99.6003341674805,54.8140447966212,5.62414291843641,7.71223402023315,133,1,0,0,1,0.463027954101562,34.2131004333496,2,1,1,19.287239074707,0,742397312,19.2451515197754,,,,,,,,,,,,,,,,,,,,,,,,,,,,,,,,,
,3842630288.83075,19.8638038635254,99.6003341674805,-3.71421960455063E-7,6.67603708083932E-9,1,10,13.3016452789307,7.98026041481815,31.3699990510941,-0.00072998317283935,-0.000103847537323833,1,1.81026472881554E-9,,,,,,,,,,,,,,,,,,,,,19.7796669006348,19.947940826416,99.6003341674805,99.6003341674805,54.8015387403135,5.62334228969344,7.72499942779541,133,1,0,0,1,0.461807250976562,34.2131004333496,6,1,1,19.947940826416,0,742397120,19.8638038635254,,,,,,,,,,,,,,,,,,,,,,,,,,,,,,,,,
,3842630358.82952,20.0000419616699,99.6003341674805,-3.72638229900954E-7,6.9109026140934E-9,1,10,13.3016452789307,7.98005356289374,31.3699990510941,-0.000731683057839418,-0.000108803319542488,1,-5.34822707666921E-10,,,,,,,,,,,,,,,,,,,,,19.9999542236328,20.000129699707,99.6003341674805,99.6003341674805,54.8585976222173,5.62387640412418,7.7311897277832,133,1,0,0,1,0.468368530273438,33.7243423461914,1,1,1,19.9999542236328,0,742397184,20.0000419616699,,,,,,,,,,,,,,,,,,,,,,,,,,,,,,,,,
,3842630428.8662,23.7930936813354,99.6003341674805,-3.74962533581799E-7,7.21165356347321E-9,1,10,13.3016452789307,7.98008250458234,31.3800014555454,-0.000735834462661151,-0.000112293475120362,1,-1.96960684023545E-9,,,,,,,,,,,,,,,,,,,,,23.3947162628174,24.1914710998535,99.6003341674805,99.6003341674805,54.8042744401308,5.62413502645293,7.83076238632202,133,1,0,0,1,0.466232299804687,34.2131004333496,2,1,1,24.1914710998535,0,742397248,23.7930936813354,,,,,,,,,,,,,,,,,,,,,,,,,,,,,,,,,
,3842630498.76883,29.3327951431274,99.6003341674805,-3.7182646390638E-7,6.82731631509014E-9,1,10,13.3016452789307,7.98014158070257,31.3800014555454,-0.000730163475356993,-0.000108092960317281,1,-2.92299578571641E-10,,,,,,,,,,,,,,,,,,,,,28.9362258911133,29.7293643951416,99.6003341674805,99.6003341674805,54.7476063724866,5.6235514335229,7.94522762298584,133,1,0,0,1,0.466384887695313,34.2131004333496,2,1,1,29.7293643951416,0,742397056,29.3327951431274,,,,,,,,,,,,,,,,,,,,,,,,,,,,,,,,,
,3842630568.85317,34.9270648956299,99.6003341674805,-3.70635831743149E-7,6.6436366334292E-9,1,10,13.3016452789307,7.980108973172,31.3800014555454,-0.000728481631126407,-0.000103278227191825,1,1.98383287756654E-9,,,,,,,,,,,,,,,,,,,,,34.5347213745117,35.319408416748,99.6003341674805,99.6003341674805,55.0692465081501,5.62368930147532,8.02538776397705,133,1,0,0,1,0.460586547851562,33.7243423461914,2,1,1,35.319408416748,0,742397280,34.9270648956299,,,,,,,,,,,,,,,,,,,,,,,,,,,,,,,,,
,3842630638.78915,40.5356597900391,99.6003341674805,-3.72591881663583E-7,6.6431007116682E-9,1,10,13.3016452789307,7.98017247009593,31.3900001347065,-0.000732197622361477,-0.00010471957183131,1,1.53817042200621E-9,,,,,,,,,,,,,,,,,,,,,40.1469802856445,40.9243392944336,99.6003341674805,99.6003341674805,54.7866877984481,5.62388220996889,8.10392951965332,133,1,0,0,1,0.46630859375,34.2131004333496,2,1,1,40.9243392944336,0,742397408,40.5356597900391,,,,,,,,,,,,,,,,,,,,,,,,,,,,,,,,,
,3842630708.77418,46.1359272003174,99.6003341674805,-3.73171029565417E-7,6.82650476876669E-9,1,10,13.3016452789307,7.98009395618233,31.3900001347065,-0.000733190366200166,-0.000105841407438625,1,1.05192951190007E-9,,,,,,,,,,,,,,,,,,,,,45.743465423584,46.5283889770508,99.6003341674805,99.6003341674805,54.8625057648135,5.62402673463221,8.17105579376221,133,1,0,0,1,0.468826293945313,33.7243423461914,2,1,1,46.5283889770508,0,742397216,46.1359272003174,,,,,,,,,,,,,,,,,,,,,,,,,,,,,,,,,
,3842630778.77239,51.7848949432373,99.6003341674805,-3.74089048895682E-7,6.39796356777697E-9,1,10,13.3016452789307,7.97996419744229,31.3999988138676,-0.000734202704187497,-0.000111429670065433,1,-1.65885748959744E-9,,,,,,,,,,,,,,,,,,,,,51.3875427246094,52.1822471618652,99.6003341674805,99.6003341674805,54.8777475209385,5.62466203586344,8.22967529296875,133,1,0,0,1,0.46600341796875,33.7243423461914,2,1,1,52.1822471618652,0,742397440,51.7848949432373,,,,,,,,,,,,,,,,,,,,,,,,,,,,,,,,,
,3842630848.75081,57.4266529083252,99.6003341674805,-3.70119712586313E-7,6.28900319396826E-9,1,10,13.3016452789307,7.98000332175389,31.3999988138676,-0.000727221951253353,-0.000104762422229928,1,1.15172114848392E-9,,,,,,,,,,,,,,,,,,,,,57.023021697998,57.8302841186523,99.6003341674805,99.6003341674805,54.8023203688327,5.62416091088028,8.28499412536621,133,1,0,0,1,0.465164184570313,34.7018585205078,2,1,1,57.8302841186523,0,742397248,57.4266529083252,,,,,,,,,,,,,,,,,,,,,,,,,,,,,,,,,
,3842630918.759,63.1177024841309,99.6003341674805,-3.71312998271695E-7,6.64382283516406E-9,1,10,13.3016452789307,7.97987622560199,31.4100012183189,-0.000729879908200654,-0.000102926444028829,1,2.26179423332333E-9,,,,,,,,,,,,,,,,,,,,,62.7293128967285,63.5060920715332,99.6003341674805,99.6003341674805,54.94731245915,5.62383751410448,8.33933353424072,133,1,0,0,1,0.462493896484375,34.2131004333496,2,1,1,63.5060920715332,0,742397248,63.1177024841309,,,,,,,,,,,,,,,,,,,,,,,,,,,,,,,,,
,3842630988.78107,68.8091735839844,99.6003341674805,-3.67423060013042E-7,6.46515588668437E-9,1,10,13.3016452789307,7.98003267831681,31.4100012183189,-0.000721100282527216,-0.000109600601158911,1,-1.70872770538009E-9,,,,,,,,,,,,,,,,,,,,,68.4065628051758,69.211784362793,99.6003341674805,99.6003341674805,54.8468731944289,5.62521822799602,8.3664722442627,133,1,0,0,1,0.463943481445313,34.2131004333496,2,1,1,69.211784362793,0,742397248,68.8091735839844,,,,,,,,,,,,,,,,,,,,,,,,,,,,,,,,,
,3842631058.74968,74.4993057250977,99.6003341674805,-3.69203213798833E-7,6.22249808940188E-9,1,10,13.3016452789307,7.97993083305949,31.41999989748,-0.000725127273071434,-0.000106473421909904,1,1.45288916978741E-10,,,,,,,,,,,,,,,,,,,,,74.0776443481445,74.9209671020508,99.6003341674805,99.6003341674805,54.8859546203904,5.62453511782042,8.40815353393555,133,1,0,0,1,0.4656982421875,34.2131004333496,2,1,1,74.9209671020508,0,742397216,74.4993057250977,,,,,,,,,,,,,,,,,,,,,,,,,,,,,,,,,
,3842631128.73348,80.1760597229004,99.6003341674805,-3.68902823990787E-7,6.80399019668561E-9,1,10,13.3016452789307,7.98023562224399,31.4299985766411,-0.000724692205437341,-0.000105443067100118,1,6.26860277417669E-10,,,,,,,,,,,,,,,,,,,,,79.7874069213867,80.5647125244141,99.6003341674805,99.6003341674805,54.8066193256885,5.62391023385525,8.43443965911865,133,1,0,0,1,0.462646484375,33.7243423461914,2,1,1,80.5647125244141,0,742397216,80.1760597229004,,,,,,,,,,,,,,,,,,,,,,,,,,,,,,,,,
,3842631198.78728,85.9125099182129,99.6003341674805,-3.68934087599166E-7,6.82953118803677E-9,1,10,13.3016452789307,7.98029711666287,31.4400009810925,-0.000724082706500914,-0.000110030595451863,1,-1.70414747857226E-9,,,,,,,,,,,,,,,,,,,,,85.5174789428711,86.3075408935547,99.6003341674805,99.6003341674805,54.7702735995443,5.62336321536826,8.46369647979736,133,1,0,0,1,0.4644775390625,34.2131004333496,2,1,1,86.3075408935547,0,742397376,85.9125099182129,,,,,,,,,,,,,,,,,,,,,,,,,,,,,,,,,
,3842631268.80316,91.726001739502,99.6003341674805,-3.67966719169052E-7,6.8347090192843E-9,1,10,13.3016452789307,7.97999484733201,31.4499996602535,-0.000723131319080564,-0.000103201658818995,1,1.62940589697899E-9,,,,,,,,,,,,,,,,,,,,,91.3220443725586,92.1299591064453,99.6003341674805,99.6003341674805,54.6878117907654,5.62424172747796,8.47800159454346,132,1,64,0,0,0.464630126953125,33.7243423461914,2,1,1,92.1299591064453,0,742397248,91.726001739502,,,,,,,,,,,,,,,,,,,,,,,,,,,,,,,,,
,3842631339.00136,97.5175399780273,99.6003341674805,-3.71802456215448E-7,6.46430705852892E-9,1,10,13.3016452789307,7.98031377502703,31.4599983394146,-0.000730436549132892,-0.000105972825409965,1,7.8434951099898E-10,,,,,,,,,,,,,,,,,,,,,97.1367950439453,97.8982849121094,99.6003341674805,99.6003341674805,54.8785291494577,5.62429832036476,8.50687599182129,132,1,64,0,0,0.46295166015625,33.7243423461914,2,1,1,97.8982849121094,0,742397248,97.5175399780273,,,,,,,,,,,,,,,,,,,,,,,,,,,,,,,,,
,3842631408.69382,103.264060974121,99.6003341674805,-3.67284875105403E-7,6.39128550386312E-9,1,10,13.3016452789307,7.98002080452452,31.470000743866,-0.000721458274708129,-0.000105281822570769,1,4.69926912422324E-10,,,,,,,,,,,,,,,,,,,,,102.866142272949,103.661979675293,99.6003341674805,99.6003341674805,54.7769174419577,5.62442247605432,8.53461074829102,133,1,0,0,1,0.4718017578125,33.7243423461914,2,1,1,103.661979675293,0,742397216,103.264060974121,,,,,,,,,,,,,,,,,,,,,,,,,,,,,,,,,
,3842631478.63952,109.061679840088,99.6003341674805,-3.65615928526734E-7,6.60455496365335E-9,1,10,13.3016452789307,7.98008077945555,31.4900018274784,-0.000717527225257029,-0.000109257809765662,1,-1.80007020474756E-9,,,,,,,,,,,,,,,,,,,,,108.646255493164,109.477104187012,99.6003341674805,99.6003341674805,54.8722761213039,5.62362494975721,8.56040382385254,133,1,0,0,1,0.469436645507812,33.7243423461914,2,1,1,109.477104187012,0,742397440,109.061679840088,,,,,,,,,,,,,,,,,,,,,,,,,,,,,,,,,
,3842631548.78155,114.869037628174,99.6003341674805,-3.68832128214993E-7,6.69503576542328E-9,1,10,13.3016452789307,7.97989696816318,31.5000005066395,-0.000724353029719775,-0.000106662842391453,1,-5.9286421970642E-12,,,,,,,,,,,,,,,,,,,,,114.43497467041,115.303100585938,99.6003341674805,99.6003341674805,54.6241090664481,5.6249306123794,8.58633327484131,131,1,64,0,0,0.46722412109375,34.2131004333496,2,1,1,115.303100585938,0,742397152,114.869037628174,,,,,,,,,,,,,,,,,,,,,,,,,,,,,,,,,
,3842631618.6932,120.644050598145,99.6003341674805,-3.6490950231287E-7,6.4973962895069E-9,1,10,13.3016452789307,7.98006079376899,31.5200015902519,-0.000717028643671015,-0.000103009966198269,1,1.27712448110834E-9,,,,,,,,,,,,,,,,,,,,,120.258888244629,121.02921295166,99.6003341674805,99.6003341674805,54.787860241227,5.62503235588063,8.59215545654297,133,1,0,0,1,0.463790893554687,34.2131004333496,2,1,1,121.02921295166,0,742397280,120.644050598145,,,,,,,,,,,,,,,,,,,,,,,,,,,,,,,,,
,3842631688.73392,126.541927337646,99.6003341674805,-3.68611151849231E-7,6.59855856114441E-9,1,10,13.3016452789307,7.97979103771291,31.530000269413,-0.000725272178222588,-9.73711185792318E-5,1,4.69239048461644E-9,,,,,,,,,,,,,,,,,,,,,126.165863037109,126.917991638184,99.6003341674805,99.6003341674805,54.9672439863904,5.6250674488316,8.58974456787109,133,1,0,0,1,0.462875366210937,34.2131004333496,2,1,1,126.917991638184,0,742397408,126.541927337646,,,,,,,,,,,,,,,,,,,,,,,,,,,,,,,,,
,3842631758.81294,132.267608642578,99.6003341674805,-3.70858922768464E-7,6.46879263142953E-9,1,10,13.3016452789307,7.97984111181557,31.5500013530254,-0.000728086166789541,-0.000108908649119966,1,-8.51266276267203E-10,,,,,,,,,,,,,,,,,,,,,131.861419677734,132.673797607422,99.6003341674805,99.6003341674805,54.7409625300731,5.62515502757602,8.59793186187744,131,1,64,0,0,0.463409423828125,33.2355842590332,2,1,1,132.673797607422,0,742397312,132.267608642578,,,,,,,,,,,,,,,,,,,,,,,,,,,,,,,,,
,3842631828.77331,138.091102600098,99.6003341674805,-3.70264430259335E-7,6.59782507192938E-9,1,10,13.3016452789307,7.97975853910659,31.5600000321865,-0.000727477921092207,-0.000104908733585977,1,1.09760453725451E-9,,,,,,,,,,,,,,,,,,,,,137.687942504883,138.494262695312,99.6003341674805,99.6003341674805,54.8128723538423,5.62528308971237,8.62238216400146,133,1,0,0,1,0.46356201171875,34.2131004333496,2,1,1,138.494262695312,0,742397248,138.091102600098,,,,,,,,,,,,,,,,,,,,,,,,,,,,,,,,,
,3842631898.58294,143.880043029785,99.6003341674805,-3.68693058602593E-7,6.98910678335573E-9,1,10,13.3016452789307,7.97979976513622,31.580001115799,-0.000724472972283743,-0.000103918467879056,1,1.37063167166466E-9,,,,,,,,,,,,,,,,,,,,,143.456893920898,144.303192138672,99.6003341674805,99.6003341674805,54.7171228602366,5.62542422930871,8.62396335601807,133,1,0,0,1,0.46417236328125,34.2131004333496,2,1,1,144.303192138672,0,742397216,143.880043029785,,,,,,,,,,,,,,,,,,,,,,,,,,,,,,,,,
,3842631968.84426,149.759132385254,99.6003341674805,-3.72335139455791E-7,6.53070431155634E-9,1,10,13.3016452789307,7.97991483847057,31.5999984741211,-0.00073162071555527,-0.000105046476636135,1,1.33294151247968E-9,,,,,,,,,,,,,,,,,,,,,149.364700317383,150.153564453125,99.6003341674805,99.6003341674805,54.9058861476308,5.62487110174405,8.62642192840576,131,1,64,0,0,0.46539306640625,34.2131004333496,2,1,1,150.153564453125,0,742397248,149.759132385254,,,,,,,,,,,,,,,,,,,,,,,,,,,,,,,,,
,3842632038.60558,155.507789611816,99.6003341674805,-3.71274055746244E-7,6.34162563108447E-9,1,10,13.3016452789307,7.97986671043047,31.6199995577335,-0.000729536137666571,-0.000104727166702306,1,1.33911839953497E-9,,,,,,,,,,,,,,,,,,,,,155.096572875977,155.919006347656,99.6003341674805,99.6003341674805,54.9000239337366,5.62506510864925,8.6333646774292,133,1,0,0,1,0.463790893554687,34.2131004333496,2,1,1,155.919006347656,0,742397184,155.507789611816,,,,,,,,,,,,,,,,,,,,,,,,,,,,,,,,,
,3842632108.80813,161.295967102051,99.6003341674805,-3.6941105002133E-7,6.67101664444753E-9,1,10,13.3016452789307,7.97992529246097,31.640000641346,-0.000725823221908225,-0.000104577031424151,1,1.1414844059445E-9,,,,,,,,,,,,,,,,,,,,,160.909912109375,161.682022094727,99.6003341674805,99.6003341674805,54.7956765264193,5.62420103127818,8.65937995910644,132,1,64,0,0,0.46356201171875,34.2131004333496,2,1,1,161.682022094727,0,742397248,161.295967102051,,,,,,,,,,,,,,,,,,,,,,,,,,,,,,,,,
,3842632178.641,167.108139038086,99.6003341674805,-3.67157338559225E-7,6.89642820609084E-9,1,10,13.3016452789307,7.98000323993553,31.6600017249584,-0.000722006484760385,-9.98142230419047E-5,1,3.23509281789247E-9,,,,,,,,,,,,,,,,,,,,,166.711242675781,167.505035400391,99.6003341674805,99.6003341674805,54.8933800913231,5.62537751530932,8.6704568862915,133,1,0,0,1,0.470428466796875,34.2131004333496,2,1,1,167.505035400391,0,742397216,167.108139038086,,,,,,,,,,,,,,,,,,,,,,,,,,,,,,,,,
,3842632248.7567,172.935585021973,99.6003341674805,-3.6811088249943E-7,6.83270128418071E-9,1,10,13.3016452789307,7.98003717124009,31.6799990832806,-0.000723433544681854,-0.000103128645198407,1,1.68796649319621E-9,,,,,,,,,,,,,,,,,,,,,172.536392211914,173.334777832031,99.6003341674805,99.6003341674805,54.9031504478135,5.62446293643204,8.67863750457764,132,1,64,0,0,0.46875,34.2131004333496,2,1,1,173.334777832031,0,742397312,172.935585021973,,,,,,,,,,,,,,,,,,,,,,,,,,,,,,,,,
,3842632318.61103,178.756340026855,99.6003341674805,-3.77829136745822E-7,6.92773681701917E-9,1,10,13.3016452789307,7.97996985465077,31.700000166893,-0.000741749884589088,-0.00011114172627316,1,-9.61542150231784E-10,,,,,,,,,,,,,,,,,,,,,178.327941894531,179.18473815918,99.6003341674805,99.6003341674805,54.779653141775,5.62549358206676,8.69128513336182,133,1,0,0,1,0.463790893554687,34.2131004333496,2,1,1,179.18473815918,0,742397344,178.756340026855,,,,,,,,,,,,,,,,,,,,,,,,,,,,,,,,,
,3842632388.65044,184.531196594238,99.6003341674805,-3.71296131809899E-7,6.64965799648542E-9,1,10,13.3016452789307,7.97973259969779,31.7200012505054,-0.000729815926856535,-0.000103079731330394,1,2.18072554172978E-9,,,,,,,,,,,,,,,,,,,,,184.125930786133,184.936462402344,99.6003341674805,99.6003341674805,54.8116999110635,5.62524337891134,8.6929292678833,132,1,64,0,0,0.463485717773438,33.7243423461914,2,1,1,184.936462402344,0,742397152,184.531196594238,,,,,,,,,,,,,,,,,,,,,,,,,,,,,,,,,
,3842632458.57025,190.326965332031,99.6003341674805,-3.69326152614575E-7,6.57477587668012E-9,1,10,13.3016452789307,7.97970179639771,31.7399986088276,-0.000725762964349624,-0.000103749755106964,1,1.5493868101974E-9,,,,,,,,,,,,,,,,,,,,,189.91227722168,190.741653442383,99.6003341674805,99.6003341674805,54.7925500123423,5.62572230016734,8.69600582122803,133,1,0,0,1,0.4644775390625,34.2131004333496,2,1,1,190.741653442383,0,742397280,190.326965332031,,,,,,,,,,,,,,,,,,,,,,,,,,,,,,,,,
,3842632528.74978,196.180587768555,99.6003341674805,-3.6960999691692E-7,7.36834134158164E-9,1,10,13.3016452789307,7.97974898166878,31.7699983716011,-0.000726689270577397,-0.000101343362755547,1,2.81667219693215E-9,,,,,,,,,,,,,,,,,,,,,195.800323486328,196.560852050781,99.6003341674805,99.6003341674805,54.9332431458039,5.6256691453343,8.70908355712891,132,1,64,0,0,0.465164184570313,34.2131004333496,2,1,1,196.560852050781,0,742397312,196.180587768555,,,,,,,,,,,,,,,,,,,,,,,,,,,,,,,,,
,3842632598.54665,202.005294799805,99.6003341674805,-3.75201058557594E-7,6.85605429953826E-9,1,10,13.3016452789307,7.97983322510572,31.7899994552135,-0.000737406676871992,-0.000104775721830845,1,1.89246507218405E-9,,,,,,,,,,,,,,,,,,,,,201.583145141602,202.427444458008,99.6003341674805,99.6003341674805,54.9977274986404,5.62534853100776,8.71746349334717,133,1,0,0,1,0.468292236328125,34.2131004333496,2,1,1,202.427444458008,0,742397216,202.005294799805,,,,,,,,,,,,,,,,,,,,,,,,,,,,,,,,,
,3842632668.7476,207.788673400879,99.6003341674805,-3.76274824000431E-7,6.92797077099055E-9,1,10,13.3016452789307,7.98021665254695,31.8199992179871,-0.000739433029538958,-0.00010578506986941,1,1.5380736218415E-9,,,,,,,,,,,,,,,,,,,,,207.408935546875,208.168411254883,99.6003341674805,99.6003341674805,54.6932831904,5.62465811148658,8.7303581237793,132,1,64,0,0,0.465774536132812,34.2131004333496,2,1,1,208.168411254883,0,742397248,207.788673400879,,,,,,,,,,,,,,,,,,,,,,,,,,,,,,,,,
,3842632738.52749,213.597450256348,99.6003341674805,-3.76927295034504E-7,6.49808987820748E-9,1,10,13.3016452789307,7.980082036557,31.8400003015995,-0.000740055556452604,-0.000110399955027409,1,-7.1618135427563E-10,,,,,,,,,,,,,,,,,,,,,213.18603515625,214.008865356445,99.6003341674805,99.6003341674805,54.8566435509193,5.62486940598976,8.75319385528564,133,1,0,0,1,0.463027954101562,34.7018585205078,2,1,1,214.008865356445,0,742397312,213.597450256348,,,,,,,,,,,,,,,,,,,,,,,,,,,,,,,,,
,3842632808.67107,219.403518676758,99.6003341674805,-3.79292229236052E-7,6.73819649410985E-9,1,10,13.3016452789307,7.98009675851307,31.870000064373,-0.000744803824106577,-0.000110385024589084,1,-3.60316748976861E-10,,,,,,,,,,,,,,,,,,,,,219.008377075195,219.79866027832,99.6003341674805,99.6003341674805,54.728847288025,5.62472009845132,8.75327301025391,131,1,64,0,0,0.4681396484375,33.2355842590332,2,1,1,219.79866027832,0,742397216,219.403518676758,,,,,,,,,,,,,,,,,,,,,,,,,,,,,,,,,
,3842632878.49656,225.208755493164,99.6003341674805,-3.78608435630223E-7,6.708624026564E-9,1,10,13.3016452789307,7.98013309151988,31.8999998271465,-0.000743735147620005,-0.000108337870201707,1,5.8151585384187E-10,,,,,,,,,,,,,,,,,,,,,224.820846557617,225.596664428711,99.6003341674805,99.6003341674805,55.0735454650058,5.62443467486352,8.76295852661133,133,1,0,0,1,0.469207763671875,34.2131004333496,2,1,1,225.615859985352,0,742397248,225.208755493164,,,,,,,,,,,,,,,,,,,,,,,,,,,,,,,,,
,3842632948.77927,231.03564453125,99.6003341674805,-3.82446926732372E-7,6.74089442259756E-9,1,10,13.3016452789307,7.98031458116519,31.92999958992,-0.000751421154215507,-0.000108513524123356,1,1.05795044864605E-9,,,,,,,,,,,,,,,,,,,,,230.636932373047,231.434356689453,99.6003341674805,99.6003341674805,54.9637266580539,5.62435709176493,8.79212379455566,132,1,64,0,0,0.467758178710937,33.2355842590332,2,1,1,231.434356689453,0,742397344,231.03564453125,,,,,,,,,,,,,,,,,,,,,,,,,,,,,,,,,
,3842633018.49474,236.82014465332,99.6003341674805,-3.79130903877275E-7,6.58020221959471E-9,1,10,13.3016452789307,7.98016491741954,31.9500006735325,-0.000745011258330787,-0.00010680255444436,1,1.44031447259085E-9,,,,,,,,,,,,,,,,,,,,,236.406143188477,237.234146118164,99.6003341674805,99.6003341674805,55.0954310635443,5.62420490289873,8.83799934387207,133,1,0,0,1,0.470962524414063,34.7018585205078,2,1,1,237.234146118164,0,742397184,236.82014465332,,,,,,,,,,,,,,,,,,,,,,,,,,,,,,,,,
,3842633088.58105,242.646675109863,99.6003341674805,-3.82440909365332E-7,6.50771146066714E-9,1,10,13.3016452789307,7.98060178515097,31.980000436306,-0.000751197439384402,-0.000110056796819985,1,2.72411106308028E-10,,,,,,,,,,,,,,,,,,,,,242.251434326172,243.041915893555,99.6003341674805,99.6003341674805,54.9160473183808,5.62398719333972,8.8969259262085,131,1,64,0,0,0.468978881835937,34.2131004333496,2,1,1,243.041915893555,0,742397344,242.646675109863,,,,,,,,,,,,,,,,,,,,,,,,,,,,,,,,,
,3842633158.56132,248.495315551758,99.6003341674805,-3.79457277724653E-7,6.41777733360419E-9,1,10,13.3016452789307,7.9803669769167,32.0100001990795,-0.000745497937274466,-0.000108018827272083,1,8.69855690252607E-10,,,,,,,,,,,,,,,,,,,,,248.09228515625,248.898345947266,99.6003341674805,99.6003341674805,54.9629450295347,5.62381048728565,9.0061559677124,133,1,0,0,1,0.468368530273438,34.2131004333496,2,1,1,248.898345947266,0,742397248,248.495315551758,,,,,,,,,,,,,,,,,,,,,,,,,,,,,,,,,
,3842633228.69892,254.26985168457,99.6003341674805,-3.81297017493943E-7,6.7016952064277E-9,1,10,13.3016452789307,7.98021227700209,32.039999961853,-0.000748244346899341,-0.000114381127556332,1,-2.09939914956702E-9,,,,,,,,,,,,,,,,,,,,,253.888549804687,254.651153564453,99.6003341674805,99.6003341674805,54.9664623578712,5.6247932202706,9.16286468505859,131,1,64,0,0,0.465469360351562,33.7243423461914,2,1,1,254.651153564453,0,742397248,254.26985168457,,,,,,,,,,,,,,,,,,,,,,,,,,,,,,,,,
,3842633298.47551,260.089828491211,99.6003341674805,-3.80932989637954E-7,6.53528294853279E-9,1,10,13.3016452789307,7.98033626396122,32.0699997246265,-0.000748483049374282,-0.0001078444550087,1,1.17579972230705E-9,,,,,,,,,,,,,,,,,,,,,259.669097900391,260.510559082031,99.6003341674805,99.6003341674805,54.921909532275,5.62478510020553,9.210524559021,133,1,0,0,1,0.469284057617188,34.2131004333496,2,1,1,260.510559082031,0,742397376,260.089828491211,,,,,,,,,,,,,,,,,,,,,,,,,,,,,,,,,
,3842633368.67011,265.901397705078,99.6003341674805,-3.83820172205631E-7,6.71910605989037E-9,1,10,13.3016452789307,7.98022226134328,32.1099981665611,-0.000754458334567104,-0.000106566141305248,1,2.25134057075902E-9,,,,,,,,,,,,,,,,,,,,,265.516326904297,266.286468505859,99.6003341674805,99.6003341674805,55.0149233260635,5.62429852307307,9.14837074279785,132,1,64,0,0,0.471115112304687,34.2131004333496,2,1,1,266.286468505859,0,742397280,265.901397705078,,,,,,,,,,,,,,,,,,,,,,,,,,,,,,,,,
,3842633438.41891,271.699234008789,99.6003341674805,-3.85381753881707E-7,6.81763766092488E-9,1,10,13.3016452789307,7.98002780959126,32.1400016546249,-0.000756760785174516,-0.000112137348975259,1,-3.56245534237628E-10,,,,,,,,,,,,,,,,,,,,,271.305847167969,272.092620849609,99.6003341674805,99.6003341674805,54.8757934496404,5.62507288208489,9.11591720581055,133,1,0,0,1,0.469894409179687,34.7018585205078,2,1,1,272.092620849609,0,742397248,271.699234008789,,,,,,,,,,,,,,,,,,,,,,,,,,,,,,,,,
,3842633508.40049,277.508819580078,99.6003341674805,-3.86906768243278E-7,6.39736636837226E-9,1,10,13.3016452789307,7.98026993511531,32.1700014173985,-0.000760554869867659,-0.000107241560391592,1,2.36207636529466E-9,,,,,,,,,,,,,,,,,,,,,277.110137939453,277.907501220703,99.6003341674805,99.6003341674805,54.9824857425154,5.6244905719461,9.13094139099121,133,1,0,0,1,0.465240478515625,34.7018585205078,2,1,1,277.943023681641,0,742397248,277.508819580078,,,,,,,,,,,,,,,,,,,,,,,,,,,,,,,,,
,3842633578.58439,283.35481262207,99.6003341674805,-3.86386979030428E-7,6.44319469671964E-9,1,10,13.3016452789307,7.98017600739688,32.209999859333,-0.000759062447404613,-0.000110259116543537,1,7.48711380182248E-10,,,,,,,,,,,,,,,,,,,,,282.957397460938,283.752227783203,99.6003341674805,99.6003341674805,54.8554711081404,5.62480381657031,9.18532848358154,132,1,64,0,0,0.465316772460937,34.7018585205078,2,1,1,283.752227783203,0,742397248,283.35481262207,,,,,,,,,,,,,,,,,,,,,,,,,,,,,,,,,
,3842633648.37172,289.104766845703,99.6003341674805,-3.8867354477263E-7,6.55132591700481E-9,1,10,13.3016452789307,7.98006004201462,32.2399996221066,-0.000763591121442874,-0.000110619009189608,1,9.016654291675E-10,,,,,,,,,,,,,,,,,,,,,288.695678710937,289.513854980469,99.6003341674805,99.6003341674805,54.8320222525635,5.62508234027627,9.2349271774292,133,1,0,0,1,0.465316772460937,34.2131004333496,2,1,1,289.513854980469,0,742397184,289.104766845703,,,,,,,,,,,,,,,,,,,,,,,,,,,,,,,,,
,3842633718.59366,294.980728149414,99.6003341674805,-3.8427106708014E-7,6.71612046083575E-9,1,10,13.3016452789307,7.98016161834392,32.2900004684925,-0.000755139247504049,-0.000108063847825375,1,1.55489722995641E-9,,,,,,,,,,,,,,,,,,,,,294.585205078125,295.376251220703,99.6003341674805,99.6003341674805,55.1466277315539,5.62452329889952,9.3405818939209,131,1,64,0,0,0.469741821289063,34.7018585205078,2,1,1,295.376251220703,0,742397344,294.980728149414,,,,,,,,,,,,,,,,,,,,,,,,,,,,,,,,,
,3842633788.61364,300.823501586914,99.6003341674805,-3.89579641675409E-7,6.98383877063076E-9,1,10,13.3016452789307,7.98009169093872,32.320000231266,-0.000766302400954712,-0.000104564550848147,1,4.11801165893175E-9,,,,,,,,,,,,,,,,,,,,,300.409790039063,301.237213134766,99.6003341674805,99.6003341674805,54.9394961739577,5.6244205161989,9.49561500549316,132,1,64,0,0,0.469207763671875,34.2131004333496,2,1,1,301.237213134766,0,742397312,300.823501586914,,,,,,,,,,,,,,,,,,,,,,,,,,,,,,,,,
,3842633858.47983,306.608978271484,99.6003341674805,-3.89554348730968E-7,6.56323410186531E-9,1,10,13.3016452789307,7.98008967769525,32.3499999940395,-0.000765223978641974,-0.000111543545732482,1,5.60713961523775E-10,,,,,,,,,,,,,,,,,,,,,306.209930419922,307.008026123047,99.6003341674805,99.6003341674805,54.996164241602,5.6245182646924,9.7782621383667,132,1,64,0,0,0.464324951171875,34.7018585205078,2,1,1,307.008026123047,0,742397216,306.608978271484,,,,,,,,,,,,,,,,,,,,,,,,,,,,,,,,,
,3842633928.47921,312.443496704102,99.6003341674805,-3.93121232806343E-7,6.47166171481034E-9,1,10,13.3016452789307,7.9801574950679,32.3899984359741,-0.000771358973583349,-0.000118510587164121,1,-2.4613019606708E-9,,,,,,,,,,,,,,,,,,,,,312.045715332031,312.841278076172,99.6003341674805,99.6003341674805,54.820297824775,5.62558492111236,10.2801647186279,132,1,64,0,0,0.465087890625,34.2131004333496,2,1,1,312.841278076172,0,742397280,312.443496704102,,,,,,,,,,,,,,,,,,,,,,,,,,,,,,,,,
,3842633998.68827,318.278289794922,99.6003341674805,-3.91302864235558E-7,6.63437195960389E-9,1,10,13.3016452789307,7.97983566063697,32.430000603199,-0.000767318774251053,-0.000121048833772011,1,-4.02285340261725E-9,,,,,,,,,,,,,,,,,,,,,317.869232177734,318.687347412109,99.6003341674805,99.6003341674805,54.9027596335539,5.62587532368484,11.023943901062,132,1,64,0,0,0.4705810546875,34.2131004333496,2,1,1,318.687347412109,0,742397248,318.278289794922,,,,,,,,,,,,,,,,,,,,,,,,,,,,,,,,,
,3842634068.62886,324.048675537109,99.6003341674805,-3.93474951159178E-7,6.83263064737026E-9,1,10,13.3016452789307,7.97971795406361,32.4600003659725,-0.000772728033718777,-0.000113865924963004,1,-4.6065770226075E-11,,,,,,,,,,,,,,,,,,,,,323.644989013672,324.452362060547,99.6003341674805,99.6003341674805,55.001244826977,5.62655074707961,11.1353340148926,131,1,64,0,0,0.46417236328125,34.7018585205078,2,1,1,324.452362060547,0,742397216,324.048675537109,,,,,,,,,,,,,,,,,,,,,,,,,,,,,,,,,
,3842634138.38235,329.846694946289,99.6003341674805,-3.97033756809872E-7,6.69196182156277E-9,1,10,13.3016452789307,7.97958083781836,32.490000128746,-0.000779363699639214,-0.000117242951291796,1,-1.24222029183368E-9,,,,,,,,,,,,,,,,,,,,,329.423309326172,330.270080566406,99.6003341674805,99.6003341674805,54.9469216448904,5.62692899586255,10.9577255249023,133,1,0,0,1,0.467453002929687,34.7018585205078,2,1,1,330.270080566406,0,742397312,329.846694946289,,,,,,,,,,,,,,,,,,,,,,,,,,,,,,,,,
,3842634208.58639,335.754730224609,99.6003341674805,-3.94066375052314E-7,7.09696544142376E-9,1,10,13.3016452789307,7.99005484387662,32.5199998915195,-0.00077475145021318,-0.000112097845476483,1,9.8288969371042E-10,,,,,,,,,,,,,,,,,,,,,335.383697509766,336.125762939453,99.6003341674805,99.6003341674805,54.9492665304481,5.6269548009695,10.8551559448242,131,1,64,0,0,0.464706420898438,34.2131004333496,2,1,1,336.125762939453,0,742397280,335.754730224609,,,,,,,,,,,,,,,,,,,,,,,,,,,,,,,,,
,3842634278.33636,341.450622558594,99.6003341674805,-3.94547374271683E-7,6.57908919919884E-9,1,10,13.3016452789307,7.98992646806975,32.5499996542931,-0.000774879568565652,-0.00011773876695398,1,-1.81705882092255E-9,,,,,,,,,,,,,,,,,,,,,341.050872802734,341.850372314453,99.6003341674805,99.6003341674805,55.0078886693904,5.62699224488226,10.7762985229492,133,1,0,0,1,0.469970703125,34.2131004333496,2,1,1,341.850372314453,0,742397376,341.450622558594,,,,,,,,,,,,,,,,,,,,,,,,,,,,,,,,,
,3842634348.55027,347.276519775391,99.6003341674805,-3.96756088201552E-7,6.53911143877642E-9,1,10,13.3016452789307,7.98979481627747,32.5900018215179,-0.000779313776785499,-0.00011769338281136,1,-1.46931756707132E-9,,,,,,,,,,,,,,,,,,,,,346.881958007812,347.671081542969,99.6003341674805,99.6003341674805,54.8093550255058,5.62724460804779,10.7068901062012,132,1,64,0,0,0.467910766601562,34.7018585205078,2,1,1,347.671081542969,0,742397280,347.276519775391,,,,,,,,,,,,,,,,,,,,,,,,,,,,,,,,,
,3842634418.32267,353.059432983398,99.6003341674805,-3.95111721369439E-7,6.72407154890755E-9,1,10,13.3016452789307,7.98969136746378,32.6099991798401,-0.000776408849089547,-0.000114959362776519,1,-3.20696253128292E-10,,,,,,,,,,,,,,,,,,,,,352.646514892578,353.472351074219,99.6003341674805,99.6003341674805,54.9738878288039,5.62843356516921,10.6614427566528,133,1,0,0,1,0.465087890625,34.7018585205078,2,1,1,353.472351074219,0,742397248,353.059432983398,,,,,,,,,,,,,,,,,,,,,,,,,,,,,,,,,
,3842634488.48924,358.89192199707,99.6003341674805,-3.96291746789093E-7,6.60805766137758E-9,1,10,13.3016452789307,7.98978804823316,32.650001347065,-0.000778356240314663,-0.000117861899058848,1,-1.62346037772738E-9,,,,,,,,,,,,,,,,,,,,,358.494903564453,359.288940429687,99.6003341674805,99.6003341674805,55.0614302229578,5.62804225191482,10.6124629974365,131,1,64,0,0,0.465927124023438,35.6793746948242,2,1,1,359.288940429687,0,742397120,358.89192199707,,,,,,,,,,,,,,,,,,,,,,,,,,,,,,,,,
,3842634558.33021,364.687515258789,99.6003341674805,-3.95467346409618E-7,6.63809820883605E-9,1,10,13.3016452789307,7.98976300142688,32.6800011098385,-0.000778069884130878,-0.000108554771101343,1,2.99082723016206E-9,,,,,,,,,,,,,,,,,,,,,364.254211425781,365.120819091797,99.6003341674805,99.6003341674805,54.9637266580539,5.62831164153641,10.5847177505493,133,1,0,0,1,0.466079711914063,34.7018585205078,2,1,1,365.120819091797,0,742397056,364.687515258789,,,,,,,,,,,,,,,,,,,,,,,,,,,,,,,,,
,3842634628.49156,370.52717590332,99.6003341674805,-4.01019334953731E-7,7.13175189724489E-9,1,10,13.3016452789307,7.98953970415042,32.7199995517731,-0.000787877079716993,-0.000117573791178218,1,-7.81834020720836E-10,,,,,,,,,,,,,,,,,,,,,370.131134033203,370.923217773438,99.6003341674805,99.6003341674805,54.9582552584193,5.62771780009435,10.5471878051758,132,1,64,0,0,0.467453002929687,34.2131004333496,2,1,1,370.923217773438,0,742397248,370.52717590332,,,,,,,,,,,,,,,,,,,,,,,,,,,,,,,,,
,3842634698.35004,376.418090820313,99.6003341674805,-3.98618141889722E-7,6.8852192628517E-9,1,10,13.3016452789307,7.98960108591537,32.7400006353855,-0.000783430145222937,-0.000115054996892935,1,1.46542109324912E-10,,,,,,,,,,,,,,,,,,,,,376.032012939453,376.804168701172,99.6003341674805,99.6003341674805,54.972715386025,5.62779125185439,10.5249814987183,133,1,0,0,1,0.470199584960937,34.2131004333496,2,1,1,376.823272705078,0,742397152,376.418090820313,,,,,,,,,,,,,,,,,,,,,,,,,,,,,,,,,
,3842634768.54953,382.13410949707,99.6003341674805,-3.99940485864382E-7,6.5760904235603E-9,1,10,13.3016452789307,7.98963159041755,32.7799990773201,-0.000786861461897606,-0.000109794668746099,1,3.01801818530634E-9,,,,,,,,,,,,,,,,,,,,,381.743621826172,382.524597167969,99.6003341674805,99.6003341674805,54.9211279037558,5.6283722998418,10.4869565963745,132,1,64,0,0,0.465164184570313,34.7018585205078,2,1,1,382.524597167969,0,742397440,382.13410949707,,,,,,,,,,,,,,,,,,,,,,,,,,,,,,,,,
,3842634838.29854,387.919677734375,99.6003341674805,-3.99606954541252E-7,6.64478243861248E-9,1,10,13.3016452789307,7.98955053308599,32.8099988400936,-0.000784913244716017,-0.000118447165408181,1,-1.43415028049166E-9,,,,,,,,,,,,,,,,,,,,,387.504913330078,388.334442138672,99.6003341674805,99.6003341674805,55.0399354386789,5.6284012383742,10.4700536727905,133,1,0,0,1,0.465240478515625,34.2131004333496,2,1,1,388.334442138672,0,742397472,387.919677734375,,,,,,,,,,,,,,,,,,,,,,,,,,,,,,,,,
,3842634908.53182,393.737884521484,99.6003341674805,-4.05175957236804E-7,6.94903009045263E-9,1,10,13.3016452789307,7.98954949529484,32.8599996864796,-0.000796492581402634,-0.000115746440329622,1,7.60042712268133E-10,,,,,,,,,,,,,,,,,,,,,393.343627929687,394.132141113281,99.6003341674805,99.6003341674805,54.9629450295347,5.62843031988071,10.4386720657349,132,1,64,0,0,0.46783447265625,34.7018585205078,2,1,1,394.132141113281,0,742397248,393.737884521484,,,,,,,,,,,,,,,,,,,,,,,,,,,,,,,,,
,3842634978.31114,399.13932800293,99.6003341674805,-4.049986652858E-7,6.86745070238365E-9,1,10,13.3016452789307,7.98949299295908,32.880000770092,-0.000795977556454648,-0.000116804735719604,1,1.95199123351025E-10,,,,,,,,,,,,,,,,,,,,,398.973358154297,399.305297851562,99.6003341674805,99.6003341674805,54.9394961739577,5.6285724786654,10.4255418777466,133,1,0,0,1,0.472335815429687,34.2131004333496,6,1,1,399.305297851562,0,742397152,399.13932800293,,,,,,,,,,,,,,,,,,,,,,,,,,,,,,,,,
,3842635048.2448,399.843276977539,99.6003341674805,-4.03344530943008E-7,6.63416879249761E-9,1,10,13.3016452789307,7.9895775425955,32.880000770092,-0.000793201839291272,-0.000113132270027429,1,1.82070034810363E-9,,,,,,,,,,,,,,,,,,,,,399.832214355469,399.854339599609,99.6003341674805,99.6003341674805,55.0528323092462,5.62851873519958,10.38987159729,133,1,0,0,1,0.464935302734375,34.7018585205078,5,1,1,399.854339599609,0,742397344,399.843276977539,,,,,,,,,,,,,,,,,,,,,,,,,,,,,,,,,
,3842635058.23399,399.864761352539,99.6003341674805,-4.01898711234921E-7,6.58498895052121E-9,1,10,13.3016452789307,7.98968808820205,32.880000770092,-0.000789875255150771,-0.000116051734136212,1,1.22742859644264E-10,,,,,,,,,,,,,,,,,,,,,399.854797363281,399.874725341797,99.6003341674805,99.6003341674805,55.021567168477,5.6287876503227,10.3869752883911,133,1,0,0,1,0.471267700195313,34.7018585205078,1,1,1,399.874725341797,0,742397440,399.864761352539,,,,,,,,,,,,,,,,,,,,,,,,,,,,,,,,,