File: demonstration_data/squid/000_MA2936-3_211005_Qrod_IP_buchner_standard_003_MT-w_100Oe_post-FC.dat
[Header]
; MPMS3 Data File (default extension .dat)
; Copyright (c) 2007, Quantum Design, Inc. All rights reserved.
TITLE,
FILEOPENTIME,3842618235.97531,10/05/2021,7:00 pm
BYAPP,MPMS3 w/ AC,1.0,1.1
INFO,MPMS3 Measurement Release 1.1.16 Build 424, MultiVu Release 2.3.4.19,APPNAME
INFO,Linear Motor Servo Controller,MOTOR_MODULE_NAME
INFO,3101-100 J0,MOTOR_HW_VERSION
INFO,MMC714,MOTOR_SERIAL_NUMBER
INFO,01.04.28,MOTOR_SOFTWARE_VERSION
INFO,Quantum Design Squid Module,SQUID_MODULE_NAME
INFO,3101-501 B0,SQUID_HW_VERSION
INFO,SQM189,SQUID_SERIAL_NUMBER
INFO,01.03.04,SQUID_SOFTWARE_VERSION
INFO,Quantum Design VSM Oven,OVEN_MODULE_NAME
INFO,3101-201 A1,OVEN_HW_VERSION
INFO,OVB229,OVEN_SERIAL_NUMBER
INFO,01.07.07,OVEN_SOFTWARE_VERSION
INFO,SQUID AC,AC_MODULE_NAME
INFO,3101-401 F1,AC_HW_VERSION
INFO,SAC108,AC_SERIAL_NUMBER
INFO,SQUID AC 00.95.07,AC_SOFTWARE_VERSION
INFO,TCI177,COIL_SERIAL_NUMBER
INFO,0,MOMENT_UNITS
INFO,A2481,SAMPLE_MATERIAL
INFO,,SAMPLE_COMMENT
INFO,,SAMPLE_MASS
INFO,,SAMPLE_VOLUME
INFO,,SAMPLE_MOLECULAR_WEIGHT
INFO,5mm x 5mm,SAMPLE_SIZE
INFO,,SAMPLE_SHAPE
INFO,Straw,SAMPLE_HOLDER
INFO,Standard,SAMPLE_HOLDER_DETAIL
INFO,65.98,SAMPLE_OFFSET
DATATYPE,COMMENT,1
DATATYPE,TIME,2
STARTUPAXIS,X,2
STARTUPAXIS,Y1,5
FIELDGROUP, VSM,2,3,4,5,6,8,9,10,11,14,15
FIELDGROUP, DC, 2,3,4,14,56,57,58,59,60,61,62,63,64,65,66,67,68,69
FIELDGROUP, AC, 2,3,4,11,16,17,18,19,20,21,22,23,24,25,26,27,28,29,30
STARTUPGROUP, All
[Data]
Comment,Time Stamp (sec),Temperature (K),Magnetic Field (Oe),Moment (emu),M. Std. Err. (emu),Transport Action,Averaging Time (sec),Frequency (Hz),Peak Amplitude (mm),Center Position (mm),Lockin Signal' (V),Lockin Signal (V),Range,M. Quad. Signal (emu),AC Moment (emu),AC M. Std Err. (emu),AC Phase (deg),AC Phase Std. Err. (deg),AC Susceptibility (emu/Oe),AC Suscept. Std Err. (emu/Oe),AC X' (emu/Oe),AC X' Std Err. (emu/Oe),AC X'' (emu/Oe),AC X'' Std Err. (emu/Oe),AC Drive (Oe),AC Frequency (Hz),AC Averaging Time (sec),AC Cycles,AC Range,AC Measure Type,AC Signal' (V),AC Signal'' (V),AC Trim Coil Ratio,AC Trim Coil Phase,Min. Temperature (K),Max. Temperature (K),Min. Field (Oe),Max. Field (Oe),Mass (grams),Motor Lag (deg),Pressure (Torr),Measure Count,Measurement Number,SQUID Status (code),Motor Status (code),Measure Status (code),Motor Current (amps),Motor Temp. (C),Temp. Status (code),Field Status (code),Chamber Status (code),Chamber Temp (K),Redirection State,Evercool Status,Average Temp (K),Rotation Angle (deg),Rotator state,DC Moment Fixed Ctr (emu),DC Moment Err Fixed Ctr (emu),DC Moment Free Ctr (emu),DC Moment Err Free Ctr (emu),DC Fixed Fit,DC Free Fit,DC Calculated Center (mm),DC Calculated Center Err (mm),DC Scan Length (mm),DC Scan Time (s),DC Number of Points,DC Squid Drift,DC Min V (V),DC Max V (V),DC Scans per Measure,Map 01,Map 02,Map 03,Map 04,Map 05,Map 06,Map 07,Map 08,Map 09,Map 10,Map 11,Map 12,Map 13,Map 14,Map 15,Map 16
,3842618398.11891,2.99931859970093,100.238250732422,6.26384034439535E-7,1.29468640964357E-8,1,10,13.3016452789307,8.00188289216476,31.360000371933,0.00121466317013368,0.000299595377722811,1,6.00884357452021E-8,,,,,,,,,,,,,,,,,,,,,2.99931859970093,2.99931859970093,100.238250732422,100.238250732422,54.8699312357462,5.62251986707835,4.61394786834717,133,1,0,0,1,0.471878051757812,33.7243423461914,1,1,1,2.99931859970093,0,742397376,2.99931859970093,,,,,,,,,,,,,,,,,,,,,,,,,,,,,,,,,
,3842618860.38998,6.50985383987427,100.238250732422,5.85541550292936E-7,1.11744765378885E-8,1,10,13.3016452789307,8.00156871520452,31.3699990510941,0.00114422058741004,0.0002204043043126,1,2.58435013456571E-8,,,,,,,,,,,,,,,,,,,,,6.47232484817505,6.54738283157349,100.238250732422,100.238250732422,54.8015387403135,5.6235754895911,6.8690013885498,133,1,0,0,1,0.474319458007812,34.2131004333496,6,1,1,6.54738283157349,0,742397248,6.50985383987427,,,,,,,,,,,,,,,,,,,,,,,,,,,,,,,,,
,3842619045.42128,7.98299646377564,100.238250732422,5.6716456654521E-7,1.29456676379274E-8,1,10,13.3016452789307,8.00157605521481,31.3699990510941,0.0011117862368582,0.000189878910469909,1,1.30297056117133E-8,,,,,,,,,,,,,,,,,,,,,7.98299646377564,7.98299646377564,100.238250732422,100.238250732422,54.9566920013808,5.62316846628571,7.08851909637451,133,1,0,0,1,0.473709106445313,33.7243423461914,6,1,1,7.98299646377564,0,742397280,7.98299646377564,,,,,,,,,,,,,,,,,,,,,,,,,,,,,,,,,
,3842619140.33986,8.74141311645508,100.238250732422,5.62778701611423E-7,1.2399320072039E-8,1,10,13.3016452789307,8.00157761524382,31.3699990510941,0.00110329087193314,0.000187718372015609,1,1.25770081159422E-8,,,,,,,,,,,,,,,,,,,,,8.70247077941895,8.78035545349121,100.238250732422,100.238250732422,54.871103678525,5.62258496612111,7.20358657836914,133,1,0,0,1,0.475387573242188,33.7243423461914,6,1,1,8.78035545349121,0,742397248,8.74141311645508,,,,,,,,,,,,,,,,,,,,,,,,,,,,,,,,,
,3842619240.27821,9.54817390441895,100.238250732422,5.51152797428991E-7,1.19760661156259E-8,1,10,13.3016452789307,8.00171894211138,31.3800014555454,0.00108003308789509,0.000187079280355052,1,1.39629022898637E-8,,,,,,,,,,,,,,,,,,,,,9.50774383544922,9.58860397338867,100.238250732422,100.238250732422,54.9668531721308,5.62328044358391,7.31349611282349,133,1,0,0,1,0.475921630859375,34.2131004333496,6,1,1,9.58860397338867,0,742397344,9.54817390441895,,,,,,,,,,,,,,,,,,,,,,,,,,,,,,,,,
,3842619340.21134,10.3520469665527,100.238250732422,5.46852294765597E-7,1.23287418163061E-8,1,10,13.3016452789307,8.00161691843836,31.3800014555454,0.00107274976649909,0.000177797340814735,1,9.87772655767001E-9,,,,,,,,,,,,,,,,,,,,,10.3123464584351,10.3917474746704,100.238250732422,100.238250732422,54.7198585600539,5.62314351671365,7.3883113861084,133,1,0,0,1,0.471038818359375,34.2131004333496,6,1,1,10.3917474746704,0,742397312,10.3520469665527,,,,,,,,,,,,,,,,,,,,,,,,,,,,,,,,,
,3842619440.25264,11.1615891456604,100.238250732422,5.4074737691662E-7,1.22030647760732E-8,1,10,13.3016452789307,8.00140544046633,31.3699990510941,0.00106094974794809,0.000174509097204526,1,9.10611932446744E-9,,,,,,,,,,,,,,,,,,,,,11.1224822998047,11.2006959915161,100.238250732422,100.238250732422,54.7327554306212,5.62306102315383,7.45895338058472,133,1,0,0,1,0.475997924804687,34.2131004333496,6,1,1,11.2006959915161,0,742397504,11.1615891456604,,,,,,,,,,,,,,,,,,,,,,,,,,,,,,,,,
,3842619540.36835,11.9751710891724,100.238250732422,5.33559328664233E-7,1.22275513453272E-8,1,10,13.3016452789307,8.00146400648988,31.3699990510941,0.00104726874383667,0.000169353025268217,1,7.54266522657211E-9,,,,,,,,,,,,,,,,,,,,,11.937047958374,12.0132942199707,100.238250732422,100.238250732422,54.8023203688327,5.62376597145536,7.5324649810791,133,1,0,0,1,0.475692749023438,34.2131004333496,6,1,1,12.0132942199707,0,742397248,11.9751710891724,,,,,,,,,,,,,,,,,,,,,,,,,,,,,,,,,
,3842619600.15116,12.4602975845337,100.238250732422,5.27206314077289E-7,1.2611691577205E-8,1,10,13.3016452789307,8.00137524783683,31.3699990510941,0.00103500564515425,0.000165888986336361,1,6.71740568057279E-9,,,,,,,,,,,,,,,,,,,,,12.4200220108032,12.5005731582642,100.238250732422,100.238250732422,54.8789199637173,5.62344385336365,7.53959178924561,133,1,0,0,1,0.476531982421875,33.7243423461914,6,1,1,12.5005731582642,0,742397504,12.4602975845337,,,,,,,,,,,,,,,,,,,,,,,,,,,,,,,,,
,3842619700.21642,13.2761845588684,100.238250732422,5.24173092879699E-7,1.20854421375888E-8,1,10,13.3016452789307,8.00161919057924,31.3699990510941,0.00102903604122594,0.000165156852703218,1,6.79034645705414E-9,,,,,,,,,,,,,,,,,,,,,13.2356243133545,13.3167448043823,100.238250732422,100.238250732422,54.8077917684673,5.62289060046667,7.61021423339844,133,1,0,0,1,0.474929809570313,34.2131004333496,6,1,1,13.3167448043823,0,742397280,13.2761845588684,,,,,,,,,,,,,,,,,,,,,,,,,,,,,,,,,
,3842619760.2621,13.7666983604431,100.238250732422,5.21561934594329E-7,1.22870275956244E-8,1,10,13.3016452789307,8.00152024755813,31.3800014555454,0.00102391427027404,0.000164255471318658,1,6.71710700571261E-9,,,,,,,,,,,,,,,,,,,,,13.7285346984863,13.8048620223999,100.238250732422,100.238250732422,54.779653141775,5.62318679761764,7.62338304519653,133,1,0,0,1,0.476455688476562,33.7243423461914,6,1,1,13.8048620223999,0,742397440,13.7666983604431,,,,,,,,,,,,,,,,,,,,,,,,,,,,,,,,,
,3842619865.32933,14.6231346130371,100.238250732422,5.15645181485548E-7,1.20057345483408E-8,1,10,13.3016452789307,8.0015694161503,31.3800014555454,0.00101285039748733,0.000158669091708892,1,4.74779364860938E-9,,,,,,,,,,,,,,,,,,,,,14.6231346130371,14.6231346130371,100.238250732422,100.238250732422,54.7988030404962,5.62292955065206,7.69460153579712,133,1,0,0,1,0.475540161132812,33.7243423461914,6,1,1,14.6231346130371,0,742397472,14.6231346130371,,,,,,,,,,,,,,,,,,,,,,,,,,,,,,,,,
,3842619920.10922,15.071834564209,100.238250732422,5.1587707641502E-7,1.20632753815855E-8,1,10,13.3016452789307,8.00148671130485,31.3800014555454,0.00101242296785235,0.000164696528173155,1,7.77855907798824E-9,,,,,,,,,,,,,,,,,,,,,15.0302715301514,15.1133975982666,100.238250732422,100.238250732422,54.7917683838231,5.62311737670799,7.70839548110962,133,1,0,0,1,0.47210693359375,34.2131004333496,6,1,1,15.1133975982666,0,742397344,15.071834564209,,,,,,,,,,,,,,,,,,,,,,,,,,,,,,,,,
,3842619980.18123,15.6203479766846,100.238250732422,5.08023435754575E-7,1.23120514287937E-8,1,10,13.3016452789307,8.0016381417531,31.3800014555454,0.000997793888109238,0.000156938255827994,1,4.9896287157969E-9,,,,,,,,,,,,,,,,,,,,,15.5824661254883,15.6582298278809,100.238250732422,100.238250732422,54.7393992730346,5.62277045335981,7.71604299545288,133,1,0,0,1,0.474166870117188,33.7243423461914,2,1,1,15.6582298278809,0,742397472,15.6203479766846,,,,,,,,,,,,,,,,,,,,,,,,,,,,,,,,,
,3842620040.12487,16.1288194656372,100.238250732422,5.10508923337198E-7,1.21943950039986E-8,1,10,13.3016452789307,8.00169060599993,31.3900001347065,0.0010020318934345,0.000162103219247463,1,7.24929481946204E-9,,,,,,,,,,,,,,,,,,,,,16.0887107849121,16.1689281463623,100.238250732422,100.238250732422,54.8199070105154,5.62257864958662,7.72359609603882,133,1,0,0,1,0.473556518554687,34.2131004333496,2,1,1,16.1689281463623,0,742397216,16.1288194656372,,,,,,,,,,,,,,,,,,,,,,,,,,,,,,,,,
,3842620100.18431,16.6254014968872,100.238250732422,5.05202573489791E-7,1.25718960407436E-8,1,10,13.3016452789307,8.00180050219141,31.3900001347065,0.000992316939909219,0.000155714097586899,1,4.78169098147779E-9,,,,,,,,,,,,,,,,,,,,,16.5845642089844,16.66623878479,100.238250732422,100.238250732422,54.9719337575058,5.62300937283257,7.74787759780884,133,1,0,0,1,0.474014282226562,33.7243423461914,2,1,1,16.66623878479,0,742397440,16.6254014968872,,,,,,,,,,,,,,,,,,,,,,,,,,,,,,,,,
,3842620200.16632,17.4430255889893,100.238250732422,5.01789027156252E-7,1.24155412353965E-8,1,10,13.3016452789307,8.00164239662635,31.3900001347065,0.000985748106175301,0.000153662538562904,1,4.24212712628011E-9,,,,,,,,,,,,,,,,,,,,,17.4031410217285,17.48291015625,100.238250732422,100.238250732422,54.8230335245923,5.62273142935445,7.78590822219849,133,1,0,0,1,0.469894409179687,33.7243423461914,2,1,1,17.48291015625,0,742397152,17.4430255889893,,,,,,,,,,,,,,,,,,,,,,,,,,,,,,,,,
,3842620260.06693,17.9359016418457,100.238250732422,4.96487250497933E-7,1.20971247180458E-8,1,10,13.3016452789307,8.00170711083276,31.3900001347065,0.000974331001524371,0.000158874517184215,1,7.67219925662524E-9,,,,,,,,,,,,,,,,,,,,,17.8925838470459,17.9792194366455,100.238250732422,100.238250732422,54.8128723538423,5.6229426953636,7.80237531661987,133,1,0,0,1,0.475921630859375,33.7243423461914,2,1,1,17.9792194366455,0,742397376,17.9359016418457,,,,,,,,,,,,,,,,,,,,,,,,,,,,,,,,,
,3842620320.09185,18.4253168106079,100.238250732422,4.97040573290656E-7,1.24949805259064E-8,1,10,13.3016452789307,8.00161683962799,31.3800014555454,0.000975682218351781,0.000157206695866508,1,6.74329940696264E-9,,,,,,,,,,,,,,,,,,,,,18.3841075897217,18.4665260314941,100.238250732422,100.238250732422,54.7839520986308,5.62306809216402,7.80231666564941,133,1,0,0,1,0.474853515625,33.7243423461914,2,1,1,18.4665260314941,0,742397408,18.4253168106079,,,,,,,,,,,,,,,,,,,,,,,,,,,,,,,,,
,3842620380.07219,18.9168272018433,100.238250732422,4.90583323480694E-7,1.23585776227604E-8,1,10,13.3016452789307,8.0015145488541,31.3900001347065,0.000963999750832757,0.000148372323236949,1,3.20308429701252E-9,,,,,,,,,,,,,,,,,,,,,18.8760070800781,18.9576473236084,100.238250732422,100.238250732422,54.78473372715,5.62371317905126,7.82828140258789,133,1,0,0,1,0.472412109375,34.2131004333496,2,1,1,18.9576473236084,0,742397248,18.9168272018433,,,,,,,,,,,,,,,,,,,,,,,,,,,,,,,,,
,3842620440.03572,19.408784866333,100.238250732422,4.87962091464163E-7,1.23712360965614E-8,1,10,13.3016452789307,8.00154263363284,31.3800014555454,0.000958311116229311,0.000151245874283042,1,5.04982965453115E-9,,,,,,,,,,,,,,,,,,,,,19.3684005737305,19.4491691589355,100.238250732422,100.238250732422,54.7882510554866,5.62248010839037,7.8370246887207,133,1,0,0,1,0.47149658203125,33.7243423461914,2,1,1,19.4508571624756,0,742397120,19.408784866333,,,,,,,,,,,,,,,,,,,,,,,,,,,,,,,,,
,3842620500.08096,19.9696836471558,100.238250732422,4.86682717087422E-7,1.25442480808012E-8,1,10,13.3016452789307,8.00158169422319,31.3800014555454,0.000956871285150469,0.000143581575790831,1,1.34136610760013E-9,,,,,,,,,,,,,,,,,,,,,19.9463748931885,19.992992401123,100.238250732422,100.238250732422,55.0727638364866,5.62323010719226,7.8478569984436,133,1,0,0,1,0.4705810546875,33.7243423461914,6,1,1,19.992992401123,0,742397344,19.9696836471558,,,,,,,,,,,,,,,,,,,,,,,,,,,,,,,,,
,3842620600.13834,21.3531723022461,100.238250732422,4.87473726351216E-7,1.2258222200399E-8,1,10,13.3016452789307,8.00141515473093,31.3800014555454,0.00095771545366399,0.000148566964894414,1,3.76041142804537E-9,,,,,,,,,,,,,,,,,,,,,20.9619579315186,21.7443866729736,100.238250732422,100.238250732422,54.7648021999096,5.62303573274451,7.89741897583008,133,1,0,0,1,0.47119140625,34.2131004333496,2,1,1,21.7443866729736,0,742397312,21.3531723022461,,,,,,,,,,,,,,,,,,,,,,,,,,,,,,,,,
,3842620660.08298,26.0977230072021,100.238250732422,4.72041877629289E-7,1.22332566479895E-8,1,10,13.3016452789307,8.00130909663568,31.3800014555454,0.000927921621726927,0.000140254852874431,1,1.80703473485276E-9,,,,,,,,,,,,,,,,,,,,,25.7163562774658,26.4790897369385,100.238250732422,100.238250732422,54.5654869275058,5.62312809093999,8.01728248596191,133,1,0,0,1,0.47210693359375,34.2131004333496,2,1,1,26.4790897369385,0,742397248,26.0977230072021,,,,,,,,,,,,,,,,,,,,,,,,,,,,,,,,,
,3842620720.00417,30.8648109436035,100.238250732422,4.55608055999267E-7,1.23438129182142E-8,1,10,13.3016452789307,8.0014001874342,31.3800014555454,0.000894475168968299,0.000143164200686119,1,5.70540162076206E-9,,,,,,,,,,,,,,,,,,,,,30.4675922393799,31.2620296478271,100.238250732422,100.238250732422,54.8038836258712,5.62260926069006,8.10642719268799,133,1,0,0,1,0.471038818359375,34.2131004333496,2,1,1,31.2620296478271,0,742397248,30.8648109436035,,,,,,,,,,,,,,,,,,,,,,,,,,,,,,,,,
,3842620780.11259,35.6631908416748,100.238250732422,4.41357038018765E-7,1.2157156498495E-8,1,10,13.3016452789307,8.00143604621286,31.3800014555454,0.000867057658169452,0.000134891796061698,1,3.5976488710193E-9,,,,,,,,,,,,,,,,,,,,,35.2686347961426,36.057746887207,100.238250732422,100.238250732422,54.9387145454385,5.62344001382143,8.18362808227539,133,1,0,0,1,0.470123291015625,34.2131004333496,2,1,1,36.057746887207,0,742397408,35.6631908416748,,,,,,,,,,,,,,,,,,,,,,,,,,,,,,,,,
,3842620839.97707,40.468376159668,100.238250732422,4.23449090865088E-7,1.2365103633551E-8,1,10,13.3016452789307,8.00144049231035,31.3900001347065,0.000832576834609376,0.000124667372312,1,1.03604978551041E-9,,,,,,,,,,,,,,,,,,,,,40.0685119628906,40.8682403564453,100.238250732422,100.238250732422,54.8777475209385,5.62317097721599,8.25852584838867,133,1,0,0,1,0.471343994140625,34.2131004333496,2,1,1,40.8682403564453,0,742397376,40.468376159668,,,,,,,,,,,,,,,,,,,,,,,,,,,,,,,,,
,3842620900.12408,45.2920780181885,100.238250732422,4.19129610163465E-7,1.22875495942037E-8,1,10,13.3016452789307,8.00142446360836,31.3900001347065,0.000822712297172841,0.000132705366541654,1,5.75876495620889E-9,,,,,,,,,,,,,,,,,,,,,44.8993682861328,45.6847877502441,100.238250732422,100.238250732422,54.8910352057654,5.62402630393952,8.31003952026367,133,1,0,0,1,0.465240478515625,34.2131004333496,2,1,1,45.6847877502441,0,742397408,45.2920780181885,,,,,,,,,,,,,,,,,,,,,,,,,,,,,,,,,
,3842620960.03815,50.1028385162354,100.238250732422,4.06418006170955E-7,1.22029418291771E-8,1,10,13.3016452789307,8.00160732026894,31.3999988138676,0.000799061018439116,0.000119919144578122,1,1.12885043289804E-9,,,,,,,,,,,,,,,,,,,,,49.6957092285156,50.5099678039551,100.238250732422,100.238250732422,54.5248422445058,5.62251513513685,8.36061477661133,133,1,0,0,1,0.466842651367188,34.2131004333496,2,1,1,50.5099678039551,0,742397440,50.1028385162354,,,,,,,,,,,,,,,,,,,,,,,,,,,,,,,,,
,3842621020.03779,54.9353427886963,100.238250732422,3.95339168294207E-7,1.21451618352201E-8,1,10,13.3016452789307,8.00139141304672,31.4100012183189,0.00077629000806284,0.000123284969336014,1,4.47222310959642E-9,,,,,,,,,,,,,,,,,,,,,54.5291061401367,55.3415794372559,100.238250732422,100.238250732422,54.789814312525,5.62298170657069,8.40460872650146,131,1,64,0,0,0.471649169921875,33.7243423461914,2,1,1,55.3415794372559,0,742397344,54.9353427886963,,,,,,,,,,,,,,,,,,,,,,,,,,,,,,,,,
,3842621080.15803,59.8015270233154,100.238250732422,3.81713667825814E-7,1.22738314133295E-8,1,10,13.3016452789307,8.00151149588152,31.4100012183189,0.000749229216829956,0.000121155702580496,1,5.39531365894082E-9,,,,,,,,,,,,,,,,,,,,,59.387336730957,60.2157173156738,100.238250732422,100.238250732422,54.7968489691981,5.62275938042544,8.44775104522705,132,1,64,0,0,0.476303100585937,33.7243423461914,2,1,1,60.2157173156738,0,742397376,59.8015270233154,,,,,,,,,,,,,,,,,,,,,,,,,,,,,,,,,
,3842621140.20101,64.6672439575195,100.238250732422,3.66619192074315E-7,1.22909355331029E-8,1,10,13.3016452789307,8.00162455822231,31.41999989748,0.00071998746686082,0.000113784207783778,1,3.86953250728802E-9,,,,,,,,,,,,,,,,,,,,,64.2854919433594,65.0489959716797,100.238250732422,100.238250732422,54.8367120236789,5.62272341932154,8.48703956604004,132,1,64,0,0,0.47088623046875,34.2131004333496,2,1,1,65.0489959716797,0,742397376,64.6672439575195,,,,,,,,,,,,,,,,,,,,,,,,,,,,,,,,,
,3842621199.96901,69.5506210327148,100.238250732422,3.59207651035688E-7,1.24350561049036E-8,1,10,13.3016452789307,8.00158684308541,31.4299985766411,0.000705333998020121,0.00011213847310729,1,4.12421969851943E-9,,,,,,,,,,,,,,,,,,,,,69.1327285766602,69.9685134887695,100.238250732422,100.238250732422,54.838666094977,5.62269854332235,8.49723243713379,133,1,0,0,1,0.469589233398438,34.2131004333496,2,1,1,69.9685134887695,0,742397344,69.5506210327148,,,,,,,,,,,,,,,,,,,,,,,,,,,,,,,,,
,3842621259.99901,74.4138069152832,100.238250732422,3.47955823779755E-7,1.24559642037183E-8,1,10,13.3016452789307,8.00158721382701,31.41999989748,0.000683494058891435,0.000106901144629553,1,3.11817219993483E-9,,,,,,,,,,,,,,,,,,,,,74.0099411010742,74.8176727294922,100.238250732422,100.238250732422,54.955519558602,5.62279520558842,8.51924896240234,133,1,0,0,1,0.466766357421875,33.7243423461914,2,1,1,74.8176727294922,0,742397216,74.4138069152832,,,,,,,,,,,,,,,,,,,,,,,,,,,,,,,,,
,3842621319.93256,79.2530937194824,100.238250732422,3.35434474641749E-7,1.2284043972198E-8,1,10,13.3016452789307,8.00172692297382,31.4299985766411,0.000658759292623394,0.000104042361413799,1,3.50781201713975E-9,,,,,,,,,,,,,,,,,,,,,78.8455810546875,79.6606063842773,100.238250732422,100.238250732422,54.9336339600635,5.62229273175591,8.53850364685059,133,1,0,0,1,0.473175048828125,35.190616607666,2,1,1,79.6606063842773,0,742397216,79.2530937194824,,,,,,,,,,,,,,,,,,,,,,,,,,,,,,,,,
,3842621380.06518,84.172492980957,100.238250732422,3.27405076089839E-7,1.27419369602474E-8,1,10,13.3016452789307,8.00164425392591,31.4400009810925,0.000642822760580835,0.000102664478237647,1,3.98980464833303E-9,,,,,,,,,,,,,,,,,,,,,83.7657623291016,84.5792236328125,100.238250732422,100.238250732422,54.7421349728519,5.62206495462947,8.54389476776123,132,1,64,0,0,0.46966552734375,33.7243423461914,2,1,1,84.5792236328125,0,742397376,84.172492980957,,,,,,,,,,,,,,,,,,,,,,,,,,,,,,,,,
,3842621439.95887,89.1342658996582,100.238250732422,3.15690451631847E-7,1.22852827984397E-8,1,10,13.3016452789307,8.00153465326896,31.4499996602535,0.00062053878713164,9.40927961985534E-5,1,1.35705586178172E-9,,,,,,,,,,,,,,,,,,,,,88.7240753173828,89.5444564819336,100.238250732422,100.238250732422,54.8968974196597,5.62304969604873,8.55917453765869,133,1,0,0,1,0.474929809570313,34.2131004333496,2,1,1,89.5444564819336,0,742397344,89.1342658996582,,,,,,,,,,,,,,,,,,,,,,,,,,,,,,,,,
,3842621500.15605,94.1024894714355,100.238250732422,3.03777587273241E-7,1.26849345445842E-8,1,10,13.3016452789307,8.00169601188479,31.4599983394146,0.000596128719906083,9.73362484485995E-5,1,4.75952021723362E-9,,,,,,,,,,,,,,,,,,,,,93.6965637207031,94.508415222168,100.238250732422,100.238250732422,54.6948464474385,5.62234454119411,8.58510875701904,132,1,64,0,0,0.470199584960937,34.2131004333496,2,1,1,94.508415222168,0,742397440,94.1024894714355,,,,,,,,,,,,,,,,,,,,,,,,,,,,,,,,,
,3842621559.90903,99.0317802429199,100.238250732422,2.97470749606452E-7,1.20065780162978E-8,1,10,13.3016452789307,8.00154415457042,31.470000743866,0.000584067177767391,9.31336699306222E-5,1,3.55198988448466E-9,,,,,,,,,,,,,,,,,,,,,98.6306610107422,99.4328994750977,100.238250732422,100.238250732422,54.7534685863808,5.62279982935653,8.60779571533203,133,1,0,0,1,0.4754638671875,34.2131004333496,2,1,1,99.4328994750977,0,742397344,99.0317802429199,,,,,,,,,,,,,,,,,,,,,,,,,,,,,,,,,
,3842621619.96351,104.004554748535,100.238250732422,2.87824498886439E-7,1.23702295936809E-8,1,10,13.3016452789307,8.00158512617553,31.479999423027,0.00056697837063407,7.75526974767998E-5,1,-2.94942617717717E-9,,,,,,,,,,,,,,,,,,,,,103.615036010742,104.394073486328,100.238250732422,100.238250732422,54.6940648189193,5.62257366718494,8.62188816070557,133,1,0,0,1,0.469207763671875,33.2355842590332,2,1,1,104.394073486328,0,742397504,104.004554748535,,,,,,,,,,,,,,,,,,,,,,,,,,,,,,,,,
,3842621680.01116,109.041213989258,100.238250732422,2.8080163293629E-7,1.2001982450361E-8,1,10,13.3016452789307,8.00159594805729,31.4900018274784,0.000551660008276147,8.5743668852571E-5,1,2.24895099757932E-9,,,,,,,,,,,,,,,,,,,,,108.644561767578,109.437866210938,100.238250732422,100.238250732422,54.6405232653519,5.6235001070548,8.64819145202637,133,1,0,0,1,0.475387573242188,34.2131004333496,2,1,1,109.437866210938,0,742397344,109.041213989258,,,,,,,,,,,,,,,,,,,,,,,,,,,,,,,,,
,3842621739.97544,113.941940307617,100.238250732422,2.67655800190061E-7,1.18774367509658E-8,1,10,13.3016452789307,8.00143390590495,31.5099991858006,0.00052463739802709,8.98142921138665E-5,1,6.25456175002048E-9,,,,,,,,,,,,,,,,,,,,,113.530853271484,114.35302734375,100.238250732422,100.238250732422,54.7687103425058,5.62377218508662,8.66137981414795,133,1,0,0,1,0.474700927734375,33.7243423461914,2,1,1,114.35302734375,0,742397312,113.941940307617,,,,,,,,,,,,,,,,,,,,,,,,,,,,,,,,,
,3842621799.89273,118.937088012695,100.238250732422,2.58023686428163E-7,1.20984540655377E-8,1,10,13.3016452789307,8.00151754964899,31.5200015902519,0.000507207019360592,7.67564806743032E-5,1,1.03370794874881E-9,,,,,,,,,,,,,,,,,,,,,118.504180908203,119.369995117188,100.238250732422,100.238250732422,54.8797015922366,5.62271179686207,8.68324375152588,133,1,0,0,1,0.472412109375,33.7243423461914,2,1,1,119.369995117188,0,742397312,118.937088012695,,,,,,,,,,,,,,,,,,,,,,,,,,,,,,,,,
,3842621859.93051,123.898006439209,100.238250732422,2.50313795482048E-7,1.18297931709349E-8,1,10,13.3016452789307,8.00156357929857,31.5200015902519,0.000491020042753536,8.14786456142446E-5,1,4.56956755647655E-9,,,,,,,,,,,,,,,,,,,,,123.51001739502,124.285995483398,100.238250732422,100.238250732422,54.9125299900443,5.62243532235276,8.68488883972168,133,1,0,0,1,0.475006103515625,34.2131004333496,2,1,1,124.285995483398,0,742397472,123.898006439209,,,,,,,,,,,,,,,,,,,,,,,,,,,,,,,,,
,3842621919.86082,128.854225158691,100.238250732422,2.39461116964122E-7,1.15735777185556E-8,1,10,13.3016452789307,8.00127753182906,31.5399989485741,0.000470902214909913,6.9927778106099E-5,1,2.95571426920085E-10,,,,,,,,,,,,,,,,,,,,,128.442581176758,129.265869140625,100.238250732422,100.238250732422,54.7902051267846,5.6238292668969,8.7037525177002,133,1,0,0,1,0.475540161132812,33.7243423461914,2,1,1,129.265869140625,0,742397376,128.854225158691,,,,,,,,,,,,,,,,,,,,,,,,,,,,,,,,,
,3842621979.98635,133.843521118164,100.238250732422,2.28665151166443E-7,1.21318894207792E-8,1,10,13.3016452789307,8.00145028123778,31.5500013530254,0.000448909235741415,7.19923173175798E-5,1,2.93434657092255E-9,,,,,,,,,,,,,,,,,,,,,133.443313598633,134.243728637695,100.238250732422,100.238250732422,54.8613333220347,5.62374348372994,8.72387218475342,133,1,0,0,1,0.470809936523438,34.2131004333496,2,1,1,134.243728637695,0,742397472,133.843521118164,,,,,,,,,,,,,,,,,,,,,,,,,,,,,,,,,
,3842622039.89592,138.83812713623,100.238250732422,2.20952624544766E-7,1.22028742548149E-8,1,10,13.3016452789307,8.00145905066468,31.5600000321865,0.000433414726957162,7.19667747843758E-5,1,4.05690062070705E-9,,,,,,,,,,,,,,,,,,,,,138.439270019531,139.23698425293,100.238250732422,100.238250732422,54.8480456372077,5.6236146426373,8.72739601135254,133,1,0,0,1,0.46844482421875,33.7243423461914,2,1,1,139.23698425293,0,742397440,138.83812713623,,,,,,,,,,,,,,,,,,,,,,,,,,,,,,,,,
,3842622100.10007,143.815322875977,100.238250732422,2.13459297979795E-7,1.20235828899836E-8,1,10,13.3016452789307,8.00160504903381,31.580001115799,0.000418785733982636,6.90822720351479E-5,1,3.6933022070783E-9,,,,,,,,,,,,,,,,,,,,,143.403457641602,144.227188110352,100.238250732422,100.238250732422,54.871103678525,5.62315145598025,8.73165798187256,132,1,64,0,0,0.475311279296875,34.2131004333496,2,1,1,144.227188110352,0,742397280,143.815322875977,,,,,,,,,,,,,,,,,,,,,,,,,,,,,,,,,
,3842622160.05658,148.809150695801,100.238250732422,1.98719007117448E-7,1.20766281442959E-8,1,10,13.3016452789307,8.00139737627668,31.5999984741211,0.000389977124271617,6.3523017043718E-5,1,3.03768378406575E-9,,,,,,,,,,,,,,,,,,,,,148.435028076172,149.18327331543,100.238250732422,100.238250732422,54.7265024024673,5.62369415454586,8.76375961303711,132,1,64,0,0,0.47515869140625,34.7018585205078,2,1,1,149.18327331543,0,742397312,148.809150695801,,,,,,,,,,,,,,,,,,,,,,,,,,,,,,,,,
,3842622219.95203,153.780464172363,100.238250732422,1.90753730016555E-7,1.2254023529899E-8,1,10,13.3016452789307,8.0014418035606,31.6199995577335,0.00037437533758336,6.07830828038068E-5,1,2.81733033628611E-9,,,,,,,,,,,,,,,,,,,,,153.33659362793,154.224334716797,100.238250732422,100.238250732422,54.8429650518327,5.623057258966,8.75901699066162,132,1,64,0,0,0.475616455078125,34.2131004333496,2,1,1,154.224334716797,0,742397408,153.780464172363,,,,,,,,,,,,,,,,,,,,,,,,,,,,,,,,,
,3842622280.06646,158.703880310059,100.238250732422,1.83291198342248E-7,1.25319563067821E-8,1,10,13.3016452789307,8.00127213791364,31.6299982368946,0.00035983349840541,5.76678313536704E-5,1,2.33258362596454E-9,,,,,,,,,,,,,,,,,,,,,158.322326660156,159.085433959961,100.238250732422,100.238250732422,54.9367604741404,5.62364607724122,8.78762054443359,131,1,64,0,0,0.473556518554687,34.2131004333496,2,1,1,159.085433959961,0,742397376,158.703880310059,,,,,,,,,,,,,,,,,,,,,,,,,,,,,,,,,
,3842622340.12522,163.717147827148,100.238250732422,1.74919377033532E-7,1.19992024039936E-8,1,10,13.3016452789307,8.00119872848077,31.649999320507,0.000342646860545304,6.01239905652504E-5,1,4.81414349079128E-9,,,,,,,,,,,,,,,,,,,,,163.336441040039,164.097854614258,100.238250732422,100.238250732422,54.80505606865,5.62374330145895,8.80402565002441,132,1,64,0,0,0.475692749023438,34.7018585205078,2,1,1,164.097854614258,0,742397248,163.717147827148,,,,,,,,,,,,,,,,,,,,,,,,,,,,,,,,,
,3842622399.90201,168.682563781738,100.238250732422,1.62600411271587E-7,1.2456581484957E-8,1,10,13.3016452789307,8.00150813005629,31.6600017249584,0.000319293469763112,5.06532294556582E-5,1,1.81220414788078E-9,,,,,,,,,,,,,,,,,,,,,168.278900146484,169.086227416992,100.238250732422,100.238250732422,54.5029566459673,5.62296761081782,8.81656455993652,131,1,64,0,0,0.467453002929687,33.7243423461914,2,1,1,169.086227416992,0,742397312,168.682563781738,,,,,,,,,,,,,,,,,,,,,,,,,,,,,,,,,
,3842622459.95905,173.670791625977,100.238250732422,1.51739616977792E-7,1.21562562935504E-8,1,10,13.3016452789307,8.00125868006795,31.6900014877319,0.000297624603413997,4.95556836453522E-5,1,2.8537350005804E-9,,,,,,,,,,,,,,,,,,,,,173.272521972656,174.069061279297,100.238250732422,100.238250732422,54.9305074459866,5.62381725575874,8.82991027832031,132,1,64,0,0,0.465927124023438,34.7018585205078,2,1,1,174.069061279297,0,742397248,173.670791625977,,,,,,,,,,,,,,,,,,,,,,,,,,,,,,,,,
,3842622519.96205,178.63321685791,100.238250732422,1.40074427897044E-7,1.24394356591774E-8,1,10,13.3016452789307,8.00128291375857,31.700000166893,0.000274404485287465,4.80572641363607E-5,1,3.8093989710148E-9,,,,,,,,,,,,,,,,,,,,,178.232376098633,179.034057617187,100.238250732422,100.238250732422,54.7816072130731,5.62373283327049,8.85421752929688,131,1,64,0,0,0.471343994140625,34.2131004333496,2,1,1,179.034057617187,0,742397440,178.63321685791,,,,,,,,,,,,,,,,,,,,,,,,,,,,,,,,,
,3842622580.04087,183.629257202148,100.238250732422,1.33117379227409E-7,1.24907507695982E-8,1,10,13.3016452789307,8.00119072147438,31.7200012505054,0.000259989679510073,5.09971868941014E-5,1,6.32861893943134E-9,,,,,,,,,,,,,,,,,,,,,183.232528686523,184.025985717773,100.238250732422,100.238250732422,54.8906443915058,5.62399727339895,8.85113430023193,132,1,64,0,0,0.474624633789063,34.7018585205078,2,1,1,184.025985717773,0,742397344,183.629257202148,,,,,,,,,,,,,,,,,,,,,,,,,,,,,,,,,
,3842622640.04726,188.632019042969,100.238250732422,1.22610706991911E-7,1.2239107062664E-8,1,10,13.3016452789307,8.00136824218695,31.7399986088276,0.000240210330972615,4.19594881873371E-5,1,3.2803135523558E-9,,,,,,,,,,,,,,,,,,,,,188.243301391602,189.020736694336,100.238250732422,100.238250732422,54.9011963765154,5.62356158776311,8.84873008728027,132,1,64,0,0,0.471343994140625,34.2131004333496,2,1,1,189.020736694336,0,742397280,188.632019042969,,,,,,,,,,,,,,,,,,,,,,,,,,,,,,,,,
,3842622700.02852,193.56810760498,100.238250732422,1.06032238224767E-7,1.2507759582017E-8,1,10,13.3016452789307,8.00138144616455,31.7699983716011,0.000207740711716497,3.62211058507064E-5,1,2.80373830363849E-9,,,,,,,,,,,,,,,,,,,,,193.182846069336,193.953369140625,100.238250732422,100.238250732422,54.8390569092366,5.62302347240671,8.85414218902588,131,1,64,0,0,0.4681396484375,33.2355842590332,2,1,1,193.953369140625,0,742397152,193.56810760498,,,,,,,,,,,,,,,,,,,,,,,,,,,,,,,,,
,3842622759.9309,198.584037780762,100.238250732422,9.84892745156832E-8,1.21471180891097E-8,1,10,13.3016452789307,8.00127257102424,31.7899994552135,0.00019255393998333,3.64081708061604E-5,1,4.00958316121701E-9,,,,,,,,,,,,,,,,,,,,,198.193786621094,198.97428894043,100.238250732422,100.238250732422,54.759330800275,5.62423505756213,8.86636734008789,131,1,64,0,0,0.476531982421875,34.2131004333496,2,1,1,198.97428894043,0,742397440,198.584037780762,,,,,,,,,,,,,,,,,,,,,,,,,,,,,,,,,
,3842622819.91754,203.554809570313,100.238250732422,8.91874463289613E-8,1.19822734611826E-8,1,10,13.3016452789307,8.00117922619775,31.8000018596649,0.000174546315528816,3.17517195836871E-5,1,3.01180500926504E-9,,,,,,,,,,,,,,,,,,,,,203.155212402344,203.954406738281,100.238250732422,100.238250732422,54.8476548229481,5.62417178815405,8.86843299865723,131,1,64,0,0,0.473861694335937,33.7243423461914,2,1,1,203.954406738281,0,742397568,203.554809570313,,,,,,,,,,,,,,,,,,,,,,,,,,,,,,,,,
,3842622879.93041,208.530197143555,100.238250732422,7.80005103811319E-8,1.23197235428514E-8,1,10,13.3016452789307,8.00108320136104,31.8199992179871,0.000152306360768144,3.01139767227733E-5,1,3.82635669788044E-9,,,,,,,,,,,,,,,,,,,,,208.107360839844,208.953033447266,100.238250732422,100.238250732422,54.8828281063135,5.62360002399758,8.88911819458008,132,1,64,0,0,0.471420288085937,34.7018585205078,2,1,1,208.953033447266,0,742397312,208.530197143555,,,,,,,,,,,,,,,,,,,,,,,,,,,,,,,,,
,3842622939.81117,213.477691650391,100.238250732422,6.73780921668863E-8,1.22399524720634E-8,1,10,13.3016452789307,8.0011425385372,31.8400003015995,0.000132254997898209,2.13282171452444E-5,1,9.23371443239117E-10,,,,,,,,,,,,,,,,,,,,,213.073150634766,213.882232666016,100.238250732422,100.238250732422,55.0141416975443,5.62394289893123,8.89420604705811,132,1,64,0,0,0.471038818359375,34.2131004333496,2,1,1,213.882232666016,0,742397376,213.477691650391,,,,,,,,,,,,,,,,,,,,,,,,,,,,,,,,,
,3842622999.97781,218.501884460449,100.238250732422,5.5028525382965E-8,1.24694240873151E-8,1,10,13.3016452789307,8.00132093390762,31.870000064373,0.000107389286066976,2.1673342335388E-5,1,2.91700827170574E-9,,,,,,,,,,,,,,,,,,,,,218.121856689453,218.881912231445,100.238250732422,100.238250732422,54.9367604741404,5.62346628044919,8.90814399719238,132,1,64,0,0,0.474319458007812,33.7243423461914,2,1,1,218.881912231445,0,742397248,218.501884460449,,,,,,,,,,,,,,,,,,,,,,,,,,,,,,,,,
,3842623059.95365,223.46125793457,100.238250732422,3.77947452997818E-8,1.26190051017892E-8,1,10,13.3016452789307,8.00138140436565,31.8900011479855,7.36915058041892E-5,1.53341572602822E-5,1,2.23143188679765E-9,,,,,,,,,,,,,,,,,,,,,223.072387695313,223.850128173828,100.238250732422,100.238250732422,54.7765266276981,5.6240309344268,8.92879676818848,132,1,64,0,0,0.474166870117188,34.2131004333496,2,1,1,223.850128173828,0,742397376,223.46125793457,,,,,,,,,,,,,,,,,,,,,,,,,,,,,,,,,
,3842623119.88613,228.447723388672,100.238250732422,3.0519288202452E-8,1.25329914682679E-8,1,10,13.3016452789307,8.00164847940973,31.9099985063076,6.0252177022015E-5,7.32188108315175E-6,1,-7.71024546111455E-10,,,,,,,,,,,,,,,,,,,,,228.060852050781,228.834594726562,100.238250732422,100.238250732422,54.9285533746885,5.62282535070337,8.93813705444336,131,1,64,0,0,0.46966552734375,34.7018585205078,2,1,1,228.834594726562,0,742397344,228.447723388672,,,,,,,,,,,,,,,,,,,,,,,,,,,,,,,,,
,3842623179.92578,233.420845031738,100.238250732422,2.25213978613076E-8,1.26162714219912E-8,1,10,13.3016452789307,8.001740500087,31.9399982690811,4.37131097647071E-5,1.04946618228671E-5,1,2.01959330164447E-9,,,,,,,,,,,,,,,,,,,,,233.01481628418,233.826873779297,100.238250732422,100.238250732422,54.7522961436019,5.62401188657596,8.95790481567383,132,1,64,0,0,0.467071533203125,34.7018585205078,2,1,1,233.826873779297,0,742397312,233.420845031738,,,,,,,,,,,,,,,,,,,,,,,,,,,,,,,,,
,3842623239.92088,238.439277648926,100.238250732422,1.2002427190398E-8,1.25383460790165E-8,1,10,13.3016452789307,8.00160145729369,31.9700017571449,2.30477077797836E-5,7.27921979919457E-6,1,1.93364936419886E-9,,,,,,,,,,,,,,,,,,,,,238.032531738281,238.84602355957,100.238250732422,100.238250732422,54.7542502149,5.62289023622516,8.99553298950195,131,1,64,0,0,0.472412109375,34.7018585205078,2,1,1,238.84602355957,0,742397376,238.439277648926,,,,,,,,,,,,,,,,,,,,,,,,,,,,,,,,,
,3842623299.90208,243.379600524902,100.238250732422,-5.08957890060607E-9,1.24399276077235E-8,1,10,13.3016452789307,8.00171450124455,32.0000015199184,-1.07889271236258E-5,3.81078714293627E-6,1,2.68680344427379E-9,,,,,,,,,,,,,,,,,,,,,242.988479614258,243.770721435547,100.238250732422,100.238250732422,54.955519558602,5.62246960036784,9.06087875366211,131,1,64,0,0,0.474624633789063,33.7243423461914,2,1,1,243.770721435547,0,742397312,243.379600524902,,,,,,,,,,,,,,,,,,,,,,,,,,,,,,,,,
,3842623359.93751,248.391807556152,100.238250732422,-1.01009097985327E-8,1.25504880895482E-8,1,10,13.3016452789307,8.00150123831672,32.0100001990795,-1.98643029688149E-5,-2.94651744432867E-6,1,-1.08353804568819E-11,,,,,,,,,,,,,,,,,,,,,248.010131835938,248.773483276367,100.238250732422,100.238250732422,54.6526385074,5.62288455110163,9.15063381195068,131,1,64,0,0,0.475082397460937,34.2131004333496,2,1,1,248.773483276367,0,742397344,248.391807556152,,,,,,,,,,,,,,,,,,,,,,,,,,,,,,,,,
,3842623419.89509,253.347129821777,100.238250732422,-2.4172517065232E-8,1.3093145495634E-8,1,10,13.3016452789307,8.00163795205347,32.039999961853,-4.90962914360772E-5,3.5337609870716E-6,1,5.35566902500583E-9,,,,,,,,,,,,,,,,,,,,,252.958435058594,253.735824584961,100.238250732422,100.238250732422,54.7292381022846,5.62268695883322,9.29608631134033,132,1,64,0,0,0.4681396484375,34.2131004333496,2,1,1,253.735824584961,0,742397312,253.347129821777,,,,,,,,,,,,,,,,,,,,,,,,,,,,,,,,,
,3842623479.91254,258.327682495117,100.238250732422,-3.53702870709006E-8,1.24355693427197E-8,1,10,13.3016452789307,8.00163082788463,32.0799984037876,-6.9246522815175E-5,-1.24423714114077E-5,1,-1.11804949178037E-9,,,,,,,,,,,,,,,,,,,,,257.930053710938,258.725311279297,100.238250732422,100.238250732422,54.8628965790731,5.62283093276606,9.48793411254883,131,1,64,0,0,0.472335815429687,34.7018585205078,2,1,1,258.725311279297,0,742397216,258.327682495117,,,,,,,,,,,,,,,,,,,,,,,,,,,,,,,,,
,3842623540.04125,263.368469238281,100.238250732422,-5.11624446424879E-8,1.25050311542139E-8,1,10,13.3016452789307,8.00157153900829,32.090000808239,-0.000101841708738433,-6.59854225965855E-6,1,4.17817800892971E-9,,,,,,,,,,,,,,,,,,,,,262.989776611328,263.747161865234,100.238250732422,100.238250732422,54.8734485640827,5.62329301961847,9.5120210647583,131,1,64,0,0,0.47576904296875,34.2131004333496,2,1,1,263.747161865234,0,742397248,263.368469238281,,,,,,,,,,,,,,,,,,,,,,,,,,,,,,,,,
,3842623599.84929,268.332473754883,100.238250732422,-5.86369476693013E-8,1.22965292891045E-8,1,10,13.3016452789307,8.00172080249057,32.1200005710125,-0.000116635696397943,-8.14429751195378E-6,1,4.49285640471529E-9,,,,,,,,,,,,,,,,,,,,,267.895263671875,268.769683837891,100.238250732422,100.238250732422,54.8867362489097,5.62292789669647,9.4060230255127,132,1,64,0,0,0.472259521484375,34.7018585205078,2,1,1,268.769683837891,0,742397344,268.332473754883,,,,,,,,,,,,,,,,,,,,,,,,,,,,,,,,,
,3842623659.82299,273.282562255859,100.238250732422,-7.37899874173593E-8,1.22213791311699E-8,1,10,13.3016452789307,8.0016341323504,32.150000333786,-0.0001452852884859,-2.03732886504745E-5,1,5.06558607565385E-10,,,,,,,,,,,,,,,,,,,,,272.901306152344,273.663818359375,100.238250732422,100.238250732422,54.6659261922269,5.62268793610667,9.34680938720703,132,1,64,0,0,0.470352172851562,34.2131004333496,2,1,1,273.663818359375,0,742397408,273.282562255859,,,,,,,,,,,,,,,,,,,,,,,,,,,,,,,,,
,3842623719.80784,278.28923034668,100.238250732422,-8.0151070505394E-8,1.17485160030288E-8,1,10,13.3016452789307,8.00143453933675,32.1899987757206,-0.000157890219920552,-2.15670742483301E-5,1,8.36054223070278E-10,,,,,,,,,,,,,,,,,,,,,277.874267578125,278.704193115234,100.238250732422,100.238250732422,54.84570075165,5.62333042671686,9.32608413696289,131,1,64,0,0,0.472335815429687,34.2131004333496,2,1,1,278.704193115234,0,742397408,278.28923034668,,,,,,,,,,,,,,,,,,,,,,,,,,,,,,,,,
,3842623779.89349,283.268310546875,100.238250732422,-9.44591201776319E-8,1.19612131742416E-8,1,10,13.3016452789307,8.0012073907923,32.209999859333,-0.000187277996781557,-1.72313000110748E-5,1,5.14696150966038E-9,,,,,,,,,,,,,,,,,,,,,282.886688232422,283.649932861328,100.238250732422,100.238250732422,55.0649475512943,5.62423384441724,9.35364532470703,132,1,64,0,0,0.475540161132812,34.2131004333496,2,1,1,283.649932861328,0,742397120,283.268310546875,,,,,,,,,,,,,,,,,,,,,,,,,,,,,,,,,
,3842623839.70284,288.243530273438,100.238250732422,-1.07369552900975E-7,1.23415262263923E-8,1,10,13.3016452789307,8.00123851981144,32.2399996221066,-0.000211039950068464,-3.2050734667325E-5,1,-4.86701630779097E-10,,,,,,,,,,,,,,,,,,,,,287.8486328125,288.638427734375,100.238250732422,100.238250732422,54.8980698624385,5.62357070937257,9.37217426300049,133,1,0,0,1,0.47027587890625,34.2131004333496,2,1,1,288.638427734375,0,742397344,288.243530273438,,,,,,,,,,,,,,,,,,,,,,,,,,,,,,,,,
,3842623899.81987,293.256210327148,100.238250732422,-1.145979161562E-7,1.26590097171393E-8,1,10,13.3016452789307,8.00120141005976,32.2699993848801,-0.000226815917483038,-2.35529795687679E-5,1,4.89801107562121E-9,,,,,,,,,,,,,,,,,,,,,292.847900390625,293.664520263672,100.238250732422,100.238250732422,55.0067162266116,5.6242170464897,9.466628074646,132,1,64,0,0,0.4736328125,35.6793746948242,2,1,1,293.664520263672,0,742397280,293.256210327148,,,,,,,,,,,,,,,,,,,,,,,,,,,,,,,,,
,3842623959.86313,298.248336791992,100.238250732422,-1.27613083365193E-7,1.23280796406924E-8,1,10,13.3016452789307,8.00145299101078,32.3100015521049,-0.000250889689207027,-3.7711322898255E-5,1,-3.83817656728442E-10,,,,,,,,,,,,,,,,,,,,,297.824859619141,298.671813964844,100.238250732422,100.238250732422,54.7745725564,5.62324365110375,9.57610130310059,132,1,64,0,0,0.477447509765625,34.2131004333496,2,1,1,298.671813964844,0,742397152,298.248336791992,,,,,,,,,,,,,,,,,,,,,,,,,,,,,,,,,
,3842624019.6984,303.183471679687,100.238250732422,-1.35897096176952E-7,1.24648875370831E-8,1,10,13.3016452789307,8.00120335467151,32.3299989104271,-0.000268851597162752,-2.87481788220538E-5,1,5.39264847777412E-9,,,,,,,,,,,,,,,,,,,,,302.759338378906,303.607604980469,100.238250732422,100.238250732422,54.8644598361116,5.62407971792933,9.75188064575195,131,1,64,0,0,0.471115112304687,34.2131004333496,2,1,1,303.607604980469,0,742397248,303.183471679687,,,,,,,,,,,,,,,,,,,,,,,,,,,,,,,,,
,3842624079.71114,308.181777954102,100.238250732422,-1.46327734178412E-7,1.205173653556E-8,1,10,13.3016452789307,8.00138012480216,32.3599986732006,-0.000288662041316118,-3.65824082489974E-5,1,2.94552022718216E-9,,,,,,,,,,,,,,,,,,,,,307.779052734375,308.584503173828,100.238250732422,100.238250732422,55.0856607070539,5.62365914215614,10.0558748245239,132,1,64,0,0,0.4681396484375,34.2131004333496,2,1,1,308.584503173828,0,742397376,308.181777954102,,,,,,,,,,,,,,,,,,,,,,,,,,,,,,,,,
,3842624139.79643,313.146926879883,100.238250732422,-1.50473621022126E-7,1.21682414334142E-8,1,10,13.3016452789307,8.00132815160533,32.4000008404255,-0.000296642573032134,-3.89568873210797E-5,1,2.34864130436834E-9,,,,,,,,,,,,,,,,,,,,,312.766082763672,313.527770996094,100.238250732422,100.238250732422,55.2814586511212,5.62493182278993,10.5435972213745,131,1,64,0,0,0.473251342773438,34.2131004333496,2,1,1,313.527770996094,0,742397344,313.146926879883,,,,,,,,,,,,,,,,,,,,,,,,,,,,,,,,,
,3842624199.79691,318.172958374023,100.238250732422,-1.5758912592908E-7,1.19676704637127E-8,1,10,13.3016452789307,8.00101290909377,32.430000603199,-0.000310342176696764,-4.29784756779215E-5,1,1.3511590240957E-9,,,,,,,,,,,,,,,,,,,,,317.792907714844,318.553009033203,100.238250732422,100.238250732422,55.0219579827366,5.62549170468631,11.2015933990479,132,1,64,0,0,0.477447509765625,34.7018585205078,2,1,1,318.553009033203,0,742397344,318.172958374023,,,,,,,,,,,,,,,,,,,,,,,,,,,,,,,,,
,3842624259.91826,323.107864379883,100.238250732422,-1.70103702958264E-7,1.22397023381997E-8,1,10,13.3016452789307,8.00083993855036,32.4699990451336,-0.000336265512172901,-3.76820327986016E-5,1,5.88640996660905E-9,,,,,,,,,,,,,,,,,,,,,322.73095703125,323.484771728516,100.238250732422,100.238250732422,54.9508297874866,5.62507372015757,11.3578262329102,132,1,64,0,0,0.4736328125,34.2131004333496,2,1,1,323.484771728516,0,742397312,323.107864379883,,,,,,,,,,,,,,,,,,,,,,,,,,,,,,,,,
,3842624319.822,328.070510864258,100.238250732422,-1.71943916568017E-7,1.23967841863109E-8,1,10,13.3016452789307,8.0007578079608,32.480001449585,-0.000338613911389088,-4.68334938583587E-5,1,1.50426269131597E-9,,,,,,,,,,,,,,,,,,,,,327.68798828125,328.453033447266,100.238250732422,100.238250732422,54.9883479564097,5.62544261090504,11.2194089889526,131,1,64,0,0,0.463104248046875,34.2131004333496,2,1,1,328.453033447266,0,742397344,328.070510864258,,,,,,,,,,,,,,,,,,,,,,,,,,,,,,,,,
,3842624379.74305,333.071426391602,100.238250732422,-1.87326066565E-7,1.23156775972376E-8,1,10,13.3016452789307,8.00059194452406,32.5100012123585,-0.000368097459474553,-5.64878599756638E-5,1,-1.13994246131437E-9,,,,,,,,,,,,,,,,,,,,,332.684539794922,333.458312988281,100.238250732422,100.238250732422,54.6866393479866,5.6259593649148,11.098895072937,132,1,64,0,0,0.469589233398438,34.2131004333496,2,1,1,333.458312988281,0,742397248,333.071426391602,,,,,,,,,,,,,,,,,,,,,,,,,,,,,,,,,
,3842624439.72953,338.06103515625,100.238250732422,-1.93672846985118E-7,1.23015699400363E-8,1,10,13.3016452789307,8.00051914436882,32.540000975132,-0.000381963161175413,-4.89190259060169E-5,1,3.64276132074392E-9,,,,,,,,,,,,,,,,,,,,,337.661010742188,338.461059570313,100.238250732422,100.238250732422,55.1278686470924,5.62728506143313,11.0056266784668,132,1,64,0,0,0.464859008789063,34.2131004333496,2,1,1,338.461059570313,0,742397376,338.06103515625,,,,,,,,,,,,,,,,,,,,,,,,,,,,,,,,,
,3842624499.80534,342.995330810547,100.238250732422,-1.98720425877899E-7,1.22779834379622E-8,1,10,13.3016452789307,8.0009256843747,32.5599983334541,-0.000390494762279168,-5.99374844752906E-5,1,-1.21552449895105E-9,,,,,,,,,,,,,,,,,,,,,342.597412109375,343.393249511719,100.238250732422,100.238250732422,54.7628481286116,5.62531604728508,10.9304389953613,132,1,64,0,0,0.46722412109375,34.2131004333496,2,1,1,343.393249511719,0,742397344,342.995330810547,,,,,,,,,,,,,,,,,,,,,,,,,,,,,,,,,
,3842624559.86014,348.026901245117,100.238250732422,-1.99302902477088E-7,1.24749005222524E-8,1,10,13.3016452789307,8.00099215944356,32.600000500679,-0.000393462496795495,-4.77433481689257E-5,1,5.07028320402659E-9,,,,,,,,,,,,,,,,,,,,,347.658905029297,348.394897460937,100.238250732422,100.238250732422,54.9973366843808,5.62579456136485,10.8750791549683,131,1,64,0,0,0.46966552734375,34.2131004333496,2,1,1,348.394897460937,0,742397312,348.026901245117,,,,,,,,,,,,,,,,,,,,,,,,,,,,,,,,,
,3842624619.82026,352.975784301758,100.238250732422,-2.08551375389803E-7,1.19722727583591E-8,1,10,13.3016452789307,8.00086899178889,32.6200015842915,-0.000409776149678308,-6.31418953764718E-5,1,-1.39741705458425E-9,,,,,,,,,,,,,,,,,,,,,352.596343994141,353.355224609375,100.238250732422,100.238250732422,54.8038836258712,5.62582740364711,10.8314237594604,131,1,64,0,0,0.469894409179687,34.7018585205078,2,1,1,353.371429443359,0,742397280,352.975784301758,,,,,,,,,,,,,,,,,,,,,,,,,,,,,,,,,
,3842624679.80353,357.936416625977,100.238250732422,-2.12282994565868E-7,1.25603069940456E-8,1,10,13.3016452789307,8.00079521514687,32.6399989426136,-0.000418277792589199,-5.63137689429881E-5,1,2.6235414463766E-9,,,,,,,,,,,,,,,,,,,,,357.560028076172,358.312805175781,100.238250732422,100.238250732422,55.0848790785347,5.62572375324668,10.7927188873291,131,1,64,0,0,0.473556518554687,33.7243423461914,2,1,1,358.312805175781,0,742397376,357.936416625977,,,,,,,,,,,,,,,,,,,,,,,,,,,,,,,,,
,3842624739.73022,362.9345703125,100.238250732422,-2.17474367145813E-7,1.23362862073754E-8,1,10,13.3016452789307,8.00038041714624,32.6699987053871,-0.000428000599935477,-6.10427932685338E-5,1,9.82574731938903E-10,,,,,,,,,,,,,,,,,,,,,362.532684326172,363.336456298828,100.238250732422,100.238250732422,54.8859546203904,5.6267790156229,10.7578344345093,131,1,64,0,0,0.470199584960937,34.7018585205078,2,1,1,363.336456298828,0,742397536,362.9345703125,,,,,,,,,,,,,,,,,,,,,,,,,,,,,,,,,
,3842624799.68534,367.896011352539,100.238250732422,-2.21121838408402E-7,1.23807359002634E-8,1,10,13.3016452789307,8.00034481382583,32.6999984681606,-0.000435282465954331,-6.13564427768306E-5,1,1.36006019366293E-9,,,,,,,,,,,,,,,,,,,,,367.48583984375,368.306182861328,100.238250732422,100.238250732422,54.9746694573231,5.62683802273864,10.7350101470947,132,1,64,0,0,0.471267700195313,34.2131004333496,2,1,1,368.306182861328,0,742397440,367.896011352539,,,,,,,,,,,,,,,,,,,,,,,,,,,,,,,,,
,3842624859.69334,372.885986328125,100.238250732422,-2.29910714068235E-7,1.24111584714175E-8,1,10,13.3016452789307,8.00045370198262,32.7299982309341,-0.000452156053881979,-6.67223445973388E-5,1,-7.39682462111806E-11,,,,,,,,,,,,,,,,,,,,,372.497009277344,373.274963378906,100.238250732422,100.238250732422,54.9344155885827,5.62688172207926,10.7080392837524,132,1,64,0,0,0.478363037109375,34.2131004333496,2,1,1,373.274963378906,0,742397216,372.885986328125,,,,,,,,,,,,,,,,,,,,,,,,,,,,,,,,,
,3842624919.67778,377.851913452148,100.238250732422,-2.34432381401441E-7,1.26064327913096E-8,1,10,13.3016452789307,8.00067110422856,32.770000398159,-0.000461401738765834,-6.56848671991444E-5,1,1.11979891482424E-9,,,,,,,,,,,,,,,,,,,,,377.443511962891,378.260314941406,100.238250732422,100.238250732422,54.8906443915058,5.62676778979813,10.6872596740723,131,1,64,0,0,0.471267700195313,34.2131004333496,2,1,1,378.260314941406,0,742397344,377.851913452148,,,,,,,,,,,,,,,,,,,,,,,,,,,,,,,,,
,3842624979.86205,382.876373291016,100.238250732422,-2.38013429740649E-7,1.21444579038909E-8,1,10,13.3016452789307,8.00056378353207,32.8000001609325,-0.000469351712514279,-6.05385317144887E-5,1,4.26345511625042E-9,,,,,,,,,,,,,,,,,,,,,382.449615478516,383.303131103516,100.238250732422,100.238250732422,54.9398869882174,5.62697733579004,10.6712999343872,131,1,64,0,0,0.47119140625,34.2131004333496,2,1,1,383.303131103516,0,742397344,382.876373291016,,,,,,,,,,,,,,,,,,,,,,,,,,,,,,,,,
,3842625039.70003,387.825668334961,100.238250732422,-2.41096127262573E-7,1.20373800877147E-8,1,10,13.3016452789307,8.00058300395705,32.820001244545,-0.000475238864166409,-6.26296148708898E-5,1,3.65417425181538E-9,,,,,,,,,,,,,,,,,,,,,387.439422607422,388.2119140625,100.238250732422,100.238250732422,55.0500966094289,5.62736438782083,10.6494131088257,132,1,64,0,0,0.475311279296875,34.7018585205078,2,1,1,388.2119140625,0,742397344,387.825668334961,,,,,,,,,,,,,,,,,,,,,,,,,,,,,,,,,
,3842625099.63677,392.765686035156,100.238250732422,-2.40212571746505E-7,1.2300622761689E-8,1,10,13.3016452789307,8.00042307228884,32.8500010073185,-0.00047330766634407,-6.36510388773379E-5,1,3.00438111294114E-9,,,,,,,,,,,,,,,,,,,,,392.367462158203,393.163909912109,100.238250732422,100.238250732422,54.9938193560443,5.62785942230623,10.6245374679565,132,1,64,0,0,0.463714599609375,34.2131004333496,2,1,1,393.163909912109,0,742397440,392.765686035156,,,,,,,,,,,,,,,,,,,,,,,,,,,,,,,,,
,3842625159.55762,397.76872253418,100.238250732422,-2.44738149476475E-7,1.19868700360422E-8,1,10,13.3016452789307,8.00038452553637,32.880000770092,-0.000482911686753016,-6.01755512883846E-5,1,5.4377511749169E-9,,,,,,,,,,,,,,,,,,,,,397.38818359375,398.149261474609,100.238250732422,100.238250732422,54.9226911607943,5.62672936311194,10.612753868103,131,1,64,0,0,0.465545654296875,34.2131004333496,2,1,1,398.149261474609,0,742397472,397.76872253418,,,,,,,,,,,,,,,,,,,,,,,,,,,,,,,,,
,3842625219.49012,399.753860473633,100.238250732422,-2.49625312442073E-7,1.23321033413809E-8,1,10,13.3016452789307,8.00056427923429,32.8899994492531,-0.000491190607486607,-7.06860917851223E-5,1,8.13633701430701E-10,,,,,,,,,,,,,,,,,,,,,399.727233886719,399.780487060547,100.238250732422,100.238250732422,54.9723245717654,5.62635161582681,10.5828371047974,133,1,0,0,1,0.470199584960937,34.7018585205078,5,1,1,399.780487060547,0,742397440,399.753860473633,,,,,,,,,,,,,,,,,,,,,,,,,,,,,,,,,
,3842625269.48624,399.887725830078,100.238250732422,-2.49947196453414E-7,1.24704879633651E-8,1,10,13.3016452789307,8.0002961058313,32.8899994492531,-0.00049129429720907,-7.43109477694698E-5,1,-9.82732616133408E-10,,,,,,,,,,,,,,,,,,,,,399.877838134766,399.897613525391,100.238250732422,100.238250732422,55.0497057951693,5.6270589790264,10.566333770752,133,1,0,0,1,0.469741821289063,34.2131004333496,1,1,1,399.897613525391,0,742397216,399.887725830078,,,,,,,,,,,,,,,,,,,,,,,,,,,,,,,,,