File: demonstration_data/squid/000_MA2936-3_211005_Qrod_IP_buchner_standard_002_MH_2K_FC.dat
[Header]
; MPMS3 Data File (default extension .dat)
; Copyright (c) 2007, Quantum Design, Inc. All rights reserved.
TITLE,
FILEOPENTIME,3842610207.97435,10/05/2021,4:46 pm
BYAPP,MPMS3 w/ AC,1.0,1.1
INFO,MPMS3 Measurement Release 1.1.16 Build 424, MultiVu Release 2.3.4.19,APPNAME
INFO,Linear Motor Servo Controller,MOTOR_MODULE_NAME
INFO,3101-100 J0,MOTOR_HW_VERSION
INFO,MMC714,MOTOR_SERIAL_NUMBER
INFO,01.04.28,MOTOR_SOFTWARE_VERSION
INFO,Quantum Design Squid Module,SQUID_MODULE_NAME
INFO,3101-501 B0,SQUID_HW_VERSION
INFO,SQM189,SQUID_SERIAL_NUMBER
INFO,01.03.04,SQUID_SOFTWARE_VERSION
INFO,Quantum Design VSM Oven,OVEN_MODULE_NAME
INFO,3101-201 A1,OVEN_HW_VERSION
INFO,OVB229,OVEN_SERIAL_NUMBER
INFO,01.07.07,OVEN_SOFTWARE_VERSION
INFO,SQUID AC,AC_MODULE_NAME
INFO,3101-401 F1,AC_HW_VERSION
INFO,SAC108,AC_SERIAL_NUMBER
INFO,SQUID AC 00.95.07,AC_SOFTWARE_VERSION
INFO,TCI177,COIL_SERIAL_NUMBER
INFO,0,MOMENT_UNITS
INFO,A2481,SAMPLE_MATERIAL
INFO,,SAMPLE_COMMENT
INFO,,SAMPLE_MASS
INFO,,SAMPLE_VOLUME
INFO,,SAMPLE_MOLECULAR_WEIGHT
INFO,5mm x 5mm,SAMPLE_SIZE
INFO,,SAMPLE_SHAPE
INFO,Straw,SAMPLE_HOLDER
INFO,Standard,SAMPLE_HOLDER_DETAIL
INFO,65.98,SAMPLE_OFFSET
DATATYPE,COMMENT,1
DATATYPE,TIME,2
STARTUPAXIS,X,2
STARTUPAXIS,Y1,5
FIELDGROUP, VSM,2,3,4,5,6,8,9,10,11,14,15
FIELDGROUP, DC, 2,3,4,14,56,57,58,59,60,61,62,63,64,65,66,67,68,69
FIELDGROUP, AC, 2,3,4,11,16,17,18,19,20,21,22,23,24,25,26,27,28,29,30
STARTUPGROUP, All
[Data]
Comment,Time Stamp (sec),Temperature (K),Magnetic Field (Oe),Moment (emu),M. Std. Err. (emu),Transport Action,Averaging Time (sec),Frequency (Hz),Peak Amplitude (mm),Center Position (mm),Lockin Signal' (V),Lockin Signal (V),Range,M. Quad. Signal (emu),AC Moment (emu),AC M. Std Err. (emu),AC Phase (deg),AC Phase Std. Err. (deg),AC Susceptibility (emu/Oe),AC Suscept. Std Err. (emu/Oe),AC X' (emu/Oe),AC X' Std Err. (emu/Oe),AC X'' (emu/Oe),AC X'' Std Err. (emu/Oe),AC Drive (Oe),AC Frequency (Hz),AC Averaging Time (sec),AC Cycles,AC Range,AC Measure Type,AC Signal' (V),AC Signal'' (V),AC Trim Coil Ratio,AC Trim Coil Phase,Min. Temperature (K),Max. Temperature (K),Min. Field (Oe),Max. Field (Oe),Mass (grams),Motor Lag (deg),Pressure (Torr),Measure Count,Measurement Number,SQUID Status (code),Motor Status (code),Measure Status (code),Motor Current (amps),Motor Temp. (C),Temp. Status (code),Field Status (code),Chamber Status (code),Chamber Temp (K),Redirection State,Evercool Status,Average Temp (K),Rotation Angle (deg),Rotator state,DC Moment Fixed Ctr (emu),DC Moment Err Fixed Ctr (emu),DC Moment Free Ctr (emu),DC Moment Err Free Ctr (emu),DC Fixed Fit,DC Free Fit,DC Calculated Center (mm),DC Calculated Center Err (mm),DC Scan Length (mm),DC Scan Time (s),DC Number of Points,DC Squid Drift,DC Min V (V),DC Max V (V),DC Scans per Measure,Map 01,Map 02,Map 03,Map 04,Map 05,Map 06,Map 07,Map 08,Map 09,Map 10,Map 11,Map 12,Map 13,Map 14,Map 15,Map 16
,3842610287.61544,3.00011849403381,69999.65625,-0.000381794452214633,8.30753817113606E-7,1,10,13.3016452789307,7.99478914174203,31.360000371933,-0.750359624210114,-0.112133947071922,1,-8.23406970795342E-7,,,,,,,,,,,,,,,,,,,,,3.00011849403381,3.00011849403381,69999.65625,69999.65625,56.0533168138617,5.61937629071992,4.54297924041748,133,1,0,0,1,0.474700927734375,32.2580642700195,1,1,1,3.00011849403381,0,742397056,3.00011849403381,,,,,,,,,,,,,,,,,,,,,,,,,,,,,,,,,
,3842610354.86601,3.00092995166779,55875.3359375,-0.000301274353045542,1.01189435171623E-6,1,10,13.3016452789307,7.99460768163638,31.360000371933,-0.59212522948449,-0.0883257288322212,1,-5.69307921507663E-7,,,,,,,,,,,,,,,,,,,,,3.00028705596924,3.00157284736633,55875.3359375,55875.3359375,55.7168257363328,5.61875780508301,4.55665063858032,133,1,0,0,1,0.472030639648438,33.2355842590332,1,1,1,3.00028705596924,0,742396896,3.00092995166779,,,,,,,,,,,,,,,,,,,,,,,,,,,,,,,,,
,3842610439.14985,2.9996964931488,35600.8828125,-0.000187002670004723,6.0064690443994E-7,1,10,13.3016452789307,7.99443627512772,31.360000371933,-0.367516992413952,-0.0549188706294318,1,-4.01826453325527E-7,,,,,,,,,,,,,,,,,,,,,2.99932837486267,3.00006461143494,35600.8828125,35600.8828125,55.2697342233328,5.61740549136357,4.57920932769775,133,1,0,0,1,0.473556518554687,33.2355842590332,1,1,1,2.99932837486267,0,742397024,2.9996964931488,,,,,,,,,,,,,,,,,,,,,,,,,,,,,,,,,
,3842610514.22915,2.99943006038666,22682.9921875,-0.000115792215770804,3.06476487006843E-7,1,10,13.3016452789307,7.99424196557219,31.360000371933,-0.227575650313071,-0.0339244817671317,1,-2.07676006971079E-7,,,,,,,,,,,,,,,,,,,,,2.99908185005188,2.99977827072144,22682.9921875,22682.9921875,55.0035897125347,5.61770086368212,4.5941104888916,133,1,0,0,1,0.470962524414063,33.7243423461914,1,1,1,2.99908185005188,0,742397120,2.99943006038666,,,,,,,,,,,,,,,,,,,,,,,,,,,,,,,,,
,3842610580.20253,2.99978816509247,14452.4404296875,-7.18181186039282E-5,1.8182310210062E-7,1,10,13.3016452789307,7.99406312989077,31.360000371933,-0.141158463475729,-0.0209703653206215,1,-9.29740368104559E-8,,,,,,,,,,,,,,,,,,,,,2.9996931552887,2.99988317489624,14452.4404296875,14452.4404296875,54.8453099373904,5.61692419699418,4.61469411849976,133,1,0,0,1,0.475311279296875,34.2131004333496,1,1,1,2.9996931552887,0,742397120,2.99978816509247,,,,,,,,,,,,,,,,,,,,,,,,,,,,,,,,,
,3842610640.72445,2.99933218955994,9208.5478515625,-4.46145366929858E-5,1.19872023831221E-7,1,10,13.3016452789307,7.99393498537076,31.360000371933,-0.0876926146923892,-0.0130028201786841,1,-4.54563091161901E-8,,,,,,,,,,,,,,,,,,,,,2.99857759475708,3.00008678436279,9208.5478515625,9208.5478515625,54.9070585904097,5.61858437655211,4.61558675765991,133,1,0,0,1,0.47271728515625,34.2131004333496,1,1,1,3.00008678436279,0,742397184,2.99933218955994,,,,,,,,,,,,,,,,,,,,,,,,,,,,,,,,,
,3842610698.51601,2.99991357326508,5867.244140625,-2.76907802061067E-5,8.0881420605043E-8,1,10,13.3016452789307,7.99383020107427,31.360000371933,-0.0544330293550859,-0.00803302284100783,1,-9.21777570476428E-9,,,,,,,,,,,,,,,,,,,,,2.99963903427124,3.00018811225891,5867.244140625,5867.244140625,54.955519558602,5.61817618294423,4.62301683425903,133,1,0,0,1,0.472335815429687,34.2131004333496,1,1,1,2.99963903427124,0,742397216,2.99991357326508,,,,,,,,,,,,,,,,,,,,,,,,,,,,,,,,,
,3842610755.7515,3.00030541419983,3738.44140625,-1.70555854700106E-5,5.56537908532612E-8,1,10,13.3016452789307,7.99377005619621,31.360000371933,-0.0335294254581201,-0.00492993360934346,1,3.39051972958307E-9,,,,,,,,,,,,,,,,,,,,,2.99930119514465,3.001309633255,3738.44140625,3738.44140625,54.8542986653616,5.61822760484426,4.62899589538574,133,1,0,0,1,0.47119140625,34.2131004333496,1,1,1,3.001309633255,0,742397152,3.00030541419983,,,,,,,,,,,,,,,,,,,,,,,,,,,,,,,,,
,3842610810.727,2.99951660633087,2382.18896484375,-1.03469211702069E-5,4.14974603892364E-8,1,10,13.3016452789307,7.99400945498382,31.360000371933,-0.0203440236521582,-0.00297208483823848,1,1.15961849186259E-8,,,,,,,,,,,,,,,,,,,,,2.99850845336914,3.0005247592926,2382.18896484375,2382.18896484375,54.799975483275,5.61765658832997,4.61850547790527,133,1,0,0,1,0.471343994140625,34.2131004333496,1,1,1,2.99850845336914,0,742397216,2.99951660633087,,,,,,,,,,,,,,,,,,,,,,,,,,,,,,,,,
,3842610866.6488,2.9993771314621,1517.79187011719,-6.09688592672232E-6,3.20183581599763E-8,1,10,13.3016452789307,7.99379953600748,31.360000371933,-0.0119916931424506,-0.00172255543595627,1,2.1436992958425E-8,,,,,,,,,,,,,,,,,,,,,2.99932098388672,2.99943327903748,1517.79187011719,1517.79187011719,54.7104790178231,5.61779213470092,4.61965703964233,133,1,0,0,1,0.472335815429687,34.2131004333496,1,1,1,2.99922370910645,0,742397152,2.9993771314621,,,,,,,,,,,,,,,,,,,,,,,,,,,,,,,,,
,3842610922.54345,2.99988842010498,967.284973144531,-3.41902462586331E-6,2.64635837577099E-8,1,10,13.3016452789307,7.99379188497601,31.360000371933,-0.00672940248878312,-0.000934199090927318,1,2.81869572625661E-8,,,,,,,,,,,,,,,,,,,,,2.99976634979248,3.00001049041748,967.284973144531,967.284973144531,54.7862969841885,5.61789798047609,4.60571098327637,133,1,0,0,1,0.474853515625,34.2131004333496,1,1,1,3.00001049041748,0,742397088,2.99988842010498,,,,,,,,,,,,,,,,,,,,,,,,,,,,,,,,,
,3842610976.05719,2.99997067451477,616.408203125,-1.72838555989064E-6,2.58345128218493E-8,1,10,13.3016452789307,7.99372601340089,31.360000371933,-0.00341191201647027,-0.000403794667503429,1,4.90738660172125E-8,,,,,,,,,,,,,,,,,,,,,2.99971675872803,3.00022459030151,616.408203125,616.408203125,54.7839520986308,5.61854456226371,4.62125635147095,133,1,0,0,1,0.472259521484375,34.7018585205078,1,1,1,3.00022459030151,0,742397248,2.99997067451477,,,,,,,,,,,,,,,,,,,,,,,,,,,,,,,,,
,3842611235.15425,2.99999940395355,392.782806396484,-6.8437130020073E-7,2.09256281703572E-8,1,10,13.3016452789307,7.99355609726246,31.360000371933,-0.00136269865621888,-8.01857514192397E-5,1,5.99738864897409E-8,,,,,,,,,,,,,,,,,,,,,2.99906873703003,3.00093007087708,392.782806396484,392.782806396484,54.7859061699289,5.6188717267354,4.62218570709229,133,1,0,0,1,0.471267700195313,34.2131004333496,1,1,1,2.99906873703003,0,742397216,2.99999940395355,,,,,,,,,,,,,,,,,,,,,,,,,,,,,,,,,
,3842611336.01794,3.00089478492737,250.295074462891,-1.06009194067005E-8,2.12589886500083E-8,1,10,13.3016452789307,7.99345587321441,31.360000371933,-3.00223581990291E-5,5.93020891177606E-5,1,3.17278846398168E-8,,,,,,,,,,,,,,,,,,,,,3.00089478492737,3.00089478492737,250.295074462891,250.295074462891,54.8343671381212,5.61907505777274,4.60689735412598,133,1,0,0,1,0.4736328125,34.7018585205078,1,1,1,3.00089478492737,0,742397344,3.00089478492737,,,,,,,,,,,,,,,,,,,,,,,,,,,,,,,,,
,3842611471.89602,3.00070786476135,159.613250732422,4.08439034395157E-7,1.81857033073662E-8,1,10,13.3016452789307,7.99331013769356,31.360000371933,0.000793665507253478,0.000180916248665219,1,3.18962715193807E-8,,,,,,,,,,,,,,,,,,,,,3.00070786476135,3.00070786476135,159.613250732422,159.613250732422,54.6244998807077,5.61879017138033,4.62554407119751,133,1,0,0,1,0.476760864257812,34.2131004333496,1,1,1,3.00070786476135,0,742397216,3.00070786476135,,,,,,,,,,,,,,,,,,,,,,,,,,,,,,,,,
,3842611607.13595,2.9999852180481,101.931167602539,6.81200829029992E-7,1.74142182074932E-8,1,10,13.3016452789307,7.99311502998767,31.360000371933,0.00133102399374125,0.000251778990630962,1,2.77859614375317E-8,,,,,,,,,,,,,,,,,,,,,2.9999852180481,2.9999852180481,101.931167602539,101.931167602539,54.8703220500058,5.61958590832131,4.61435317993164,133,1,0,0,1,0.473251342773438,34.7018585205078,1,1,1,2.9999852180481,0,742397312,2.9999852180481,,,,,,,,,,,,,,,,,,,,,,,,,,,,,,,,,
,3842611657.64055,3.00004005432129,65.1530227661133,8.14097864602577E-7,3.2141912475224E-8,1,10,13.3016452789307,7.99324019199728,31.360000371933,0.001583858184329,0.000347441278508944,1,5.68818505804181E-8,,,,,,,,,,,,,,,,,,,,,2.9998996257782,3.00018048286438,65.1530227661133,65.1530227661133,54.6061316105058,5.61962857077588,4.61903190612793,133,1,0,0,1,0.474853515625,34.2131004333496,1,1,1,2.9998996257782,0,742397344,3.00004005432129,,,,,,,,,,,,,,,,,,,,,,,,,,,,,,,,,
,3842611712.91727,3.00043618679047,41.4888954162598,9.53733622566087E-7,1.71393034383121E-8,1,10,13.3016452789307,7.99335531403571,31.360000371933,0.00185789114171262,0.000391068588801666,1,5.85144169517951E-8,,,,,,,,,,,,,,,,,,,,,3.000333070755,3.00053930282593,41.4888954162598,41.4888954162598,54.6381783797942,5.61841615782191,4.63695096969604,133,1,0,0,1,0.47393798828125,34.7018585205078,1,1,1,3.000333070755,0,742397280,3.00043618679047,,,,,,,,,,,,,,,,,,,,,,,,,,,,,,,,,
,3842611808.3928,3.00010216236114,26.547004699707,1.02778675908784E-6,1.67743643366873E-8,1,10,13.3016452789307,7.99327761945953,31.360000371933,0.00201025885110345,0.000366269950409635,1,3.49969465034498E-8,,,,,,,,,,,,,,,,,,,,,2.99984884262085,3.00035548210144,26.547004699707,26.547004699707,54.9754510858424,5.61875986903397,4.62113046646118,133,1,0,0,1,0.472793579101562,34.2131004333496,1,1,1,3.00035548210144,0,742397152,3.00010216236114,,,,,,,,,,,,,,,,,,,,,,,,,,,,,,,,,
,3842611862.33262,3.00058162212372,16.9905738830566,1.06998042040792E-6,1.64402652998127E-8,1,10,13.3016452789307,7.99301734773729,31.360000371933,0.00209346321697601,0.000376439711979827,1,3.39614436667169E-8,,,,,,,,,,,,,,,,,,,,,3.00040006637573,3.0007631778717,16.9905738830566,16.9905738830566,54.9457492021116,5.62004420227322,4.63128662109375,133,1,0,0,1,0.475921630859375,34.2131004333496,1,1,1,3.00040006637573,0,742397120,3.00058162212372,,,,,,,,,,,,,,,,,,,,,,,,,,,,,,,,,
,3842611916.10382,3.00031852722168,10.9794683456421,1.09818070220963E-6,1.62080619862453E-8,1,10,13.3016452789307,7.99317545007753,31.360000371933,0.00215122366825799,0.000368967782650646,1,2.60061658776233E-8,,,,,,,,,,,,,,,,,,,,,2.99978137016296,3.0008556842804,10.9794683456421,10.9794683456421,54.904713704852,5.61976396108954,4.63868045806885,133,1,0,0,1,0.473251342773438,34.7018585205078,1,1,1,3.0008556842804,0,742397280,3.00031852722168,,,,,,,,,,,,,,,,,,,,,,,,,,,,,,,,,
,3842611969.88761,3.00037169456482,7.09065103530884,1.12435721414184E-6,1.66367633781779E-8,1,10,13.3016452789307,7.99311182440207,31.360000371933,0.00220326537115098,0.00037250120783058,1,2.39503755583482E-8,,,,,,,,,,,,,,,,,,,,,3.00027656555176,3.00046682357788,7.09065103530884,7.09065103530884,54.7937224551212,5.61949200204814,4.64265537261963,133,1,0,0,1,0.474166870117188,34.2131004333496,1,1,1,2.99948048591614,0,742397152,3.00037169456482,,,,,,,,,,,,,,,,,,,,,,,,,,,,,,,,,
,3842612020.9612,2.99977612495422,4.75981426239014,1.13740992452205E-6,1.63616769535852E-8,1,10,13.3016452789307,7.99309383768758,31.360000371933,0.00222966418971647,0.000371229828344251,1,2.13820150436939E-8,,,,,,,,,,,,,,,,,,,,,2.99958968162537,2.99996256828308,4.75981426239014,4.75981426239014,54.8722761213039,5.62010144178979,4.63882350921631,133,1,0,0,1,0.473403930664063,34.2131004333496,1,1,1,2.99996256828308,0,742397312,2.99977612495422,,,,,,,,,,,,,,,,,,,,,,,,,,,,,,,,,
,3842612071.16801,2.9997673034668,2.98101758956909,1.13866096967352E-6,1.66673899582795E-8,1,10,13.3016452789307,7.99298912636025,31.360000371933,0.0022319528491184,0.000372636375802929,1,2.19147382491017E-8,,,,,,,,,,,,,,,,,,,,,2.99939322471619,3.00014138221741,2.98101758956909,2.98101758956909,54.8331946953423,5.62043161149504,4.6267671585083,133,1,0,0,1,0.4754638671875,34.7018585205078,1,1,1,2.99939322471619,0,742397216,2.9997673034668,,,,,,,,,,,,,,,,,,,,,,,,,,,,,,,,,
,3842612120.70596,3.00005400180817,2.19589352607727,1.14800430621115E-6,1.63923347520832E-8,1,10,13.3016452789307,7.99285950827336,31.360000371933,0.00225125952820982,0.000368812340341023,1,1.85954113592609E-8,,,,,,,,,,,,,,,,,,,,,2.9991340637207,3.00097393989563,2.19589352607727,2.19589352607727,55.0430619527558,5.620343589182,4.63804244995117,133,1,0,0,1,0.472946166992188,34.2131004333496,1,1,1,2.9991340637207,0,742397280,3.00005400180817,,,,,,,,,,,,,,,,,,,,,,,,,,,,,,,,,
,3842612172.67649,3.00027692317963,-0.858729302883148,1.15878060430656E-6,1.63150951195812E-8,1,10,13.3016452789307,7.99275661457203,31.360000371933,0.00227228678760848,0.000372875362320922,1,1.90770701472907E-8,,,,,,,,,,,,,,,,,,,,,3.00002098083496,3.00053286552429,-0.858729302883148,-0.858729302883148,54.9039320763327,5.61993359953048,4.62770748138428,133,1,0,0,1,0.47637939453125,34.7018585205078,1,1,1,3.00002098083496,0,742397312,3.00027692317963,,,,,,,,,,,,,,,,,,,,,,,,,,,,,,,,,
,3842612222.59526,2.99938714504242,-1.52117776870728,1.16655245159607E-6,1.63624437859207E-8,1,10,13.3016452789307,7.99290362966423,31.360000371933,0.00228854710207097,0.000368610747385446,1,1.57613189553754E-8,,,,,,,,,,,,,,,,,,,,,2.99904561042786,2.99972867965698,-1.52117776870728,-1.52117776870728,54.8734485640827,5.62006731737386,4.64259576797485,133,1,0,0,1,0.472335815429687,34.2131004333496,1,1,1,2.99904561042786,0,742397152,2.99938714504242,,,,,,,,,,,,,,,,,,,,,,,,,,,,,,,,,
,3842612272.61918,3.0001904964447,-2.28176665306091,1.16710606822669E-6,1.61265183738737E-8,1,10,13.3016452789307,7.99268334707493,31.360000371933,0.00228910211464571,0.000372146735925163,1,1.748156235051E-8,,,,,,,,,,,,,,,,,,,,,3.00003981590271,3.00034117698669,-2.28176665306091,-2.28176665306091,55.0528323092462,5.62046013400055,4.63872623443604,133,1,0,0,1,0.47088623046875,34.2131004333496,1,1,1,3.00003981590271,0,742397248,3.0001904964447,,,,,,,,,,,,,,,,,,,,,,,,,,,,,,,,,
,3842612323.4481,3.00043118000031,-4.18323850631714,1.17734059156694E-6,1.62503854444607E-8,1,10,13.3016452789307,7.99250989714349,31.3699990510941,0.0023088978705372,0.000377100983591179,1,1.84973726797074E-8,,,,,,,,,,,,,,,,,,,,,2.99991083145142,3.00095152854919,-4.18323850631714,-4.18323850631714,54.7718368565827,5.6208439743776,4.63363599777222,133,1,0,0,1,0.468368530273438,34.2131004333496,1,1,1,3.00095152854919,0,742397376,3.00043118000031,,,,,,,,,,,,,,,,,,,,,,,,,,,,,,,,,
,3842612375.42932,2.999995470047,-6.46500539779663,1.18483427720907E-6,1.64226785001626E-8,1,10,13.3016452789307,7.99272753877405,31.360000371933,0.00232569981828028,0.000365444432096415,1,1.14610981634346E-8,,,,,,,,,,,,,,,,,,,,,2.99987840652466,3.00011253356934,-6.46500539779663,-6.46500539779663,54.8972882339193,5.62102659905134,4.62915563583374,133,1,0,0,1,0.473785400390625,34.2131004333496,1,1,1,3.00011253356934,0,742397056,2.999995470047,,,,,,,,,,,,,,,,,,,,,,,,,,,,,,,,,
,3842612431.66977,2.99953484535217,-10.3660898208618,1.20295830552173E-6,1.66107602321425E-8,1,10,13.3016452789307,7.9925180545865,31.360000371933,0.00235830513193463,0.000390966274306482,1,2.17791638573482E-8,,,,,,,,,,,,,,,,,,,,,2.99931406974793,2.99975562095642,-10.3660898208618,-10.3660898208618,54.9645082865731,5.6211589442282,4.64828205108643,133,1,0,0,1,0.4736328125,34.2131004333496,1,1,1,2.99931406974793,0,742397184,2.99953484535217,,,,,,,,,,,,,,,,,,,,,,,,,,,,,,,,,
,3842612487.60203,2.999884724617,-16.4753360748291,1.22139663806852E-6,1.64671197280344E-8,1,10,13.3016452789307,7.99257855931046,31.360000371933,0.00239553049689672,0.000389704774932713,1,1.8421765101099E-8,,,,,,,,,,,,,,,,,,,,,2.99986934661865,2.99990010261536,-16.4753360748291,-16.4753360748291,54.8797015922366,5.62092433594123,4.62953042984009,133,1,0,0,1,0.474166870117188,34.2131004333496,1,1,1,2.99990010261536,0,742397120,2.999884724617,,,,,,,,,,,,,,,,,,,,,,,,,,,,,,,,,
,3842612543.19967,2.99875164031982,-26.0195007324219,1.25933711572848E-6,1.64364882088671E-8,1,10,13.3016452789307,7.99270320353259,31.360000371933,0.00246853932183926,0.000411496086055285,1,2.39196744068825E-8,,,,,,,,,,,,,,,,,,,,,2.99848747253418,2.99901580810547,-26.0195007324219,-26.0195007324219,54.7300197308039,5.62089435775017,4.63169717788696,133,1,0,0,1,0.473175048828125,34.2131004333496,1,1,1,2.99875450134277,0,742397280,2.99875164031982,,,,,,,,,,,,,,,,,,,,,,,,,,,,,,,,,
,3842612599.01219,2.99971985816956,-41.0104598999023,1.3115184696026E-6,1.63695154188831E-8,1,10,13.3016452789307,7.99261415355838,31.360000371933,0.00256781882795243,0.000448849993339433,1,3.52411007149831E-8,,,,,,,,,,,,,,,,,,,,,2.99950075149536,2.99993896484375,-41.0104598999023,-41.0104598999023,54.8652414646308,5.62058537151492,4.63548803329468,133,1,0,0,1,0.473098754882812,34.2131004333496,1,1,1,2.99993896484375,0,742397216,2.99971985816956,,,,,,,,,,,,,,,,,,,,,,,,,,,,,,,,,
,3842612737.96416,2.99971270561218,-64.3310928344727,1.40945470552115E-6,1.53882200588249E-8,1,10,13.3016452789307,7.99241789331055,31.360000371933,0.00276474781623656,0.000446922066232389,1,1.98436798872073E-8,,,,,,,,,,,,,,,,,,,,,2.99971270561218,2.99971270561218,-64.3310928344727,-64.3310928344727,54.7132147176404,5.62129702466363,4.63679361343384,133,1,0,0,1,0.475006103515625,34.2131004333496,1,1,1,2.99971270561218,0,742397344,2.99971270561218,,,,,,,,,,,,,,,,,,,,,,,,,,,,,,,,,
,3842612872.30731,2.99931764602661,-101.096984863281,1.55372441752914E-6,1.58881172973407E-8,1,10,13.3016452789307,7.99232809518034,31.360000371933,0.00304538280308109,0.000508567181717193,1,2.99648224172236E-8,,,,,,,,,,,,,,,,,,,,,2.99931764602661,2.99931764602661,-101.096984863281,-101.096984863281,54.8175621249577,5.62131745026928,4.63861131668091,133,1,0,0,1,0.470428466796875,34.2131004333496,1,1,1,2.99931764602661,0,742397248,2.99931764602661,,,,,,,,,,,,,,,,,,,,,,,,,,,,,,,,,
,3842612965.91035,3.00109267234802,-159.12255859375,1.78267535300616E-6,1.52313070912546E-8,1,10,13.3016452789307,7.99235657825701,31.3699990510941,0.00349548422373192,0.000574418829444334,1,2.97558495943935E-8,,,,,,,,,,,,,,,,,,,,,3.00109267234802,3.00109267234802,-159.12255859375,-159.12255859375,54.6319253516404,5.6219611432407,4.65289783477783,133,1,0,0,1,0.474700927734375,34.2131004333496,1,1,1,3.00109267234802,0,742397216,3.00109267234802,,,,,,,,,,,,,,,,,,,,,,,,,,,,,,,,,
,3842613099.7315,2.99952578544617,-249.828903198242,2.16455830927242E-6,1.3972633891893E-8,1,10,13.3016452789307,7.99219231232072,31.360000371933,0.00424594744438469,0.000685828244606072,1,3.02113722588981E-8,,,,,,,,,,,,,,,,,,,,,2.99952578544617,2.99952578544617,-249.828903198242,-249.828903198242,54.8554711081404,5.62189715969692,4.65323495864868,133,1,0,0,1,0.476226806640625,34.2131004333496,1,1,1,2.99952578544617,0,742397216,2.99952578544617,,,,,,,,,,,,,,,,,,,,,,,,,,,,,,,,,
,3842613193.46969,3.00028252601624,-392.243041992188,2.79240953633607E-6,1.290450544859E-8,1,10,13.3016452789307,7.9922649263509,31.360000371933,0.00548148937569007,0.00085803403356451,1,2.53758153648545E-8,,,,,,,,,,,,,,,,,,,,,3.00028252601624,3.00028252601624,-392.243041992188,-392.243041992188,54.8714944927847,5.62230018570659,4.65317487716675,133,1,0,0,1,0.468597412109375,34.7018585205078,1,1,1,3.00028252601624,0,742397312,3.00028252601624,,,,,,,,,,,,,,,,,,,,,,,,,,,,,,,,,
,3842613282.45821,2.99965214729309,-615.708923339844,3.74964216897862E-6,7.24489164179871E-8,1,10,13.3016452789307,7.9921505408079,31.3699990510941,0.00734976261050804,0.00122490936203619,1,7.10870940963245E-8,,,,,,,,,,,,,,,,,,,,,2.99925398826599,3.00005030632019,-615.708923339844,-615.708923339844,54.6119938244,5.62192577884063,4.6519627571106,133,1,0,0,1,0.475845336914063,34.7018585205078,1,1,1,3.00005030632019,0,742397280,2.99965214729309,,,,,,,,,,,,,,,,,,,,,,,,,,,,,,,,,
,3842613336.92911,3.00041711330414,-966.401733398438,5.46307811128567E-6,8.23236402231727E-9,1,10,13.3016452789307,7.99207718239948,31.360000371933,0.0107362324139745,0.0015946102118625,1,6.89606394716307E-9,,,,,,,,,,,,,,,,,,,,,2.99996948242188,3.0008647441864,-966.401733398438,-966.401733398438,54.8230335245923,5.62192215871884,4.63863468170166,133,1,0,0,1,0.475540161132812,34.7018585205078,1,1,1,2.99996948242188,0,742397216,3.00041711330414,,,,,,,,,,,,,,,,,,,,,,,,,,,,,,,,,
,3842613390.87516,3.00005447864532,-1517.26440429687,8.10972069327067E-6,5.35872205173894E-9,1,10,13.3016452789307,7.99198697811326,31.360000371933,0.0159370396109604,0.00236961007048622,1,1.15037507784746E-8,,,,,,,,,,,,,,,,,,,,,2.99963283538818,3.00047612190247,-1517.26440429687,-1517.26440429687,54.7628481286116,5.62264577463611,4.63918352127075,133,1,0,0,1,0.469436645507812,34.7018585205078,1,1,1,3.00047612190247,0,742397408,3.00005447864532,,,,,,,,,,,,,,,,,,,,,,,,,,,,,,,,,
,3842613445.07745,3.00008451938629,-2381.1953125,1.23207514307261E-5,1.30512200203699E-8,1,10,13.3016452789307,7.99219602260857,31.360000371933,0.0242120612609427,0.00360523296837993,1,2.00885734176989E-8,,,,,,,,,,,,,,,,,,,,,2.99972224235535,3.00044679641724,-2381.1953125,-2381.1953125,54.7886418697462,5.62237672286562,4.65217399597168,133,1,0,0,1,0.474014282226562,34.2131004333496,1,1,1,3.00044679641724,0,742397344,3.00008451938629,,,,,,,,,,,,,,,,,,,,,,,,,,,,,,,,,
,3842613500.16195,2.99973511695862,-3737.72998046875,1.89916631172549E-5,3.13457993408828E-8,1,10,13.3016452789307,7.99202189703615,31.360000371933,0.0373208679960775,0.00555747836654773,1,3.11211894790622E-8,,,,,,,,,,,,,,,,,,,,,2.99926686286926,3.00020337104797,-3737.72998046875,-3737.72998046875,54.7679287139866,5.62271129843406,4.65252113342285,133,1,0,0,1,0.47637939453125,34.2131004333496,1,1,1,3.00020337104797,0,742397216,2.99973511695862,,,,,,,,,,,,,,,,,,,,,,,,,,,,,,,,,
,3842613556.10337,3.00036072731018,-5866.421875,2.95887559112013E-5,6.03326876653278E-8,1,10,13.3016452789307,7.99205939866818,31.360000371933,0.0581475583768786,0.00864495242232232,1,4.15943608110786E-8,,,,,,,,,,,,,,,,,,,,,3.00019812583923,3.00052332878113,-5866.421875,-5866.421875,54.8308498097847,5.62306955138206,4.63737392425537,133,1,0,0,1,0.4754638671875,34.2131004333496,1,1,1,3.00052332878113,0,742397024,3.00036072731018,,,,,,,,,,,,,,,,,,,,,,,,,,,,,,,,,
,3842613614.88156,2.99924266338348,-9207.921875,4.64810792927257E-5,1.03043929478063E-7,1,10,13.3016452789307,7.99201464823152,31.360000371933,0.0913428771603517,0.0135873875657405,1,6.8924611784174E-8,,,,,,,,,,,,,,,,,,,,,2.99915027618408,2.99933505058289,-9207.921875,-9207.921875,54.84570075165,5.62183447037857,4.63881540298462,133,1,0,0,1,0.474166870117188,34.7018585205078,1,1,1,2.99933505058289,0,742397312,2.99924266338348,,,,,,,,,,,,,,,,,,,,,,,,,,,,,,,,,
,3842613675.75611,2.99988222122192,-14451.7158203125,7.36105062976066E-5,1.75104847104191E-7,1,10,13.3016452789307,7.99202390879125,31.360000371933,0.144652453929843,0.0215467746082875,1,1.23844556878802E-7,,,,,,,,,,,,,,,,,,,,,2.99982905387878,2.99993538856506,-14451.7158203125,-14451.7158203125,54.8746210068616,5.62362531474378,4.65071582794189,133,1,0,0,1,0.475006103515625,34.2131004333496,1,1,1,2.99993538856506,0,742397216,2.99988222122192,,,,,,,,,,,,,,,,,,,,,,,,,,,,,,,,,
,3842613741.76572,3.0001950263977,-22682.44140625,0.000117450024150308,2.95126289540383E-7,1,10,13.3016452789307,7.99198052236337,31.360000371933,0.230787422052223,0.0344716706032764,1,2.44707255810219E-7,,,,,,,,,,,,,,,,,,,,,2.99993872642517,3.00045132637024,-22682.44140625,-22682.44140625,55.1345124895058,5.62318748705359,4.63189935684204,131,1,32,0,0,0.474472045898438,34.2131004333496,1,1,1,3.00011467933655,0,742397216,3.0001950263977,,,,,,,,,,,,,,,,,,,,,,,,,,,,,,,,,
,3842613813.86788,3.00034034252167,-35600.1328125,0.000188602461342116,5.91489963433839E-7,1,10,13.3016452789307,7.99193827067988,31.3699990510941,0.370594541474171,0.0553900152073512,1,4.10869137903871E-7,,,,,,,,,,,,,,,,,,,,,3.00032520294189,3.00035548210144,-35600.1328125,-35600.1328125,55.3119421633712,5.62363467260698,4.6287202835083,133,1,0,0,1,0.47576904296875,34.7018585205078,1,1,1,3.00032520294189,0,742397152,3.00034034252167,,,,,,,,,,,,,,,,,,,,,,,,,,,,,,,,,
,3842613896.63893,2.99936091899872,-55874.51171875,0.000302334209500575,1.08337987324632E-6,1,10,13.3016452789307,7.99201149887081,31.360000371933,0.594026499280957,0.0891205114398999,1,8.25783602685289E-7,,,,,,,,,,,,,,,,,,,,,2.99821972846985,3.00050210952759,-55874.51171875,-55874.51171875,55.6531230120155,5.62596561383052,4.63540458679199,129,1,32,0,0,0.475234985351562,34.7018585205078,1,1,1,3.00050210952759,0,742397024,2.99936091899872,,,,,,,,,,,,,,,,,,,,,,,,,,,,,,,,,
,3842613992.32208,3.00010001659393,-55875.3359375,0.000302460072370453,1.05415312582343E-6,1,10,13.3016452789307,7.99186375563006,31.360000371933,0.594302732345462,0.088918310128513,1,7.04850503688699E-7,,,,,,,,,,,,,,,,,,,,,2.99998641014099,3.00021362304687,-55875.3359375,-55875.3359375,55.7015839802078,5.62518627135544,4.64317560195923,131,1,32,0,0,0.470504760742188,34.2131004333496,1,1,1,2.99998641014099,0,742397088,3.00010001659393,,,,,,,,,,,,,,,,,,,,,,,,,,,,,,,,,
,3842614075.54874,3.00002372264862,-35600.84765625,0.00018831000457153,6.04370658142988E-7,1,10,13.3016452789307,7.99192073169501,31.360000371933,0.370034139935773,0.0552041017871394,1,3.59379454224167E-7,,,,,,,,,,,,,,,,,,,,,2.99988198280334,3.0001654624939,-35600.84765625,-35600.84765625,55.3338277619097,5.62448564344683,4.63524293899536,133,1,0,0,1,0.476608276367188,34.2131004333496,1,1,1,2.99988198280334,0,742397120,3.00002372264862,,,,,,,,,,,,,,,,,,,,,,,,,,,,,,,,,
,3842614151.42208,3.00001955032349,-22682.96875,0.000117266206900515,3.14644448987209E-7,1,10,13.3016452789307,7.99187353419239,31.3699990510941,0.230426651087785,0.0344028136320703,1,2.36871935152105E-7,,,,,,,,,,,,,,,,,,,,,2.9995744228363,3.00046467781067,-22682.96875,-22682.96875,54.7409625300731,5.62439830894624,4.64873218536377,133,1,0,0,1,0.472488403320313,34.7018585205078,1,1,1,2.9995744228363,0,742397152,3.00001955032349,,,,,,,,,,,,,,,,,,,,,,,,,,,,,,,,,
,3842614218.95684,2.9998574256897,-14452.40234375,7.329505421025E-5,1.91110075279132E-7,1,10,13.3016452789307,7.99199760757412,31.3699990510941,0.14403995143928,0.0214023719947121,1,9.684543310695E-8,,,,,,,,,,,,,,,,,,,,,2.99953413009644,3.00018072128296,-14452.40234375,-14452.40234375,55.0665108083327,5.62286155004747,4.65151453018188,133,1,0,0,1,0.4736328125,34.2131004333496,1,1,1,2.99953413009644,0,742397216,2.9998574256897,,,,,,,,,,,,,,,,,,,,,,,,,,,,,,,,,
,3842614281.18724,3.00004768371582,-9208.36328125,4.61076983948933E-5,1.22567447877943E-7,1,10,13.3016452789307,7.99171138684772,31.360000371933,0.0906101020371383,0.0134582093886554,1,5.83257310630387E-8,,,,,,,,,,,,,,,,,,,,,2.9998517036438,3.00024366378784,-9208.36328125,-9208.36328125,55.021567168477,5.62295365485061,4.64316892623901,133,1,0,0,1,0.475082397460937,34.2131004333496,1,1,1,2.9998517036438,0,742397152,3.00004768371582,,,,,,,,,,,,,,,,,,,,,,,,,,,,,,,,,
,3842614339.1497,2.99943542480469,-5867.32958984375,2.91916778083482E-5,8.13781820604783E-8,1,10,13.3016452789307,7.99190728409647,31.3699990510941,0.0573699491596129,0.00850618024056711,1,2.95043013037655E-8,,,,,,,,,,,,,,,,,,,,,2.99932384490967,2.99954700469971,-5867.32958984375,-5867.32958984375,54.9004147479962,5.62270417036395,4.65267324447632,133,1,0,0,1,0.475540161132812,35.190616607666,1,1,1,2.99954700469971,0,742397280,2.99943542480469,,,,,,,,,,,,,,,,,,,,,,,,,,,,,,,,,
,3842614396.68962,3.00004863739014,-3738.50268554687,1.85511471881789E-5,5.88503897839535E-8,1,10,13.3016452789307,7.99183957741928,31.360000371933,0.0364640275712285,0.00536539310061656,1,-1.70786436138769E-9,,,,,,,,,,,,,,,,,,,,,3.00000810623169,3.00008916854858,-3738.50268554687,-3738.50268554687,54.7300197308039,5.62342609992155,4.65126180648804,133,1,0,0,1,0.475234985351562,34.7018585205078,1,1,1,3.00008916854858,0,742397376,3.00004863739014,,,,,,,,,,,,,,,,,,,,,,,,,,,,,,,,,
,3842614453.63933,2.99987816810608,-2382.04150390625,1.18369967035988E-5,4.19107770423095E-8,1,10,13.3016452789307,7.99200737576619,31.3699990510941,0.023270324406168,0.00340101892694663,1,-1.25554601377232E-8,,,,,,,,,,,,,,,,,,,,,2.99915218353271,3.00060415267944,-2382.04150390625,-2382.04150390625,54.792940826602,5.62294482513819,4.64503955841064,133,1,0,0,1,0.471572875976562,34.7018585205078,1,1,1,3.00060415267944,0,742397152,2.99987816810608,,,,,,,,,,,,,,,,,,,,,,,,,,,,,,,,,
,3842614509.98876,3.00009179115295,-1517.96362304687,7.5882468007421E-6,3.32303643544234E-8,1,10,13.3016452789307,7.99193776696957,31.360000371933,0.0149210744741325,0.00215695334797404,1,-1.9902537239393E-8,,,,,,,,,,,,,,,,,,,,,2.99989199638367,3.00029158592224,-1517.96362304687,-1517.96362304687,54.4689558053808,5.62293513258895,4.64755916595459,133,1,0,0,1,0.47210693359375,34.7018585205078,1,1,1,2.99989199638367,0,742397344,3.00009179115295,,,,,,,,,,,,,,,,,,,,,,,,,,,,,,,,,
,3842614564.07194,3.00080919265747,-967.199157714844,4.90795573840539E-6,2.70039043767501E-8,1,10,13.3016452789307,7.99171279351065,31.360000371933,0.00965459838594599,0.00136762016279853,1,-2.68333522320984E-8,,,,,,,,,,,,,,,,,,,,,2.99980211257935,3.0018162727356,-967.199157714844,-967.199157714844,54.8918168342847,5.62406780350154,4.64454460144043,133,1,0,0,1,0.47210693359375,34.7018585205078,1,1,1,2.99980211257935,0,742397312,3.00080919265747,,,,,,,,,,,,,,,,,,,,,,,,,,,,,,,,,
,3842614621.6649,2.99985682964325,-616.481811523437,3.23465876831481E-6,2.40543966560104E-8,1,10,13.3016452789307,7.99160173965252,31.360000371933,0.00637033359642572,0.000851209900689275,1,-4.31908399280468E-8,,,,,,,,,,,,,,,,,,,,,2.99934959411621,3.00036406517029,-616.481811523437,-616.481811523437,54.7968489691981,5.62327323471374,4.65510940551758,133,1,0,0,1,0.470046997070313,35.190616607666,1,1,1,2.99934959411621,0,742397408,2.99985682964325,,,,,,,,,,,,,,,,,,,,,,,,,,,,,,,,,
,3842614836.00012,2.99978196620941,-392.880950927734,2.17680439323944E-6,2.14880587454488E-8,1,10,13.3016452789307,7.99157535217139,31.360000371933,0.00429519540819373,0.000517090635946878,1,-5.7424941674784E-8,,,,,,,,,,,,,,,,,,,,,2.99962973594666,2.99993419647217,-392.880950927734,-392.880950927734,54.8671955359289,5.62330560302156,4.64576148986816,133,1,0,0,1,0.470504760742188,34.2131004333496,1,1,1,2.99962973594666,0,742397280,2.99978196620941,,,,,,,,,,,,,,,,,,,,,,,,,,,,,,,,,
,3842614936.6413,2.99891424179077,-250.442276000977,1.50542583229638E-6,1.96582170645155E-8,1,10,13.3016452789307,7.99163502815917,31.360000371933,0.00296769615494634,0.000376426774406998,1,-3.01398723453037E-8,,,,,,,,,,,,,,,,,,,,,2.99891424179077,2.99891424179077,-250.442276000977,-250.442276000977,54.8453099373904,5.6226966689324,4.63394451141357,133,1,0,0,1,0.471572875976562,34.7018585205078,1,1,1,2.99891424179077,0,742397376,2.99891424179077,,,,,,,,,,,,,,,,,,,,,,,,,,,,,,,,,
,3842615071.22153,3.0006115436554,-159.613250732422,1.08148656098171E-6,1.85965572829454E-8,1,10,13.3016452789307,7.99162072865383,31.360000371933,0.00213385743773408,0.00025759182877094,1,-2.8179761773798E-8,,,,,,,,,,,,,,,,,,,,,3.0006115436554,3.0006115436554,-159.613250732422,-159.613250732422,54.8070101399481,5.62336503331973,4.63957262039185,133,1,0,0,1,0.476760864257812,34.7018585205078,1,1,1,3.0006115436554,0,742397280,3.0006115436554,,,,,,,,,,,,,,,,,,,,,,,,,,,,,,,,,
,3842615163.22964,2.99983036518097,-101.894371032715,8.1899436562742E-7,1.87180751340459E-8,1,10,13.3016452789307,7.99170308879433,31.360000371933,0.00162710779607047,0.000119284530072298,1,-5.98979241090658E-8,,,,,,,,,,,,,,,,,,,,,2.99928522109985,3.00037550926209,-101.894371032715,-101.894371032715,54.891426020025,5.62343098935902,4.65459299087524,133,1,0,0,1,0.476608276367188,34.2131004333496,1,1,1,2.99928522109985,0,742397408,2.99983036518097,,,,,,,,,,,,,,,,,,,,,,,,,,,,,,,,,
,3842615220.48771,3.00012409687042,-65.1039505004883,6.5632979973804E-7,1.83049061888913E-8,1,10,13.3016452789307,7.99146854886039,31.360000371933,0.00130772860116871,6.97125414763905E-5,1,-6.11676690070107E-8,,,,,,,,,,,,,,,,,,,,,3.00004434585571,3.00020384788513,-65.1039505004883,-65.1039505004883,54.8890811344673,5.62414620636562,4.65373802185059,133,1,0,0,1,0.475387573242188,34.7018585205078,1,1,1,3.00020384788513,0,742397376,3.00012409687042,,,,,,,,,,,,,,,,,,,,,,,,,,,,,,,,,
,3842615276.40621,2.99986374378204,-41.2680816650391,5.42011465460286E-7,1.81643759779242E-8,1,10,13.3016452789307,7.99147230347999,31.3699990510941,0.00108033647715745,5.49526729260934E-5,1,-5.18452957523796E-8,,,,,,,,,,,,,,,,,,,,,2.99982690811157,2.99990057945251,-41.2680816650391,-41.2680816650391,54.9348064028424,5.6231636439265,4.64592409133911,133,1,0,0,1,0.46722412109375,34.7018585205078,1,1,1,2.99982690811157,0,742397312,2.99986374378204,,,,,,,,,,,,,,,,,,,,,,,,,,,,,,,,,
,3842615371.97635,2.99991250038147,-26.5592727661133,4.6651091455745E-7,1.79252004432426E-8,1,10,13.3016452789307,7.99152181517984,31.360000371933,0.000925883655629102,7.42511439959342E-5,1,-3.09104950555221E-8,,,,,,,,,,,,,,,,,,,,,2.99944663047791,3.00037837028503,-26.5592727661133,-26.5592727661133,54.8222518960731,5.62366373334149,4.65567350387573,133,1,0,0,1,0.468368530273438,34.2131004333496,1,1,1,2.99969577789307,0,742397440,2.99991250038147,,,,,,,,,,,,,,,,,,,,,,,,,,,,,,,,,
,3842615425.73231,3.00042080879211,-17.1745872497559,4.18087385515725E-7,1.74298652130694E-8,1,10,13.3016452789307,7.99137461929753,31.360000371933,0.0008294205714529,6.89094438740163E-5,1,-2.64981372734499E-8,,,,,,,,,,,,,,,,,,,,,2.99955868721008,3.00128293037415,-17.1745872497559,-17.1745872497559,54.8175621249577,5.62348209095128,4.65268707275391,133,1,0,0,1,0.469970703125,34.7018585205078,1,1,1,3.00128293037415,0,742397216,3.00042080879211,,,,,,,,,,,,,,,,,,,,,,,,,,,,,,,,,
,3842615479.6935,3.00000083446503,-11.0530729293823,3.935225927734E-7,1.84612231934921E-8,1,10,13.3016452789307,7.991529817321,31.360000371933,0.00078130694743282,6.07141939575613E-5,1,-2.70511908044389E-8,,,,,,,,,,,,,,,,,,,,,2.9993326663971,3.00066900253296,-11.0530729293823,-11.0530729293823,55.0274293823712,5.62410681350069,4.65178155899048,133,1,0,0,1,0.473556518554687,34.7018585205078,1,1,1,3.00066900253296,0,742397472,3.00000083446503,,,,,,,,,,,,,,,,,,,,,,,,,,,,,,,,,
,3842615533.6703,3.00011825561523,-7.02931308746338,3.77431225970905E-7,1.79306295784578E-8,1,10,13.3016452789307,7.99150446722596,31.3699990510941,0.000747944394826196,6.78291336043574E-5,1,-2.10620310427451E-8,,,,,,,,,,,,,,,,,,,,,2.99984526634216,3.00039124488831,-7.02931308746338,-7.02931308746338,54.8273324814481,5.62341232447325,4.64759635925293,133,1,0,0,1,0.47637939453125,34.2131004333496,1,1,1,3.00039124488831,0,742397408,3.00011825561523,,,,,,,,,,,,,,,,,,,,,,,,,,,,,,,,,
,3842615583.74532,2.99968433380127,-4.72301149368286,3.61621690838417E-7,1.75369266707415E-8,1,10,13.3016452789307,7.99149111155153,31.360000371933,0.000715883963652644,6.99490953603367E-5,1,-1.7655687919825E-8,,,,,,,,,,,,,,,,,,,,,2.99951481819153,2.99985384941101,-4.72301149368286,-4.72301149368286,54.9578644441597,5.62366093307305,4.6368408203125,133,1,0,0,1,0.470046997070313,34.2131004333496,1,1,1,2.99951481819153,0,742397376,2.99968433380127,,,,,,,,,,,,,,,,,,,,,,,,,,,,,,,,,
,3842615633.76824,2.99949407577515,-3.23863649368286,3.57784054335187E-7,1.76839633300058E-8,1,10,13.3016452789307,7.99156847505952,31.360000371933,0.000708700272571032,6.64249812662122E-5,1,-1.88838008776533E-8,,,,,,,,,,,,,,,,,,,,,2.99891877174377,3.00006937980652,-3.23863649368286,-3.23863649368286,54.962554215275,5.6230141692778,4.64079284667969,133,1,0,0,1,0.475845336914063,34.7018585205078,1,1,1,2.99891877174377,0,742397376,2.99949407577515,,,,,,,,,,,,,,,,,,,,,,,,,,,,,,,,,
,3842615683.41066,2.99933040142059,-2.18362617492676,3.54521337720557E-7,1.62016521973065E-8,1,10,13.3016452789307,7.9916225043342,31.360000371933,0.000701323998741082,7.2041685830552E-5,1,-1.55459472296096E-8,,,,,,,,,,,,,,,,,,,,,2.999098777771,2.99956202507019,-2.18362617492676,-2.18362617492676,54.975841900102,5.62293609677936,4.64308547973633,133,1,0,0,1,0.470504760742188,34.7018585205078,1,1,1,2.999098777771,0,742397216,2.99933040142059,,,,,,,,,,,,,,,,,,,,,,,,,,,,,,,,,
,3842615733.26913,2.99934899806976,-1.49664258956909,3.45924772081585E-7,1.7811842329103E-8,1,10,13.3016452789307,7.99142774319177,31.360000371933,0.000684343040917071,7.00604515702735E-5,1,-1.52877207551714E-8,,,,,,,,,,,,,,,,,,,,,2.99880170822144,2.99989628791809,-1.49664258956909,-1.49664258956909,54.7862969841885,5.62333809373654,4.6433367729187,133,1,0,0,1,0.471649169921875,34.7018585205078,1,1,1,2.99989628791809,0,742397440,2.99934899806976,,,,,,,,,,,,,,,,,,,,,,,,,,,,,,,,,
,3842615784.98151,3.00011730194092,1.37396705150604,3.35473721727226E-7,1.79927721644531E-8,1,10,13.3016452789307,7.99156812646908,31.3699990510941,0.000664104092742118,6.50251519701244E-5,1,-1.63111018999399E-8,,,,,,,,,,,,,,,,,,,,,2.99996542930603,3.00026917457581,1.37396705150604,1.37396705150604,54.8093550255058,5.62267475730003,4.63353109359741,133,1,0,0,1,0.467681884765625,34.7018585205078,1,1,1,2.99938583374023,0,742397248,3.00011730194092,,,,,,,,,,,,,,,,,,,,,,,,,,,,,,,,,
,3842615835.21691,2.9994193315506,2.34310436248779,3.30108144669729E-7,1.7874927795314E-8,1,10,13.3016452789307,7.99145384889413,31.360000371933,0.00065300955681259,6.71604302493385E-5,1,-1.44344584466464E-8,,,,,,,,,,,,,,,,,,,,,2.99936723709106,2.99947142601013,2.34310436248779,2.34310436248779,54.9437951308135,5.62345965237532,4.63253307342529,133,1,0,0,1,0.468368530273438,34.2131004333496,1,1,1,2.99947142601013,0,742397472,2.9994193315506,,,,,,,,,,,,,,,,,,,,,,,,,,,,,,,,,
,3842615885.01362,2.99974715709686,3.98695755004883,3.25253548219324E-7,1.6395667715078E-8,1,10,13.3016452789307,7.99149809669603,31.360000371933,0.000643819367381471,6.33813817895444E-5,1,-1.56424631223882E-8,,,,,,,,,,,,,,,,,,,,,2.99939441680908,3.00009989738464,3.98695755004883,3.98695755004883,54.932070703025,5.62347178586748,4.63711309432983,133,1,0,0,1,0.4742431640625,33.7243423461914,1,1,1,2.99939441680908,0,742397216,2.99974715709686,,,,,,,,,,,,,,,,,,,,,,,,,,,,,,,,,
,3842615936.84159,3.00040209293366,6.51407527923584,3.11302597193796E-7,1.68512646319692E-8,1,10,13.3016452789307,7.99152115797719,31.360000371933,0.000615348052855196,6.64852628755288E-5,1,-1.20092686658969E-8,,,,,,,,,,,,,,,,,,,,,2.99996662139893,3.00083756446838,6.51407527923584,6.51407527923584,54.9277717461693,5.62340655348354,4.64422273635864,133,1,0,0,1,0.47607421875,34.2131004333496,1,1,1,2.99996662139893,0,742397312,3.00040209293366,,,,,,,,,,,,,,,,,,,,,,,,,,,,,,,,,
,3842615991.79427,3.00009918212891,10.3538227081299,2.99935427689975E-7,1.57998903294023E-8,1,10,13.3016452789307,7.99142180942761,31.360000371933,0.000593134056483435,6.22947557304429E-5,1,-1.24673949253462E-8,,,,,,,,,,,,,,,,,,,,,2.99953031539917,3.00066804885864,10.3538227081299,10.3538227081299,54.9328523315443,5.62447593026813,4.65003967285156,133,1,0,0,1,0.467376708984375,34.2131004333496,1,1,1,3.00066804885864,0,742397344,3.00009918212891,,,,,,,,,,,,,,,,,,,,,,,,,,,,,,,,,
,3842616047.51128,2.9993394613266,16.2545204162598,2.76546977119722E-7,1.63240282106267E-8,1,10,13.3016452789307,7.99149902328929,31.360000371933,0.00054739865442144,5.39517948036517E-5,1,-1.32685985061236E-8,,,,,,,,,,,,,,,,,,,,,2.99907469749451,2.99960422515869,16.2545204162598,16.2545204162598,54.8898627629866,5.62416720173979,4.63503360748291,133,1,0,0,1,0.4693603515625,34.2131004333496,1,1,1,2.99907469749451,0,742397312,2.9993394613266,,,,,,,,,,,,,,,,,,,,,,,,,,,,,,,,,
,3842616103.05312,3.00055289268494,25.835485458374,2.3593674365992E-7,1.71435047826716E-8,1,10,13.3016452789307,7.9914884072362,31.360000371933,0.000469999007536091,2.57566914837693E-5,1,-2.16341472217524E-8,,,,,,,,,,,,,,,,,,,,,3.00050663948059,3.00059914588928,25.835485458374,25.835485458374,54.9441859450731,5.6233244686659,4.63284635543823,133,1,0,0,1,0.467529296875,34.2131004333496,1,1,1,3.00059914588928,0,742397216,3.00055289268494,,,,,,,,,,,,,,,,,,,,,,,,,,,,,,,,,
,3842616158.59738,3.00005483627319,40.8141784667969,1.88517448279428E-7,1.88643208803035E-8,1,10,13.3016452789307,7.99135810983746,31.360000371933,0.000381921782964596,-2.28066622240876E-5,1,-3.93600665769469E-8,,,,,,,,,,,,,,,,,,,,,2.99999213218689,3.0001175403595,40.8141784667969,40.8141784667969,54.9484849019289,5.6237801659773,4.65112161636353,133,1,0,0,1,0.475540161132812,34.2131004333496,1,1,1,3.0001175403595,0,742397184,3.00005483627319,,,,,,,,,,,,,,,,,,,,,,,,,,,,,,,,,
,3842616252.32554,3.00021934509277,64.2574920654297,8.99691300026979E-8,1.58200938651005E-8,1,10,13.3016452789307,7.99136765454445,31.360000371933,0.000187497346693042,-4.63832752596204E-5,1,-3.68453935085134E-8,,,,,,,,,,,,,,,,,,,,,2.99995565414429,3.00048303604126,64.2574920654297,64.2574920654297,54.8081825827269,5.62360294975873,4.64662456512451,133,1,0,0,1,0.472030639648438,34.7018585205078,1,1,1,2.99995565414429,0,742397376,3.00021934509277,,,,,,,,,,,,,,,,,,,,,,,,,,,,,,,,,
,3842616346.03361,3.00001549720764,101.072448730469,-4.74826468116075E-8,1.65622157551377E-8,1,10,13.3016452789307,7.99114602513555,31.360000371933,-7.80719172939045E-5,-0.000117342467511896,1,-5.27107692078262E-8,,,,,,,,,,,,,,,,,,,,,2.99976301193237,3.00026798248291,101.072448730469,101.072448730469,54.904713704852,5.62421160613288,4.64663076400757,133,1,0,0,1,0.46905517578125,34.2131004333496,1,1,1,2.99976301193237,0,742397152,3.00001549720764,,,,,,,,,,,,,,,,,,,,,,,,,,,,,,,,,
,3842616484.92382,3.00016331672668,158.987609863281,-2.83882406676525E-7,2.72836453039885E-8,1,10,13.3016452789307,7.99121451886313,31.360000371933,-0.000543828476419479,-0.000178169194120955,1,-4.8851389439835E-8,,,,,,,,,,,,,,,,,,,,,3.00016331672668,3.00016331672668,158.987609863281,158.987609863281,54.747215558227,5.62326789794072,4.64915752410889,133,1,0,0,1,0.467910766601562,34.2131004333496,1,1,1,3.00016331672668,0,742397440,3.00016331672668,,,,,,,,,,,,,,,,,,,,,,,,,,,,,,,,,
,3842616573.53271,2.99988126754761,249.571273803711,-6.54846195501808E-7,1.55405385054561E-8,1,10,13.3016452789307,7.99114042572429,31.360000371933,-0.00127101989312177,-0.000298590832299243,1,-5.55011701244056E-8,,,,,,,,,,,,,,,,,,,,,2.99916386604309,3.00059866905212,249.571273803711,249.571273803711,55.0094519264289,5.62478068638598,4.63068771362305,131,1,32,0,0,0.474700927734375,34.2131004333496,1,1,1,2.99916386604309,0,742397216,2.99988126754761,,,,,,,,,,,,,,,,,,,,,,,,,,,,,,,,,
,3842616626.93254,2.99989438056946,392.120361328125,-1.27880598701819E-6,1.37806648285557E-8,1,10,13.3016452789307,7.99122823971825,31.360000371933,-0.00249922585590459,-0.000466829188451459,1,-4.92272341157652E-8,,,,,,,,,,,,,,,,,,,,,2.9995288848877,3.00025987625122,392.120361328125,392.120361328125,54.9578644441597,5.62339476791186,4.64940929412842,133,1,0,0,1,0.469589233398438,34.2131004333496,1,1,1,3.00025987625122,0,742397280,2.99989438056946,,,,,,,,,,,,,,,,,,,,,,,,,,,,,,,,,
,3842616720.36358,3.00000905990601,615.659851074219,-2.30527863694297E-6,1.28758355936748E-8,1,10,13.3016452789307,7.99128391887264,31.360000371933,-0.00452020184573096,-0.000740495349116259,1,-3.7327956602603E-8,,,,,,,,,,,,,,,,,,,,,2.99984192848206,3.00017619132996,615.659851074219,615.659851074219,54.955519558602,5.62336705501106,4.63733243942261,133,1,0,0,1,0.468978881835937,33.7243423461914,1,1,1,3.00017619132996,0,742397376,3.00000905990601,,,,,,,,,,,,,,,,,,,,,,,,,,,,,,,,,
,3842616774.40954,2.99977910518646,966.720703125,-3.96489723460637E-6,8.80569260260737E-9,1,10,13.3016452789307,7.99110243774206,31.360000371933,-0.00779087205803929,-0.00116096342096707,1,-6.90485669246497E-9,,,,,,,,,,,,,,,,,,,,,2.99960398674011,2.99995422363281,966.720703125,966.720703125,54.8058376971693,5.62438709998015,4.63734531402588,133,1,0,0,1,0.47515869140625,34.2131004333496,1,1,1,2.99960398674011,0,742397088,2.99977910518646,,,,,,,,,,,,,,,,,,,,,,,,,,,,,,,,,
,3842616828.96947,2.99960041046143,1517.12939453125,-6.61334103917633E-6,5.42261553775973E-9,1,10,13.3016452789307,7.99117741806338,31.360000371933,-0.0129959578901956,-0.00193017495478918,1,-8.31649843214417E-9,,,,,,,,,,,,,,,,,,,,,2.99909973144531,3.00010108947754,1517.12939453125,1517.12939453125,54.6573282785154,5.62426458990693,4.6475305557251,133,1,0,0,1,0.469894409179687,34.2131004333496,1,1,1,2.99909973144531,0,742397152,2.99960041046143,,,,,,,,,,,,,,,,,,,,,,,,,,,,,,,,,
,3842616882.78711,2.99948692321777,2381.1953125,-1.08270554604905E-5,1.59789511478976E-8,1,10,13.3016452789307,7.99130382089157,31.3699990510941,-0.0212734345684605,-0.00318130785871553,1,-2.4445660294819E-8,,,,,,,,,,,,,,,,,,,,,2.99919533729553,2.99977850914001,2381.1953125,2381.1953125,54.8820464777943,5.62390910157147,4.64099502563477,133,1,0,0,1,0.475616455078125,33.7243423461914,1,1,1,2.99977850914001,0,742397152,2.99948692321777,,,,,,,,,,,,,,,,,,,,,,,,,,,,,,,,,
,3842616937.54307,2.99986660480499,3737.66870117188,-1.74962105764573E-5,3.20951685104565E-8,1,10,13.3016452789307,7.99126515473836,31.360000371933,-0.0343809073684797,-0.00511547611754015,1,-2.65743650045705E-8,,,,,,,,,,,,,,,,,,,,,2.99981546401978,2.99991774559021,3737.66870117188,3737.66870117188,54.8343671381212,5.62322184572658,4.63886594772339,133,1,0,0,1,0.4730224609375,34.2131004333496,1,1,1,2.99991774559021,0,742397280,2.99986660480499,,,,,,,,,,,,,,,,,,,,,,,,,,,,,,,,,
,3842616993.75958,2.99988961219788,5866.65478515625,-2.81085228855008E-5,6.01206878142626E-8,1,10,13.3016452789307,7.99126619657193,31.360000371933,-0.0552387187030597,-0.00819044625403059,1,-2.85396231971912E-8,,,,,,,,,,,,,,,,,,,,,2.99984765052795,2.9999315738678,5866.65478515625,5866.65478515625,54.9570828156404,5.6241001333382,4.62814807891846,133,1,0,0,1,0.47607421875,34.2131004333496,1,1,1,2.9999315738678,0,742397344,2.99988961219788,,,,,,,,,,,,,,,,,,,,,,,,,,,,,,,,,
,3842617051.90994,3.00024139881134,9207.7861328125,-4.50006579627613E-5,1.0760811563658E-7,1,10,13.3016452789307,7.99116232560121,31.360000371933,-0.0884299232194303,-0.0131429471168234,1,-6.11858539465305E-8,,,,,,,,,,,,,,,,,,,,,2.99971032142639,3.00077247619629,9207.7861328125,9207.7861328125,55.0457976525731,5.62459602785321,4.63655519485474,133,1,0,0,1,0.469131469726562,34.2131004333496,1,1,1,3.00077247619629,0,742397280,3.00024139881134,,,,,,,,,,,,,,,,,,,,,,,,,,,,,,,,,
,3842617112.71414,2.99962437152863,14451.9736328125,-7.21359956254148E-5,1.72447032543324E-7,1,10,13.3016452789307,7.99120046031123,31.360000371933,-0.141744713013234,-0.0211273894284531,1,-1.28203803541155E-7,,,,,,,,,,,,,,,,,,,,,2.99941444396973,2.99983429908752,14451.9736328125,14451.9736328125,54.7718368565827,5.62423286104788,4.62535238265991,133,1,0,0,1,0.474014282226562,34.7018585205078,1,1,1,2.99983429908752,0,742397312,2.99962437152863,,,,,,,,,,,,,,,,,,,,,,,,,,,,,,,,,
,3842617177.22942,2.99988424777985,22682.21875,-0.000116015213910419,2.93283395014276E-7,1,10,13.3016452789307,7.9913464121742,31.360000371933,-0.227950598056407,-0.0340986213009092,1,-2.66944892937084E-7,,,,,,,,,,,,,,,,,,,,,2.99906086921692,3.00070762634277,22682.21875,22682.21875,54.8175621249577,5.62477737033229,4.63100814819336,133,1,0,0,1,0.472259521484375,34.2131004333496,1,1,1,2.99906086921692,0,742397152,2.99988424777985,,,,,,,,,,,,,,,,,,,,,,,,,,,,,,,,,
,3842617334.92719,2.99996399879456,35600.05078125,-0.00018707575420848,5.74559583064439E-7,1,10,13.3016452789307,7.99149165283904,31.360000371933,-0.367573953316698,-0.0550021552661124,1,-4.39206793316018E-7,,,,,,,,,,,,,,,,,,,,,2.99996399879456,2.99996399879456,35600.05078125,35600.05078125,55.3615755743424,5.62478173644309,4.63481616973877,132,1,68,0,0,0.474777221679687,34.2131004333496,1,1,1,2.99996399879456,0,742397408,2.99996399879456,,,,,,,,,,,,,,,,,,,,,,,,,,,,,,,,,
,3842617414.13197,2.99979162216186,55874.57421875,-0.00030119902169098,1.02781906232664E-6,1,10,13.3016452789307,7.99133749331743,31.360000371933,-0.591826419457289,-0.0883855292841641,1,-6.21126986694389E-7,,,,,,,,,,,,,,,,,,,,,2.9995129108429,3.00007033348084,55874.57421875,55874.57421875,55.7406654061694,5.62733655884607,4.62823581695557,133,1,0,0,1,0.47027587890625,33.7243423461914,1,1,1,3.00007033348084,0,742397152,2.99979162216186,,,,,,,,,,,,,,,,,,,,,,,,,,,,,,,,,
,3842617485.9176,2.99950397014618,69999.5078125,-0.000381268811821592,7.72242286546283E-7,1,10,13.3016452789307,7.99163647677521,31.360000371933,-0.749126863677478,-0.112186442286095,1,-9.40115218551886E-7,,,,,,,,,,,,,,,,,,,,,2.9992823600769,2.99972558021545,69999.5078125,69999.5078125,56.0787197407367,5.62608104241118,4.62504100799561,131,1,32,0,0,0.476303100585937,33.7243423461914,1,1,1,2.99972558021545,0,742397280,2.99950397014618,,,,,,,,,,,,,,,,,,,,,,,,,,,,,,,,,