File: demonstration_data/squid/000_MA2936-3_211005_Qrod_IP_buchner_standard_005_MT-c_100Oe_post-ZFC.dat
[Header]
; MPMS3 Data File (default extension .dat)
; Copyright (c) 2007, Quantum Design, Inc. All rights reserved.
TITLE,
FILEOPENTIME,3842635063.83503,10/05/2021,11:41 pm
BYAPP,MPMS3 w/ AC,1.0,1.1
INFO,MPMS3 Measurement Release 1.1.16 Build 424, MultiVu Release 2.3.4.19,APPNAME
INFO,Linear Motor Servo Controller,MOTOR_MODULE_NAME
INFO,3101-100 J0,MOTOR_HW_VERSION
INFO,MMC714,MOTOR_SERIAL_NUMBER
INFO,01.04.28,MOTOR_SOFTWARE_VERSION
INFO,Quantum Design Squid Module,SQUID_MODULE_NAME
INFO,3101-501 B0,SQUID_HW_VERSION
INFO,SQM189,SQUID_SERIAL_NUMBER
INFO,01.03.04,SQUID_SOFTWARE_VERSION
INFO,Quantum Design VSM Oven,OVEN_MODULE_NAME
INFO,3101-201 A1,OVEN_HW_VERSION
INFO,OVB229,OVEN_SERIAL_NUMBER
INFO,01.07.07,OVEN_SOFTWARE_VERSION
INFO,SQUID AC,AC_MODULE_NAME
INFO,3101-401 F1,AC_HW_VERSION
INFO,SAC108,AC_SERIAL_NUMBER
INFO,SQUID AC 00.95.07,AC_SOFTWARE_VERSION
INFO,TCI177,COIL_SERIAL_NUMBER
INFO,0,MOMENT_UNITS
INFO,A2481,SAMPLE_MATERIAL
INFO,,SAMPLE_COMMENT
INFO,,SAMPLE_MASS
INFO,,SAMPLE_VOLUME
INFO,,SAMPLE_MOLECULAR_WEIGHT
INFO,5mm x 5mm,SAMPLE_SIZE
INFO,,SAMPLE_SHAPE
INFO,Straw,SAMPLE_HOLDER
INFO,Standard,SAMPLE_HOLDER_DETAIL
INFO,65.98,SAMPLE_OFFSET
DATATYPE,COMMENT,1
DATATYPE,TIME,2
STARTUPAXIS,X,2
STARTUPAXIS,Y1,5
FIELDGROUP, VSM,2,3,4,5,6,8,9,10,11,14,15
FIELDGROUP, DC, 2,3,4,14,56,57,58,59,60,61,62,63,64,65,66,67,68,69
FIELDGROUP, AC, 2,3,4,11,16,17,18,19,20,21,22,23,24,25,26,27,28,29,30
STARTUPGROUP, All
[Data]
Comment,Time Stamp (sec),Temperature (K),Magnetic Field (Oe),Moment (emu),M. Std. Err. (emu),Transport Action,Averaging Time (sec),Frequency (Hz),Peak Amplitude (mm),Center Position (mm),Lockin Signal' (V),Lockin Signal (V),Range,M. Quad. Signal (emu),AC Moment (emu),AC M. Std Err. (emu),AC Phase (deg),AC Phase Std. Err. (deg),AC Susceptibility (emu/Oe),AC Suscept. Std Err. (emu/Oe),AC X' (emu/Oe),AC X' Std Err. (emu/Oe),AC X'' (emu/Oe),AC X'' Std Err. (emu/Oe),AC Drive (Oe),AC Frequency (Hz),AC Averaging Time (sec),AC Cycles,AC Range,AC Measure Type,AC Signal' (V),AC Signal'' (V),AC Trim Coil Ratio,AC Trim Coil Phase,Min. Temperature (K),Max. Temperature (K),Min. Field (Oe),Max. Field (Oe),Mass (grams),Motor Lag (deg),Pressure (Torr),Measure Count,Measurement Number,SQUID Status (code),Motor Status (code),Measure Status (code),Motor Current (amps),Motor Temp. (C),Temp. Status (code),Field Status (code),Chamber Status (code),Chamber Temp (K),Redirection State,Evercool Status,Average Temp (K),Rotation Angle (deg),Rotator state,DC Moment Fixed Ctr (emu),DC Moment Err Fixed Ctr (emu),DC Moment Free Ctr (emu),DC Moment Err Free Ctr (emu),DC Fixed Fit,DC Free Fit,DC Calculated Center (mm),DC Calculated Center Err (mm),DC Scan Length (mm),DC Scan Time (s),DC Number of Points,DC Squid Drift,DC Min V (V),DC Max V (V),DC Scans per Measure,Map 01,Map 02,Map 03,Map 04,Map 05,Map 06,Map 07,Map 08,Map 09,Map 10,Map 11,Map 12,Map 13,Map 14,Map 15,Map 16
,3842635071.9268,399.890747070313,99.6003341674805,-4.05550980868446E-7,7.04885741747233E-9,1,10,13.3016452789307,7.98956906588871,32.880000770092,-0.000797086092746725,-0.000116837216891037,1,2.60309975898896E-10,,,,,,,,,,,,,,,,,,,,,399.888549804687,399.892944335937,99.6003341674805,99.6003341674805,54.9965550558616,5.62891300785092,10.3807277679443,133,1,0,0,1,0.471954345703125,34.2131004333496,1,1,1,399.892944335937,0,742397376,399.890747070313,,,,,,,,,,,,,,,,,,,,,,,,,,,,,,,,,
,3842635138.28343,396.567199707031,99.6003341674805,-4.04748242285784E-7,6.65406042378377E-9,1,10,13.3016452789307,7.98951739486384,32.8599996864796,-0.000795119466219452,-0.000119227189915304,1,-1.07421639608496E-9,,,,,,,,,,,,,,,,,,,,,396.152801513672,396.981597900391,99.6003341674805,99.6003341674805,54.9520022302654,5.62891860429095,10.3630399703979,132,1,64,0,0,0.464935302734375,34.7018585205078,2,1,1,396.152801513672,0,742396864,396.567199707031,,,,,,,,,,,,,,,,,,,,,,,,,,,,,,,,,
,3842635208.49237,390.544418334961,99.6003341674805,-4.00898789384069E-7,6.79906094035439E-9,1,10,13.3016452789307,7.9893608871294,32.820001244545,-0.00078845020992835,-0.000111968616512825,1,2.05184438424051E-9,,,,,,,,,,,,,,,,,,,,,390.165985107422,390.9228515625,99.6003341674805,99.6003341674805,55.0117968119866,5.62875690847762,10.3474760055542,132,1,64,0,0,0.469589233398438,34.2131004333496,2,1,1,390.165985107422,0,742397376,390.544418334961,,,,,,,,,,,,,,,,,,,,,,,,,,,,,,,,,
,3842635278.23849,384.934829711914,99.6003341674805,-3.99947800506509E-7,6.80035713203877E-9,1,10,13.3016452789307,7.98946623941298,32.8000001609325,-0.000785923233895118,-0.000116203306998529,1,-2.42549264452916E-10,,,,,,,,,,,,,,,,,,,,,384.5361328125,385.333526611328,99.6003341674805,99.6003341674805,55.1016840916981,5.62871766643916,10.3212022781372,133,1,0,0,1,0.465774536132812,34.2131004333496,2,1,1,384.5361328125,0,742397280,384.934829711914,,,,,,,,,,,,,,,,,,,,,,,,,,,,,,,,,
,3842635348.36777,379.252838134766,99.6003341674805,-3.97751354778975E-7,6.85913722439859E-9,1,10,13.3016452789307,7.9894537791988,32.760001718998,-0.000780766681523005,-0.000121268190347712,1,-3.14323349866115E-9,,,,,,,,,,,,,,,,,,,,,378.854888916016,379.650787353516,99.6003341674805,99.6003341674805,55.0000723841981,5.62829909968067,10.3138542175293,131,1,64,0,0,0.469818115234375,34.7018585205078,2,1,1,378.854888916016,0,742397088,379.252838134766,,,,,,,,,,,,,,,,,,,,,,,,,,,,,,,,,
,3842635418.39006,373.420257568359,99.6003341674805,-3.99921252382654E-7,6.77720865434752E-9,1,10,13.3016452789307,7.98939230494202,32.7199995517731,-0.000786039379765276,-0.000115024093189013,1,3.53273274212981E-10,,,,,,,,,,,,,,,,,,,,,373.031066894531,373.809448242188,99.6003341674805,99.6003341674805,54.945358387852,5.62898597420497,10.2965526580811,131,1,64,0,0,0.470962524414063,34.2131004333496,2,1,1,373.031066894531,0,742397184,373.420257568359,,,,,,,,,,,,,,,,,,,,,,,,,,,,,,,,,
,3842635488.18383,367.591430664063,99.6003341674805,-3.94182813797617E-7,6.82938910671168E-9,1,10,13.3016452789307,7.98935462581422,32.6999984681606,-0.00077388787252436,-0.000119286531193799,1,-2.66071904934649E-9,,,,,,,,,,,,,,,,,,,,,367.164276123047,368.018585205078,99.6003341674805,99.6003341674805,54.996164241602,5.62851049049501,10.2839546203613,133,1,0,0,1,0.464324951171875,34.7018585205078,2,1,1,367.164276123047,0,742397088,367.591430664063,,,,,,,,,,,,,,,,,,,,,,,,,,,,,,,,,
,3842635558.25498,361.761901855469,99.6003341674805,-3.98060492111191E-7,6.96278275203698E-9,1,10,13.3016452789307,7.98943917623787,32.660000026226,-0.00078264986631527,-0.000112688053483872,1,1.26817627558413E-9,,,,,,,,,,,,,,,,,,,,,361.363189697266,362.160614013672,99.6003341674805,99.6003341674805,54.9207370894962,5.62946784165625,10.2723560333252,131,1,64,0,0,0.469131469726562,34.2131004333496,2,1,1,361.363189697266,0,742397280,361.761901855469,,,,,,,,,,,,,,,,,,,,,,,,,,,,,,,,,
,3842635628.19861,355.952865600586,99.6003341674805,-3.93840467340377E-7,6.72772404421085E-9,1,10,13.3016452789307,7.9892895063884,32.6200015842915,-0.00077407908482642,-0.000113294765908106,1,3.37507259342673E-10,,,,,,,,,,,,,,,,,,,,,355.554382324219,356.351348876953,99.6003341674805,99.6003341674805,54.9195646467173,5.62785122785723,10.2685575485229,133,1,0,0,1,0.4644775390625,34.7018585205078,2,1,1,355.554382324219,0,742397344,355.952865600586,,,,,,,,,,,,,,,,,,,,,,,,,,,,,,,,,
,3842635698.26097,350.132827758789,99.6003341674805,-3.91942627761834E-7,7.10506887036894E-9,1,10,13.3016452789307,7.98916031057491,32.600000500679,-0.000770991578950416,-0.000108335669745566,1,2.58101224107692E-9,,,,,,,,,,,,,,,,,,,,,349.743011474609,350.522644042969,99.6003341674805,99.6003341674805,54.9176105754193,5.62887505639243,10.2663383483887,131,1,64,0,0,0.4693603515625,34.2131004333496,2,1,1,349.743011474609,0,742397376,350.132827758789,,,,,,,,,,,,,,,,,,,,,,,,,,,,,,,,,
,3842635768.16607,344.261367797852,99.6003341674805,-3.91003943131027E-7,6.66762627590076E-9,1,10,13.3016452789307,7.98899024189288,32.5599983334541,-0.00076734454747183,-0.000120241403186712,1,-3.61621535217417E-9,,,,,,,,,,,,,,,,,,,,,343.867370605469,344.655364990234,99.6003341674805,99.6003341674805,54.92699011765,5.62887714497307,10.2496366500854,133,1,0,0,1,0.466079711914063,34.2131004333496,2,1,1,343.867370605469,0,742397248,344.261367797852,,,,,,,,,,,,,,,,,,,,,,,,,,,,,,,,,
,3842635838.43319,338.399993896484,99.6003341674805,-3.90071576883817E-7,6.89603537655905E-9,1,10,13.3016452789307,7.98935640501434,32.5299985706806,-0.000766802120141666,-0.000111348229571465,1,7.73351847170566E-10,,,,,,,,,,,,,,,,,,,,,338.019989013672,338.779998779297,99.6003341674805,99.6003341674805,54.9426226880347,5.6285702257505,10.2291803359985,131,1,64,0,0,0.4644775390625,34.7018585205078,2,1,1,338.019989013672,0,742397088,338.399993896484,,,,,,,,,,,,,,,,,,,,,,,,,,,,,,,,,
,3842635908.27244,332.605270385742,99.6003341674805,-3.89796866770498E-7,6.59971951512443E-9,1,10,13.3016452789307,7.98927202008387,32.5100012123585,-0.000766789840255819,-0.00010765394074201,1,2.61240979393706E-9,,,,,,,,,,,,,,,,,,,,,332.221038818359,332.989501953125,99.6003341674805,99.6003341674805,54.9641174723135,5.6286010896962,10.2163600921631,133,1,0,0,1,0.466461181640625,34.2131004333496,2,1,1,332.221038818359,0,742397184,332.605270385742,,,,,,,,,,,,,,,,,,,,,,,,,,,,,,,,,
,3842635978.21491,326.796722412109,99.6003341674805,-3.86894776565539E-7,6.48270634558189E-9,1,10,13.3016452789307,7.98938813885523,32.4699990451336,-0.000760459430306947,-0.000111116996254591,1,4.23400657659066E-10,,,,,,,,,,,,,,,,,,,,,326.383697509766,327.209747314453,99.6003341674805,99.6003341674805,55.00827948365,5.62840390611626,10.1996212005615,132,1,64,0,0,0.464553833007812,34.2131004333496,2,1,1,326.383697509766,0,742397312,326.796722412109,,,,,,,,,,,,,,,,,,,,,,,,,,,,,,,,,
,3842636048.15545,320.986892700195,99.6003341674805,-3.83092256236414E-7,7.02955552089003E-9,1,10,13.3016452789307,7.98957248715972,32.4399992823601,-0.000753053706313237,-0.000109628680949941,1,6.21578998616076E-10,,,,,,,,,,,,,,,,,,,,,320.590667724609,321.383117675781,99.6003341674805,99.6003341674805,55.0352456675635,5.62773243100659,10.2092733383179,133,1,0,0,1,0.471725463867188,34.2131004333496,2,1,1,320.590667724609,0,742397152,320.986892700195,,,,,,,,,,,,,,,,,,,,,,,,,,,,,,,,,
,3842636118.36884,315.130157470703,99.6003341674805,-3.83332787799793E-7,6.86145690676916E-9,1,10,13.3016452789307,7.98929142074005,32.4000008404255,-0.000752435314227845,-0.000117005546206928,1,-3.09782558476806E-9,,,,,,,,,,,,,,,,,,,,,314.754089355469,315.506225585937,99.6003341674805,99.6003341674805,54.9899112134481,5.62847870637533,10.1808891296387,132,1,64,0,0,0.469589233398438,34.2131004333496,2,1,1,314.754089355469,0,742395904,315.130157470703,,,,,,,,,,,,,,,,,,,,,,,,,,,,,,,,,
,3842636188.12392,309.053924560547,99.6003341674805,-3.79723583855816E-7,6.83467602833893E-9,1,10,13.3016452789307,7.98958092041686,32.379999756813,-0.00074639850143237,-0.000108894075679581,1,4.99417982186797E-10,,,,,,,,,,,,,,,,,,,,,308.621734619141,309.486114501953,99.6003341674805,99.6003341674805,54.9594277011981,5.62820666814838,10.1712017059326,133,1,0,0,1,0.464019775390625,34.7018585205078,2,1,1,308.621734619141,0,742396928,309.053924560547,,,,,,,,,,,,,,,,,,,,,,,,,,,,,,,,,
,3842636258.31192,303.089050292969,99.6003341674805,-3.78281913275226E-7,6.58360333179695E-9,1,10,13.3016452789307,7.98954317000583,32.3499999940395,-0.00074476484895271,-0.00010031578338522,1,4.6519913801626E-9,,,,,,,,,,,,,,,,,,,,,302.703674316406,303.474426269531,99.6003341674805,99.6003341674805,54.9355880313616,5.62723772957458,10.1590394973755,131,1,64,0,0,0.466156005859375,34.2131004333496,2,1,1,302.703674316406,0,742397504,303.089050292969,,,,,,,,,,,,,,,,,,,,,,,,,,,,,,,,,
,3842636328.19131,297.565032958984,99.6003341674805,-3.78546315435804E-7,6.78203089953335E-9,1,10,13.3016452789307,7.98952710619754,32.3400013148785,-0.000744251006565292,-0.000107405519020102,1,1.08331140787095E-9,,,,,,,,,,,,,,,,,,,,,297.179412841797,297.950653076172,99.6003341674805,99.6003341674805,54.9480940876693,5.62798656020097,10.1541662216187,133,1,0,0,1,0.466995239257812,34.7018585205078,2,1,1,297.179412841797,0,742397440,297.565032958984,,,,,,,,,,,,,,,,,,,,,,,,,,,,,,,,,
,3842636398.16222,291.752487182617,99.6003341674805,-3.75841380578588E-7,6.7539219727462E-9,1,10,13.3016452789307,7.98944224357756,32.2999991476536,-0.000738846280242507,-0.000107195765253779,1,7.91453336180364E-10,,,,,,,,,,,,,,,,,,,,,291.367370605469,292.137603759766,99.6003341674805,99.6003341674805,55.0098427406885,5.62773856602202,10.1351737976074,132,1,64,0,0,0.467453002929687,34.2131004333496,2,1,1,291.367370605469,0,742397376,291.752487182617,,,,,,,,,,,,,,,,,,,,,,,,,,,,,,,,,
,3842636468.02567,285.813064575195,99.6003341674805,-3.75915640574247E-7,6.50075446457873E-9,1,10,13.3016452789307,7.98943704057827,32.2800017893314,-0.000738710723743311,-0.000109127238580028,1,-1.80452911023662E-10,,,,,,,,,,,,,,,,,,,,,285.392028808594,286.234100341797,99.6003341674805,99.6003341674805,54.7941132693808,5.62795270840397,10.089674949646,133,1,0,0,1,0.465927124023438,34.7018585205078,2,1,1,285.392028808594,0,742396832,285.813064575195,,,,,,,,,,,,,,,,,,,,,,,,,,,,,,,,,
,3842636538.18851,279.681442260742,99.6003341674805,-3.70316437533262E-7,6.89775322054754E-9,1,10,13.3016452789307,7.98946244932951,32.2399996221066,-0.000727521702545783,-0.000108774397664161,1,-8.25217885257464E-10,,,,,,,,,,,,,,,,,,,,,279.269104003906,280.093780517578,99.6003341674805,99.6003341674805,54.9152656898616,5.62614021920809,10.0248794555664,131,1,64,0,0,0.470809936523438,34.2131004333496,2,1,1,279.269104003906,0,742396992,279.681442260742,,,,,,,,,,,,,,,,,,,,,,,,,,,,,,,,,
,3842636608.07946,274.146469116211,99.6003341674805,-3.72657667390548E-7,6.83803263050318E-9,1,10,13.3016452789307,7.98965807997578,32.2199985384941,-0.000731054695340297,-0.00011677593842523,1,-4.55122201497973E-9,,,,,,,,,,,,,,,,,,,,,273.771575927734,274.521362304687,99.6003341674805,99.6003341674805,54.8476548229481,5.62730128011919,9.987961769104,133,1,0,0,1,0.4656982421875,34.2131004333496,2,1,1,273.771575927734,0,742397216,274.146469116211,,,,,,,,,,,,,,,,,,,,,,,,,,,,,,,,,
,3842636678.19241,268.385467529297,99.6003341674805,-3.71130023870822E-7,6.5400347816216E-9,1,10,13.3016452789307,7.98972255270569,32.200001180172,-0.000729062175068867,-0.000109499097508531,1,-1.07316917023019E-9,,,,,,,,,,,,,,,,,,,,,267.951049804687,268.819885253906,99.6003341674805,99.6003341674805,54.9985091271597,5.62672786190277,9.92539978027344,132,1,64,0,0,0.466995239257812,34.2131004333496,2,1,1,267.951049804687,0,742395904,268.385467529297,,,,,,,,,,,,,,,,,,,,,,,,,,,,,,,,,
,3842636748.05251,262.237731933594,99.6003341674805,-3.71732300510348E-7,6.69897757364079E-9,1,10,13.3016452789307,7.98970454130838,32.1599990129471,-0.000730317410661689,-0.000109180688625549,1,-8.22545157100821E-10,,,,,,,,,,,,,,,,,,,,,261.802917480469,262.672546386719,99.6003341674805,99.6003341674805,54.9238636035731,5.62698626501455,9.85598850250244,133,1,0,0,1,0.467376708984375,34.7018585205078,2,1,1,261.802917480469,0,742396928,262.237731933594,,,,,,,,,,,,,,,,,,,,,,,,,,,,,,,,,
,3842636818.12133,256.465026855469,99.6003341674805,-3.72050903661745E-7,6.46518045435973E-9,1,10,13.3016452789307,7.98969695682156,32.1400016546249,-0.000731186741904503,-0.000107618480984757,1,1.92417653993528E-11,,,,,,,,,,,,,,,,,,,,,256.090759277344,256.839294433594,99.6003341674805,99.6003341674805,54.911748361525,5.62657371372921,9.82532691955566,131,1,64,0,0,0.464096069335937,34.2131004333496,2,1,1,256.090759277344,0,742397472,256.465026855469,,,,,,,,,,,,,,,,,,,,,,,,,,,,,,,,,
,3842636888.06995,250.894927978516,99.6003341674805,-3.72490266650662E-7,6.15691653480747E-9,1,10,13.3016452789307,7.98950282918988,32.1200005710125,-0.000732639164824597,-0.000103676244188063,1,2.08916202843417E-9,,,,,,,,,,,,,,,,,,,,,250.478256225586,251.311599731445,99.6003341674805,99.6003341674805,54.8394477234962,5.626882245875,9.80208110809326,133,1,0,0,1,0.467147827148438,34.2131004333496,2,1,1,250.478256225586,0,742395904,250.894927978516,,,,,,,,,,,,,,,,,,,,,,,,,,,,,,,,,
,3842636958.24445,244.736907958984,99.6003341674805,-3.64765012502982E-7,6.54964743641367E-9,1,10,13.3016452789307,7.98959082832624,32.0799984037876,-0.000717222425647301,-0.000103065850292221,1,1.26264402487722E-9,,,,,,,,,,,,,,,,,,,,,244.340454101562,245.133361816406,99.6003341674805,99.6003341674805,54.90666777615,5.62704470522875,9.7537727355957,131,1,64,0,0,0.467071533203125,34.2131004333496,2,1,1,244.340454101562,0,742396992,244.736907958984,,,,,,,,,,,,,,,,,,,,,,,,,,,,,,,,,
,3842637028.01275,238.827766418457,99.6003341674805,-3.66995077926375E-7,6.48167218486552E-9,1,10,13.3016452789307,7.98955717808398,32.0600010454655,-0.000722079976315493,-0.000100473879124916,1,2.90976601456425E-9,,,,,,,,,,,,,,,,,,,,,238.423873901367,239.231658935547,99.6003341674805,99.6003341674805,54.9695888719481,5.62703669751058,9.7341423034668,133,1,0,0,1,0.463714599609375,34.2131004333496,2,1,1,238.423873901367,0,742397152,238.827766418457,,,,,,,,,,,,,,,,,,,,,,,,,,,,,,,,,
,3842637098.08903,233.023162841797,99.6003341674805,-3.62434978680511E-7,6.28547971269976E-9,1,10,13.3016452789307,7.98966965329522,32.039999961853,-0.00071241336098559,-0.000103980786545005,1,4.54316437562859E-10,,,,,,,,,,,,,,,,,,,,,232.620544433594,233.42578125,99.6003341674805,99.6003341674805,54.8621149505539,5.62650452509989,9.67101860046387,132,1,64,0,0,0.466384887695313,34.2131004333496,2,1,1,232.620544433594,0,742396800,233.023162841797,,,,,,,,,,,,,,,,,,,,,,,,,,,,,,,,,
,3842637168.04087,227.205604553223,99.6003341674805,-3.61863261714352E-7,6.75394867703945E-9,1,10,13.3016452789307,7.98959552825685,32.0100001990795,-0.00071122128957406,-0.000104254850478142,1,2.30408990968402E-10,,,,,,,,,,,,,,,,,,,,,226.796966552734,227.614242553711,99.6003341674805,99.6003341674805,54.9875663278904,5.62717753986514,9.63290786743164,133,1,0,0,1,0.463485717773438,34.2131004333496,2,1,1,226.796966552734,0,742396896,227.205604553223,,,,,,,,,,,,,,,,,,,,,,,,,,,,,,,,,
,3842637238.17285,221.347137451172,99.6003341674805,-3.61208179276364E-7,6.60925729345542E-9,1,10,13.3016452789307,7.98956197790159,32.0000015199184,-0.000708950833702463,-0.000110730372980063,1,-3.16117457651206E-9,,,,,,,,,,,,,,,,,,,,,220.965286254883,221.728988647461,99.6003341674805,99.6003341674805,54.9465308306308,5.62595608534054,9.59289360046387,131,1,64,0,0,0.472030639648438,34.2131004333496,2,1,1,220.965286254883,0,742396800,221.347137451172,,,,,,,,,,,,,,,,,,,,,,,,,,,,,,,,,
,3842637307.93863,215.527198791504,99.6003341674805,-3.61108553949162E-7,6.53826349649592E-9,1,10,13.3016452789307,7.98955241160646,31.9599993526936,-0.000710620978356718,-9.80251671746414E-5,1,3.28904390986098E-9,,,,,,,,,,,,,,,,,,,,,215.127243041992,215.927154541016,99.6003341674805,99.6003341674805,54.9871755136308,5.6269687659244,9.55271816253662,133,1,0,0,1,0.469131469726562,34.7018585205078,2,1,1,215.127243041992,0,742397088,215.527198791504,,,,,,,,,,,,,,,,,,,,,,,,,,,,,,,,,
,3842637378.17834,209.723106384277,99.6003341674805,-3.632949346184E-7,6.6175054784496E-9,1,10,13.3016452789307,7.98945309031823,31.9399982690811,-0.000714831819553475,-9.92069676462696E-5,1,3.00925771303635E-9,,,,,,,,,,,,,,,,,,,,,209.347045898438,210.099166870117,99.6003341674805,99.6003341674805,54.8124815395827,5.62709821742008,9.50381183624268,131,1,64,0,0,0.46630859375,34.2131004333496,2,1,1,209.347045898438,0,742396768,209.723106384277,,,,,,,,,,,,,,,,,,,,,,,,,,,,,,,,,
,3842637448.04976,203.878074645996,99.6003341674805,-3.54402717764202E-7,6.38137772608901E-9,1,10,13.3016452789307,7.98963891334351,31.9099985063076,-0.000696897522480291,-9.98143404282995E-5,1,1.39160716631516E-9,,,,,,,,,,,,,,,,,,,,,203.435989379883,204.320159912109,99.6003341674805,99.6003341674805,54.7397900872942,5.62670835496329,9.4812593460083,133,1,0,0,1,0.467071533203125,34.2131004333496,2,1,1,203.435989379883,0,742396864,203.878074645996,,,,,,,,,,,,,,,,,,,,,,,,,,,,,,,,,
,3842637518.01447,198.04150390625,99.6003341674805,-3.59787136303647E-7,6.72325898141642E-9,1,10,13.3016452789307,7.98944498442717,31.8900011479855,-0.000706965489494437,-0.000104795372946933,1,-3.50874836117349E-10,,,,,,,,,,,,,,,,,,,,,197.633224487305,198.449783325195,99.6003341674805,99.6003341674805,54.9082310331885,5.62668258540686,9.43931484222412,131,1,64,0,0,0.47149658203125,34.2131004333496,2,1,1,197.633224487305,0,742396992,198.04150390625,,,,,,,,,,,,,,,,,,,,,,,,,,,,,,,,,
,3842637587.97931,192.255836486816,99.6003341674805,-3.58480253055394E-7,6.61641097264414E-9,1,10,13.3016452789307,7.98955963146003,31.870000064373,-0.000704453213762207,-0.000104075863416205,1,-1.76750141807341E-10,,,,,,,,,,,,,,,,,,,,,191.839691162109,192.671981811523,99.6003341674805,99.6003341674805,54.6846852766885,5.62707576789184,9.3963737487793,133,1,0,0,1,0.466156005859375,34.2131004333496,2,1,1,191.839691162109,0,742396960,192.255836486816,,,,,,,,,,,,,,,,,,,,,,,,,,,,,,,,,
,3842637658.12873,186.442764282227,99.6003341674805,-3.58958307611442E-7,6.44398311944878E-9,1,10,13.3016452789307,7.98943685457146,31.8400003015995,-0.000705997671602916,-0.000100063181105474,1,1.93501214678793E-9,,,,,,,,,,,,,,,,,,,,,186.058700561523,186.82682800293,99.6003341674805,99.6003341674805,54.8523445940635,5.62734635558525,9.34404754638672,132,1,64,0,0,0.470199584960937,34.2131004333496,2,1,1,186.025482177734,0,742396896,186.442764282227,,,,,,,,,,,,,,,,,,,,,,,,,,,,,,,,,
,3842637727.96264,180.568748474121,99.6003341674805,-3.52174978094648E-7,6.33666830897994E-9,1,10,13.3016452789307,7.98934974594903,31.8199992179871,-0.000692714904355752,-9.77444746745462E-5,1,2.11581796125547E-9,,,,,,,,,,,,,,,,,,,,,180.170745849609,180.966751098633,99.6003341674805,99.6003341674805,54.74408904415,5.62717897183585,9.31088447570801,133,1,0,0,1,0.4669189453125,34.7018585205078,2,1,1,180.170745849609,0,742396896,180.568748474121,,,,,,,,,,,,,,,,,,,,,,,,,,,,,,,,,
,3842637797.93529,174.776298522949,99.6003341674805,-3.55161171391118E-7,6.640716212272E-9,1,10,13.3016452789307,7.98948229665817,31.8000018596649,-0.00069844937733712,-9.95642038370377E-5,1,1.63000022224158E-9,,,,,,,,,,,,,,,,,,,,,174.37678527832,175.175811767578,99.6003341674805,99.6003341674805,54.8359303951596,5.62702689742576,9.27175617218018,131,1,64,0,0,0.473480224609375,34.2131004333496,2,1,1,174.37678527832,0,742397056,174.776298522949,,,,,,,,,,,,,,,,,,,,,,,,,,,,,,,,,
,3842637867.92352,168.947883605957,99.6003341674805,-3.52051990592634E-7,6.46288575698723E-9,1,10,13.3016452789307,7.98940835367289,31.7800007760525,-0.000692091756634423,-0.000100319398480327,1,7.87675541604519E-10,,,,,,,,,,,,,,,,,,,,,168.506805419922,169.388961791992,99.6003341674805,99.6003341674805,54.8308498097847,5.62771311998682,9.22359657287598,133,1,0,0,1,0.46539306640625,34.7018585205078,2,1,1,168.506805419922,0,742397056,168.947883605957,,,,,,,,,,,,,,,,,,,,,,,,,,,,,,,,,
,3842637938.09435,163.149810791016,99.6003341674805,-3.51723978568175E-7,6.65737623758446E-9,1,10,13.3016452789307,7.9893359364236,31.7399986088276,-0.000691202838316983,-0.000101859303707091,1,-4.44577634840119E-11,,,,,,,,,,,,,,,,,,,,,162.744445800781,163.55517578125,99.6003341674805,99.6003341674805,54.6397416368327,5.62722008521681,9.18462181091309,132,1,64,0,0,0.467529296875,34.2131004333496,2,1,1,162.744445800781,0,742397120,163.149810791016,,,,,,,,,,,,,,,,,,,,,,,,,,,,,,,,,
,3842638007.88109,157.309997558594,99.6003341674805,-3.5353841151998E-7,6.64659900048948E-9,1,10,13.3016452789307,7.98950178912436,31.7200012505054,-0.00069502023740912,-0.000100731450964937,1,7.97195854499145E-10,,,,,,,,,,,,,,,,,,,,,156.902984619141,157.717010498047,99.6003341674805,99.6003341674805,54.8636782075923,5.62715529482383,9.14811134338379,133,1,0,0,1,0.463485717773438,34.7018585205078,2,1,1,156.902984619141,0,742397088,157.309997558594,,,,,,,,,,,,,,,,,,,,,,,,,,,,,,,,,
,3842638078.02325,151.469108581543,99.6003341674805,-3.50497721101413E-7,6.70674442368535E-9,1,10,13.3016452789307,7.98952049681776,31.7099988460541,-0.000689436245910308,-9.71974766279348E-5,1,2.14779744398534E-9,,,,,,,,,,,,,,,,,,,,,151.080963134766,151.85725402832,99.6003341674805,99.6003341674805,54.8492180799866,5.62764504026469,9.11170959472656,131,1,64,0,0,0.468978881835937,34.2131004333496,2,1,1,151.080963134766,0,742397056,151.469108581543,,,,,,,,,,,,,,,,,,,,,,,,,,,,,,,,,
,3842638147.8792,145.660179138184,99.6003341674805,-3.48472996553615E-7,6.43194284910653E-9,1,10,13.3016452789307,7.98938773006633,31.6900014877319,-0.000684095337508291,-0.000105816516953944,1,-2.53654528596895E-9,,,,,,,,,,,,,,,,,,,,,145.255569458008,146.064788818359,99.6003341674805,99.6003341674805,54.950438973227,5.62778138464359,9.07445049285889,133,1,0,0,1,0.471878051757812,34.2131004333496,2,1,1,145.255569458008,0,742396416,145.660179138184,,,,,,,,,,,,,,,,,,,,,,,,,,,,,,,,,
,3842638217.87759,139.841857910156,99.6003341674805,-3.48087989505357E-7,6.74102131826058E-9,1,10,13.3016452789307,7.98934817592974,31.6600017249584,-0.000684091907485171,-0.000100576345747046,1,7.30683144115167E-11,,,,,,,,,,,,,,,,,,,,,139.445785522461,140.237930297852,99.6003341674805,99.6003341674805,55.0504874236885,5.62811086450416,9.04309558868408,131,1,64,0,0,0.463790893554687,34.7018585205078,2,1,1,139.445785522461,0,742396960,139.841857910156,,,,,,,,,,,,,,,,,,,,,,,,,,,,,,,,,
,3842638287.92602,134.005020141602,99.6003341674805,-3.48314443180627E-7,6.77043496473138E-9,1,10,13.3016452789307,7.98945208073703,31.640000641346,-0.000684560030820834,-0.000100519727535537,1,1.35594076252439E-10,,,,,,,,,,,,,,,,,,,,,133.58235168457,134.427688598633,99.6003341674805,99.6003341674805,54.818343753477,5.62733860310689,9.01620101928711,133,1,0,0,1,0.466156005859375,34.2131004333496,2,1,1,133.58235168457,0,742397248,134.005020141602,,,,,,,,,,,,,,,,,,,,,,,,,,,,,,,,,
,3842638357.92382,128.146308898926,99.6003341674805,-3.49235280681409E-7,6.6535363081561E-9,1,10,13.3016452789307,7.98935416876047,31.6199995577335,-0.000686573533243826,-9.93689759507182E-5,1,8.56379956822995E-10,,,,,,,,,,,,,,,,,,,,,127.711608886719,128.581008911133,99.6003341674805,99.6003341674805,54.7964581549385,5.62718701430571,8.98653316497803,131,1,64,0,0,0.473175048828125,34.2131004333496,2,1,1,127.711608886719,0,742397120,128.146308898926,,,,,,,,,,,,,,,,,,,,,,,,,,,,,,,,,
,3842638427.79622,122.369049072266,99.6003341674805,-3.44759943633149E-7,6.83454255274118E-9,1,10,13.3016452789307,7.98945980667473,31.5999984741211,-0.000677849850906943,-9.76242723922113E-5,1,1.08560582692168E-9,,,,,,,,,,,,,,,,,,,,,121.95947265625,122.778625488281,99.6003341674805,99.6003341674805,54.8570343651789,5.62737781389214,8.96139812469482,133,1,0,0,1,0.462799072265625,34.2131004333496,2,1,1,121.95947265625,0,742396896,122.369049072266,,,,,,,,,,,,,,,,,,,,,,,,,,,,,,,,,
,3842638497.98561,116.483089447021,99.6003341674805,-3.42008036449176E-7,6.81548807350911E-9,1,10,13.3016452789307,7.9893904897745,31.580001115799,-0.000672711607105472,-9.49720845891637E-5,1,2.02973986220496E-9,,,,,,,,,,,,,,,,,,,,,116.096183776855,116.869995117188,99.6003341674805,99.6003341674805,54.8714944927847,5.62721504011434,8.92970943450928,132,1,64,0,0,0.469284057617188,34.2131004333496,2,1,1,116.096183776855,0,742396992,116.483089447021,,,,,,,,,,,,,,,,,,,,,,,,,,,,,,,,,
,3842638567.95383,110.705867767334,99.6003341674805,-3.41912686806253E-7,6.61288066748424E-9,1,10,13.3016452789307,7.98939293284325,31.5600000321865,-0.000673713604196816,-8.68672448609457E-5,1,6.1398271532009E-9,,,,,,,,,,,,,,,,,,,,,110.318328857422,111.093406677246,99.6003341674805,99.6003341674805,54.8605516935154,5.62739285466039,8.89960193634033,132,1,64,0,0,0.464096069335937,34.2131004333496,2,1,1,110.318328857422,0,742396864,110.705867767334,,,,,,,,,,,,,,,,,,,,,,,,,,,,,,,,,
,3842638637.78905,104.852710723877,99.6003341674805,-3.43089028516475E-7,6.38707947356454E-9,1,10,13.3016452789307,7.98936437029815,31.5600000321865,-0.000674564630974785,-9.71194021302413E-5,1,1.09615541498941E-9,,,,,,,,,,,,,,,,,,,,,104.407073974609,105.298347473145,99.6003341674805,99.6003341674805,54.8359303951596,5.62785974426828,8.84700584411621,133,1,0,0,1,0.463180541992188,34.2131004333496,2,1,1,104.407073974609,0,742397120,104.852710723877,,,,,,,,,,,,,,,,,,,,,,,,,,,,,,,,,
,3842638707.94972,99.0084381103516,99.6003341674805,-3.42181598165006E-7,6.97616709021042E-9,1,10,13.3016452789307,7.98922969189569,31.530000269413,-0.000673033052942224,-9.51029759160501E-5,1,1.98814388499568E-9,,,,,,,,,,,,,,,,,,,,,98.5731811523437,99.4436950683594,99.6003341674805,99.6003341674805,54.8961157911404,5.6284497441843,8.80749320983887,132,1,64,0,0,0.46600341796875,34.2131004333496,2,1,1,98.5731811523437,0,742396928,99.0084381103516,,,,,,,,,,,,,,,,,,,,,,,,,,,,,,,,,
,3842638777.75394,93.2550468444824,99.6003341674805,-3.43282972015103E-7,6.85390558839589E-9,1,10,13.3016452789307,7.98916642081065,31.530000269413,-0.000674176837281455,-0.000102332855950413,1,-1.52886576762493E-9,,,,,,,,,,,,,,,,,,,,,92.8308792114258,93.6792144775391,99.6003341674805,99.6003341674805,54.8171713106981,5.62827368148459,8.75423908233643,133,1,0,0,1,0.4693603515625,34.7018585205078,2,1,1,92.8308792114258,0,742396832,93.2550468444824,,,,,,,,,,,,,,,,,,,,,,,,,,,,,,,,,
,3842638847.83217,87.3877563476563,99.6003341674805,-3.41368708593102E-7,6.57039047609977E-9,1,10,13.3016452789307,7.98930275199737,31.5099991858006,-0.000671303472826465,-9.57887595982779E-5,1,1.51974496291948E-9,,,,,,,,,,,,,,,,,,,,,86.9970626831055,87.778450012207,99.6003341674805,99.6003341674805,54.840620166275,5.62804804107324,8.72523212432861,133,1,0,0,1,0.467605590820313,34.2131004333496,2,1,1,86.9970626831055,0,742396960,87.3877563476563,,,,,,,,,,,,,,,,,,,,,,,,,,,,,,,,,
,3842638917.92775,81.4821968078613,99.6003341674805,-3.42256667100446E-7,6.56280279756909E-9,1,10,13.3016452789307,7.98922540867271,31.4900018274784,-0.000673250033383828,-9.46515706053581E-5,1,2.22888081321385E-9,,,,,,,,,,,,,,,,,,,,,81.0766525268555,81.8877410888672,99.6003341674805,99.6003341674805,54.7077433180058,5.62827752188058,8.68789863586426,132,1,64,0,0,0.46630859375,34.7018585205078,2,1,1,81.0766525268555,0,742397056,81.4821968078613,,,,,,,,,,,,,,,,,,,,,,,,,,,,,,,,,
,3842638987.71494,75.6464309692383,99.6003341674805,-3.43369159211913E-7,6.98967347640404E-9,1,10,13.3016452789307,7.98914631551451,31.479999423027,-0.000674725855403799,-9.97727118598267E-5,1,-2.13506999131537E-10,,,,,,,,,,,,,,,,,,,,,75.2021636962891,76.0906982421875,99.6003341674805,99.6003341674805,54.7311921735827,5.62844939733322,8.6381721496582,133,1,0,0,1,0.469589233398438,34.7018585205078,2,1,1,75.2021636962891,0,742396960,75.6464309692383,,,,,,,,,,,,,,,,,,,,,,,,,,,,,,,,,
,3842639057.79242,69.7463264465332,99.6003341674805,-3.3930448304325E-7,6.64926810921071E-9,1,10,13.3016452789307,7.98916431598374,31.4599983394146,-0.000667200740378625,-9.54594181737193E-5,1,1.38292890811555E-9,,,,,,,,,,,,,,,,,,,,,69.3451385498047,70.1475143432617,99.6003341674805,99.6003341674805,54.7565951004577,5.62832972024341,8.588547706604,133,1,0,0,1,0.467681884765625,34.7018585205078,2,1,1,69.3451385498047,0,742397184,69.7463264465332,,,,,,,,,,,,,,,,,,,,,,,,,,,,,,,,,
,3842639127.78789,63.8222103118897,99.6003341674805,-3.41939481958028E-7,6.71854149941342E-9,1,10,13.3016452789307,7.98927935987302,31.4599983394146,-0.000672545618057176,-9.51281629673304E-5,1,1.93984813994053E-9,,,,,,,,,,,,,,,,,,,,,63.427417755127,64.2170028686523,99.6003341674805,99.6003341674805,54.88634543465,5.6278450829641,8.55739784240723,131,1,64,0,0,0.46722412109375,34.7018585205078,2,1,1,63.427417755127,0,742396864,63.8222103118897,,,,,,,,,,,,,,,,,,,,,,,,,,,,,,,,,
,3842639197.8321,57.9185619354248,99.6003341674805,-3.37897371181112E-7,6.71197596804203E-9,1,10,13.3016452789307,7.98920315203457,31.4400009810925,-0.000664020817755113,-9.78812038515747E-5,1,-5.6449387383493E-11,,,,,,,,,,,,,,,,,,,,,57.5095062255859,58.3276176452637,99.6003341674805,99.6003341674805,54.8754026353808,5.62791311409938,8.49109363555908,132,1,64,0,0,0.463485717773438,34.2131004333496,2,1,1,57.5095062255859,0,742397216,57.9185619354248,,,,,,,,,,,,,,,,,,,,,,,,,,,,,,,,,
,3842639267.71127,52.0361061096191,99.6003341674805,-3.40490420418823E-7,6.89460064228737E-9,1,10,13.3016452789307,7.98925637208963,31.4400009810925,-0.000670112859417448,-9.18830598064376E-5,1,3.37769035720373E-9,,,,,,,,,,,,,,,,,,,,,51.6205520629883,52.45166015625,99.6003341674805,99.6003341674805,54.789814312525,5.6280202550524,8.42153358459473,133,1,0,0,1,0.466384887695313,34.2131004333496,2,1,1,51.6205520629883,0,742397120,52.0361061096191,,,,,,,,,,,,,,,,,,,,,,,,,,,,,,,,,
,3842639337.67868,46.1137523651123,99.6003341674805,-3.36385865804023E-7,6.59018538502257E-9,1,10,13.3016452789307,7.98926198854713,31.41999989748,-0.000662277432851903,-8.9129060642722E-5,1,4.1747452732619E-9,,,,,,,,,,,,,,,,,,,,,45.6944236755371,46.5330810546875,99.6003341674805,99.6003341674805,54.9637266580539,5.62769671471791,8.35020542144775,133,1,0,0,1,0.472030639648438,34.7018585205078,2,1,1,45.6944236755371,0,742396768,46.1137523651123,,,,,,,,,,,,,,,,,,,,,,,,,,,,,,,,,
,3842639407.67179,40.1891212463379,99.6003341674805,-3.36658380799406E-7,6.5950448395324E-9,1,10,13.3016452789307,7.98934508874839,31.41999989748,-0.000661291422436073,-9.95688766760353E-5,1,-1.09714564057846E-9,,,,,,,,,,,,,,,,,,,,,39.7867126464844,40.5915298461914,99.6003341674805,99.6003341674805,54.8238151531116,5.62753748078664,8.26718902587891,133,1,0,0,1,0.467681884765625,34.7018585205078,2,1,1,39.7867126464844,0,742396992,40.1891212463379,,,,,,,,,,,,,,,,,,,,,,,,,,,,,,,,,
,3842639477.69257,34.2931423187256,99.6003341674805,-3.35145142127318E-7,6.58207815702066E-9,1,10,13.3016452789307,7.98926064827956,31.3999988138676,-0.000659036750083582,-9.42193614741172E-5,1,1.4018566787923E-9,,,,,,,,,,,,,,,,,,,,,33.8724555969238,34.7138290405273,99.6003341674805,99.6003341674805,54.8777475209385,5.62784327286947,8.14565658569336,133,1,0,0,1,0.471725463867188,34.2131004333496,2,1,1,33.8724555969238,0,742396960,34.2931423187256,,,,,,,,,,,,,,,,,,,,,,,,,,,,,,,,,
,3842639547.69043,28.3567295074463,99.6003341674805,-3.32019374177769E-7,6.61690805473292E-9,1,10,13.3016452789307,7.98928064797409,31.3999988138676,-0.000653339599972953,-9.02945461717306E-5,1,2.93884166205825E-9,,,,,,,,,,,,,,,,,,,,,27.9472465515137,28.7662124633789,99.6003341674805,99.6003341674805,54.7605032430539,5.62786908540404,8.01668357849121,133,1,0,0,1,0.466842651367188,34.2131004333496,2,1,1,27.9472465515137,0,742396992,28.3567295074463,,,,,,,,,,,,,,,,,,,,,,,,,,,,,,,,,
,3842639617.61542,22.5481004714966,99.6003341674805,-3.28394313005117E-7,6.90831144888398E-9,1,10,13.3016452789307,7.98942812695644,31.3900001347065,-0.000646326187093531,-8.85408149965511E-5,1,3.29795535976833E-9,,,,,,,,,,,,,,,,,,,,,22.1379852294922,22.958215713501,99.6003341674805,99.6003341674805,54.9942101703039,5.6273039867671,7.8215184211731,133,1,0,0,1,0.4644775390625,34.7018585205078,2,1,1,22.1379852294922,0,742397184,22.5481004714966,,,,,,,,,,,,,,,,,,,,,,,,,,,,,,,,,
,3842639687.6447,19.9939346313477,99.6003341674805,-3.28871321475806E-7,6.53627943551779E-9,1,10,13.3016452789307,7.98956015653208,31.3900001347065,-0.00064632812685995,-9.50741507348259E-5,1,4.41814930429914E-11,,,,,,,,,,,,,,,,,,,,,19.9933586120605,19.9945106506348,99.6003341674805,99.6003341674805,54.8734485640827,5.62732322674074,7.62045431137085,133,1,0,0,1,0.463180541992188,34.2131004333496,5,1,1,19.9945106506348,0,742397184,19.9939346313477,,,,,,,,,,,,,,,,,,,,,,,,,,,,,,,,,
,3842639757.61951,19.8564682006836,99.6003341674805,-3.28266334329548E-7,6.48441042191733E-9,1,10,13.3016452789307,7.98933798930106,31.3800014555454,-0.000644689393663503,-9.78840189668655E-5,1,-1.47544651757479E-9,,,,,,,,,,,,,,,,,,,,,19.8152770996094,19.8976593017578,99.6003341674805,99.6003341674805,54.7890326840058,5.62750899456546,7.58981370925903,133,1,0,0,1,0.465774536132812,34.2131004333496,2,1,1,19.8152770996094,0,742397600,19.8564682006836,,,,,,,,,,,,,,,,,,,,,,,,,,,,,,,,,
,3842639827.68925,19.2791528701782,99.6003341674805,-3.27719399171654E-7,6.75218139438617E-9,1,10,13.3016452789307,7.98948720698576,31.3800014555454,-0.000644226601035396,-9.36156599753071E-5,1,6.16471617923225E-10,,,,,,,,,,,,,,,,,,,,,19.2378959655762,19.3204097747803,99.6003341674805,99.6003341674805,54.8855638061308,5.62717504786928,7.58205223083496,133,1,0,0,1,0.473709106445313,34.2131004333496,2,1,1,19.2378959655762,0,742397248,19.2791528701782,,,,,,,,,,,,,,,,,,,,,,,,,,,,,,,,,
,3842639897.66424,18.6982564926147,99.6003341674805,-3.27196481595762E-7,6.41557014839024E-9,1,10,13.3016452789307,7.98939010630264,31.3800014555454,-0.000643065090578936,-9.43429874041792E-5,1,1.69056197649276E-10,,,,,,,,,,,,,,,,,,,,,18.6574172973633,18.7390956878662,99.6003341674805,99.6003341674805,54.8116999110635,5.62711737969983,7.57661628723145,133,1,0,0,1,0.467605590820313,34.2131004333496,2,1,1,18.6574172973633,0,742397312,18.6982564926147,,,,,,,,,,,,,,,,,,,,,,,,,,,,,,,,,
,3842639967.67413,18.1159887313843,99.6003341674805,-3.30567105621606E-7,6.57435247112273E-9,1,10,13.3016452789307,7.9894493145183,31.3800014555454,-0.000649332527749646,-9.7759090863073E-5,1,-1.07273115006805E-9,,,,,,,,,,,,,,,,,,,,,18.0770874023438,18.1548900604248,99.6003341674805,99.6003341674805,54.8730577498231,5.62755574760173,7.51994943618774,133,1,0,0,1,0.46478271484375,34.2131004333496,2,1,1,18.0770874023438,0,742397344,18.1159887313843,,,,,,,,,,,,,,,,,,,,,,,,,,,,,,,,,
,3842640037.70106,17.5362529754639,99.6003341674805,-3.28483569781907E-7,6.50955530238774E-9,1,10,13.3016452789307,7.98955910948071,31.3800014555454,-0.000646742083283393,-8.69745445249449E-5,1,4.10849358482762E-9,,,,,,,,,,,,,,,,,,,,,17.4976711273193,17.5748348236084,99.6003341674805,99.6003341674805,54.899633119477,5.62745625711509,7.48733711242676,133,1,0,0,1,0.469131469726562,34.2131004333496,2,1,1,17.4976711273193,0,742397248,17.5362529754639,,,,,,,,,,,,,,,,,,,,,,,,,,,,,,,,,
,3842640107.66409,16.9567394256592,99.6003341674805,-3.26878749647412E-7,6.70806808411395E-9,1,10,13.3016452789307,7.98956763421733,31.3800014555454,-0.000643162884181804,-8.94015553731006E-5,1,2.63727218407799E-9,,,,,,,,,,,,,,,,,,,,,16.9164047241211,16.9970741271973,99.6003341674805,99.6003341674805,54.7902051267846,5.62671662343785,7.45589733123779,133,1,0,0,1,0.4705810546875,34.7018585205078,2,1,1,16.9164047241211,0,742397312,16.9567394256592,,,,,,,,,,,,,,,,,,,,,,,,,,,,,,,,,
,3842640177.641,16.3752813339233,99.6003341674805,-3.28132189963131E-7,6.34385192279E-9,1,10,13.3016452789307,7.98962742043966,31.3800014555454,-0.000645018227917585,-9.39123650039932E-5,1,5.26743956120374E-10,,,,,,,,,,,,,,,,,,,,,16.331995010376,16.4185676574707,99.6003341674805,99.6003341674805,54.8460915659097,5.62649957221657,7.4111442565918,133,1,0,0,1,0.470809936523438,34.7018585205078,2,1,1,16.331995010376,0,742397472,16.3752813339233,,,,,,,,,,,,,,,,,,,,,,,,,,,,,,,,,
,3842640247.60517,15.7981295585632,99.6003341674805,-3.24935546929015E-7,6.19553682885769E-9,1,10,13.3016452789307,7.9897179036201,31.3800014555454,-0.000639100874821694,-9.0537311244161E-5,1,1.77373088535059E-9,,,,,,,,,,,,,,,,,,,,,15.7587947845459,15.8374643325806,99.6003341674805,99.6003341674805,54.7108698320827,5.62736595626648,7.40353345870972,133,1,0,0,1,0.46539306640625,34.2131004333496,2,1,1,15.7587947845459,0,742397248,15.7981295585632,,,,,,,,,,,,,,,,,,,,,,,,,,,,,,,,,
,3842640317.66404,15.2173204421997,99.6003341674805,-3.24800199757627E-7,6.68764289304821E-9,1,10,13.3016452789307,7.98966980870826,31.3800014555454,-0.000639312384524789,-8.72400603453698E-5,1,3.43140854797959E-9,,,,,,,,,,,,,,,,,,,,,15.1762647628784,15.258376121521,99.6003341674805,99.6003341674805,54.90666777615,5.62658559233188,7.35133218765259,133,1,0,0,1,0.473556518554687,34.7018585205078,2,1,1,15.1762647628784,0,742397376,15.2173204421997,,,,,,,,,,,,,,,,,,,,,,,,,,,,,,,,,
,3842640387.61906,14.6376338005066,99.6003341674805,-3.22380815745639E-7,6.51815557908E-9,1,10,13.3016452789307,7.98964536770841,31.3800014555454,-0.000633680078968434,-9.24927110546134E-5,1,4.02366943584215E-10,,,,,,,,,,,,,,,,,,,,,14.5979223251343,14.6773452758789,99.6003341674805,99.6003341674805,54.8816556635346,5.62710839292446,7.31981325149536,133,1,0,0,1,0.466156005859375,33.7243423461914,2,1,1,14.5979223251343,0,742397152,14.6376338005066,,,,,,,,,,,,,,,,,,,,,,,,,,,,,,,,,
,3842640457.52286,14.060022354126,99.6003341674805,-3.26677654569821E-7,6.67444278230183E-9,1,10,13.3016452789307,7.98975070146213,31.3800014555454,-0.000641822076423395,-9.58230468325406E-5,1,-6.59221235008733E-10,,,,,,,,,,,,,,,,,,,,,14.0197839736938,14.1002607345581,99.6003341674805,99.6003341674805,54.8445283088712,5.62640517420823,7.28711843490601,133,1,0,0,1,0.4681396484375,34.7018585205078,2,1,1,14.0183200836182,0,742397024,14.060022354126,,,,,,,,,,,,,,,,,,,,,,,,,,,,,,,,,
,3842640527.53615,13.4794335365295,99.6003341674805,-3.2197662059374E-7,6.4072547250166E-9,1,10,13.3016452789307,7.98976459103805,31.3900001347065,-0.000633330447200061,-8.93920943022579E-5,1,1.92094532843373E-9,,,,,,,,,,,,,,,,,,,,,13.4372825622559,13.5215845108032,99.6003341674805,99.6003341674805,54.7499512580443,5.62748587045041,7.23001670837402,133,1,0,0,1,0.471267700195313,34.7018585205078,2,1,1,13.4372825622559,0,742397216,13.4794335365295,,,,,,,,,,,,,,,,,,,,,,,,,,,,,,,,,
,3842640597.57226,12.9011116027832,99.6003341674805,-3.23472658841869E-7,6.42940527824541E-9,1,10,13.3016452789307,7.98970052685973,31.3800014555454,-0.000635531414968359,-9.48254200951407E-5,1,-6.23656628062401E-10,,,,,,,,,,,,,,,,,,,,,12.8605804443359,12.9416427612305,99.6003341674805,99.6003341674805,54.8081825827269,5.62739154942252,7.18248701095581,133,1,0,0,1,0.466690063476562,34.7018585205078,2,1,1,12.8605804443359,0,742397152,12.9011116027832,,,,,,,,,,,,,,,,,,,,,,,,,,,,,,,,,
,3842640667.52704,12.3233270645142,99.6003341674805,-3.24195828025898E-7,6.83425374042222E-9,1,10,13.3016452789307,7.98952594295552,31.3800014555454,-0.000637506937759835,-9.12157449847584E-5,1,1.3189807777541E-9,,,,,,,,,,,,,,,,,,,,,12.2824306488037,12.3642234802246,99.6003341674805,99.6003341674805,54.8836097348327,5.62734396630191,7.12849903106689,133,1,0,0,1,0.472259521484375,34.2131004333496,2,1,1,12.2824306488037,0,742397120,12.3233270645142,,,,,,,,,,,,,,,,,,,,,,,,,,,,,,,,,
,3842640737.49131,11.7457213401794,99.6003341674805,-3.2149123812068E-7,6.16442729472507E-9,1,10,13.3016452789307,7.98970121371231,31.3900001347065,-0.000631678470873297,-9.39732324986859E-5,1,-4.81767913273809E-10,,,,,,,,,,,,,,,,,,,,,11.7041549682617,11.7872877120972,99.6003341674805,99.6003341674805,55.0196130971789,5.62646504766043,7.07366943359375,133,1,0,0,1,0.46966552734375,34.7018585205078,2,1,1,11.7041549682617,0,742397216,11.7457213401794,,,,,,,,,,,,,,,,,,,,,,,,,,,,,,,,,
,3842640807.50781,11.1709923744202,99.6003341674805,-3.18865422564973E-7,6.52141537095149E-9,1,10,13.3016452789307,7.98953311246436,31.3900001347065,-0.000627045200026208,-8.95816073046401E-5,1,1.36569258085954E-9,,,,,,,,,,,,,,,,,,,,,11.1295680999756,11.2124166488647,99.6003341674805,99.6003341674805,54.9946009845635,5.62615687331207,7.0086932182312,133,1,0,0,1,0.469284057617188,34.7018585205078,2,1,1,11.1295680999756,0,742397120,11.1709923744202,,,,,,,,,,,,,,,,,,,,,,,,,,,,,,,,,
,3842640877.61323,10.5935544967651,99.6003341674805,-3.19217026989929E-7,6.62207745165126E-9,1,10,13.3016452789307,7.98956171308048,31.3800014555454,-0.000627731297842808,-8.9725324819621E-5,1,1.34442381908128E-9,,,,,,,,,,,,,,,,,,,,,10.5530776977539,10.6340312957764,99.6003341674805,99.6003341674805,54.8968974196597,5.6270180306969,6.93745613098145,133,1,0,0,1,0.47271728515625,34.7018585205078,2,1,1,10.5530776977539,0,742397152,10.5935544967651,,,,,,,,,,,,,,,,,,,,,,,,,,,,,,,,,
,3842640947.5797,10.0593872070312,99.6003341674805,-3.17415090188493E-7,6.39367939516797E-9,1,10,13.3016452789307,7.98972142929324,31.3800014555454,-0.000624322856578301,-8.83504126280824E-5,1,1.77922888423741E-9,,,,,,,,,,,,,,,,,,,,,10.0089321136475,10.109842300415,99.6003341674805,99.6003341674805,54.747215558227,5.62584387504291,6.89244556427002,133,1,0,0,1,0.464706420898438,34.2131004333496,6,1,1,10.0089321136475,0,742397536,10.0593872070312,,,,,,,,,,,,,,,,,,,,,,,,,,,,,,,,,
,3842641017.51449,9.44878435134888,99.6003341674805,-3.15928277578341E-7,6.38430004559933E-9,1,10,13.3016452789307,7.98968015036987,31.3900001347065,-0.000622280957158421,-8.19302426566846E-5,1,4.82699987833386E-9,,,,,,,,,,,,,,,,,,,,,9.41026020050049,9.48730850219727,99.6003341674805,99.6003341674805,54.7042259896693,5.62671057424994,6.86921834945679,133,1,0,0,1,0.469970703125,34.7018585205078,6,1,1,9.41026020050049,0,742397280,9.44878435134888,,,,,,,,,,,,,,,,,,,,,,,,,,,,,,,,,
,3842641087.54636,8.86840486526489,99.6003341674805,-3.18881640979803E-7,6.09908019683229E-9,1,10,13.3016452789307,7.99022585085463,31.3800014555454,-0.000627156950085004,-8.92554549258054E-5,1,1.53625083987109E-9,,,,,,,,,,,,,,,,,,,,,8.82887077331543,8.90793895721436,99.6003341674805,99.6003341674805,54.899633119477,5.62510275916261,6.83263206481934,133,1,0,0,1,0.4669189453125,34.2131004333496,6,1,1,8.82887077331543,0,742397184,8.86840486526489,,,,,,,,,,,,,,,,,,,,,,,,,,,,,,,,,
,3842641157.46462,8.29438066482544,99.6003341674805,-3.14890205704759E-7,6.4239758384588E-9,1,10,13.3016452789307,7.99019399053308,31.3800014555454,-0.000619280973905885,-8.83043045027609E-5,1,1.43242781762028E-9,,,,,,,,,,,,,,,,,,,,,8.25359153747559,8.33516979217529,99.6003341674805,99.6003341674805,54.8296773670058,5.62630632929538,6.77016735076904,133,1,0,0,1,0.466156005859375,34.2131004333496,6,1,1,8.25359153747559,0,742397184,8.29438066482544,,,,,,,,,,,,,,,,,,,,,,,,,,,,,,,,,
,3842641227.48619,7.72144174575806,99.6003341674805,-3.13531614452634E-7,6.62857866944063E-9,1,10,13.3016452789307,7.99009347323657,31.3800014555454,-0.000615621843236089,-9.45983246152661E-5,1,-1.97045453730155E-9,,,,,,,,,,,,,,,,,,,,,7.68187141418457,7.76101207733154,99.6003341674805,99.6003341674805,54.8015387403135,5.62662772789804,6.70334243774414,133,1,0,0,1,0.470046997070313,34.2131004333496,6,1,1,7.68187141418457,0,742397376,7.72144174575806,,,,,,,,,,,,,,,,,,,,,,,,,,,,,,,,,
,3842641297.4859,7.15125298500061,99.6003341674805,-3.07939782981493E-7,6.37332819665592E-9,1,10,13.3016452789307,7.99011599573186,31.3800014555454,-0.00060503922921506,-9.0221515191483E-5,1,-5.66687844221504E-10,,,,,,,,,,,,,,,,,,,,,7.11307334899902,7.1894326210022,99.6003341674805,99.6003341674805,54.9394961739577,5.62554669666074,6.64591360092163,133,1,0,0,1,0.471038818359375,34.7018585205078,6,1,1,7.11307334899902,0,742397248,7.15125298500061,,,,,,,,,,,,,,,,,,,,,,,,,,,,,,,,,
,3842641367.45447,6.58468198776245,99.6003341674805,-3.06618740417478E-7,6.8178533769204E-9,1,10,13.3016452789307,7.98993926088272,31.3800014555454,-0.000602632421067853,-8.85004434918436E-5,1,1.13964331758548E-10,,,,,,,,,,,,,,,,,,,,,6.54560852050781,6.62375545501709,99.6003341674805,99.6003341674805,54.9617725867558,5.62635399806465,6.57012319564819,133,1,0,0,1,0.46905517578125,34.2131004333496,6,1,1,6.54560852050781,0,742397344,6.58468198776245,,,,,,,,,,,,,,,,,,,,,,,,,,,,,,,,,
,3842641437.43879,6.01913619041443,99.6003341674805,-3.04480276691405E-7,6.35938960632017E-9,1,10,13.3016452789307,7.9900025731725,31.3800014555454,-0.000597916753573003,-9.13838653342773E-5,1,-1.66785026725815E-9,,,,,,,,,,,,,,,,,,,,,5.97911596298218,6.05915641784668,99.6003341674805,99.6003341674805,54.9367604741404,5.62667262000853,6.4705867767334,133,1,0,0,1,0.470046997070313,34.2131004333496,6,1,1,5.97911596298218,0,742397312,6.01913619041443,,,,,,,,,,,,,,,,,,,,,,,,,,,,,,,,,
,3842641507.49845,5.45379614830017,99.6003341674805,-3.00583615925368E-7,6.67135463235064E-9,1,10,13.3016452789307,7.99008949575605,31.3800014555454,-0.000590220494348677,-9.05400869242089E-5,1,-1.81196309564961E-9,,,,,,,,,,,,,,,,,,,,,5.41539001464844,5.4922022819519,99.6003341674805,99.6003341674805,54.962554215275,5.62661722382854,6.3501238822937,133,1,0,0,1,0.469970703125,34.2131004333496,6,1,1,5.41539001464844,0,742397312,5.45379614830017,,,,,,,,,,,,,,,,,,,,,,,,,,,,,,,,,
,3842641577.51582,4.89156103134155,99.6003341674805,-2.96935509157279E-7,6.49008893862899E-9,1,10,13.3016452789307,7.99006268242367,31.3800014555454,-0.00058365086048068,-8.54011502979599E-5,1,2.65622904998016E-10,,,,,,,,,,,,,,,,,,,,,4.85253143310547,4.93059062957764,99.6003341674805,99.6003341674805,54.8472640086885,5.62609544282165,6.22453594207764,133,1,0,0,1,0.476760864257812,34.2131004333496,6,1,1,4.85253143310547,0,742397216,4.89156103134155,,,,,,,,,,,,,,,,,,,,,,,,,,,,,,,,,
,3842641647.4858,4.3377993106842,99.6003341674805,-2.94860935976698E-7,6.53779269769409E-9,1,10,13.3016452789307,7.99011025086288,31.3800014555454,-0.000578875618056298,-8.95552135852052E-5,1,-2.15335733124542E-9,,,,,,,,,,,,,,,,,,,,,4.29952049255371,4.3760781288147,99.6003341674805,99.6003341674805,54.7007086613327,5.62614000638033,6.084228515625,133,1,0,0,1,0.46722412109375,34.2131004333496,6,1,1,4.29952049255371,0,742397216,4.3377993106842,,,,,,,,,,,,,,,,,,,,,,,,,,,,,,,,,
,3842641717.38142,3.77026951313019,99.6003341674805,-2.85175506805665E-7,6.49926207355347E-9,1,10,13.3016452789307,7.98999978967919,31.3900001347065,-0.000561509152767914,-7.53896455329398E-5,1,3.62803367437803E-9,,,,,,,,,,,,,,,,,,,,,3.71584248542786,3.82469654083252,99.6003341674805,99.6003341674805,55.1161442193039,5.62552827761483,4.93617248535156,133,1,0,0,1,0.475997924804687,34.7018585205078,6,1,1,3.71584248542786,0,742397344,3.77026951313019,,,,,,,,,,,,,,,,,,,,,,,,,,,,,,,,,
,3842641787.5101,3.21119928359985,99.6003341674805,-2.78823713877013E-7,6.47534975434334E-9,1,10,13.3016452789307,7.99023513405922,31.3800014555454,-0.000548472214839641,-7.73749616198213E-5,1,1.68329336812573E-9,,,,,,,,,,,,,,,,,,,,,3.16565608978271,3.25674247741699,99.6003341674805,99.6003341674805,55.0309467107077,5.62630174491107,4.74945783615112,133,1,0,0,1,0.470428466796875,33.7243423461914,2,1,1,3.16565608978271,0,742397376,3.21119928359985,,,,,,,,,,,,,,,,,,,,,,,,,,,,,,,,,
,3842641857.46254,2.99925684928894,99.6003341674805,-2.74905323573606E-7,6.28101777217762E-9,1,10,13.3016452789307,7.99003909011653,31.3800014555454,-0.000539904302060014,-8.20774177627568E-5,1,-1.28689638993572E-9,,,,,,,,,,,,,,,,,,,,,2.9987301826477,2.99978351593018,99.6003341674805,99.6003341674805,54.975841900102,5.62594761482332,4.66636419296265,133,1,0,0,1,0.46417236328125,34.2131004333496,5,1,1,2.99978351593018,0,742397216,2.99925684928894,,,,,,,,,,,,,,,,,,,,,,,,,,,,,,,,,
,3842641877.42866,2.99945998191833,99.6003341674805,-2.72253663890163E-7,6.17254466934841E-9,1,10,13.3016452789307,7.99007707361537,31.3800014555454,-0.000534388100362452,-8.33904695512291E-5,1,-2.34531455051115E-9,,,,,,,,,,,,,,,,,,,,,2.99937891960144,2.99954104423523,99.6003341674805,99.6003341674805,54.9121391757847,5.6265151922912,4.67614555358887,133,1,0,0,1,0.468902587890625,34.2131004333496,1,1,1,2.99954104423523,0,742397280,2.99945998191833,,,,,,,,,,,,,,,,,,,,,,,,,,,,,,,,,