File: demonstration_data/vsm/plots/plot_data/000_MA2937-3_210926_Qrod_IP_buchner_standard_001_MH_300K_plt_emu_dat.csv
Magnetic Field (T),Moment (emu),M. Std. Err. (emu),Moment (emu)_lin-part,Moment (emu)_y-lin-subtract
6.9999859375,-0.0004284939250903,8.7313852274617e-07,-0.0004299006979789391,1.4067728886391225e-06
6.99998125,-0.0004283849115463,8.71064457532464e-07,-0.00042990041009842916,1.5154985521291606e-06
5.587530859375001,-0.0003415780662196,1.11419048448536e-06,-0.00034315546314969643,1.5773969300964322e-06
4.4600453125,-0.0002724444754112,9.66864255001652e-07,-0.0002739114921059719,1.467016694771926e-06
3.5600796875,-0.000217031780903,6.25345531924626e-07,-0.0002186405453070803,1.6087644040802917e-06
2.841728125,-0.000172799770013,4.42763859431968e-07,-0.0001745233369483297,1.7235669353297066e-06
2.268308984375,-0.0001375750526139,3.20021543948488e-07,-0.0001393070820886504,1.7320294747504158e-06
1.8105941406250001,-0.0001093748916668,2.54176866444292e-07,-0.00011119674978793699,1.821858121136996e-06
1.4452660156250001,-8.68487043385587e-05,1.99151366714133e-07,-8.87603024391687e-05,1.9115981006100026e-06
1.15361455078125,-6.89324384702125e-05,1.64850184348979e-07,-7.08486709841365e-05,1.9162325139239944e-06
0.9208375976562501,-5.46249135927262e-05,1.35732302140136e-07,-5.655278874732331e-05,1.92787515459711e-06
0.7350306152343751,-4.31938360973448e-05,1.06575193066285e-07,-4.514154418973029e-05,1.947708092385494e-06
0.5867341796875001,-3.40982985844552e-05,8.80936684847161e-08,-3.603399144339446e-05,1.935692858939263e-06
0.46834609375,-2.68436186444266e-05,7.38375262676355e-08,-2.8763245297424526e-05,1.919626652997925e-06
0.37385517578125,-2.10787194237559e-05,6.16199123061052e-08,-2.296013198403634e-05,1.8814125602804409e-06
0.298408447265625,-1.64962647563053e-05,5.26103877658377e-08,-1.8326608211461657e-05,1.8303434551563554e-06
0.23819189453125,-1.28627268468063e-05,4.54819612384601e-08,-1.4628438203474638e-05,1.7657113566683378e-06
0.190158239746094,-9.99113112082058e-06,3.97808996674413e-08,-1.1678474888835054e-05,1.6873437680144744e-06
0.151777954101562,-7.72336030246933e-06,3.4305770795356e-08,-9.3213684982602e-06,1.5980081957908704e-06
0.12115811767578101,-5.95074597390754e-06,3.06536088701426e-08,-7.440866284544975e-06,1.4901203106374352e-06
0.0967235961914062,-4.56213069227525e-06,2.82306701754031e-08,-5.940232149747599e-06,1.3781014574723489e-06
0.0772218505859375,-3.50707080954009e-06,4.50686440494758e-08,-4.7425420225881535e-06,1.2354712130480636e-06
0.0616371398925781,-2.63526607173962e-06,2.4512155477056e-08,-3.785414670519806e-06,1.150148598780186e-06
0.0492162322998047,-1.99632251763258e-06,2.30779221268587e-08,-3.0225907318231166e-06,1.0262682141905366e-06
0.0392831878662109,-1.47572280346787e-06,2.24262131023523e-08,-2.4125576870163333e-06,9.368348835484632e-07
0.031364477539062505,-1.08264853051424e-06,2.16947052033933e-08,-1.9262339819218715e-06,8.435854514076315e-07
0.025031959533691403,-7.7699198255746e-07,2.13948178847958e-08,-1.5373254991363322e-06,7.603335165788722e-07
0.0199936737060547,-5.4724674764392e-07,1.98845972213611e-08,-1.2279016498232898e-06,6.806549021793698e-07
0.0159772720336914,-3.61343276672905e-07,1.92400874194754e-08,-9.812363139598547e-07,6.198930372869497e-07
0.012730049133300801,-2.13663101029852e-07,1.93516551478141e-08,-7.818097145587592e-07,5.681466135289072e-07
0.0101857566833496,-1.13308363888333e-07,1.92892674495771e-08,-6.255532434940177e-07,5.122448796056847e-07
0.00815056838989258,-2.42043000802287e-08,1.89726162059533e-08,-5.005631541298933e-07,4.7635885404966465e-07
0.00651039505004883,4.84962181688379e-08,1.88347848894914e-08,-3.9983271411173783e-07,4.4832893228057573e-07
0.00520512657165527,9.76785856813641e-08,1.88903699617407e-08,-3.1967029165525706e-07,4.173488773366212e-07
0.0041501163482666,1.3281243491456e-07,1.87443023518787e-08,-2.548773570037786e-07,3.8768979191833865e-07
0.0033294166564941403,1.68408606858766e-07,1.82929863621318e-08,-2.0447448855886173e-07,3.7288309541762773e-07
0.00265838088989258,2.03365144694068e-07,1.8028340111267e-08,-1.6326315656383323e-07,3.6662830125790123e-07
0.0021296487808227503,2.20333777845961e-07,1.78690682512632e-08,-1.307913337969755e-07,3.511251116429365e-07
0.0016978305816650401,2.35743587645186e-07,1.8302254059361e-08,-1.0427143120354147e-07,3.4001501884872747e-07
0.00136660642623901,2.47269930481514e-07,1.79959326792888e-08,-8.392946239438842e-08,3.3119939287590244e-07
0.00111512136459351,2.60215869698642e-07,1.82327720889725e-08,-6.848463086215693e-08,3.2870050056079895e-07
0.000889398288726807,2.73283963056426e-07,1.783401633149e-08,-5.462195903231818e-08,3.279059220887442e-07
0.000711518621444702,2.78490955327802e-07,1.76291572577208e-08,-4.369756664016012e-08,3.221885219679621e-07
0.0005778021812438961,2.80596022385643e-07,1.83403449876383e-08,-3.548543714635204e-08,3.1608145953199504e-07
0.000455126571655273,2.87356213059798e-07,1.78777685392805e-08,-2.795137484136746e-08,3.1530758790116546e-07
0.000371707153320313,2.94308489345119e-07,1.79073761142974e-08,-2.2828212239700248e-08,3.171367015848192e-07
0.00029442150592804003,2.96614070871563e-07,1.78321238057517e-08,-1.8081752167587804e-08,3.1469582303915084e-07
0.00026252582073211703,2.96657648896178e-07,1.84313465061213e-08,-1.6122894328347492e-08,3.127805432245255e-07
0.00021590909957885704,3.00486944662741e-07,1.80956690520553e-08,-1.3259951296717147e-08,3.137468959594582e-07
0.000186466932296753,2.99649868113014e-07,1.83284695683064e-08,-1.1451775054993202e-08,3.111016431680072e-07
-8.58729302883148e-05,3.1140937541084e-07,1.80707626572499e-08,5.273843833124603e-09,3.061355315777154e-07
-0.000103047525882721,3.11379785342805e-07,1.78219317125537e-08,6.328613185443925e-09,3.050511721573611e-07
-0.000144757235050201,3.13680104119917e-07,1.80741240580877e-08,8.890194486277533e-09,3.0478990963363947e-07
-0.000180333161354065,3.1632192536286e-07,1.79455395405982e-08,1.107507252543837e-08,3.052468528374216e-07
-0.00022940340042114298,3.17828670958751e-07,1.73642293100211e-08,1.4088697154585024e-08,3.03739973804166e-07
-0.00029810175895690904,3.15146843684732e-07,1.73936571529926e-08,1.830777309962627e-08,2.9683907058510576e-07
-0.00040237603187561003,3.23149570583162e-07,1.77041366804774e-08,2.471172635171035e-08,2.984378442314517e-07
-0.000522598171234131,3.25726452106421e-07,1.78867702447861e-08,3.209510998765061e-08,2.936313421187704e-07
-0.000645273733139038,3.27622973712134e-07,1.80607340306159e-08,3.962916936416319e-08,2.8799380434797083e-07
-0.0008194731712341311,3.35392196425855e-07,1.78196836635271e-08,5.032754228851873e-08,2.8506465413733626e-07
-0.0010292484283447299,3.40124418894537e-07,1.76474722671836e-08,6.321078666297328e-08,2.769136322315637e-07
-0.00129790802001953,3.49222155578774e-07,1.76384523039518e-08,7.97103835208753e-08,2.695117720578987e-07
-0.0016340393066406201,3.61758235850519e-07,1.79486298061662e-08,1.0035372138200447e-07,2.6140451446851453e-07
-0.00206463069915771,3.77578257252676e-07,1.74545377730748e-08,1.2679828024820866e-07,2.5077997700446735e-07
-0.0025933626174926803,3.91542097356428e-07,1.79390616404321e-08,1.592700913011787e-07,2.3227200605524928e-07
-0.00327298583984375,4.07411299621223e-07,1.79397867552688e-08,2.0100881767293014e-07,2.0640248194829285e-07
-0.00408877830505371,4.35733438289685e-07,1.78307025572215e-08,2.5111031120892644e-07,1.8462312708075854e-07
-0.00512661399841309,4.67932903359329e-07,1.81951123243509e-08,3.14848480534735e-07,1.5308442282459398e-07
-0.00641961517333984,5.07314872118319e-07,1.76710028280353e-08,3.9425751257446517e-07,1.1305735954385385e-07
-0.008061014556884771,5.68556134076427e-07,1.74289173819461e-08,4.950632494642996e-07,7.349288461212735e-08
-0.0101207382202148,6.33282714381115e-07,1.72908809681688e-08,6.215601665174729e-07,1.1722547863642075e-08
-0.012683432769775401,7.31222066169589e-07,1.64341782042332e-08,7.789467934906683e-07,-4.7724727321079275e-08
-0.015892626953125,8.54593556659662e-07,1.60920487899432e-08,9.760378779142852e-07,-1.2144432125462314e-07
-0.0199372421264648,1.02574853363661e-06,1.53819282148389e-08,1.224435932081803e-06,-1.9868739844519302e-07
-0.024979211425781304,1.24307265102948e-06,1.77903123156058e-08,1.5340859999987499e-06,-2.9101334896926994e-07
-0.03130068359375,1.52574789008141e-06,1.60989228936102e-08,1.922316108105904e-06,-3.965682180244939e-07
-0.0392083557128906,1.92023104652849e-06,1.3724153976928e-08,2.407961907077502e-06,-4.877308605490117e-07
-0.0491389465332031,2.40566081509534e-06,1.26034140424754e-08,3.017844264429822e-06,-6.121834493344821e-07
-0.0615598571777344,3.06442719432656e-06,1.22856845493367e-08,3.780668390548724e-06,-7.16241196222164e-07
-0.0771273864746094,3.90741392099707e-06,1.0748913272351e-08,4.736740555591434e-06,-8.293266345943635e-07
-0.09664508056640621,4.99087430372618e-06,9.017449977900861e-09,5.935410151204869e-06,-9.44535847478689e-07
-0.12109924316406201,6.38701895819575e-06,1.58974859886137e-08,7.437250535326741e-06,-1.0502315771309913e-06
-0.151719079589844,8.13711698791334e-06,5.56051540578649e-09,9.317752749042028e-06,-1.1806357611286878e-06
-0.190076062011719,1.0377149092133e-05,9.572488815257982e-09,1.1673427983643877e-05,-1.2962788915108773e-06
-0.23812934570312502,1.32145763672653e-05,1.50962823819553e-08,1.4624596797919144e-05,-1.410020430653844e-06
-0.298347119140625,1.68110605836555e-05,2.41359608432859e-08,1.832284177478898e-05,-1.511781191133482e-06
-0.37377668457031304,2.13742237346209e-05,3.54400749340701e-08,2.2955311484871302e-05,-1.5810877502504022e-06
-0.46826020507812505,2.71024680512908e-05,4.88148505282841e-08,2.8757970486829587e-05,-1.6555024355387885e-06
-0.58663974609375,3.43222658298415e-05,6.64970626845509e-08,3.602819185061981e-05,-1.7059260207783123e-06
-0.734969287109375,4.34098903259895e-05,8.57047548562301e-08,4.5137777753057614e-05,-1.7278874270681152e-06
-0.9207873046875,5.479918958283e-05,1.12322586115464e-07,5.654970002935129e-05,-1.750510446521289e-06
-1.1535384765625,6.9064074790102e-05,1.44043621285669e-07,7.08439989233594e-05,-1.779924133257397e-06
-1.4451728515625,8.69603317606951e-05,1.85787714073546e-07,8.875458081403218e-05,-1.7942490533370798e-06
-1.8105142578125002,0.0001094060407999,2.4478736011664e-07,0.00011119184382424552,-1.7858030243455165e-06
-2.2682416015625,0.0001375089622323,3.17777170364427e-07,0.00013930294380631896,-1.7939815740189663e-06
-2.8416419921875002,0.0001728393255965,4.35937360248419e-07,0.0001745180471439582,-1.6787215474581957e-06
-3.5600171875,0.0002169832559861,6.19668951604419e-07,0.0002186367069002801,-1.6534509141800783e-06
-4.459991015625,0.0002723168061766,9.69056637054247e-07,0.0002739081574900643,-1.5913513134642736e-06
-5.587451171875,0.0003415854054305,1.15975810273666e-06,0.00034315056918102617,-1.5651637505261894e-06
-6.999971875,0.0004281535360619,8.70506208929655e-07,0.0004298998343374091,-1.746298275509062e-06
-5.58752265625,0.0003414250423764,1.10270811789925e-06,0.00034315495935880385,-1.7299169824038646e-06
-4.460042578125,0.000272195666482,9.83509426663185e-07,0.0002739113241756744,-1.7156576936744306e-06
-3.5600835937500004,0.000216921052724,6.31042436382925e-07,0.0002186407852075053,-1.7197324835053162e-06
-2.841712109375,0.0001727212792988,4.32024597201949e-07,0.00017452235335658713,-1.8010740577871433e-06
-2.26831875,0.0001374263816891,3.28581296334157e-07,0.00013930768183971295,-1.8813001506129325e-06
-1.810596484375,0.0001092722314293,2.54615320957458e-07,0.00011119689372819198,-1.9246622988919755e-06
-1.4452598632812501,8.67618304613321e-05,2.01375598891357e-07,8.875992459599931e-05,-1.9980941346672143e-06
-1.153612109375,6.89008280025514e-05,1.60418562154482e-07,7.084852104637085e-05,-1.9476930438194496e-06
-0.9208314453125,5.45676383792869e-05,1.30919816176746e-07,5.655241090415392e-05,-1.9847725248670203e-06
-0.735033056640625,4.31466148123567e-05,1.05508549693144e-07,4.5141694127495926e-05,-1.9950793151392245e-06
-0.58673544921875,3.40632266834261e-05,8.90525315829132e-08,3.6034069411032587e-05,-1.9708427276064853e-06
-0.4683375,2.68012861895495e-05,7.40880157687233e-08,2.8762717516489498e-05,-1.961431326939999e-06
-0.37385148925781203,2.10351926224561e-05,6.10120438788195e-08,2.295990557801021e-05,-1.9247129555541087e-06
-0.298419482421875,1.6470132592071e-05,5.12733115837109e-08,1.8327285930162315e-05,-1.857153338091315e-06
-0.23819189453125,1.28276300509673e-05,4.42061157462191e-08,1.4628438203474638e-05,-1.8008081525073385e-06
-0.19015703125,9.96519339803023e-06,3.86792248822349e-08,1.1678400669641051e-05,-1.7132072716108215e-06
-0.151780407714844,7.70070306031477e-06,3.53252502554638e-08,9.321519185714705e-06,-1.6208161253999348e-06
-0.121160571289062,5.93133241974075e-06,3.08908869808546e-08,7.4410169719994195e-06,-1.5096845522586695e-06
-0.09671132812500001,4.54235222896875e-06,2.97445926911926e-08,5.939478712475301e-06,-1.3971264835065513e-06
-0.0771960876464844,3.45425352629327e-06,2.70768179202791e-08,4.740959804316322e-06,-1.2867062780230524e-06
-0.0616248718261719,2.6156058688136e-06,2.49824209578508e-08,3.7846612332475075e-06,-1.1690553644339077e-06
-0.0492174591064453,1.98087949888723e-06,2.4055121396815e-08,3.0226660755503454e-06,-1.0417865766631153e-06
-0.0392795074462891,1.4602476545624e-06,2.32601576944631e-08,2.4123316558346475e-06,-9.520840012722474e-07
-0.031366931152343805,1.06038636014694e-06,2.20963037041679e-08,1.926384669376335e-06,-8.659983092293951e-07
-0.025033186340332,7.56670927252445e-07,2.17151928026923e-08,1.5374008428635607e-06,-7.807299156111156e-07
-0.019980178833007803,5.19963306792381e-07,2.07014198890205e-08,1.2270728688237568e-06,-7.071095620313758e-07
-0.015978498840332,3.40175401976197e-07,2.02253915167545e-08,9.813116576870831e-07,-6.411362557108862e-07
-0.012769305419921901,2.00237111159653e-07,2.05985290530292e-08,7.842206201190209e-07,-5.839835089593679e-07
-0.0101906639099121,9.1224201276278e-08,1.96747231752881e-08,6.258546184029383e-07,-5.346304171266603e-07
-0.008146887969970701,1.39610088126352e-08,1.97782948841266e-08,5.003371229482026e-07,-4.863761141355675e-07
-0.0065079421997070305,-4.86710569028022e-08,1.98617271810376e-08,3.996820735128291e-07,-4.483531304156313e-07
-0.00520144653320313,-9.74334667612241e-08,1.86217080295293e-08,3.1944428390134304e-07,-4.168777506625671e-07
-0.0041439823150634806,-1.48267359663898e-07,1.90457537777049e-08,2.5450063836762823e-07,-4.0276799803152624e-07
-0.0033294166564941403,-1.88455286701944e-07,1.90792014729192e-08,2.0447448855886173e-07,-3.929297752608057e-07
-0.00265715408325195,-2.21319620424185e-07,2.07489593477448e-08,1.631878128366028e-07,-3.845074332607878e-07
-0.00213332901000977,-2.29867868960322e-07,1.85430654663551e-08,1.3101735326477853e-07,-3.608852222251005e-07
-0.0017162319183349599,-2.48773865547299e-07,1.83120799361799e-08,1.0540154025644182e-07,-3.5417540580374085e-07
-0.00136537961959839,-2.58680233597992e-07,1.89393781822698e-08,8.385411866715857e-08,-3.425343522651506e-07
-0.00108935947418213,-2.72941076109648e-07,1.83938216611831e-08,6.690247701670727e-08,-3.3984355312635527e-07
-0.00088449125289917,-2.80451154019822e-07,1.86672006556826e-08,5.4320595837285504e-08,-3.347717498571075e-07
-0.00070661153793335,-2.88410982943802e-07,1.84494373882192e-08,4.3396200516655506e-08,-3.318071834604575e-07
-0.0005790289402008061,-2.86464019354681e-07,1.83993771003629e-08,3.556077794511026e-08,-3.220247972997913e-07
-0.000457580089569092,-2.96103296064936e-07,1.82902354866257e-08,2.8102056438883832e-08,-3.242053525038198e-07
-0.000374160647392273,-2.99256755354922e-07,1.86868860890342e-08,2.2978892372980555e-08,-3.222356477279025e-07
-0.000306689047813416,-3.00289168823637e-07,1.87029233017406e-08,1.883515722669747e-08,-3.1912432605033444e-07
-0.000245351243019104,-3.02901148827629e-07,1.84943833899125e-08,1.5068126074205152e-08,-3.179692749018341e-07
-0.00021345558166503903,-3.09491407688569e-07,1.88365502644175e-08,1.3109269699200838e-08,-3.2260067738776984e-07
-0.00016806560754776002,-3.09423280503181e-07,1.87266853830076e-08,1.0321666734210707e-08,-3.197449472373917e-07
-0.000133716428279877,-3.09371343837381e-07,1.83902402205817e-08,8.212128761690085e-09,-3.1758347259907105e-07
0.00010427428483963,-3.1586700938705e-07,1.83983715390207e-08,-6.403953984202079e-09,-3.094630554028479e-07
0.00015211777687072802,-3.21298300875979e-07,1.80833157776062e-08,-9.34223854670858e-09,-3.119560623292704e-07
0.000185240185260773,-3.20567334906054e-07,1.8498112609084e-08,-1.1376434988353047e-08,-3.0919089991770097e-07
0.00023185691833496098,-3.22315731425546e-07,1.85287542385457e-08,-1.4239378752101332e-08,-3.0807635267344465e-07
0.00031650309562683104,-3.2479289043674e-07,1.8123871074476e-08,-1.9437882152526765e-08,-3.0535500828421325e-07
0.000408509826660156,-3.34692647400567e-07,1.86208451270695e-08,-2.5088430345501176e-08,-3.0960421705506584e-07
0.000520144605636597,-3.32954787396151e-07,1.81812653159611e-08,-3.194442546166231e-08,-3.010103619344887e-07
0.0006465005397796631,-3.34816593455814e-07,1.8848066989171e-08,-3.9704513091393344e-08,-2.9511208036442065e-07
0.0008047520637512211,-3.40624603145244e-07,1.79613111910871e-08,-4.9423452703420765e-08,-2.912011504418232e-07
0.00103047523498535,-3.53255904181969e-07,1.83297206292726e-08,-6.328613039020313e-08,-2.8996977379176587e-07
0.0013015884399414101,-3.54658089179684e-07,1.82847872754587e-08,-7.993641470256607e-08,-2.7472167447711793e-07
0.00164017314910889,-3.70447177969524e-07,1.87477098572022e-08,-1.0073042830426778e-07,-2.697167496652562e-07
0.0020707645416259803,-3.86031928783473e-07,1.84765691748227e-08,-1.27174987170472e-07,-2.5885694161300097e-07
0.0025933626174926803,-4.01257206867988e-07,1.790102073051e-08,-1.592700913011787e-07,-2.4198711556680933e-07
0.00326685180664063,-4.19474889253882e-07,1.8149659002415e-08,-2.006320990367797e-07,-2.1884279021710233e-07
0.00409123191833496,-4.40398431148682e-07,1.8412400113831e-08,-2.5126099866338674e-07,-1.8913743248529526e-07
0.00512784080505371,-4.76927466121748e-07,1.83249696789347e-08,-3.1492382426196486e-07,-1.6200364185978314e-07
0.006441696929931641,-4.89595413270223e-07,2.75689696434392e-08,-3.956136528090563e-07,-9.39817604611667e-08
0.00806469573974609,-5.70745340317001e-07,1.74544994153505e-08,-4.952893275015412e-07,-7.545601281545974e-08
0.0101133781433105,-6.46206824350963e-07,1.76586463314601e-08,-6.211081510096436e-07,-2.5098673341319374e-08
0.0126772979736328,-7.42002257866208e-07,1.71305324509509e-08,-7.785700279989644e-07,3.65677701327564e-08
0.0158950805664062,-8.70668252935012e-07,1.68564144767104e-08,-9.761885653687424e-07,1.055203124337304e-07
0.0199163864135742,-1.01696669289889e-06,1.89845971573926e-08,-1.223155088718892e-06,2.0618839582000198e-07
0.0249877990722656,-1.24540452206899e-06,1.80617131501698e-08,-1.534613406089356e-06,2.89208884020366e-07
0.0313068206787109,-1.55064355799221e-06,1.74973484067171e-08,-1.922693014164259e-06,3.7204945617204895e-07
0.0392218505859375,-1.93111595235772e-06,1.37514503976742e-08,-2.4087906880770353e-06,4.776747357193152e-07
0.0491426300048828,-2.41509493803227e-06,1.50216179393381e-08,-3.01807048303372e-06,6.029755450014502e-07
0.0615598571777344,-3.07355720377969e-06,1.26330950798712e-08,-3.780668390548724e-06,7.07111186769034e-07
0.0771396606445313,-3.92356935408753e-06,1.25417231127093e-08,-4.73749436770815e-06,8.139250136206201e-07
0.0966647094726563,-5.00215256383672e-06,1.02205551183274e-08,-5.936615650840558e-06,9.344630870038385e-07
0.121082067871094,-6.38069947862701e-06,6.672420313563131e-09,-7.436195723145564e-06,1.0554962445185542e-06
0.151720300292969,-8.11809550861547e-06,2.64956610741986e-08,-9.317827717924844e-06,1.1997322093093737e-06
0.19007115478515602,-1.03634894177028e-05,2.56740384872985e-08,-1.1673126608734926e-05,1.3096371910321263e-06
0.23814895019531301,-1.32460327204492e-05,1.64226259317775e-08,-1.4625800798177201e-05,1.3797680777280011e-06
0.298344653320313,-1.68270966716708e-05,2.51830719649343e-08,-1.8322690337645723e-05,1.4955936659749221e-06
0.373780322265625,-2.13825737461425e-05,3.471879002155e-08,-2.295553489214206e-05,1.572961145999559e-06
0.468258984375,-2.71172711702733e-05,4.78392128005991e-08,-2.875789551794677e-05,1.6406243476734703e-06
0.586645849609375,-3.43441929476615e-05,6.4422510538163e-08,-3.602856669503389e-05,1.6843737473723922e-06
0.734968017578125,-4.34067407865607e-05,8.44670767301462e-08,-4.513769978541948e-05,1.7309589988587844e-06
0.9207982421875001,-5.47985790074254e-05,1.11841242738164e-07,-5.6550371750541326e-05,1.751792743115927e-06
1.1535434570312502,-6.90878084289976e-05,1.4268724861667e-07,-7.08443047964013e-05,1.7564963674036968e-06
1.4451728515625,-8.69748598412367e-05,1.88469996013508e-07,-8.875458081403218e-05,1.7797209727954736e-06
1.8105142578125002,-0.0001094380929191,2.39025685498096e-07,-0.00011119184382424552,1.7537509051455128e-06
2.268246484375,-0.0001375835037506,3.13336418178735e-07,-0.00013930324368185024,1.719739931250238e-06
2.841645703125,-0.0001728549416482,4.24131433216414e-07,-0.00017451827504936197,1.663333401161985e-06
3.560016015625,-0.0002169690660235,6.0906802012381e-07,-0.0002186366349301526,1.667568906652591e-06
4.459975,-0.0002723323238471,9.55191110423513e-07,-0.00027390717389832173,1.57485005122175e-06
5.587457421875,-0.0003415293458499,1.15576202082762e-06,-0.00034315095302170617,1.6216071718061498e-06
6.999951562500001,-0.0004282884617995,8.61303618447458e-07,-0.0004298985868551991,1.6101250556991198e-06
6.99997734375,-0.0004282669230389,8.72269370128969e-07,-0.0004299001701980041,1.6332471591041261e-06