File: demonstration_data/squid/plots/plot_data/000_MA2936-3_211005_Qrod_IP_buchner_standard_002_MH_2K_FC_plt_emu_dat.csv
Magnetic Field (T),Moment (emu),M. Std. Err. (emu),Moment (emu)_lin-part,Moment (emu)_y-lin-subtract
6.999965625000001,-0.0003817944522146,8.30753817113606e-07,-0.0003965753390941875,1.4780886879587501e-05
6.999959375,-0.0003817896973492,8.26062029310716e-07,-0.00039657498500732447,1.4785287658124495e-05
5.58753359375,-0.0003012743530455,1.01189435171623e-06,-0.00031655555874841456,1.5281205702914573e-05
4.460055078125,-0.0002374868931411,9.48260262551178e-07,-0.000252679505834884,1.5192612693783972e-05
3.56008828125,-0.0001870026700047,6.0064690443994e-07,-0.00020169287864780933,1.4690208643109337e-05
2.8417267578125003,-0.0001471688425404,4.06320999735949e-07,-0.00016099489811316297,1.3826055572762957e-05
2.26829921875,-0.0001157922157708,3.06476487006843e-07,-0.00012850799275787326,1.2715776987073262e-05
1.8105927734375,-9.11940847303756e-05,2.38668054298821e-07,-0.00010257713845379945,1.1383053723423858e-05
1.44524404296875,-7.18181186039282e-05,1.8182310210062e-07,-8.187870871354264e-05,1.0060590109614435e-05
1.15361455078125,-5.66083038238247e-05,1.52191889804399e-07,-6.535676118553267e-05,8.748457361707973e-06
0.9208547851562501,-4.46145366929858e-05,1.19872023831221e-07,-5.2170013146292415e-05,7.555476453306616e-06
0.7350306152343751,-3.5172899859077e-05,9.72663829509179e-08,-4.16423495624211e-05,6.469449703344104e-06
0.5867244140625,-2.76907802061067e-05,8.0881420605043e-08,-3.3240225156344876e-05,5.549444950238178e-06
0.46834609375,-2.17615246550646e-05,6.85137164313162e-08,-2.653363186227709e-05,4.772107207212489e-06
0.37384414062500004,-1.70555854700106e-05,5.56537908532612e-08,-2.117972784141129e-05,4.124142371400693e-06
0.29840107421875,-1.33170176967496e-05,4.72997996020098e-08,-1.690558404626031e-05,3.5885663495107105e-06
0.238218896484375,-1.03469211702069e-05,4.14974603892364e-08,-1.349602908256198e-05,3.1491079123550804e-06
0.190154577636719,-7.98090695147497e-06,3.61985975076272e-08,-1.0772998061200312e-05,2.792091109725341e-06
0.151779187011719,-6.09688592672232e-06,3.20183581599763e-08,-8.59888259188595e-06,2.50199666516363e-06
0.12116425781250001,-4.60166622062054e-06,2.92744577730624e-08,-6.864427513254787e-06,2.2627612926342468e-06
0.09672849731445311,-3.41902462586331e-06,2.64635837577099e-08,-5.4800464284494885e-06,2.0610218025861785e-06
0.0772206237792969,-2.48224264260319e-06,2.45541811771925e-08,-4.374849349397962e-06,1.8926067067947717e-06
0.061640820312500004,-1.72838555989064e-06,2.58345128218493e-08,-3.4921927516570577e-06,1.7638071917664177e-06
0.049222366333007805,-1.16061850983325e-06,2.18720312366198e-08,-2.7886389255705647e-06,1.6280204157373146e-06
0.0392782806396484,-6.8437130020073e-07,2.09256281703572e-08,-2.2252677081832415e-06,1.5408964079825113e-06
0.031363250732421896,-3.18424445389035e-07,2.06099163944085e-08,-1.7768504105055853e-06,1.4584259651165502e-06
0.025029507446289102,-1.06009194067005e-08,2.12589886500083e-08,-1.4180191638973357e-06,1.4074182444906351e-06
0.0200108474731445,2.27744472801546e-07,2.21927038776133e-08,-1.1336925132720696e-06,1.3614369860736155e-06
0.0159613250732422,4.08439034395157e-07,1.81857033073662e-08,-9.042712839484238e-07,1.3127103183435808e-06
0.012760718536377,5.55678310103151e-07,1.80509680529689e-08,-7.229444474092246e-07,1.2786227575123755e-06
0.010193116760253902,6.81200829029992e-07,1.74142182074932e-08,-5.774797980703421e-07,1.258680627100334e-06
0.00813830108642578,7.68045052050725e-07,1.73281284894631e-08,-4.610664803085941e-07,1.2291115323593191e-06
0.00651530227661133,8.14097864602577e-07,3.2141912475224e-08,-3.691172711506379e-07,1.1832151357532148e-06
0.00520144653320313,9.05853013192577e-07,1.71762560055172e-08,-2.946822217695272e-07,1.2005352349621042e-06
0.00414888954162598,9.53733622566087e-07,1.71393034383121e-08,-2.3505076524352946e-07,1.1887843878096165e-06
0.0033232826232910202,9.90084324317424e-07,1.70643994892737e-08,-1.8827691503663023e-07,1.1783612393540544e-06
0.0026547004699707002,1.02778675908784e-06,1.67743643366873e-08,-1.5039912986317405e-07,1.178185888951014e-06
0.00213210220336914,1.04975334594466e-06,1.64495159708466e-08,-1.2079190092945362e-07,1.1705452468741135e-06
0.0016990573883056603,1.06998042040792e-06,1.64402652998127e-08,-9.625822411203651e-08,1.1662386445199566e-06
0.00136537961959839,1.08720382863811e-06,1.69256096725254e-08,-7.735407781156414e-08,1.1645579064496741e-06
0.00109794683456421,1.09818070220963e-06,1.62080619862453e-08,-6.220296806453123e-08,1.1603836702741613e-06
0.000891851711273193,1.12004420875121e-06,1.91431302152049e-08,-5.052687595446555e-08,1.1705710847056754e-06
0.000709065103530884,1.12435721414184e-06,1.66367633781779e-08,-4.01713021087322e-08,1.1645285162505722e-06
0.000566761350631714,1.12922291807958e-06,1.65595847983776e-08,-3.210923979533852e-08,1.1613321578749186e-06
0.000475981426239014,1.13740992452205e-06,1.63616769535852e-08,-2.6966203210929617e-08,1.1643761277329797e-06
0.00035821280479431204,1.13867273507495e-06,1.66522175917126e-08,-2.0294151734378592e-08,1.1589668868093285e-06
0.00029810175895690904,1.13866096967352e-06,1.66673899582795e-08,-1.6888626669921673e-08,1.1555495963434415e-06
0.000252711772918701,1.14613526558586e-06,1.63678192726662e-08,-1.431710702698303e-08,1.160452372612843e-06
0.00021958935260772702,1.14800430621115e-06,1.63923347520832e-08,-1.2440592802465717e-08,1.1604448990136157e-06
0.00016929235458374,1.14843446831502e-06,1.64078353255971e-08,-9.591071802599046e-09,1.158025540117619e-06
-8.58729302883148e-05,1.15878060430656e-06,1.63150951195812e-08,4.865036240531532e-09,1.1539155680660286e-06
-0.00011408833265304601,1.15701436415293e-06,1.84377379373771e-08,6.4635487704373095e-09,1.1505508153824928e-06
-0.00015211777687072802,1.16655245159607e-06,1.63624437859207e-08,8.618065027249745e-09,1.1579343865688203e-06
-0.000176652884483337,1.16717131786879e-06,1.64661165976057e-08,1.0008074513358156e-08,1.157163243355432e-06
-0.000228176665306091,1.16710606822669e-06,1.61265183738737e-08,1.292709754087456e-08,1.1541789706858153e-06
-0.000322636866569519,1.17336617252136e-06,1.67259773321946e-08,1.8278636156030137e-08,1.1550875363653298e-06
-0.00041832385063171395,1.17734059156694e-06,1.62503854444607e-08,2.369967679883545e-08,1.1536409147681045e-06
-0.0005164643764495849,1.17915681242555e-06,1.63524105667528e-08,2.9259720146206035e-08,1.149897092279344e-06
-0.0006465005397796631,1.18483427720907e-06,1.64226785001626e-08,3.662677569044421e-08,1.1482075015186259e-06
-0.000814566135406494,1.191961774364e-06,1.65966590553409e-08,4.614834681612771e-08,1.1458134275478721e-06
-0.00103660898208618,1.20295830552173e-06,1.66107602321425e-08,5.872793962169026e-08,1.1442303659000398e-06
-0.0013089488983154302,1.21468023932413e-06,1.60509772522552e-08,7.415705747932224e-08,1.1405231818448078e-06
-0.0016475336074829102,1.22139663806852e-06,1.64671197280344e-08,9.333920108452032e-08,1.1280574369839997e-06
-0.00205604343414307,1.24429296387846e-06,1.64514024107206e-08,1.1648287516949994e-07,1.1278100887089602e-06
-0.00260195007324219,1.25933711572848e-06,1.64364882088671e-08,1.474106142631475e-07,1.1119265014653324e-06
-0.0032742126464843802,1.28900491640369e-06,1.61960810018325e-08,1.854969095717552e-07,1.103508006831935e-06
-0.004101045989990231,1.3115184696026e-06,1.63695154188831e-08,2.3234024154529093e-07,1.0791782280573092e-06
-0.00512784080505371,1.35372647790603e-06,1.61029999532759e-08,2.905121703487203e-07,1.0632143075573097e-06
-0.00643310928344727,1.40945470552115e-06,1.53882200588249e-08,3.6446071769289103e-07,1.044993987828259e-06
-0.008067148590087891,1.47222013702823e-06,1.54596220534014e-08,4.5703541403280845e-07,1.0151847229954216e-06
-0.0101096984863281,1.55372441752914e-06,1.58881172973407e-08,5.72753827681198e-07,9.80970589847942e-07
-0.0126822052001953,1.64868423862657e-06,1.68194156175699e-08,7.184963608631319e-07,9.301878777634381e-07
-0.015912255859375002,1.78267535300616e-06,1.52313070912546e-08,9.014913217070423e-07,8.811840312991177e-07
-0.0199151596069336,1.95214852835254e-06,1.52358329113284e-08,1.1282714226521014e-06,8.238771057004386e-07
-0.0249828903198242,2.16455830927242e-06,1.3972633891893e-08,1.415378121965731e-06,7.49180187306689e-07
-0.0312847351074219,2.422705493947e-06,1.4882132233831e-08,1.772402194289014e-06,6.503032996579857e-07
-0.0392243041992188,2.79240953633607e-06,1.290450544859e-08,2.22220973242833e-06,5.701998039077401e-07
-0.049152441406250004,3.23842117250053e-06,1.2059930739599e-08,2.7846774058966575e-06,4.537437666038724e-07
-0.0615708923339844,3.74964216897862e-06,7.24489164179871e-08,3.488231059089175e-06,2.6141110988944527e-07
-0.0771273864746094,4.54800940517893e-06,9.746354548986341e-09,4.369567092640782e-06,1.78442312538148e-07
-0.0966401733398438,5.46307811128567e-06,8.23236402231727e-09,5.475042530993802e-06,-1.1964419708132089e-08
-0.121090649414062,6.6388468404817e-06,6.9703334109842506e-09,6.860257310551722e-06,-2.2141047007002186e-07
-0.151726440429687,8.10972069327067e-06,5.3587220517389406e-09,8.59589429240335e-06,-4.861735991326802e-07
-0.19006870117187502,9.97672545188725e-06,7.79739136677736e-09,1.0768132824713424e-05,-7.914073728261746e-07
-0.23811953125000002,1.23207514307261e-05,1.30512200203699e-08,1.3490399654700836e-05,-1.1696482239747366e-06
-0.298355688476562,1.5259672879645e-05,2.1297736279194e-08,1.690301276704803e-05,-1.6433398874030305e-06
-0.373772998046875,1.89916631172549e-05,3.13457993408828e-08,2.1175697337040925e-05,-2.184034219786023e-06
-0.46828349609375003,2.36825134049646e-05,4.45435207653545e-08,2.653008546103975e-05,-2.8475720560751495e-06
-0.5866421875000001,2.95887559112013e-05,6.03326876653278e-08,3.3235566701053396e-05,-3.6468107898520953e-06
-0.734969287109375,3.70583256832801e-05,8.15869260556478e-08,4.163887508507781e-05,-4.580549401797711e-06
-0.9207921875,4.64810792927257e-05,1.03043929478063e-07,5.216646674505507e-05,-5.685387452329366e-06
-1.15356796875,5.84226356485777e-05,1.32359760138836e-07,6.53541221318818e-05,-6.931486483304092e-06
-1.44517158203125,7.36105062976066e-05,1.75104847104191e-07,8.18746035189746e-05,-8.264097221368001e-06
-1.8105400390625002,9.29339514109463e-05,2.25176790755035e-07,0.00010257415084589281,-9.640199434946513e-06
-2.2682441406250002,0.0001174500241503,2.95126289540383e-07,0.000128504872367393,-1.1054848217092992e-05
-2.84164453125,0.0001488014333767,4.01944690819393e-07,0.00016099023965787147,-1.2188806281171466e-05
-3.5600132812500003,0.0001886024613421,5.91489963433839e-07,0.0002016886296054532,-1.3086168263353191e-05
-4.459973828125,0.000238970374537,9.44941629104946e-07,0.0002526749027056648,-1.3704528168664826e-05
-5.587451171875,0.0003023342095005,1.08337987324632e-06,0.0003165508892279086,-1.4216679727408637e-05
-6.99996796875,0.0003825537308621,8.11803018316533e-07,0.00039657547187676106,-1.4021741014661057e-05
-5.58753359375,0.0003024600723704,1.05415312582343e-06,0.00031655555874841456,-1.4095486378014571e-05
-4.460053515625,0.0002387230131806,9.5020965227327e-07,0.0002526794173131682,-1.3956404132568203e-05
-3.560084765625,0.0001883100045715,6.04370658142988e-07,0.00020169267947394887,-1.3382674902448884e-05
-2.8417083984375,0.0001485343243556,4.13791474684056e-07,0.00016099385798300285,-1.2459533627402856e-05
-2.2682968750000003,0.0001172662069005,3.14644448987209e-07,0.00012850785997529964,-1.1241653074799639e-05
-1.810596484375,9.2635373852417e-05,2.40263197681719e-07,0.00010257734869287437,-9.941974840457372e-06
-1.4452402343750002,7.329505421025e-05,1.91110075279132e-07,8.18784929418605e-05,-8.583438731610499e-06
-1.1536390625000001,5.81124007726656e-05,1.5701714381456e-07,6.535814986994854e-05,-7.245749097282945e-06
-0.920836328125,4.61076983948933e-05,1.22567447877943e-07,5.216896748352508e-05,-6.061269088631784e-06
-0.7350256835937501,3.66764217649939e-05,1.00611039983463e-07,4.164207016575576e-05,-4.9656484007618585e-06
-0.586732958984375,2.91916778083482e-05,8.13781820604783e-08,3.32407092594779e-05,-4.049031451129696e-06
-0.46833134765625,2.32599051395023e-05,6.93466340020496e-08,2.653279643858467e-05,-3.2728912990823726e-06
-0.373850268554687,1.85511471881789e-05,5.88503897839535e-08,2.118007501251523e-05,-2.6289278243363285e-06
-0.298420727539063,1.48077751149923e-05,4.93865099695965e-08,1.690669748346629e-05,-2.098922368473992e-06
-0.238204150390625,1.18369967035988e-05,4.19107770423095e-08,1.3495193658869565e-05,-1.6581969552707657e-06
-0.19013372802734402,9.47134374303289e-06,3.7500256371211e-08,1.0771816849555738e-05,-1.3004731065228482e-06
-0.15179636230468702,7.5882468007421e-06,3.32303643544234e-08,8.599855639183284e-06,-1.0116088384411837e-06
-0.12115567626953101,6.09759905797804e-06,2.9650590368329e-08,6.863941335394037e-06,-7.663422774159971e-07
-0.09671991577148441,4.90795573840539e-06,2.70039043767501e-08,5.479560250588756e-06,-5.716045121833657e-07
-0.0771875,3.96959858048846e-06,2.56191400193098e-08,4.372972758181594e-06,-4.033741776931339e-07
-0.06164818115234371,3.23465876831481e-06,2.40543966560104e-08,3.492609771927359e-06,-2.5795100361254896e-07
-0.049212548828125,2.65501914177141e-06,2.26096600844029e-08,2.7880827256495175e-06,-1.3306358387810739e-07
-0.0392880950927734,2.17680439323944e-06,2.14880587454488e-08,2.225823735210313e-06,-4.901934197087302e-08
-0.0313485290527344,1.80974489727171e-06,2.10574885501922e-08,1.7760163699649785e-06,3.372852730673162e-08
-0.0250442276000977,1.50542583229638e-06,1.96582170645155e-08,1.4188531179909548e-06,8.657271430542511e-08
-0.0200120742797852,1.27688176498901e-06,1.92878720327305e-08,1.133762016650458e-06,1.431197483385521e-07
-0.0159613250732422,1.08148656098171e-06,1.85965572829454e-08,9.042712839484238e-07,1.7721527703328619e-07
-0.012761944580078101,9.38419480288402e-07,1.82974814979802e-08,7.230139075641104e-07,2.154055727242916e-07
-0.0101894371032715,8.1899436562742e-07,1.87180751340459e-08,5.772713311586855e-07,2.4172303446873445e-07
-0.008129713439941412,7.37830843160605e-07,1.83615524713778e-08,4.605799566599069e-07,2.7725088650069807e-07
-0.00651039505004883,6.5632979973804e-07,1.83049061888913e-08,3.688392576371022e-07,2.874905421009378e-07
-0.00519776649475098,5.93335105660876e-07,1.8238607038273e-08,2.944737332461223e-07,2.988613724147537e-07
-0.00412680816650391,5.42011465460286e-07,1.81643759779242e-08,2.337997692678598e-07,3.0821169619242623e-07
-0.00333064308166504,5.02048044141496e-07,1.83699886935748e-08,1.8869391369518655e-07,3.133541304463095e-07
-0.00265592727661133,4.6651091455745e-07,1.79252004432426e-08,1.5046863324155822e-07,3.160422813158918e-07
-0.00213087558746338,4.44181951461991e-07,1.7463905942634e-08,1.207224083569433e-07,3.234595431050477e-07
-0.00171745872497559,4.18087385515725e-07,1.74298652130694e-08,9.730073156430186e-08,3.207866539514231e-07
-0.00136415300369263,4.06705233788011e-07,1.75144745407412e-08,7.728458523905382e-08,3.294206485489572e-07
-0.00110530729293823,3.935225927734e-07,1.84612231934921e-08,6.261996672308757e-08,3.309026260503124e-07
-0.000886944770812988,3.86549383015976e-07,1.77831233900352e-08,5.024887864974009e-08,3.363005043662359e-07
-0.000702931308746338,3.77431225970905e-07,1.79306295784578e-08,3.982379872415444e-08,3.3760742724675054e-07
-0.0005827092170715331,3.72948375821054e-07,1.73690113871788e-08,3.301274859524067e-08,3.3993562722581335e-07
-0.0004723011493682861,3.61621690838417e-07,1.75369266707415e-08,2.675770118018294e-08,3.3486398965823405e-07
-0.00037048037052154505,3.58677880526896e-07,1.75659295647992e-08,2.0989157152799867e-08,3.3768872337409615e-07
-0.000323863649368286,3.57784054335187e-07,1.76839633300058e-08,1.8348138183679873e-08,3.394359161515071e-07
-0.000268659615516663,3.53205421216358e-07,1.78227652101157e-08,1.522061447615104e-08,3.3798480674020693e-07
-0.00021836261749267602,3.54521337720557e-07,1.62016521973065e-08,1.237109347628437e-08,3.421502442442726e-07
-0.000184013426303864,3.52844435671157e-07,1.66182042008717e-08,1.0425077899484419e-08,3.424193577716726e-07
-0.000149664258956909,3.45924772081585e-07,1.7811842329103e-08,8.479063673418607e-09,3.374457084081664e-07
0.000110408055782318,3.34225034944348e-07,1.58828302670223e-08,-6.2550467396906284e-09,3.4048008168403863e-07
0.000137396705150604,3.35473721727226e-07,1.79927721644531e-08,-7.784058930364372e-09,3.4325778065759033e-07
0.00016929235458374,3.32440962037137e-07,1.58141164224511e-08,-9.591071802599046e-09,3.420320338397361e-07
0.000234310436248779,3.30108144669729e-07,1.7874927795314e-08,-1.3274599574718127e-08,3.4338274424444714e-07
0.000303008770942688,3.25215503306181e-07,1.6922735925251e-08,-1.71666280268497e-08,3.423821313330307e-07
0.000398695755004883,3.25253548219324e-07,1.6395667715078e-08,-2.258766866965501e-08,3.47841216888979e-07
0.000510330581665039,3.19200076367288e-07,1.71931598894877e-08,-2.8912216761628277e-08,3.4811229312891626e-07
0.000651407527923584,3.11302597193796e-07,1.68512646319692e-08,-3.6904775696638035e-08,3.4820737289043403e-07
0.000825606918334961,3.09381476496047e-07,1.7985905867277e-08,-4.677385020689931e-08,3.561553267029463e-07
0.0010353822708129901,2.99935427689975e-07,1.57998903294023e-08,-5.8658441646243284e-08,3.585938693362183e-07
0.0013089488983154302,2.81777345255206e-07,1.73998297466831e-08,-7.415705747932224e-08,3.559344027345282e-07
0.0016254520416259801,2.76546977119722e-07,1.63240282106267e-08,-9.208819430297736e-08,3.6863517142269935e-07
0.00207321796417236,2.5787485283622e-07,1.75037494642116e-08,-1.1745587924338052e-07,3.7533073207960047e-07
0.0025835485458373998,2.3593674365992e-07,1.71435047826716e-08,-1.4636809600500883e-07,3.823048396649288e-07
0.0032521305084228505,2.1191151180488e-07,1.55805095200971e-08,-1.8424587037259116e-07,3.961573821774712e-07
0.00408141784667969,1.88517448279428e-07,1.88643208803035e-08,-2.3122823071464246e-07,4.1974567899407043e-07
0.00512784080505371,1.42742528409661e-07,1.72668980160926e-08,-2.905121703487203e-07,4.332546987583813e-07
0.006425749206542971,8.99691300026979e-08,1.58200938651005e-08,-3.640437406460813e-07,4.540128706487792e-07
0.008067148590087891,2.34795288622429e-08,1.54025221388049e-08,-4.5703541403280845e-07,4.805149428950513e-07
0.010107244873046902,-4.74826468116075e-08,1.65622157551377e-08,-5.726148209244331e-07,5.251321741128256e-07
0.012683432769775401,-1.5262949384077e-07,1.55470542049624e-08,-7.185659074650111e-07,5.659364136242411e-07
0.0158987609863281,-2.83882406676525e-07,2.72836453039885e-08,-9.007267845448176e-07,6.168443778682925e-07
0.0199163864135742,-4.50295108954017e-07,1.51289659330229e-08,-1.1283409260304842e-06,6.780458170764672e-07
0.024957127380371102,-6.54846195501808e-07,1.55405385054561e-08,-1.4139185510196702e-06,7.590723555178622e-07
0.0313068206787109,-9.42399239830428e-07,1.45631799900583e-08,-1.7736534279938974e-06,8.312541881634695e-07
0.0392120361328125,-1.27880598701819e-06,1.37806648285557e-08,-2.221514698644488e-06,9.427087116262979e-07
0.0491426300048828,-1.72987120120278e-06,1.2494357586676e-08,-2.7841215517635613e-06,1.0542503505607812e-06
0.0615659851074219,-2.30527863694297e-06,1.28758355936748e-08,-3.4879530455756395e-06,1.1826744086326693e-06
0.0771261596679688,-3.06144112631507e-06,3.89197955407603e-08,-4.3694975892624005e-06,1.3080564629473306e-06
0.09667207031250001,-3.96489723460637e-06,8.80569260260737e-09,-5.476849618831781e-06,1.5119523842254109e-06
0.121098010253906,-5.13335347140998e-06,6.4153145053670605e-09,-6.8606743308220405e-06,1.7273208594120603e-06
0.151712939453125,-6.61334103917633e-06,5.42261553775973e-09,-8.595129409453204e-06,1.9817883702768732e-06
0.19006870117187502,-8.4748473601276e-06,7.431263350441211e-09,-1.0768132824713424e-05,2.2932854645858244e-06
0.23811953125000002,-1.08270554604905e-05,1.59789511478976e-08,-1.3490399654700836e-05,2.6633441942103356e-06
0.298336083984375,-1.37657849396069e-05,2.14300130173561e-08,-1.690190209614572e-05,3.136117156538821e-06
0.373766870117188,-1.74962105764573e-05,3.20951685104565e-08,-2.1175350165936987e-05,3.679139589479688e-06
0.46826264648437504,-2.21939290266377e-05,4.55192939730634e-08,-2.6528904249395174e-05,4.3349752227574746e-06
0.586665478515625,-2.81085228855008e-05,6.01206878142626e-08,-3.323688622787883e-05,5.1283633423780275e-06
0.734969287109375,-3.55743732714871e-05,7.96393923877743e-08,-4.163887508507781e-05,6.06450181359071e-06
0.92077861328125,-4.50006579627613e-05,1.0760811563658e-07,-5.216569771264947e-05,7.165039749888172e-06
1.1535458984375,-5.69378738063013e-05,1.36045988485231e-07,-6.535287176264679e-05,8.414997956345488e-06
1.44519736328125,-7.21359956254148e-05,1.72447032543324e-07,-8.187606412728452e-05,9.74006850186973e-06
1.810519140625,-9.14614403052668e-05,2.16381961693251e-07,-0.00010257296686794461,1.1111526562677815e-05
2.268221875,-0.0001160152139104,2.93283395014276e-07,-0.0001285036109329435,1.2488397022543496e-05
2.84164453125,-0.0001473308468734,4.05075808552998e-07,-0.00016099023965787147,1.3659392784471465e-05
3.560005078125,-0.0001870757542084,5.74559583064439e-07,-0.0002016881648664455,1.4612410658045494e-05
4.45998515625,-0.0002375939929395,9.42261255494657e-07,-0.000252675544488104,1.508155154860403e-05
5.587457421875,-0.0003011990216909,1.02781906232664e-06,-0.00031655124331477164,1.535222162387165e-05
6.999951562500001,-0.0003813710346809,8.00692534026924e-07,-0.0003965745423987457,1.5203507717845722e-05
6.99995078125,-0.0003812688118215,7.72242286546283e-07,-0.0003965744981378878,1.53056863163878e-05