File: demonstration_data/squid/plots/plot_data/000_MA2937-3_210926_Qrod_IP_buchner_standard_002_MH_2K_FC_plt_emu_dat.csv
Magnetic Field (T),Moment (emu),M. Std. Err. (emu),Moment (emu)_lin-part,Moment (emu)_y-lin-subtract
6.99997421875,-0.0004116189514725,8.71875829687273e-07,-0.000428802736736823,1.718378526432301e-05
6.999972656250001,-0.0004116233643508,8.75203757805699e-07,-0.0004288026410215739,1.7179276670773944e-05
5.587527343750001,-0.0003244216238329,1.15308272954498e-06,-0.0003422794058546805,1.7857782021780478e-05
4.4600437500000005,-0.0002553464547128,9.86383526025535e-07,-0.00027321228710289143,1.7865832390091417e-05
3.560084765625,-0.000200682309601,6.34621459297265e-07,-0.00021808281613752494,1.7400506536524953e-05
2.8417230468750003,-0.000157457606135,4.38376128055531e-07,-0.00017407758678369823,1.661998064869823e-05
2.2682882812500003,-0.0001234303447501,3.23683302468802e-07,-0.0001389502578599143,1.5519913109814294e-05
1.810596484375,-9.66983515753828e-05,2.58220135609804e-07,-0.000110913083872002,1.42147322966192e-05
1.44525751953125,-7.57746026992583e-05,2.05154893058337e-07,-8.853323745171435e-05,1.2758634752456057e-05
1.1536231445312501,-5.93400204648741e-05,1.64641467313805e-07,-7.066836906526137e-05,1.1328348600387262e-05
0.92084736328125,-4.64553640692992e-05,1.31339810576052e-07,-5.6409046255373035e-05,9.953682186073836e-06
0.7350453125,-3.63672942697395e-05,1.05562928844274e-07,-4.502722892625987e-05,8.659934656520365e-06
0.586720703125,-2.83894481272779e-05,8.7453937218538e-08,-3.594119568701491e-05,7.551747559737013e-06
0.46832280273437504,-2.20808145991777e-05,7.24733770472071e-08,-2.868840558738798e-05,6.60759098821028e-06
0.373828198242188,-1.71300540949263e-05,6.04815615381402e-08,-2.2899877837588758e-05,5.769823742662459e-06
0.29841335449218803,-1.31928233451819e-05,5.05958122187014e-08,-1.8280133481393894e-05,5.087310136211994e-06
0.238220092773438,-1.01039654399441e-05,4.39050159883524e-08,-1.4592829135475176e-05,4.4888636955310766e-06
0.190153332519531,-7.68824185511492e-06,3.86274270210439e-08,-1.1648367099066614e-05,3.960125243951694e-06
0.151790222167969,-5.78778141853934e-06,3.54710843336511e-08,-9.298328914008258e-06,3.510547495468918e-06
0.12115198974609401,-4.30838109665519e-06,3.09426124772704e-08,-7.4214994428241625e-06,3.1131183461689722e-06
0.0967051940917969,-3.16320867047678e-06,2.7929854994371e-08,-5.92394351569956e-06,2.76073484522278e-06
0.07720099487304691,-2.26702424654601e-06,2.60235416320844e-08,-4.729159972003355e-06,2.462135725457345e-06
0.0616543151855469,-1.58038068548853e-06,2.47287116023592e-08,-3.7768052077080623e-06,2.1964245222195324e-06
0.0492039642333984,-1.07036524772916e-06,2.32427526497988e-08,-3.014124604211706e-06,1.943759356482546e-06
0.0392930023193359,-6.56563817185105e-07,2.28381312989547e-08,-2.4070012835199153e-06,1.7504374663348103e-06
0.031374291992187504,-3.38657471905879e-07,2.20180354138944e-08,-1.921918831271437e-06,1.583261359365558e-06
0.0250393203735352,-1.04413281182735e-07,2.0984631388187e-08,-1.5338526638344246e-06,1.4294393826516895e-06
0.019985086059570303,7.6121035194081e-08,1.96484762590977e-08,-1.224241594106182e-06,1.300362629300263e-06
0.0159527374267578,2.16785441816363e-07,1.97538832502436e-08,-9.772289516030852e-07,1.194014393419448e-06
0.012750904083252001,3.08362648014391e-07,4.14690817668694e-08,-7.810918148986489e-07,1.0894544629130398e-06
0.010199251556396501,4.10730204555526e-07,1.89867781629301e-08,-6.247832982492184e-07,1.0355135028047443e-06
0.00814320831298828,4.74136055473775e-07,1.85940093438051e-08,-4.988346958584892e-07,9.729707513322643e-07
0.006505488586425781,5.12595264114611e-07,2.00385403941551e-08,-3.9851165482830595e-07,9.11106918942917e-07
0.00519285926818848,5.48445778567428e-07,1.86797748518692e-08,-3.1810292382562873e-07,8.665487023930567e-07
0.00415870361328125,5.92642999430773e-07,1.86548929998476e-08,-2.547528654999469e-07,8.473958649307199e-07
0.00333064308166504,6.15853205562929e-07,1.82238379148665e-08,-2.0402773265735965e-07,8.198809382202886e-07
0.0026645145416259804,6.41699898134494e-07,1.83183247821661e-08,-1.6322219079948407e-07,8.049220889339781e-07
0.00212719535827637,6.54990191432321e-07,1.78793917194631e-08,-1.3030722152654703e-07,7.85297412958868e-07
0.0017064178466796901,6.6156909930576e-07,1.854693262677e-08,-1.045313339458944e-07,7.661004332516544e-07
0.0013580190658569302,6.75202837595642e-07,1.82630534362371e-08,-8.318920524313331e-08,7.583920428387753e-07
0.00110285387039185,6.83717483623158e-07,1.83335059670958e-08,-6.755835708338804e-08,7.512758407065461e-07
0.000874677181243896,6.88943361346072e-07,1.90966230199689e-08,-5.358076435110195e-08,7.425241256971739e-07
0.00069925103187561,6.96880151127021e-07,1.79007496963198e-08,-4.283455149465568e-08,7.397147026216767e-07
0.000576575422286987,6.9842474664732e-07,1.76659351344808e-08,-3.5319718514048914e-08,7.337444651613689e-07
0.00046862087249755906,6.9927188204988e-07,1.84026401874235e-08,-2.8706664673235675e-08,7.279785467231156e-07
0.000369253611564636,7.08548408162787e-07,1.8183423261732e-08,-2.2619648907385015e-08,7.311680570701721e-07
0.000323863649368286,7.0892434024431e-07,1.8048197325171e-08,-1.9839161522439842e-08,7.287635017667499e-07
0.000257618808746338,7.12312464924009e-07,1.75272490779172e-08,-1.5781151011872777e-08,7.280936159358818e-07
0.00021345558166503903,7.12172835780675e-07,1.79538798805668e-08,-1.3075810671494717e-08,7.252486464521697e-07
0.000182786679267883,7.1274236271735e-07,1.81318255480279e-08,-1.119710242634301e-08,7.23939465143693e-07
-7.23786175251007e-05,7.19178540508532e-07,1.78632637085146e-08,4.433751940522597e-09,7.147447885680095e-07
-0.00010427428483963,7.22390669094701e-07,1.76404052255059e-08,6.387609055864904e-09,7.160030600388361e-07
-0.000153344523906708,7.25495089537866e-07,1.82413143164045e-08,9.393541956007876e-09,7.161015475818581e-07
-0.000191373956203461,7.22023905956548e-07,1.7838533108528e-08,1.1723139771056315e-08,7.103007661854917e-07
-0.000246578001976013,7.24882917665191e-07,1.78171719775056e-08,1.510481592677825e-08,7.097781017384128e-07
-0.000301782035827637,7.30499293029531e-07,1.80732175518943e-08,1.848649135225084e-08,7.120128016772801e-07
-0.000412190103530884,7.29277784727731e-07,1.77989564442213e-08,2.5249842203195968e-08,7.040279425245351e-07
-0.000510330581665039,7.31316998956372e-07,1.79111951099311e-08,3.1261708003481847e-08,7.000552909528901e-07
-0.0006465005397796631,7.34920641405724e-07,1.76360090052802e-08,3.9603174539813776e-08,6.953174668659102e-07
-0.0008231534004211429,7.38571673846951e-07,1.79617238783176e-08,5.042453298032841e-08,6.881471408666225e-07
-0.00103170204162598,7.46333885003763e-07,1.7500342341325e-08,6.319975547355482e-08,6.831341295302082e-07
-0.0013015884399414101,7.50574827691216e-07,1.76844227260363e-08,7.973239153608685e-08,6.708424361551291e-07
-0.0016340393066406201,7.5978521249715e-07,1.75982320426918e-08,1.0009758675199243e-07,6.596876257451577e-07
-0.00205358982086182,7.69033368966485e-07,1.77912008650734e-08,1.2579831122259167e-07,6.432350577438934e-07
-0.0025970428466796903,7.74780216049226e-07,1.78577758681475e-08,1.590890259418558e-07,6.156911901073701e-07
-0.0032680786132812502,7.90768984510489e-07,1.76990597963946e-08,2.001951735039855e-07,5.905738110065035e-07
-0.00408019142150879,8.09962642019636e-07,1.76769767154488e-08,2.4994338454370856e-07,5.600192574759275e-07
-0.0051511497497558605,8.28023429837136e-07,1.77270661929845e-08,3.1554789217937275e-07,5.124755376577633e-07
-0.00643801651000977,8.20567197089292e-07,1.74569436542589e-08,3.9437846660269736e-07,4.261887304865947e-07
-0.00806469573974609,8.63577967120682e-07,1.69142872331634e-08,4.940251915342699e-07,3.6955277558641206e-07
-0.010118285369873,9.15552983260661e-07,1.73073848353067e-08,6.198234910728684e-07,2.9572949218779263e-07
-0.012690792846679701,9.76231984102243e-07,1.65093358802329e-08,7.774095352294189e-07,1.9882244887282416e-07
-0.015892626953125,1.06812186228762e-06,1.61721218732799e-08,9.735467186698196e-07,9.457514361780047e-08
-0.0199200668334961,1.18290862511759e-06,1.59209131995786e-08,1.2202586619967395e-06,-3.735003687914955e-08
-0.0249902496337891,1.33834493009407e-06,1.70170916887765e-08,1.5308467002638065e-06,-1.9250177016973643e-07
-0.031308047485351605,1.55048012175533e-06,1.75286128314399e-08,1.9178608412078556e-06,-3.6738071945252556e-07
-0.0392144897460937,1.85058837985463e-06,1.34903020560117e-08,2.4021917791956955e-06,-5.516033993410655e-07
-0.0491377197265625,2.23081595992847e-06,1.3105764216062e-08,3.0100666141481245e-06,-7.792506542196545e-07
-0.061577032470703105,2.73628406045038e-06,1.38212997256813e-08,3.7720710417537498e-06,-1.03578698130337e-06
-0.0771322937011719,3.40592716116869e-06,1.07674777346329e-08,4.724951492143798e-06,-1.3190243309751077e-06
-0.09666348266601561,4.27650169850259e-06,9.786581598937362e-09,5.9213883672133985e-06,-1.6448866687108085e-06
-0.12108575439453101,5.41146998950076e-06,2.12329945718586e-08,7.4174420135920855e-06,-2.0059720240913255e-06
-0.151720300292969,6.866878757536e-06,5.51291043131571e-09,9.29404565661033e-06,-2.4271668990743294e-06
-0.190076062011719,8.74414455504345e-06,8.731291144057091e-09,1.1643633680887718e-05,-2.8994891258442676e-06
-0.238126879882813,1.11560598988679e-05,1.52778327411501e-08,1.4587119122645117e-05,-3.431059223777217e-06
-0.29835937500000004,1.42214808673356e-05,2.38678067299474e-08,1.827682681864707e-05,-4.0553459513114696e-06
-0.373780322265625,1.81274129220306e-05,3.50509503313362e-08,2.2896945062533794e-05,-4.7695321405031926e-06
-0.468288427734375,2.30806241762974e-05,5.05142503106012e-08,2.8686299851907433e-05,-5.605675675610034e-06
-0.5866581542968751,2.93686179173552e-05,6.54992359625033e-08,3.593736408594875e-05,-6.5687461685935525e-06
-0.734990087890625,3.73208911471938e-05,8.6985593828419e-08,4.502384599042393e-05,-7.702954843230133e-06
-0.9207946289062501,4.74298381396506e-05,1.11632017268e-07,5.640581586571538e-05,-8.975977726064778e-06
-1.15357646484375,6.02489907691765e-05,1.47945706486196e-07,7.066550957219403e-05,-1.0416518803017524e-05
-1.4451764648437502,7.66403379658026e-05,1.92485636422837e-07,8.852827222316648e-05,-1.1887934257363885e-05
-1.810515625,9.74999491390756e-05,2.40692739765705e-07,0.00011090813060786026,-1.3408181468784665e-05
-2.2682427734375,0.0001242416378849,3.12763551601654e-07,0.0001389474701532838,-1.4705832268383797e-05
-2.8416470703125003,0.0001582083184651,4.27459556608264e-07,0.00017407293262970997,-1.5864614164609966e-05
-3.560016015625,0.0002014402726068,6.16325129959849e-07,0.00021807860466656386,-1.6638332059763853e-05
-4.4599730468750005,0.0002560593393067,9.75457016511867e-07,0.0002732079559878689,-1.7148616681168945e-05
-5.587447265625,0.0003250977363808,1.15759298213494e-06,0.0003422745004481633,-1.7176764067363347e-05
-6.9999484375000005,0.0004118414452172,9.02822530592172e-07,0.00042880115743521263,-1.6959712218012632e-05
-5.587521484375,0.0003248849740916,1.15317285739841e-06,0.0003422790469224963,-1.7394072830896265e-05
-4.46006015625,0.0002556617185718,9.63467361405538e-07,0.0002732132921130071,-1.7551573541207076e-05
-3.560084765625,0.0002011383201774,6.32751194790152e-07,0.00021808281613752494,-1.694449596012493e-05
-2.8417171875,0.0001579781208535,4.39035609873953e-07,0.00017407722785151402,-1.6099106998014015e-05
-2.2682978515625,0.0001239506090675,3.28898334028852e-07,0.0001389508441158151,-1.5000235048315106e-05
-1.8106001953125002,9.72331250135781e-05,2.50595530156935e-07,0.00011091331119571865,-1.368018618214055e-05
-1.4452427734375,7.63558261021864e-05,2.0685126398614e-07,8.853233413905082e-05,-1.2176508036864422e-05
-1.15361572265625,5.99748503366714e-05,1.60562323299724e-07,7.066791441782806e-05,-1.0693064081156655e-05
-0.92083876953125,4.71152068327459e-05,1.30257946592206e-07,5.640851982150289e-05,-9.29331298875699e-06
-0.735033056640625,3.69706003504034e-05,1.07676301966116e-07,4.502647815977461e-05,-8.055877809371208e-06
-0.5867255859375,2.90218112726871e-05,9.14825967623064e-08,3.5941494797168394e-05,-6.919683524481294e-06
-0.46833623046875,2.2696412367761e-05,7.42048312972162e-08,2.8689228140310065e-05,-5.992815772549067e-06
-0.373828198242188,1.77205842776925e-05,6.17027449362891e-08,2.2899877837588758e-05,-5.17929355989626e-06
-0.298412133789063,1.37934055051937e-05,5.32246770113746e-08,1.8280058703855522e-05,-4.486653198661822e-06
-0.23820046386718702,1.06974011670216e-05,4.59769614593793e-08,1.45916267126581e-05,-3.894225545636499e-06
-0.190158239746094,8.25755211303456e-06,4.04136948958642e-08,1.1648667704770896e-05,-3.391115591736336e-06
-0.151787768554687,6.37572016725784e-06,3.57864042158743e-08,9.298178611156084e-06,-2.9224584438982442e-06
-0.12115076904296901,4.88600624410577e-06,3.14495492852205e-08,7.421424665285791e-06,-2.535418421180021e-06
-0.0967101013183594,3.73443240787136e-06,4.88792545421514e-08,5.924244121403814e-06,-2.189811713532454e-06
-0.07721448974609371,2.84636249810794e-06,2.81532185606136e-08,4.729986637690049e-06,-1.883624139582109e-06
-0.06164327392578121,2.18457403433586e-06,2.4485401204805e-08,3.7761288448734864e-06,-1.5915548105376265e-06
-0.049202737426757806,1.64297550839283e-06,2.33167925117784e-08,3.0140494527856443e-06,-1.3710739443928143e-06
-0.0392770538330078,1.24261539844783e-06,2.14090878242196e-08,2.4060243149810914e-06,-1.1634089165332613e-06
-0.031350979614257805,9.32798965024066e-07,2.26534997503542e-08,1.9204907672323836e-06,-9.876918022083176e-07
-0.025036868286132802,6.86998933730268e-07,2.13452043711727e-08,1.5337024544542172e-06,-8.467035207239493e-07
-0.0199777252197266,5.02893424657033e-07,2.06568100648273e-08,1.2237906855498038e-06,-7.208972608927708e-07
-0.015983406066894502,3.71869012253966e-07,1.9973849567834e-08,9.791076437827492e-07,-6.072386315287832e-07
-0.0127570381164551,2.58356752153356e-07,1.89612293803487e-08,7.814675720289649e-07,-5.231108198756089e-07
-0.0101955703735352,1.88162083407665e-07,1.75550773390794e-08,6.245577972350681e-07,-4.363957138274031e-07
-0.008134620666503911,1.30752884682425e-07,2.32627131249802e-08,4.98308635876045e-07,-3.6755575119362007e-07
-0.00647604598999023,6.32224566675855e-08,1.76103574354855e-08,3.9670806733874286e-07,-3.3348561067115737e-07
-0.00520144653320313,2.71540135747569e-08,1.87420918853301e-08,3.1862896044009267e-07,-2.914749468653358e-07
-0.00414766273498535,-5.28097229266737e-09,1.86801573116594e-08,2.540765260333559e-07,-2.593574983260233e-07
-0.00333064308166504,-2.31565116712261e-08,1.8124502942899e-08,2.0402773265735965e-07,-2.2718424432858575e-07
-0.0026632877349853502,-4.73895510129872e-08,1.78676642539215e-08,1.6314703937342023e-07,-2.1053659038640743e-07
-0.00213332901000977,-5.5203834196493e-08,2.01623961241755e-08,1.3068295528888395e-07,-1.8588678948537696e-07
-0.0017039644241333002,-6.67326494414119e-08,1.75657966340087e-08,1.0438104277775754e-07,-1.7111369221916946e-07
-0.0013629261970520001,-7.93788641229163e-08,1.79041140857847e-08,8.34898051053923e-08,-1.628686692283086e-07
-0.00109181299209595,-9.03857858498472e-08,1.91210164582659e-08,6.688201761679706e-08,-1.5726780346664427e-07
-0.000886944770812988,-9.78360796904869e-08,1.92793766102989e-08,5.4332249401761196e-08,-1.521683290922481e-07
-0.000707838344573975,-1.02144818165349e-07,1.6977524266708e-08,4.336059103011718e-08,-1.455054091954662e-07
-0.0005814824581146241,-1.06025408130013e-07,1.92002580449833e-08,3.562031253431262e-08,-1.4164572066432562e-07
-0.000467394113540649,-1.08930841137894e-07,1.7107405216531e-08,2.8631516168169695e-08,-1.375623573060637e-07
-0.00036066632270813,-1.09607428223978e-07,1.93386941794437e-08,2.209361083242237e-08,-1.3170103905640038e-07
-0.000291967988014221,-1.13446577292657e-07,1.771161040324e-08,1.7885304772222225e-08,-1.3133188206487923e-07
-0.000263752579689026,-1.13703520767614e-07,1.83923546180443e-08,1.61568920767036e-08,-1.298604128443176e-07
-0.00021590909957885704,-1.12548584569183e-07,1.88066049956615e-08,1.3226107681626543e-08,-1.2577469225080955e-07
-0.000186466932296753,-1.21422647359797e-07,1.82477739638858e-08,1.1422546481042005e-08,-1.32845193840839e-07
-0.000153344523906708,-1.20532845377574e-07,1.85545778943119e-08,9.393541956007876e-09,-1.2992638733358187e-07
0.00010059400796890301,-1.23329224423496e-07,1.79155581779137e-08,-6.162163540667168e-09,-1.1716706088282884e-07
0.000153344523906708,-1.2474161701835e-07,1.84557758609034e-08,-9.393541956007876e-09,-1.1534807506234212e-07
0.00018155990839004502,-1.27966591494733e-07,1.83141968469761e-08,-1.1121953191027698e-08,-1.1684463830370529e-07
0.000225723147392273,-1.2948721016882e-07,1.85735929615072e-08,-1.3827294261655159e-08,-1.1565991590716482e-07
0.000326317167282105,-1.34140428539852e-07,1.81453888410085e-08,-1.998945853257173e-08,-1.1415097000728027e-07
0.000407283067703247,-1.36547403861484e-07,1.8492736219938e-08,-2.4949248182932257e-08,-1.1159815567855175e-07
0.000515237617492676,-1.39035175018468e-07,1.85560395091135e-08,-3.1562302023745555e-08,-1.0747287299472244e-07
0.000648954010009766,-1.41201480590836e-07,1.87356754707033e-08,-3.975346862894805e-08,-1.0144801196188794e-07
0.0008096590995788571,-1.45891272036023e-07,1.85294340879776e-08,-4.959790234560081e-08,-9.629336969042218e-08
0.00103170204162598,-1.503378251958e-07,1.78924308414501e-08,-6.319975547355482e-08,-8.713806972224519e-08
0.00130281505584717,-1.57743865162966e-07,1.8527553230575e-08,-7.980753127815988e-08,-7.793633388480611e-08
0.00163771953582764,-1.61585542745634e-07,1.8469402458925e-08,-1.0032302934619312e-07,-6.126251339944089e-08
0.00205113639831543,-1.73344880075613e-07,1.83948458871333e-08,-1.256480200544548e-07,-4.76968600211582e-08
0.00259090919494629,-1.84946210520213e-07,1.85330401280988e-08,-1.5871329217951887e-07,-2.6232918340694136e-08
0.0032509040832519502,-1.97671742248524e-07,1.86864683916108e-08,-1.9914310027505756e-07,1.4713580265335473e-09
0.00409123191833496,-2.16113744536493e-07,1.86590423051639e-08,-2.506197006423186e-07,3.45059561058256e-08
0.00512538719177246,-2.37589510113626e-07,1.82829953940544e-08,-3.1396973560001955e-07,7.638022548639355e-08
0.00643801651000977,-2.68184950486535e-07,1.78981352783878e-08,-3.9437846660269736e-07,1.2619351611616235e-07
0.008076963043212891,-2.95706120153129e-07,1.7837759897964e-08,-4.947766590589439e-07,1.990705389058149e-07
0.0101146049499512,-3.51063472741585e-07,1.76077330767689e-08,-6.195980367946824e-07,2.6853456405309745e-07
0.012684659576416001,-4.17370840955343e-07,1.72697321013046e-08,-7.770338248350611e-07,3.596629838797181e-07
0.0158914001464844,-5.12902911656398e-07,1.68241968899431e-08,-9.734715672437576e-07,4.6056865558735964e-07
0.0199482833862305,-6.30968521402578e-07,1.67845413363814e-08,-1.221987144796202e-06,5.91018623393624e-07
0.0249828903198242,-7.37368897712467e-07,1.59663526485146e-08,-1.5303958851793448e-06,7.930269874668778e-07
0.031303137207031304,-9.4632578816199e-07,1.57551979963346e-08,-1.917560048559756e-06,9.712342603977661e-07
0.0392255310058594,-1.2412817718886e-06,1.42452891540881e-08,-2.4028681420302714e-06,1.1615863701416715e-06
0.04912054748535161,-1.62768379635468e-06,1.79039914407981e-08,-3.0090146811270834e-06,1.3813308847724034e-06
0.0615598571777344,-2.1146849085709e-06,1.27761240814938e-08,-3.7710189217888633e-06,1.6563340132179633e-06
0.0771408874511719,-2.78774862804854e-06,1.14091301892791e-08,-4.725477926013933e-06,1.9377292979653935e-06
0.09664753417968751,-3.65056446339215e-06,9.34222925649145e-09,-5.920411398674574e-06,2.2698469352824236e-06
0.121095556640625,-4.78191461544024e-06,7.230737884385581e-09,-7.418042477225225e-06,2.6361278617849846e-06
0.15170557861328102,-6.23072195783508e-06,1.01211946717073e-08,-9.293143839497537e-06,3.0624218816624574e-06
0.19008464355468702,-8.11948532734879e-06,9.183302910346972e-09,-1.1644159366982426e-05,3.5246740396336364e-06
0.238128100585938,-1.05319917593057e-05,1.46720267691895e-08,-1.4587193900183488e-05,4.055202140877788e-06
0.29834833984375003,-1.3593621539159e-05,2.28115614515064e-08,-1.827615082970019e-05,4.68252929054119e-06
0.37377668457031304,-1.7505962681773e-05,3.39224134842479e-08,-2.289672222546948e-05,5.390759543696477e-06
0.468258984375,-2.245359493487e-05,4.95903775807804e-08,-2.868449621768191e-05,6.230901282811908e-06
0.586659375,-2.87549809136103e-05,6.43033992643238e-08,-3.5937438863487114e-05,7.182457949876815e-06
0.734969287109375,-3.67000938156684e-05,8.58770017677934e-08,-4.5022571781170076e-05,8.322477965501676e-06
0.9207897460937501,-4.68005395893342e-05,1.10329353200755e-07,-5.640551675556189e-05,9.604977166227693e-06
1.1535642578125,-5.96476343547078e-05,1.43583618442762e-07,-7.066476179681031e-05,1.1017127442102511e-05
1.4451728515625,-7.6021052485911e-05,1.90701326159171e-07,-8.852805088165288e-05,1.2506998395741886e-05
1.8105425781250002,-9.69203071612978e-05,2.45235679510729e-07,-0.00011090978169590751,1.3989474534609718e-05
2.2682476562500002,-0.0001235499686532,3.19068547885781e-07,-0.0001389477692634373,1.5397800610237287e-05
2.8416408203125,-0.0001575084792541,4.25566021152676e-07,-0.0001740725497687135,1.656407051461349e-05
3.5600109375,-0.0002007839370183,6.17447616435175e-07,-0.00021807829359200422,1.7294356573704212e-05
4.45996796875,-0.0002554445043496,9.84342669811073e-07,-0.00027320764491330925,1.776314056370923e-05
5.587463671875001,-0.0003242583421184,1.16005802077577e-06,-0.00034227550545827903,1.8017163339879058e-05
6.999953125,-0.0004111016081896,8.79634157521682e-07,-0.00042880144458095997,1.769983639135996e-05
6.999953125,-0.0004111236173404,8.72569332628838e-07,-0.00042880144458095997,1.7677827240559975e-05